Issue while building the feature

Traceback (most recent call last):
  File "src/genie/cli/commands/learn.py", line 365, in genie.cli.commands.learn.LearnCommand._retrieve_ops
  File "/home/ipvzero/Nornir/pyATS-Network-Testing/lib/python3.10/site-packages/genie/libs/ops/device/iosxe/device.py", line 249, in learn
    self.make()
  File "/home/ipvzero/Nornir/pyATS-Network-Testing/lib/python3.10/site-packages/genie/ops/base/base.py", line 103, in make
    self.maker.make(*args, **kwargs)
  File "src/genie/ops/base/maker.py", line 315, in genie.ops.base.maker.Maker.make
  File "src/genie/ops/base/maker.py", line 427, in genie.ops.base.maker.Maker._call_parser
  File "src/genie/metaparser/_metaparser.py", line 308, in genie.metaparser._metaparser.MetaParser.parse
  File "/home/ipvzero/Nornir/pyATS-Network-Testing/lib/python3.10/site-packages/genie/libs/parser/iosxe/show_inventory.py", line 82, in cli
    name_dict['pid'] = group['pid'].replace(' ','')
UnboundLocalError: local variable 'name_dict' referenced before assignment
