2023-02-25 07:07:30,338 -  nornir.core -     INFO -        run() - Running task 'backup_configurations' with args {} on 7 hosts
2023-02-25 07:15:29,482 -  nornir.core -     INFO -        run() - Running task 'test' with args {} on 7 hosts
2023-02-25 07:15:29,484 - nornir.core.task -    ERROR -      start() - Host 'R1': task 'test' failed with traceback:
Traceback (most recent call last):
  File "/home/ipvzero/Nornir/.venv/lib/python3.10/site-packages/nornir/core/task.py", line 99, in start
    r = self.task(self, **self.params)
  File "/home/ipvzero/Nornir/Backups-Napalm/push-archive.py", line 9, in test
    task.run(send=send_configs_from_file, file='napalm-startup.txt')
TypeError: Task.run() missing 1 required positional argument: 'task'

2023-02-25 07:15:29,484 - nornir.core.task -    ERROR -      start() - Host 'R2': task 'test' failed with traceback:
Traceback (most recent call last):
  File "/home/ipvzero/Nornir/.venv/lib/python3.10/site-packages/nornir/core/task.py", line 99, in start
    r = self.task(self, **self.params)
  File "/home/ipvzero/Nornir/Backups-Napalm/push-archive.py", line 9, in test
    task.run(send=send_configs_from_file, file='napalm-startup.txt')
TypeError: Task.run() missing 1 required positional argument: 'task'

2023-02-25 07:15:29,485 - nornir.core.task -    ERROR -      start() - Host 'R5': task 'test' failed with traceback:
Traceback (most recent call last):
  File "/home/ipvzero/Nornir/.venv/lib/python3.10/site-packages/nornir/core/task.py", line 99, in start
    r = self.task(self, **self.params)
  File "/home/ipvzero/Nornir/Backups-Napalm/push-archive.py", line 9, in test
    task.run(send=send_configs_from_file, file='napalm-startup.txt')
TypeError: Task.run() missing 1 required positional argument: 'task'

2023-02-25 07:15:29,484 - nornir.core.task -    ERROR -      start() - Host 'R4': task 'test' failed with traceback:
Traceback (most recent call last):
  File "/home/ipvzero/Nornir/.venv/lib/python3.10/site-packages/nornir/core/task.py", line 99, in start
    r = self.task(self, **self.params)
  File "/home/ipvzero/Nornir/Backups-Napalm/push-archive.py", line 9, in test
    task.run(send=send_configs_from_file, file='napalm-startup.txt')
TypeError: Task.run() missing 1 required positional argument: 'task'

2023-02-25 07:15:29,484 - nornir.core.task -    ERROR -      start() - Host 'R3': task 'test' failed with traceback:
Traceback (most recent call last):
  File "/home/ipvzero/Nornir/.venv/lib/python3.10/site-packages/nornir/core/task.py", line 99, in start
    r = self.task(self, **self.params)
  File "/home/ipvzero/Nornir/Backups-Napalm/push-archive.py", line 9, in test
    task.run(send=send_configs_from_file, file='napalm-startup.txt')
TypeError: Task.run() missing 1 required positional argument: 'task'

2023-02-25 07:15:29,485 - nornir.core.task -    ERROR -      start() - Host 'R6': task 'test' failed with traceback:
Traceback (most recent call last):
  File "/home/ipvzero/Nornir/.venv/lib/python3.10/site-packages/nornir/core/task.py", line 99, in start
    r = self.task(self, **self.params)
  File "/home/ipvzero/Nornir/Backups-Napalm/push-archive.py", line 9, in test
    task.run(send=send_configs_from_file, file='napalm-startup.txt')
TypeError: Task.run() missing 1 required positional argument: 'task'

2023-02-25 07:15:29,486 - nornir.core.task -    ERROR -      start() - Host 'R7': task 'test' failed with traceback:
Traceback (most recent call last):
  File "/home/ipvzero/Nornir/.venv/lib/python3.10/site-packages/nornir/core/task.py", line 99, in start
    r = self.task(self, **self.params)
  File "/home/ipvzero/Nornir/Backups-Napalm/push-archive.py", line 9, in test
    task.run(send=send_configs_from_file, file='napalm-startup.txt')
TypeError: Task.run() missing 1 required positional argument: 'task'

2023-02-25 07:16:27,165 -  nornir.core -     INFO -        run() - Running task 'test' with args {} on 7 hosts
2023-02-25 07:16:27,605 - nornir.core.task -    ERROR -      start() - Host 'R1': task 'send_configs_from_file' failed with traceback:
Traceback (most recent call last):
  File "/home/ipvzero/Nornir/.venv/lib/python3.10/site-packages/nornir/core/task.py", line 99, in start
    r = self.task(self, **self.params)
  File "/home/ipvzero/Nornir/.venv/lib/python3.10/site-packages/nornir_scrapli/tasks/core/send_configs_from_file.py", line 58, in send_configs_from_file
    scrapli_conn = task.host.get_connection("scrapli", task.nornir.config)
  File "/home/ipvzero/Nornir/.venv/lib/python3.10/site-packages/nornir/core/inventory.py", line 494, in get_connection
    self.open_connection(
  File "/home/ipvzero/Nornir/.venv/lib/python3.10/site-packages/nornir/core/inventory.py", line 546, in open_connection
    conn_obj.open(
  File "/home/ipvzero/Nornir/.venv/lib/python3.10/site-packages/nornir_scrapli/connection.py", line 105, in open
    connection.open()
  File "/home/ipvzero/Nornir/.venv/lib/python3.10/site-packages/scrapli/driver/base/sync_driver.py", line 88, in open
    self.channel.channel_authenticate_ssh(
  File "/home/ipvzero/Nornir/.venv/lib/python3.10/site-packages/scrapli/decorators.py", line 216, in decorate
    return _multiprocessing_timeout(
  File "/home/ipvzero/Nornir/.venv/lib/python3.10/site-packages/scrapli/decorators.py", line 113, in _multiprocessing_timeout
    return future.result()
  File "/usr/lib/python3.10/concurrent/futures/_base.py", line 451, in result
    return self.__get_result()
  File "/usr/lib/python3.10/concurrent/futures/_base.py", line 403, in __get_result
    raise self._exception
  File "/usr/lib/python3.10/concurrent/futures/thread.py", line 58, in run
    result = self.fn(*self.args, **self.kwargs)
  File "/home/ipvzero/Nornir/.venv/lib/python3.10/site-packages/scrapli/channel/sync_channel.py", line 290, in channel_authenticate_ssh
    self._ssh_message_handler(output=authenticate_buf)
  File "/home/ipvzero/Nornir/.venv/lib/python3.10/site-packages/scrapli/channel/base_channel.py", line 432, in _ssh_message_handler
    raise ScrapliAuthenticationFailed(msg)
scrapli.exceptions.ScrapliAuthenticationFailed: Host key verification failed

2023-02-25 07:16:27,605 - nornir.core.task -    ERROR -      start() - Host 'R3': task 'send_configs_from_file' failed with traceback:
Traceback (most recent call last):
  File "/home/ipvzero/Nornir/.venv/lib/python3.10/site-packages/nornir/core/task.py", line 99, in start
    r = self.task(self, **self.params)
  File "/home/ipvzero/Nornir/.venv/lib/python3.10/site-packages/nornir_scrapli/tasks/core/send_configs_from_file.py", line 58, in send_configs_from_file
    scrapli_conn = task.host.get_connection("scrapli", task.nornir.config)
  File "/home/ipvzero/Nornir/.venv/lib/python3.10/site-packages/nornir/core/inventory.py", line 494, in get_connection
    self.open_connection(
  File "/home/ipvzero/Nornir/.venv/lib/python3.10/site-packages/nornir/core/inventory.py", line 546, in open_connection
    conn_obj.open(
  File "/home/ipvzero/Nornir/.venv/lib/python3.10/site-packages/nornir_scrapli/connection.py", line 105, in open
    connection.open()
  File "/home/ipvzero/Nornir/.venv/lib/python3.10/site-packages/scrapli/driver/base/sync_driver.py", line 88, in open
    self.channel.channel_authenticate_ssh(
  File "/home/ipvzero/Nornir/.venv/lib/python3.10/site-packages/scrapli/decorators.py", line 216, in decorate
    return _multiprocessing_timeout(
  File "/home/ipvzero/Nornir/.venv/lib/python3.10/site-packages/scrapli/decorators.py", line 113, in _multiprocessing_timeout
    return future.result()
  File "/usr/lib/python3.10/concurrent/futures/_base.py", line 451, in result
    return self.__get_result()
  File "/usr/lib/python3.10/concurrent/futures/_base.py", line 403, in __get_result
    raise self._exception
  File "/usr/lib/python3.10/concurrent/futures/thread.py", line 58, in run
    result = self.fn(*self.args, **self.kwargs)
  File "/home/ipvzero/Nornir/.venv/lib/python3.10/site-packages/scrapli/channel/sync_channel.py", line 290, in channel_authenticate_ssh
    self._ssh_message_handler(output=authenticate_buf)
  File "/home/ipvzero/Nornir/.venv/lib/python3.10/site-packages/scrapli/channel/base_channel.py", line 432, in _ssh_message_handler
    raise ScrapliAuthenticationFailed(msg)
scrapli.exceptions.ScrapliAuthenticationFailed: Host key verification failed

2023-02-25 07:16:27,606 - nornir.core.task -    ERROR -      start() - Host 'R1': task 'test' failed with traceback:
Traceback (most recent call last):
  File "/home/ipvzero/Nornir/.venv/lib/python3.10/site-packages/nornir/core/task.py", line 99, in start
    r = self.task(self, **self.params)
  File "/home/ipvzero/Nornir/Backups-Napalm/push-archive.py", line 9, in test
    task.run(task=send_configs_from_file, file='napalm-startup.txt')
  File "/home/ipvzero/Nornir/.venv/lib/python3.10/site-packages/nornir/core/task.py", line 174, in run
    raise NornirSubTaskError(task=run_task, result=r)
nornir.core.exceptions.NornirSubTaskError: Subtask: send_configs_from_file (failed)


2023-02-25 07:16:27,607 - nornir.core.task -    ERROR -      start() - Host 'R7': task 'send_configs_from_file' failed with traceback:
Traceback (most recent call last):
  File "/home/ipvzero/Nornir/.venv/lib/python3.10/site-packages/nornir/core/task.py", line 99, in start
    r = self.task(self, **self.params)
  File "/home/ipvzero/Nornir/.venv/lib/python3.10/site-packages/nornir_scrapli/tasks/core/send_configs_from_file.py", line 58, in send_configs_from_file
    scrapli_conn = task.host.get_connection("scrapli", task.nornir.config)
  File "/home/ipvzero/Nornir/.venv/lib/python3.10/site-packages/nornir/core/inventory.py", line 494, in get_connection
    self.open_connection(
  File "/home/ipvzero/Nornir/.venv/lib/python3.10/site-packages/nornir/core/inventory.py", line 546, in open_connection
    conn_obj.open(
  File "/home/ipvzero/Nornir/.venv/lib/python3.10/site-packages/nornir_scrapli/connection.py", line 105, in open
    connection.open()
  File "/home/ipvzero/Nornir/.venv/lib/python3.10/site-packages/scrapli/driver/base/sync_driver.py", line 88, in open
    self.channel.channel_authenticate_ssh(
  File "/home/ipvzero/Nornir/.venv/lib/python3.10/site-packages/scrapli/decorators.py", line 216, in decorate
    return _multiprocessing_timeout(
  File "/home/ipvzero/Nornir/.venv/lib/python3.10/site-packages/scrapli/decorators.py", line 113, in _multiprocessing_timeout
    return future.result()
  File "/usr/lib/python3.10/concurrent/futures/_base.py", line 451, in result
    return self.__get_result()
  File "/usr/lib/python3.10/concurrent/futures/_base.py", line 403, in __get_result
    raise self._exception
  File "/usr/lib/python3.10/concurrent/futures/thread.py", line 58, in run
    result = self.fn(*self.args, **self.kwargs)
  File "/home/ipvzero/Nornir/.venv/lib/python3.10/site-packages/scrapli/channel/sync_channel.py", line 290, in channel_authenticate_ssh
    self._ssh_message_handler(output=authenticate_buf)
  File "/home/ipvzero/Nornir/.venv/lib/python3.10/site-packages/scrapli/channel/base_channel.py", line 432, in _ssh_message_handler
    raise ScrapliAuthenticationFailed(msg)
scrapli.exceptions.ScrapliAuthenticationFailed: Host key verification failed

2023-02-25 07:16:27,607 - nornir.core.task -    ERROR -      start() - Host 'R3': task 'test' failed with traceback:
Traceback (most recent call last):
  File "/home/ipvzero/Nornir/.venv/lib/python3.10/site-packages/nornir/core/task.py", line 99, in start
    r = self.task(self, **self.params)
  File "/home/ipvzero/Nornir/Backups-Napalm/push-archive.py", line 9, in test
    task.run(task=send_configs_from_file, file='napalm-startup.txt')
  File "/home/ipvzero/Nornir/.venv/lib/python3.10/site-packages/nornir/core/task.py", line 174, in run
    raise NornirSubTaskError(task=run_task, result=r)
nornir.core.exceptions.NornirSubTaskError: Subtask: send_configs_from_file (failed)


2023-02-25 07:16:27,610 - nornir.core.task -    ERROR -      start() - Host 'R7': task 'test' failed with traceback:
Traceback (most recent call last):
  File "/home/ipvzero/Nornir/.venv/lib/python3.10/site-packages/nornir/core/task.py", line 99, in start
    r = self.task(self, **self.params)
  File "/home/ipvzero/Nornir/Backups-Napalm/push-archive.py", line 9, in test
    task.run(task=send_configs_from_file, file='napalm-startup.txt')
  File "/home/ipvzero/Nornir/.venv/lib/python3.10/site-packages/nornir/core/task.py", line 174, in run
    raise NornirSubTaskError(task=run_task, result=r)
nornir.core.exceptions.NornirSubTaskError: Subtask: send_configs_from_file (failed)


2023-02-25 07:16:27,658 - nornir.core.task -    ERROR -      start() - Host 'R2': task 'send_configs_from_file' failed with traceback:
Traceback (most recent call last):
  File "/home/ipvzero/Nornir/.venv/lib/python3.10/site-packages/nornir/core/task.py", line 99, in start
    r = self.task(self, **self.params)
  File "/home/ipvzero/Nornir/.venv/lib/python3.10/site-packages/nornir_scrapli/tasks/core/send_configs_from_file.py", line 58, in send_configs_from_file
    scrapli_conn = task.host.get_connection("scrapli", task.nornir.config)
  File "/home/ipvzero/Nornir/.venv/lib/python3.10/site-packages/nornir/core/inventory.py", line 494, in get_connection
    self.open_connection(
  File "/home/ipvzero/Nornir/.venv/lib/python3.10/site-packages/nornir/core/inventory.py", line 546, in open_connection
    conn_obj.open(
  File "/home/ipvzero/Nornir/.venv/lib/python3.10/site-packages/nornir_scrapli/connection.py", line 105, in open
    connection.open()
  File "/home/ipvzero/Nornir/.venv/lib/python3.10/site-packages/scrapli/driver/base/sync_driver.py", line 88, in open
    self.channel.channel_authenticate_ssh(
  File "/home/ipvzero/Nornir/.venv/lib/python3.10/site-packages/scrapli/decorators.py", line 216, in decorate
    return _multiprocessing_timeout(
  File "/home/ipvzero/Nornir/.venv/lib/python3.10/site-packages/scrapli/decorators.py", line 113, in _multiprocessing_timeout
    return future.result()
  File "/usr/lib/python3.10/concurrent/futures/_base.py", line 451, in result
    return self.__get_result()
  File "/usr/lib/python3.10/concurrent/futures/_base.py", line 403, in __get_result
    raise self._exception
  File "/usr/lib/python3.10/concurrent/futures/thread.py", line 58, in run
    result = self.fn(*self.args, **self.kwargs)
  File "/home/ipvzero/Nornir/.venv/lib/python3.10/site-packages/scrapli/channel/sync_channel.py", line 290, in channel_authenticate_ssh
    self._ssh_message_handler(output=authenticate_buf)
  File "/home/ipvzero/Nornir/.venv/lib/python3.10/site-packages/scrapli/channel/base_channel.py", line 432, in _ssh_message_handler
    raise ScrapliAuthenticationFailed(msg)
scrapli.exceptions.ScrapliAuthenticationFailed: Host key verification failed

2023-02-25 07:16:27,658 - nornir.core.task -    ERROR -      start() - Host 'R2': task 'test' failed with traceback:
Traceback (most recent call last):
  File "/home/ipvzero/Nornir/.venv/lib/python3.10/site-packages/nornir/core/task.py", line 99, in start
    r = self.task(self, **self.params)
  File "/home/ipvzero/Nornir/Backups-Napalm/push-archive.py", line 9, in test
    task.run(task=send_configs_from_file, file='napalm-startup.txt')
  File "/home/ipvzero/Nornir/.venv/lib/python3.10/site-packages/nornir/core/task.py", line 174, in run
    raise NornirSubTaskError(task=run_task, result=r)
nornir.core.exceptions.NornirSubTaskError: Subtask: send_configs_from_file (failed)


2023-02-25 07:16:27,659 - nornir.core.task -    ERROR -      start() - Host 'R6': task 'send_configs_from_file' failed with traceback:
Traceback (most recent call last):
  File "/home/ipvzero/Nornir/.venv/lib/python3.10/site-packages/nornir/core/task.py", line 99, in start
    r = self.task(self, **self.params)
  File "/home/ipvzero/Nornir/.venv/lib/python3.10/site-packages/nornir_scrapli/tasks/core/send_configs_from_file.py", line 58, in send_configs_from_file
    scrapli_conn = task.host.get_connection("scrapli", task.nornir.config)
  File "/home/ipvzero/Nornir/.venv/lib/python3.10/site-packages/nornir/core/inventory.py", line 494, in get_connection
    self.open_connection(
  File "/home/ipvzero/Nornir/.venv/lib/python3.10/site-packages/nornir/core/inventory.py", line 546, in open_connection
    conn_obj.open(
  File "/home/ipvzero/Nornir/.venv/lib/python3.10/site-packages/nornir_scrapli/connection.py", line 105, in open
    connection.open()
  File "/home/ipvzero/Nornir/.venv/lib/python3.10/site-packages/scrapli/driver/base/sync_driver.py", line 88, in open
    self.channel.channel_authenticate_ssh(
  File "/home/ipvzero/Nornir/.venv/lib/python3.10/site-packages/scrapli/decorators.py", line 216, in decorate
    return _multiprocessing_timeout(
  File "/home/ipvzero/Nornir/.venv/lib/python3.10/site-packages/scrapli/decorators.py", line 113, in _multiprocessing_timeout
    return future.result()
  File "/usr/lib/python3.10/concurrent/futures/_base.py", line 451, in result
    return self.__get_result()
  File "/usr/lib/python3.10/concurrent/futures/_base.py", line 403, in __get_result
    raise self._exception
  File "/usr/lib/python3.10/concurrent/futures/thread.py", line 58, in run
    result = self.fn(*self.args, **self.kwargs)
  File "/home/ipvzero/Nornir/.venv/lib/python3.10/site-packages/scrapli/channel/sync_channel.py", line 290, in channel_authenticate_ssh
    self._ssh_message_handler(output=authenticate_buf)
  File "/home/ipvzero/Nornir/.venv/lib/python3.10/site-packages/scrapli/channel/base_channel.py", line 432, in _ssh_message_handler
    raise ScrapliAuthenticationFailed(msg)
scrapli.exceptions.ScrapliAuthenticationFailed: Host key verification failed

2023-02-25 07:16:27,660 - nornir.core.task -    ERROR -      start() - Host 'R6': task 'test' failed with traceback:
Traceback (most recent call last):
  File "/home/ipvzero/Nornir/.venv/lib/python3.10/site-packages/nornir/core/task.py", line 99, in start
    r = self.task(self, **self.params)
  File "/home/ipvzero/Nornir/Backups-Napalm/push-archive.py", line 9, in test
    task.run(task=send_configs_from_file, file='napalm-startup.txt')
  File "/home/ipvzero/Nornir/.venv/lib/python3.10/site-packages/nornir/core/task.py", line 174, in run
    raise NornirSubTaskError(task=run_task, result=r)
nornir.core.exceptions.NornirSubTaskError: Subtask: send_configs_from_file (failed)


2023-02-25 07:16:27,668 - nornir.core.task -    ERROR -      start() - Host 'R4': task 'send_configs_from_file' failed with traceback:
Traceback (most recent call last):
  File "/home/ipvzero/Nornir/.venv/lib/python3.10/site-packages/nornir/core/task.py", line 99, in start
    r = self.task(self, **self.params)
  File "/home/ipvzero/Nornir/.venv/lib/python3.10/site-packages/nornir_scrapli/tasks/core/send_configs_from_file.py", line 58, in send_configs_from_file
    scrapli_conn = task.host.get_connection("scrapli", task.nornir.config)
  File "/home/ipvzero/Nornir/.venv/lib/python3.10/site-packages/nornir/core/inventory.py", line 494, in get_connection
    self.open_connection(
  File "/home/ipvzero/Nornir/.venv/lib/python3.10/site-packages/nornir/core/inventory.py", line 546, in open_connection
    conn_obj.open(
  File "/home/ipvzero/Nornir/.venv/lib/python3.10/site-packages/nornir_scrapli/connection.py", line 105, in open
    connection.open()
  File "/home/ipvzero/Nornir/.venv/lib/python3.10/site-packages/scrapli/driver/base/sync_driver.py", line 88, in open
    self.channel.channel_authenticate_ssh(
  File "/home/ipvzero/Nornir/.venv/lib/python3.10/site-packages/scrapli/decorators.py", line 216, in decorate
    return _multiprocessing_timeout(
  File "/home/ipvzero/Nornir/.venv/lib/python3.10/site-packages/scrapli/decorators.py", line 113, in _multiprocessing_timeout
    return future.result()
  File "/usr/lib/python3.10/concurrent/futures/_base.py", line 451, in result
    return self.__get_result()
  File "/usr/lib/python3.10/concurrent/futures/_base.py", line 403, in __get_result
    raise self._exception
  File "/usr/lib/python3.10/concurrent/futures/thread.py", line 58, in run
    result = self.fn(*self.args, **self.kwargs)
  File "/home/ipvzero/Nornir/.venv/lib/python3.10/site-packages/scrapli/channel/sync_channel.py", line 290, in channel_authenticate_ssh
    self._ssh_message_handler(output=authenticate_buf)
  File "/home/ipvzero/Nornir/.venv/lib/python3.10/site-packages/scrapli/channel/base_channel.py", line 432, in _ssh_message_handler
    raise ScrapliAuthenticationFailed(msg)
scrapli.exceptions.ScrapliAuthenticationFailed: Host key verification failed

2023-02-25 07:16:27,669 - nornir.core.task -    ERROR -      start() - Host 'R4': task 'test' failed with traceback:
Traceback (most recent call last):
  File "/home/ipvzero/Nornir/.venv/lib/python3.10/site-packages/nornir/core/task.py", line 99, in start
    r = self.task(self, **self.params)
  File "/home/ipvzero/Nornir/Backups-Napalm/push-archive.py", line 9, in test
    task.run(task=send_configs_from_file, file='napalm-startup.txt')
  File "/home/ipvzero/Nornir/.venv/lib/python3.10/site-packages/nornir/core/task.py", line 174, in run
    raise NornirSubTaskError(task=run_task, result=r)
nornir.core.exceptions.NornirSubTaskError: Subtask: send_configs_from_file (failed)


2023-02-25 07:16:27,710 - nornir.core.task -    ERROR -      start() - Host 'R5': task 'send_configs_from_file' failed with traceback:
Traceback (most recent call last):
  File "/home/ipvzero/Nornir/.venv/lib/python3.10/site-packages/nornir/core/task.py", line 99, in start
    r = self.task(self, **self.params)
  File "/home/ipvzero/Nornir/.venv/lib/python3.10/site-packages/nornir_scrapli/tasks/core/send_configs_from_file.py", line 58, in send_configs_from_file
    scrapli_conn = task.host.get_connection("scrapli", task.nornir.config)
  File "/home/ipvzero/Nornir/.venv/lib/python3.10/site-packages/nornir/core/inventory.py", line 494, in get_connection
    self.open_connection(
  File "/home/ipvzero/Nornir/.venv/lib/python3.10/site-packages/nornir/core/inventory.py", line 546, in open_connection
    conn_obj.open(
  File "/home/ipvzero/Nornir/.venv/lib/python3.10/site-packages/nornir_scrapli/connection.py", line 105, in open
    connection.open()
  File "/home/ipvzero/Nornir/.venv/lib/python3.10/site-packages/scrapli/driver/base/sync_driver.py", line 88, in open
    self.channel.channel_authenticate_ssh(
  File "/home/ipvzero/Nornir/.venv/lib/python3.10/site-packages/scrapli/decorators.py", line 216, in decorate
    return _multiprocessing_timeout(
  File "/home/ipvzero/Nornir/.venv/lib/python3.10/site-packages/scrapli/decorators.py", line 113, in _multiprocessing_timeout
    return future.result()
  File "/usr/lib/python3.10/concurrent/futures/_base.py", line 451, in result
    return self.__get_result()
  File "/usr/lib/python3.10/concurrent/futures/_base.py", line 403, in __get_result
    raise self._exception
  File "/usr/lib/python3.10/concurrent/futures/thread.py", line 58, in run
    result = self.fn(*self.args, **self.kwargs)
  File "/home/ipvzero/Nornir/.venv/lib/python3.10/site-packages/scrapli/channel/sync_channel.py", line 290, in channel_authenticate_ssh
    self._ssh_message_handler(output=authenticate_buf)
  File "/home/ipvzero/Nornir/.venv/lib/python3.10/site-packages/scrapli/channel/base_channel.py", line 432, in _ssh_message_handler
    raise ScrapliAuthenticationFailed(msg)
scrapli.exceptions.ScrapliAuthenticationFailed: Host key verification failed

2023-02-25 07:16:27,710 - nornir.core.task -    ERROR -      start() - Host 'R5': task 'test' failed with traceback:
Traceback (most recent call last):
  File "/home/ipvzero/Nornir/.venv/lib/python3.10/site-packages/nornir/core/task.py", line 99, in start
    r = self.task(self, **self.params)
  File "/home/ipvzero/Nornir/Backups-Napalm/push-archive.py", line 9, in test
    task.run(task=send_configs_from_file, file='napalm-startup.txt')
  File "/home/ipvzero/Nornir/.venv/lib/python3.10/site-packages/nornir/core/task.py", line 174, in run
    raise NornirSubTaskError(task=run_task, result=r)
nornir.core.exceptions.NornirSubTaskError: Subtask: send_configs_from_file (failed)


2023-02-25 07:18:41,455 -  nornir.core -     INFO -        run() - Running task 'test' with args {} on 7 hosts
2023-02-25 07:18:41,668 - nornir.core.task -    ERROR -      start() - Host 'R1': task 'send_configs_from_file' failed with traceback:
Traceback (most recent call last):
  File "/home/ipvzero/Nornir/.venv/lib/python3.10/site-packages/nornir/core/task.py", line 99, in start
    r = self.task(self, **self.params)
  File "/home/ipvzero/Nornir/.venv/lib/python3.10/site-packages/nornir_scrapli/tasks/core/send_configs_from_file.py", line 58, in send_configs_from_file
    scrapli_conn = task.host.get_connection("scrapli", task.nornir.config)
  File "/home/ipvzero/Nornir/.venv/lib/python3.10/site-packages/nornir/core/inventory.py", line 494, in get_connection
    self.open_connection(
  File "/home/ipvzero/Nornir/.venv/lib/python3.10/site-packages/nornir/core/inventory.py", line 546, in open_connection
    conn_obj.open(
  File "/home/ipvzero/Nornir/.venv/lib/python3.10/site-packages/nornir_scrapli/connection.py", line 105, in open
    connection.open()
  File "/home/ipvzero/Nornir/.venv/lib/python3.10/site-packages/scrapli/driver/base/sync_driver.py", line 88, in open
    self.channel.channel_authenticate_ssh(
  File "/home/ipvzero/Nornir/.venv/lib/python3.10/site-packages/scrapli/decorators.py", line 216, in decorate
    return _multiprocessing_timeout(
  File "/home/ipvzero/Nornir/.venv/lib/python3.10/site-packages/scrapli/decorators.py", line 113, in _multiprocessing_timeout
    return future.result()
  File "/usr/lib/python3.10/concurrent/futures/_base.py", line 451, in result
    return self.__get_result()
  File "/usr/lib/python3.10/concurrent/futures/_base.py", line 403, in __get_result
    raise self._exception
  File "/usr/lib/python3.10/concurrent/futures/thread.py", line 58, in run
    result = self.fn(*self.args, **self.kwargs)
  File "/home/ipvzero/Nornir/.venv/lib/python3.10/site-packages/scrapli/channel/sync_channel.py", line 290, in channel_authenticate_ssh
    self._ssh_message_handler(output=authenticate_buf)
  File "/home/ipvzero/Nornir/.venv/lib/python3.10/site-packages/scrapli/channel/base_channel.py", line 432, in _ssh_message_handler
    raise ScrapliAuthenticationFailed(msg)
scrapli.exceptions.ScrapliAuthenticationFailed: Host key verification failed

2023-02-25 07:18:41,668 - nornir.core.task -    ERROR -      start() - Host 'R1': task 'test' failed with traceback:
Traceback (most recent call last):
  File "/home/ipvzero/Nornir/.venv/lib/python3.10/site-packages/nornir/core/task.py", line 99, in start
    r = self.task(self, **self.params)
  File "/home/ipvzero/Nornir/Backups-Napalm/push-archive.py", line 14, in test
    task.run(task=send_configs_from_file, file='napalm-startup.txt')
  File "/home/ipvzero/Nornir/.venv/lib/python3.10/site-packages/nornir/core/task.py", line 174, in run
    raise NornirSubTaskError(task=run_task, result=r)
nornir.core.exceptions.NornirSubTaskError: Subtask: send_configs_from_file (failed)


2023-02-25 07:18:41,776 - nornir.core.task -    ERROR -      start() - Host 'R3': task 'send_configs_from_file' failed with traceback:
Traceback (most recent call last):
  File "/home/ipvzero/Nornir/.venv/lib/python3.10/site-packages/nornir/core/task.py", line 99, in start
    r = self.task(self, **self.params)
  File "/home/ipvzero/Nornir/.venv/lib/python3.10/site-packages/nornir_scrapli/tasks/core/send_configs_from_file.py", line 58, in send_configs_from_file
    scrapli_conn = task.host.get_connection("scrapli", task.nornir.config)
  File "/home/ipvzero/Nornir/.venv/lib/python3.10/site-packages/nornir/core/inventory.py", line 494, in get_connection
    self.open_connection(
  File "/home/ipvzero/Nornir/.venv/lib/python3.10/site-packages/nornir/core/inventory.py", line 546, in open_connection
    conn_obj.open(
  File "/home/ipvzero/Nornir/.venv/lib/python3.10/site-packages/nornir_scrapli/connection.py", line 105, in open
    connection.open()
  File "/home/ipvzero/Nornir/.venv/lib/python3.10/site-packages/scrapli/driver/base/sync_driver.py", line 88, in open
    self.channel.channel_authenticate_ssh(
  File "/home/ipvzero/Nornir/.venv/lib/python3.10/site-packages/scrapli/decorators.py", line 216, in decorate
    return _multiprocessing_timeout(
  File "/home/ipvzero/Nornir/.venv/lib/python3.10/site-packages/scrapli/decorators.py", line 113, in _multiprocessing_timeout
    return future.result()
  File "/usr/lib/python3.10/concurrent/futures/_base.py", line 451, in result
    return self.__get_result()
  File "/usr/lib/python3.10/concurrent/futures/_base.py", line 403, in __get_result
    raise self._exception
  File "/usr/lib/python3.10/concurrent/futures/thread.py", line 58, in run
    result = self.fn(*self.args, **self.kwargs)
  File "/home/ipvzero/Nornir/.venv/lib/python3.10/site-packages/scrapli/channel/sync_channel.py", line 290, in channel_authenticate_ssh
    self._ssh_message_handler(output=authenticate_buf)
  File "/home/ipvzero/Nornir/.venv/lib/python3.10/site-packages/scrapli/channel/base_channel.py", line 432, in _ssh_message_handler
    raise ScrapliAuthenticationFailed(msg)
scrapli.exceptions.ScrapliAuthenticationFailed: Host key verification failed

2023-02-25 07:18:41,777 - nornir.core.task -    ERROR -      start() - Host 'R3': task 'test' failed with traceback:
Traceback (most recent call last):
  File "/home/ipvzero/Nornir/.venv/lib/python3.10/site-packages/nornir/core/task.py", line 99, in start
    r = self.task(self, **self.params)
  File "/home/ipvzero/Nornir/Backups-Napalm/push-archive.py", line 14, in test
    task.run(task=send_configs_from_file, file='napalm-startup.txt')
  File "/home/ipvzero/Nornir/.venv/lib/python3.10/site-packages/nornir/core/task.py", line 174, in run
    raise NornirSubTaskError(task=run_task, result=r)
nornir.core.exceptions.NornirSubTaskError: Subtask: send_configs_from_file (failed)


2023-02-25 07:18:41,795 - nornir.core.task -    ERROR -      start() - Host 'R5': task 'send_configs_from_file' failed with traceback:
Traceback (most recent call last):
  File "/home/ipvzero/Nornir/.venv/lib/python3.10/site-packages/nornir/core/task.py", line 99, in start
    r = self.task(self, **self.params)
  File "/home/ipvzero/Nornir/.venv/lib/python3.10/site-packages/nornir_scrapli/tasks/core/send_configs_from_file.py", line 58, in send_configs_from_file
    scrapli_conn = task.host.get_connection("scrapli", task.nornir.config)
  File "/home/ipvzero/Nornir/.venv/lib/python3.10/site-packages/nornir/core/inventory.py", line 494, in get_connection
    self.open_connection(
  File "/home/ipvzero/Nornir/.venv/lib/python3.10/site-packages/nornir/core/inventory.py", line 546, in open_connection
    conn_obj.open(
  File "/home/ipvzero/Nornir/.venv/lib/python3.10/site-packages/nornir_scrapli/connection.py", line 105, in open
    connection.open()
  File "/home/ipvzero/Nornir/.venv/lib/python3.10/site-packages/scrapli/driver/base/sync_driver.py", line 88, in open
    self.channel.channel_authenticate_ssh(
  File "/home/ipvzero/Nornir/.venv/lib/python3.10/site-packages/scrapli/decorators.py", line 216, in decorate
    return _multiprocessing_timeout(
  File "/home/ipvzero/Nornir/.venv/lib/python3.10/site-packages/scrapli/decorators.py", line 113, in _multiprocessing_timeout
    return future.result()
  File "/usr/lib/python3.10/concurrent/futures/_base.py", line 451, in result
    return self.__get_result()
  File "/usr/lib/python3.10/concurrent/futures/_base.py", line 403, in __get_result
    raise self._exception
  File "/usr/lib/python3.10/concurrent/futures/thread.py", line 58, in run
    result = self.fn(*self.args, **self.kwargs)
  File "/home/ipvzero/Nornir/.venv/lib/python3.10/site-packages/scrapli/channel/sync_channel.py", line 290, in channel_authenticate_ssh
    self._ssh_message_handler(output=authenticate_buf)
  File "/home/ipvzero/Nornir/.venv/lib/python3.10/site-packages/scrapli/channel/base_channel.py", line 432, in _ssh_message_handler
    raise ScrapliAuthenticationFailed(msg)
scrapli.exceptions.ScrapliAuthenticationFailed: Host key verification failed

2023-02-25 07:18:41,795 - nornir.core.task -    ERROR -      start() - Host 'R5': task 'test' failed with traceback:
Traceback (most recent call last):
  File "/home/ipvzero/Nornir/.venv/lib/python3.10/site-packages/nornir/core/task.py", line 99, in start
    r = self.task(self, **self.params)
  File "/home/ipvzero/Nornir/Backups-Napalm/push-archive.py", line 14, in test
    task.run(task=send_configs_from_file, file='napalm-startup.txt')
  File "/home/ipvzero/Nornir/.venv/lib/python3.10/site-packages/nornir/core/task.py", line 174, in run
    raise NornirSubTaskError(task=run_task, result=r)
nornir.core.exceptions.NornirSubTaskError: Subtask: send_configs_from_file (failed)


2023-02-25 07:18:41,857 - nornir.core.task -    ERROR -      start() - Host 'R4': task 'send_configs_from_file' failed with traceback:
Traceback (most recent call last):
  File "/home/ipvzero/Nornir/.venv/lib/python3.10/site-packages/nornir/core/task.py", line 99, in start
    r = self.task(self, **self.params)
  File "/home/ipvzero/Nornir/.venv/lib/python3.10/site-packages/nornir_scrapli/tasks/core/send_configs_from_file.py", line 58, in send_configs_from_file
    scrapli_conn = task.host.get_connection("scrapli", task.nornir.config)
  File "/home/ipvzero/Nornir/.venv/lib/python3.10/site-packages/nornir/core/inventory.py", line 494, in get_connection
    self.open_connection(
  File "/home/ipvzero/Nornir/.venv/lib/python3.10/site-packages/nornir/core/inventory.py", line 546, in open_connection
    conn_obj.open(
  File "/home/ipvzero/Nornir/.venv/lib/python3.10/site-packages/nornir_scrapli/connection.py", line 105, in open
    connection.open()
  File "/home/ipvzero/Nornir/.venv/lib/python3.10/site-packages/scrapli/driver/base/sync_driver.py", line 88, in open
    self.channel.channel_authenticate_ssh(
  File "/home/ipvzero/Nornir/.venv/lib/python3.10/site-packages/scrapli/decorators.py", line 216, in decorate
    return _multiprocessing_timeout(
  File "/home/ipvzero/Nornir/.venv/lib/python3.10/site-packages/scrapli/decorators.py", line 113, in _multiprocessing_timeout
    return future.result()
  File "/usr/lib/python3.10/concurrent/futures/_base.py", line 451, in result
    return self.__get_result()
  File "/usr/lib/python3.10/concurrent/futures/_base.py", line 403, in __get_result
    raise self._exception
  File "/usr/lib/python3.10/concurrent/futures/thread.py", line 58, in run
    result = self.fn(*self.args, **self.kwargs)
  File "/home/ipvzero/Nornir/.venv/lib/python3.10/site-packages/scrapli/channel/sync_channel.py", line 290, in channel_authenticate_ssh
    self._ssh_message_handler(output=authenticate_buf)
  File "/home/ipvzero/Nornir/.venv/lib/python3.10/site-packages/scrapli/channel/base_channel.py", line 432, in _ssh_message_handler
    raise ScrapliAuthenticationFailed(msg)
scrapli.exceptions.ScrapliAuthenticationFailed: Host key verification failed

2023-02-25 07:18:41,857 - nornir.core.task -    ERROR -      start() - Host 'R4': task 'test' failed with traceback:
Traceback (most recent call last):
  File "/home/ipvzero/Nornir/.venv/lib/python3.10/site-packages/nornir/core/task.py", line 99, in start
    r = self.task(self, **self.params)
  File "/home/ipvzero/Nornir/Backups-Napalm/push-archive.py", line 14, in test
    task.run(task=send_configs_from_file, file='napalm-startup.txt')
  File "/home/ipvzero/Nornir/.venv/lib/python3.10/site-packages/nornir/core/task.py", line 174, in run
    raise NornirSubTaskError(task=run_task, result=r)
nornir.core.exceptions.NornirSubTaskError: Subtask: send_configs_from_file (failed)


2023-02-25 07:18:41,885 - nornir.core.task -    ERROR -      start() - Host 'R6': task 'send_configs_from_file' failed with traceback:
Traceback (most recent call last):
  File "/home/ipvzero/Nornir/.venv/lib/python3.10/site-packages/nornir/core/task.py", line 99, in start
    r = self.task(self, **self.params)
  File "/home/ipvzero/Nornir/.venv/lib/python3.10/site-packages/nornir_scrapli/tasks/core/send_configs_from_file.py", line 58, in send_configs_from_file
    scrapli_conn = task.host.get_connection("scrapli", task.nornir.config)
  File "/home/ipvzero/Nornir/.venv/lib/python3.10/site-packages/nornir/core/inventory.py", line 494, in get_connection
    self.open_connection(
  File "/home/ipvzero/Nornir/.venv/lib/python3.10/site-packages/nornir/core/inventory.py", line 546, in open_connection
    conn_obj.open(
  File "/home/ipvzero/Nornir/.venv/lib/python3.10/site-packages/nornir_scrapli/connection.py", line 105, in open
    connection.open()
  File "/home/ipvzero/Nornir/.venv/lib/python3.10/site-packages/scrapli/driver/base/sync_driver.py", line 88, in open
    self.channel.channel_authenticate_ssh(
  File "/home/ipvzero/Nornir/.venv/lib/python3.10/site-packages/scrapli/decorators.py", line 216, in decorate
    return _multiprocessing_timeout(
  File "/home/ipvzero/Nornir/.venv/lib/python3.10/site-packages/scrapli/decorators.py", line 113, in _multiprocessing_timeout
    return future.result()
  File "/usr/lib/python3.10/concurrent/futures/_base.py", line 451, in result
    return self.__get_result()
  File "/usr/lib/python3.10/concurrent/futures/_base.py", line 403, in __get_result
    raise self._exception
  File "/usr/lib/python3.10/concurrent/futures/thread.py", line 58, in run
    result = self.fn(*self.args, **self.kwargs)
  File "/home/ipvzero/Nornir/.venv/lib/python3.10/site-packages/scrapli/channel/sync_channel.py", line 290, in channel_authenticate_ssh
    self._ssh_message_handler(output=authenticate_buf)
  File "/home/ipvzero/Nornir/.venv/lib/python3.10/site-packages/scrapli/channel/base_channel.py", line 432, in _ssh_message_handler
    raise ScrapliAuthenticationFailed(msg)
scrapli.exceptions.ScrapliAuthenticationFailed: Host key verification failed

2023-02-25 07:18:41,886 - nornir.core.task -    ERROR -      start() - Host 'R6': task 'test' failed with traceback:
Traceback (most recent call last):
  File "/home/ipvzero/Nornir/.venv/lib/python3.10/site-packages/nornir/core/task.py", line 99, in start
    r = self.task(self, **self.params)
  File "/home/ipvzero/Nornir/Backups-Napalm/push-archive.py", line 14, in test
    task.run(task=send_configs_from_file, file='napalm-startup.txt')
  File "/home/ipvzero/Nornir/.venv/lib/python3.10/site-packages/nornir/core/task.py", line 174, in run
    raise NornirSubTaskError(task=run_task, result=r)
nornir.core.exceptions.NornirSubTaskError: Subtask: send_configs_from_file (failed)


2023-02-25 07:18:41,961 - nornir.core.task -    ERROR -      start() - Host 'R2': task 'send_configs_from_file' failed with traceback:
Traceback (most recent call last):
  File "/home/ipvzero/Nornir/.venv/lib/python3.10/site-packages/nornir/core/task.py", line 99, in start
    r = self.task(self, **self.params)
  File "/home/ipvzero/Nornir/.venv/lib/python3.10/site-packages/nornir_scrapli/tasks/core/send_configs_from_file.py", line 58, in send_configs_from_file
    scrapli_conn = task.host.get_connection("scrapli", task.nornir.config)
  File "/home/ipvzero/Nornir/.venv/lib/python3.10/site-packages/nornir/core/inventory.py", line 494, in get_connection
    self.open_connection(
  File "/home/ipvzero/Nornir/.venv/lib/python3.10/site-packages/nornir/core/inventory.py", line 546, in open_connection
    conn_obj.open(
  File "/home/ipvzero/Nornir/.venv/lib/python3.10/site-packages/nornir_scrapli/connection.py", line 105, in open
    connection.open()
  File "/home/ipvzero/Nornir/.venv/lib/python3.10/site-packages/scrapli/driver/base/sync_driver.py", line 88, in open
    self.channel.channel_authenticate_ssh(
  File "/home/ipvzero/Nornir/.venv/lib/python3.10/site-packages/scrapli/decorators.py", line 216, in decorate
    return _multiprocessing_timeout(
  File "/home/ipvzero/Nornir/.venv/lib/python3.10/site-packages/scrapli/decorators.py", line 113, in _multiprocessing_timeout
    return future.result()
  File "/usr/lib/python3.10/concurrent/futures/_base.py", line 451, in result
    return self.__get_result()
  File "/usr/lib/python3.10/concurrent/futures/_base.py", line 403, in __get_result
    raise self._exception
  File "/usr/lib/python3.10/concurrent/futures/thread.py", line 58, in run
    result = self.fn(*self.args, **self.kwargs)
  File "/home/ipvzero/Nornir/.venv/lib/python3.10/site-packages/scrapli/channel/sync_channel.py", line 290, in channel_authenticate_ssh
    self._ssh_message_handler(output=authenticate_buf)
  File "/home/ipvzero/Nornir/.venv/lib/python3.10/site-packages/scrapli/channel/base_channel.py", line 432, in _ssh_message_handler
    raise ScrapliAuthenticationFailed(msg)
scrapli.exceptions.ScrapliAuthenticationFailed: Host key verification failed

2023-02-25 07:18:41,962 - nornir.core.task -    ERROR -      start() - Host 'R2': task 'test' failed with traceback:
Traceback (most recent call last):
  File "/home/ipvzero/Nornir/.venv/lib/python3.10/site-packages/nornir/core/task.py", line 99, in start
    r = self.task(self, **self.params)
  File "/home/ipvzero/Nornir/Backups-Napalm/push-archive.py", line 14, in test
    task.run(task=send_configs_from_file, file='napalm-startup.txt')
  File "/home/ipvzero/Nornir/.venv/lib/python3.10/site-packages/nornir/core/task.py", line 174, in run
    raise NornirSubTaskError(task=run_task, result=r)
nornir.core.exceptions.NornirSubTaskError: Subtask: send_configs_from_file (failed)


2023-02-25 07:18:41,964 - nornir.core.task -    ERROR -      start() - Host 'R7': task 'send_configs_from_file' failed with traceback:
Traceback (most recent call last):
  File "/home/ipvzero/Nornir/.venv/lib/python3.10/site-packages/nornir/core/task.py", line 99, in start
    r = self.task(self, **self.params)
  File "/home/ipvzero/Nornir/.venv/lib/python3.10/site-packages/nornir_scrapli/tasks/core/send_configs_from_file.py", line 58, in send_configs_from_file
    scrapli_conn = task.host.get_connection("scrapli", task.nornir.config)
  File "/home/ipvzero/Nornir/.venv/lib/python3.10/site-packages/nornir/core/inventory.py", line 494, in get_connection
    self.open_connection(
  File "/home/ipvzero/Nornir/.venv/lib/python3.10/site-packages/nornir/core/inventory.py", line 546, in open_connection
    conn_obj.open(
  File "/home/ipvzero/Nornir/.venv/lib/python3.10/site-packages/nornir_scrapli/connection.py", line 105, in open
    connection.open()
  File "/home/ipvzero/Nornir/.venv/lib/python3.10/site-packages/scrapli/driver/base/sync_driver.py", line 88, in open
    self.channel.channel_authenticate_ssh(
  File "/home/ipvzero/Nornir/.venv/lib/python3.10/site-packages/scrapli/decorators.py", line 216, in decorate
    return _multiprocessing_timeout(
  File "/home/ipvzero/Nornir/.venv/lib/python3.10/site-packages/scrapli/decorators.py", line 113, in _multiprocessing_timeout
    return future.result()
  File "/usr/lib/python3.10/concurrent/futures/_base.py", line 451, in result
    return self.__get_result()
  File "/usr/lib/python3.10/concurrent/futures/_base.py", line 403, in __get_result
    raise self._exception
  File "/usr/lib/python3.10/concurrent/futures/thread.py", line 58, in run
    result = self.fn(*self.args, **self.kwargs)
  File "/home/ipvzero/Nornir/.venv/lib/python3.10/site-packages/scrapli/channel/sync_channel.py", line 290, in channel_authenticate_ssh
    self._ssh_message_handler(output=authenticate_buf)
  File "/home/ipvzero/Nornir/.venv/lib/python3.10/site-packages/scrapli/channel/base_channel.py", line 432, in _ssh_message_handler
    raise ScrapliAuthenticationFailed(msg)
scrapli.exceptions.ScrapliAuthenticationFailed: Host key verification failed

2023-02-25 07:18:41,965 - nornir.core.task -    ERROR -      start() - Host 'R7': task 'test' failed with traceback:
Traceback (most recent call last):
  File "/home/ipvzero/Nornir/.venv/lib/python3.10/site-packages/nornir/core/task.py", line 99, in start
    r = self.task(self, **self.params)
  File "/home/ipvzero/Nornir/Backups-Napalm/push-archive.py", line 14, in test
    task.run(task=send_configs_from_file, file='napalm-startup.txt')
  File "/home/ipvzero/Nornir/.venv/lib/python3.10/site-packages/nornir/core/task.py", line 174, in run
    raise NornirSubTaskError(task=run_task, result=r)
nornir.core.exceptions.NornirSubTaskError: Subtask: send_configs_from_file (failed)


2023-02-25 07:19:11,679 -  nornir.core -     INFO -        run() - Running task 'backup_configurations' with args {} on 7 hosts
2023-02-25 07:21:12,536 -  nornir.core -     INFO -        run() - Running task 'test' with args {} on 7 hosts
2023-02-25 07:21:12,845 - nornir.core.task -    ERROR -      start() - Host 'R2': task 'send_configs_from_file' failed with traceback:
Traceback (most recent call last):
  File "/home/ipvzero/Nornir/.venv/lib/python3.10/site-packages/nornir/core/task.py", line 99, in start
    r = self.task(self, **self.params)
  File "/home/ipvzero/Nornir/.venv/lib/python3.10/site-packages/nornir_scrapli/tasks/core/send_configs_from_file.py", line 58, in send_configs_from_file
    scrapli_conn = task.host.get_connection("scrapli", task.nornir.config)
  File "/home/ipvzero/Nornir/.venv/lib/python3.10/site-packages/nornir/core/inventory.py", line 494, in get_connection
    self.open_connection(
  File "/home/ipvzero/Nornir/.venv/lib/python3.10/site-packages/nornir/core/inventory.py", line 546, in open_connection
    conn_obj.open(
  File "/home/ipvzero/Nornir/.venv/lib/python3.10/site-packages/nornir_scrapli/connection.py", line 105, in open
    connection.open()
  File "/home/ipvzero/Nornir/.venv/lib/python3.10/site-packages/scrapli/driver/base/sync_driver.py", line 88, in open
    self.channel.channel_authenticate_ssh(
  File "/home/ipvzero/Nornir/.venv/lib/python3.10/site-packages/scrapli/decorators.py", line 216, in decorate
    return _multiprocessing_timeout(
  File "/home/ipvzero/Nornir/.venv/lib/python3.10/site-packages/scrapli/decorators.py", line 113, in _multiprocessing_timeout
    return future.result()
  File "/usr/lib/python3.10/concurrent/futures/_base.py", line 451, in result
    return self.__get_result()
  File "/usr/lib/python3.10/concurrent/futures/_base.py", line 403, in __get_result
    raise self._exception
  File "/usr/lib/python3.10/concurrent/futures/thread.py", line 58, in run
    result = self.fn(*self.args, **self.kwargs)
  File "/home/ipvzero/Nornir/.venv/lib/python3.10/site-packages/scrapli/channel/sync_channel.py", line 290, in channel_authenticate_ssh
    self._ssh_message_handler(output=authenticate_buf)
  File "/home/ipvzero/Nornir/.venv/lib/python3.10/site-packages/scrapli/channel/base_channel.py", line 432, in _ssh_message_handler
    raise ScrapliAuthenticationFailed(msg)
scrapli.exceptions.ScrapliAuthenticationFailed: Host key verification failed

2023-02-25 07:21:12,845 - nornir.core.task -    ERROR -      start() - Host 'R2': task 'test' failed with traceback:
Traceback (most recent call last):
  File "/home/ipvzero/Nornir/.venv/lib/python3.10/site-packages/nornir/core/task.py", line 99, in start
    r = self.task(self, **self.params)
  File "/home/ipvzero/Nornir/Backups-Napalm/push-archive.py", line 16, in test
    task.run(task=send_configs_from_file, file='napalm-startup.txt')
  File "/home/ipvzero/Nornir/.venv/lib/python3.10/site-packages/nornir/core/task.py", line 174, in run
    raise NornirSubTaskError(task=run_task, result=r)
nornir.core.exceptions.NornirSubTaskError: Subtask: send_configs_from_file (failed)


2023-02-25 07:21:12,870 - nornir.core.task -    ERROR -      start() - Host 'R7': task 'send_configs_from_file' failed with traceback:
Traceback (most recent call last):
  File "/home/ipvzero/Nornir/.venv/lib/python3.10/site-packages/nornir/core/task.py", line 99, in start
    r = self.task(self, **self.params)
  File "/home/ipvzero/Nornir/.venv/lib/python3.10/site-packages/nornir_scrapli/tasks/core/send_configs_from_file.py", line 58, in send_configs_from_file
    scrapli_conn = task.host.get_connection("scrapli", task.nornir.config)
  File "/home/ipvzero/Nornir/.venv/lib/python3.10/site-packages/nornir/core/inventory.py", line 494, in get_connection
    self.open_connection(
  File "/home/ipvzero/Nornir/.venv/lib/python3.10/site-packages/nornir/core/inventory.py", line 546, in open_connection
    conn_obj.open(
  File "/home/ipvzero/Nornir/.venv/lib/python3.10/site-packages/nornir_scrapli/connection.py", line 105, in open
    connection.open()
  File "/home/ipvzero/Nornir/.venv/lib/python3.10/site-packages/scrapli/driver/base/sync_driver.py", line 88, in open
    self.channel.channel_authenticate_ssh(
  File "/home/ipvzero/Nornir/.venv/lib/python3.10/site-packages/scrapli/decorators.py", line 216, in decorate
    return _multiprocessing_timeout(
  File "/home/ipvzero/Nornir/.venv/lib/python3.10/site-packages/scrapli/decorators.py", line 113, in _multiprocessing_timeout
    return future.result()
  File "/usr/lib/python3.10/concurrent/futures/_base.py", line 451, in result
    return self.__get_result()
  File "/usr/lib/python3.10/concurrent/futures/_base.py", line 403, in __get_result
    raise self._exception
  File "/usr/lib/python3.10/concurrent/futures/thread.py", line 58, in run
    result = self.fn(*self.args, **self.kwargs)
  File "/home/ipvzero/Nornir/.venv/lib/python3.10/site-packages/scrapli/channel/sync_channel.py", line 290, in channel_authenticate_ssh
    self._ssh_message_handler(output=authenticate_buf)
  File "/home/ipvzero/Nornir/.venv/lib/python3.10/site-packages/scrapli/channel/base_channel.py", line 432, in _ssh_message_handler
    raise ScrapliAuthenticationFailed(msg)
scrapli.exceptions.ScrapliAuthenticationFailed: Host key verification failed

2023-02-25 07:21:12,870 - nornir.core.task -    ERROR -      start() - Host 'R7': task 'test' failed with traceback:
Traceback (most recent call last):
  File "/home/ipvzero/Nornir/.venv/lib/python3.10/site-packages/nornir/core/task.py", line 99, in start
    r = self.task(self, **self.params)
  File "/home/ipvzero/Nornir/Backups-Napalm/push-archive.py", line 16, in test
    task.run(task=send_configs_from_file, file='napalm-startup.txt')
  File "/home/ipvzero/Nornir/.venv/lib/python3.10/site-packages/nornir/core/task.py", line 174, in run
    raise NornirSubTaskError(task=run_task, result=r)
nornir.core.exceptions.NornirSubTaskError: Subtask: send_configs_from_file (failed)


2023-02-25 07:21:12,943 - nornir.core.task -    ERROR -      start() - Host 'R4': task 'send_configs_from_file' failed with traceback:
Traceback (most recent call last):
  File "/home/ipvzero/Nornir/.venv/lib/python3.10/site-packages/nornir/core/task.py", line 99, in start
    r = self.task(self, **self.params)
  File "/home/ipvzero/Nornir/.venv/lib/python3.10/site-packages/nornir_scrapli/tasks/core/send_configs_from_file.py", line 58, in send_configs_from_file
    scrapli_conn = task.host.get_connection("scrapli", task.nornir.config)
  File "/home/ipvzero/Nornir/.venv/lib/python3.10/site-packages/nornir/core/inventory.py", line 494, in get_connection
    self.open_connection(
  File "/home/ipvzero/Nornir/.venv/lib/python3.10/site-packages/nornir/core/inventory.py", line 546, in open_connection
    conn_obj.open(
  File "/home/ipvzero/Nornir/.venv/lib/python3.10/site-packages/nornir_scrapli/connection.py", line 105, in open
    connection.open()
  File "/home/ipvzero/Nornir/.venv/lib/python3.10/site-packages/scrapli/driver/base/sync_driver.py", line 88, in open
    self.channel.channel_authenticate_ssh(
  File "/home/ipvzero/Nornir/.venv/lib/python3.10/site-packages/scrapli/decorators.py", line 216, in decorate
    return _multiprocessing_timeout(
  File "/home/ipvzero/Nornir/.venv/lib/python3.10/site-packages/scrapli/decorators.py", line 113, in _multiprocessing_timeout
    return future.result()
  File "/usr/lib/python3.10/concurrent/futures/_base.py", line 451, in result
    return self.__get_result()
  File "/usr/lib/python3.10/concurrent/futures/_base.py", line 403, in __get_result
    raise self._exception
  File "/usr/lib/python3.10/concurrent/futures/thread.py", line 58, in run
    result = self.fn(*self.args, **self.kwargs)
  File "/home/ipvzero/Nornir/.venv/lib/python3.10/site-packages/scrapli/channel/sync_channel.py", line 290, in channel_authenticate_ssh
    self._ssh_message_handler(output=authenticate_buf)
  File "/home/ipvzero/Nornir/.venv/lib/python3.10/site-packages/scrapli/channel/base_channel.py", line 432, in _ssh_message_handler
    raise ScrapliAuthenticationFailed(msg)
scrapli.exceptions.ScrapliAuthenticationFailed: Host key verification failed

2023-02-25 07:21:12,943 - nornir.core.task -    ERROR -      start() - Host 'R4': task 'test' failed with traceback:
Traceback (most recent call last):
  File "/home/ipvzero/Nornir/.venv/lib/python3.10/site-packages/nornir/core/task.py", line 99, in start
    r = self.task(self, **self.params)
  File "/home/ipvzero/Nornir/Backups-Napalm/push-archive.py", line 16, in test
    task.run(task=send_configs_from_file, file='napalm-startup.txt')
  File "/home/ipvzero/Nornir/.venv/lib/python3.10/site-packages/nornir/core/task.py", line 174, in run
    raise NornirSubTaskError(task=run_task, result=r)
nornir.core.exceptions.NornirSubTaskError: Subtask: send_configs_from_file (failed)


2023-02-25 07:21:12,951 - nornir.core.task -    ERROR -      start() - Host 'R3': task 'send_configs_from_file' failed with traceback:
Traceback (most recent call last):
  File "/home/ipvzero/Nornir/.venv/lib/python3.10/site-packages/nornir/core/task.py", line 99, in start
    r = self.task(self, **self.params)
  File "/home/ipvzero/Nornir/.venv/lib/python3.10/site-packages/nornir_scrapli/tasks/core/send_configs_from_file.py", line 58, in send_configs_from_file
    scrapli_conn = task.host.get_connection("scrapli", task.nornir.config)
  File "/home/ipvzero/Nornir/.venv/lib/python3.10/site-packages/nornir/core/inventory.py", line 494, in get_connection
    self.open_connection(
  File "/home/ipvzero/Nornir/.venv/lib/python3.10/site-packages/nornir/core/inventory.py", line 546, in open_connection
    conn_obj.open(
  File "/home/ipvzero/Nornir/.venv/lib/python3.10/site-packages/nornir_scrapli/connection.py", line 105, in open
    connection.open()
  File "/home/ipvzero/Nornir/.venv/lib/python3.10/site-packages/scrapli/driver/base/sync_driver.py", line 88, in open
    self.channel.channel_authenticate_ssh(
  File "/home/ipvzero/Nornir/.venv/lib/python3.10/site-packages/scrapli/decorators.py", line 216, in decorate
    return _multiprocessing_timeout(
  File "/home/ipvzero/Nornir/.venv/lib/python3.10/site-packages/scrapli/decorators.py", line 113, in _multiprocessing_timeout
    return future.result()
  File "/usr/lib/python3.10/concurrent/futures/_base.py", line 451, in result
    return self.__get_result()
  File "/usr/lib/python3.10/concurrent/futures/_base.py", line 403, in __get_result
    raise self._exception
  File "/usr/lib/python3.10/concurrent/futures/thread.py", line 58, in run
    result = self.fn(*self.args, **self.kwargs)
  File "/home/ipvzero/Nornir/.venv/lib/python3.10/site-packages/scrapli/channel/sync_channel.py", line 290, in channel_authenticate_ssh
    self._ssh_message_handler(output=authenticate_buf)
  File "/home/ipvzero/Nornir/.venv/lib/python3.10/site-packages/scrapli/channel/base_channel.py", line 432, in _ssh_message_handler
    raise ScrapliAuthenticationFailed(msg)
scrapli.exceptions.ScrapliAuthenticationFailed: Host key verification failed

2023-02-25 07:21:12,952 - nornir.core.task -    ERROR -      start() - Host 'R3': task 'test' failed with traceback:
Traceback (most recent call last):
  File "/home/ipvzero/Nornir/.venv/lib/python3.10/site-packages/nornir/core/task.py", line 99, in start
    r = self.task(self, **self.params)
  File "/home/ipvzero/Nornir/Backups-Napalm/push-archive.py", line 16, in test
    task.run(task=send_configs_from_file, file='napalm-startup.txt')
  File "/home/ipvzero/Nornir/.venv/lib/python3.10/site-packages/nornir/core/task.py", line 174, in run
    raise NornirSubTaskError(task=run_task, result=r)
nornir.core.exceptions.NornirSubTaskError: Subtask: send_configs_from_file (failed)


2023-02-25 07:21:12,988 - nornir.core.task -    ERROR -      start() - Host 'R1': task 'send_configs_from_file' failed with traceback:
Traceback (most recent call last):
  File "/home/ipvzero/Nornir/.venv/lib/python3.10/site-packages/nornir/core/task.py", line 99, in start
    r = self.task(self, **self.params)
  File "/home/ipvzero/Nornir/.venv/lib/python3.10/site-packages/nornir_scrapli/tasks/core/send_configs_from_file.py", line 58, in send_configs_from_file
    scrapli_conn = task.host.get_connection("scrapli", task.nornir.config)
  File "/home/ipvzero/Nornir/.venv/lib/python3.10/site-packages/nornir/core/inventory.py", line 494, in get_connection
    self.open_connection(
  File "/home/ipvzero/Nornir/.venv/lib/python3.10/site-packages/nornir/core/inventory.py", line 546, in open_connection
    conn_obj.open(
  File "/home/ipvzero/Nornir/.venv/lib/python3.10/site-packages/nornir_scrapli/connection.py", line 105, in open
    connection.open()
  File "/home/ipvzero/Nornir/.venv/lib/python3.10/site-packages/scrapli/driver/base/sync_driver.py", line 88, in open
    self.channel.channel_authenticate_ssh(
  File "/home/ipvzero/Nornir/.venv/lib/python3.10/site-packages/scrapli/decorators.py", line 216, in decorate
    return _multiprocessing_timeout(
  File "/home/ipvzero/Nornir/.venv/lib/python3.10/site-packages/scrapli/decorators.py", line 113, in _multiprocessing_timeout
    return future.result()
  File "/usr/lib/python3.10/concurrent/futures/_base.py", line 451, in result
    return self.__get_result()
  File "/usr/lib/python3.10/concurrent/futures/_base.py", line 403, in __get_result
    raise self._exception
  File "/usr/lib/python3.10/concurrent/futures/thread.py", line 58, in run
    result = self.fn(*self.args, **self.kwargs)
  File "/home/ipvzero/Nornir/.venv/lib/python3.10/site-packages/scrapli/channel/sync_channel.py", line 290, in channel_authenticate_ssh
    self._ssh_message_handler(output=authenticate_buf)
  File "/home/ipvzero/Nornir/.venv/lib/python3.10/site-packages/scrapli/channel/base_channel.py", line 432, in _ssh_message_handler
    raise ScrapliAuthenticationFailed(msg)
scrapli.exceptions.ScrapliAuthenticationFailed: Host key verification failed

2023-02-25 07:21:12,989 - nornir.core.task -    ERROR -      start() - Host 'R1': task 'test' failed with traceback:
Traceback (most recent call last):
  File "/home/ipvzero/Nornir/.venv/lib/python3.10/site-packages/nornir/core/task.py", line 99, in start
    r = self.task(self, **self.params)
  File "/home/ipvzero/Nornir/Backups-Napalm/push-archive.py", line 16, in test
    task.run(task=send_configs_from_file, file='napalm-startup.txt')
  File "/home/ipvzero/Nornir/.venv/lib/python3.10/site-packages/nornir/core/task.py", line 174, in run
    raise NornirSubTaskError(task=run_task, result=r)
nornir.core.exceptions.NornirSubTaskError: Subtask: send_configs_from_file (failed)


2023-02-25 07:21:13,020 - nornir.core.task -    ERROR -      start() - Host 'R6': task 'send_configs_from_file' failed with traceback:
Traceback (most recent call last):
  File "/home/ipvzero/Nornir/.venv/lib/python3.10/site-packages/nornir/core/task.py", line 99, in start
    r = self.task(self, **self.params)
  File "/home/ipvzero/Nornir/.venv/lib/python3.10/site-packages/nornir_scrapli/tasks/core/send_configs_from_file.py", line 58, in send_configs_from_file
    scrapli_conn = task.host.get_connection("scrapli", task.nornir.config)
  File "/home/ipvzero/Nornir/.venv/lib/python3.10/site-packages/nornir/core/inventory.py", line 494, in get_connection
    self.open_connection(
  File "/home/ipvzero/Nornir/.venv/lib/python3.10/site-packages/nornir/core/inventory.py", line 546, in open_connection
    conn_obj.open(
  File "/home/ipvzero/Nornir/.venv/lib/python3.10/site-packages/nornir_scrapli/connection.py", line 105, in open
    connection.open()
  File "/home/ipvzero/Nornir/.venv/lib/python3.10/site-packages/scrapli/driver/base/sync_driver.py", line 88, in open
    self.channel.channel_authenticate_ssh(
  File "/home/ipvzero/Nornir/.venv/lib/python3.10/site-packages/scrapli/decorators.py", line 216, in decorate
    return _multiprocessing_timeout(
  File "/home/ipvzero/Nornir/.venv/lib/python3.10/site-packages/scrapli/decorators.py", line 113, in _multiprocessing_timeout
    return future.result()
  File "/usr/lib/python3.10/concurrent/futures/_base.py", line 451, in result
    return self.__get_result()
  File "/usr/lib/python3.10/concurrent/futures/_base.py", line 403, in __get_result
    raise self._exception
  File "/usr/lib/python3.10/concurrent/futures/thread.py", line 58, in run
    result = self.fn(*self.args, **self.kwargs)
  File "/home/ipvzero/Nornir/.venv/lib/python3.10/site-packages/scrapli/channel/sync_channel.py", line 290, in channel_authenticate_ssh
    self._ssh_message_handler(output=authenticate_buf)
  File "/home/ipvzero/Nornir/.venv/lib/python3.10/site-packages/scrapli/channel/base_channel.py", line 432, in _ssh_message_handler
    raise ScrapliAuthenticationFailed(msg)
scrapli.exceptions.ScrapliAuthenticationFailed: Host key verification failed

2023-02-25 07:21:13,021 - nornir.core.task -    ERROR -      start() - Host 'R6': task 'test' failed with traceback:
Traceback (most recent call last):
  File "/home/ipvzero/Nornir/.venv/lib/python3.10/site-packages/nornir/core/task.py", line 99, in start
    r = self.task(self, **self.params)
  File "/home/ipvzero/Nornir/Backups-Napalm/push-archive.py", line 16, in test
    task.run(task=send_configs_from_file, file='napalm-startup.txt')
  File "/home/ipvzero/Nornir/.venv/lib/python3.10/site-packages/nornir/core/task.py", line 174, in run
    raise NornirSubTaskError(task=run_task, result=r)
nornir.core.exceptions.NornirSubTaskError: Subtask: send_configs_from_file (failed)


2023-02-25 07:21:13,027 - nornir.core.task -    ERROR -      start() - Host 'R5': task 'send_configs_from_file' failed with traceback:
Traceback (most recent call last):
  File "/home/ipvzero/Nornir/.venv/lib/python3.10/site-packages/nornir/core/task.py", line 99, in start
    r = self.task(self, **self.params)
  File "/home/ipvzero/Nornir/.venv/lib/python3.10/site-packages/nornir_scrapli/tasks/core/send_configs_from_file.py", line 58, in send_configs_from_file
    scrapli_conn = task.host.get_connection("scrapli", task.nornir.config)
  File "/home/ipvzero/Nornir/.venv/lib/python3.10/site-packages/nornir/core/inventory.py", line 494, in get_connection
    self.open_connection(
  File "/home/ipvzero/Nornir/.venv/lib/python3.10/site-packages/nornir/core/inventory.py", line 546, in open_connection
    conn_obj.open(
  File "/home/ipvzero/Nornir/.venv/lib/python3.10/site-packages/nornir_scrapli/connection.py", line 105, in open
    connection.open()
  File "/home/ipvzero/Nornir/.venv/lib/python3.10/site-packages/scrapli/driver/base/sync_driver.py", line 88, in open
    self.channel.channel_authenticate_ssh(
  File "/home/ipvzero/Nornir/.venv/lib/python3.10/site-packages/scrapli/decorators.py", line 216, in decorate
    return _multiprocessing_timeout(
  File "/home/ipvzero/Nornir/.venv/lib/python3.10/site-packages/scrapli/decorators.py", line 113, in _multiprocessing_timeout
    return future.result()
  File "/usr/lib/python3.10/concurrent/futures/_base.py", line 451, in result
    return self.__get_result()
  File "/usr/lib/python3.10/concurrent/futures/_base.py", line 403, in __get_result
    raise self._exception
  File "/usr/lib/python3.10/concurrent/futures/thread.py", line 58, in run
    result = self.fn(*self.args, **self.kwargs)
  File "/home/ipvzero/Nornir/.venv/lib/python3.10/site-packages/scrapli/channel/sync_channel.py", line 290, in channel_authenticate_ssh
    self._ssh_message_handler(output=authenticate_buf)
  File "/home/ipvzero/Nornir/.venv/lib/python3.10/site-packages/scrapli/channel/base_channel.py", line 432, in _ssh_message_handler
    raise ScrapliAuthenticationFailed(msg)
scrapli.exceptions.ScrapliAuthenticationFailed: Host key verification failed

2023-02-25 07:21:13,027 - nornir.core.task -    ERROR -      start() - Host 'R5': task 'test' failed with traceback:
Traceback (most recent call last):
  File "/home/ipvzero/Nornir/.venv/lib/python3.10/site-packages/nornir/core/task.py", line 99, in start
    r = self.task(self, **self.params)
  File "/home/ipvzero/Nornir/Backups-Napalm/push-archive.py", line 16, in test
    task.run(task=send_configs_from_file, file='napalm-startup.txt')
  File "/home/ipvzero/Nornir/.venv/lib/python3.10/site-packages/nornir/core/task.py", line 174, in run
    raise NornirSubTaskError(task=run_task, result=r)
nornir.core.exceptions.NornirSubTaskError: Subtask: send_configs_from_file (failed)


2023-02-25 07:23:25,069 -  nornir.core -     INFO -        run() - Running task 'test' with args {} on 7 hosts
2023-02-26 05:00:09,196 -  nornir.core -     INFO -        run() - Running task 'replace_stuff' with args {} on 7 hosts
2023-02-26 05:00:31,150 - nornir.core.task -    ERROR -      start() - Host 'R2': task 'napalm_configure' failed with traceback:
Traceback (most recent call last):
  File "/home/ipvzero/Nornir/.venv/lib/python3.10/site-packages/nornir/core/task.py", line 99, in start
    r = self.task(self, **self.params)
  File "/home/ipvzero/Nornir/.venv/lib/python3.10/site-packages/nornir_napalm/plugins/tasks/napalm_configure.py", line 36, in napalm_configure
    diff = device.compare_config()
  File "/home/ipvzero/Nornir/.venv/lib/python3.10/site-packages/napalm/ios/ios.py", line 421, in compare_config
    diff = self.device.send_command(cmd)
  File "/home/ipvzero/Nornir/.venv/lib/python3.10/site-packages/netmiko/utilities.py", line 592, in wrapper_decorator
    return func(self, *args, **kwargs)
  File "/home/ipvzero/Nornir/.venv/lib/python3.10/site-packages/netmiko/base_connection.py", line 1721, in send_command
    raise ReadTimeout(msg)
netmiko.exceptions.ReadTimeout: 
Pattern not detected: 'R2\\#' in output.

Things you might try to fix this:
1. Explicitly set your pattern using the expect_string argument.
2. Increase the read_timeout to a larger value.

You can also look at the Netmiko session_log or debug log for more information.



2023-02-26 05:00:31,151 - nornir.core.task -    ERROR -      start() - Host 'R2': task 'replace_stuff' failed with traceback:
Traceback (most recent call last):
  File "/home/ipvzero/Nornir/.venv/lib/python3.10/site-packages/nornir/core/task.py", line 99, in start
    r = self.task(self, **self.params)
  File "/home/ipvzero/Nornir/Backups-Napalm/replace_test.py", line 8, in replace_stuff
    task.run(task=napalm_configure, filename=f"backup-directory/{task.host}.txt", replace=True)
  File "/home/ipvzero/Nornir/.venv/lib/python3.10/site-packages/nornir/core/task.py", line 174, in run
    raise NornirSubTaskError(task=run_task, result=r)
nornir.core.exceptions.NornirSubTaskError: Subtask: napalm_configure (failed)


2023-02-26 05:00:31,673 - nornir.core.task -    ERROR -      start() - Host 'R4': task 'napalm_configure' failed with traceback:
Traceback (most recent call last):
  File "/home/ipvzero/Nornir/.venv/lib/python3.10/site-packages/nornir/core/task.py", line 99, in start
    r = self.task(self, **self.params)
  File "/home/ipvzero/Nornir/.venv/lib/python3.10/site-packages/nornir_napalm/plugins/tasks/napalm_configure.py", line 36, in napalm_configure
    diff = device.compare_config()
  File "/home/ipvzero/Nornir/.venv/lib/python3.10/site-packages/napalm/ios/ios.py", line 421, in compare_config
    diff = self.device.send_command(cmd)
  File "/home/ipvzero/Nornir/.venv/lib/python3.10/site-packages/netmiko/utilities.py", line 592, in wrapper_decorator
    return func(self, *args, **kwargs)
  File "/home/ipvzero/Nornir/.venv/lib/python3.10/site-packages/netmiko/base_connection.py", line 1721, in send_command
    raise ReadTimeout(msg)
netmiko.exceptions.ReadTimeout: 
Pattern not detected: 'R4\\#' in output.

Things you might try to fix this:
1. Explicitly set your pattern using the expect_string argument.
2. Increase the read_timeout to a larger value.

You can also look at the Netmiko session_log or debug log for more information.



2023-02-26 05:00:31,674 - nornir.core.task -    ERROR -      start() - Host 'R4': task 'replace_stuff' failed with traceback:
Traceback (most recent call last):
  File "/home/ipvzero/Nornir/.venv/lib/python3.10/site-packages/nornir/core/task.py", line 99, in start
    r = self.task(self, **self.params)
  File "/home/ipvzero/Nornir/Backups-Napalm/replace_test.py", line 8, in replace_stuff
    task.run(task=napalm_configure, filename=f"backup-directory/{task.host}.txt", replace=True)
  File "/home/ipvzero/Nornir/.venv/lib/python3.10/site-packages/nornir/core/task.py", line 174, in run
    raise NornirSubTaskError(task=run_task, result=r)
nornir.core.exceptions.NornirSubTaskError: Subtask: napalm_configure (failed)


2023-02-26 05:00:46,172 - nornir.core.task -    ERROR -      start() - Host 'R3': task 'napalm_configure' failed with traceback:
Traceback (most recent call last):
  File "/home/ipvzero/Nornir/.venv/lib/python3.10/site-packages/nornir/core/task.py", line 99, in start
    r = self.task(self, **self.params)
  File "/home/ipvzero/Nornir/.venv/lib/python3.10/site-packages/nornir_napalm/plugins/tasks/napalm_configure.py", line 43, in napalm_configure
    device.commit_config()
  File "/home/ipvzero/Nornir/.venv/lib/python3.10/site-packages/napalm/ios/ios.py", line 559, in commit_config
    output = self._commit_handler(cmd)
  File "/home/ipvzero/Nornir/.venv/lib/python3.10/site-packages/napalm/ios/ios.py", line 467, in wrapper
    return f(self, *args, **kwargs)
  File "/home/ipvzero/Nornir/.venv/lib/python3.10/site-packages/napalm/ios/ios.py", line 484, in _commit_handler
    output = self.device.send_command(cmd, expect_string=patterns)
  File "/home/ipvzero/Nornir/.venv/lib/python3.10/site-packages/netmiko/utilities.py", line 592, in wrapper_decorator
    return func(self, *args, **kwargs)
  File "/home/ipvzero/Nornir/.venv/lib/python3.10/site-packages/netmiko/base_connection.py", line 1721, in send_command
    raise ReadTimeout(msg)
netmiko.exceptions.ReadTimeout: 
Pattern not detected: '(?:[>##]\\s*$|.*all username.*confirm)' in output.

Things you might try to fix this:
1. Explicitly set your pattern using the expect_string argument.
2. Increase the read_timeout to a larger value.

You can also look at the Netmiko session_log or debug log for more information.



2023-02-26 05:00:46,172 - nornir.core.task -    ERROR -      start() - Host 'R3': task 'replace_stuff' failed with traceback:
Traceback (most recent call last):
  File "/home/ipvzero/Nornir/.venv/lib/python3.10/site-packages/nornir/core/task.py", line 99, in start
    r = self.task(self, **self.params)
  File "/home/ipvzero/Nornir/Backups-Napalm/replace_test.py", line 8, in replace_stuff
    task.run(task=napalm_configure, filename=f"backup-directory/{task.host}.txt", replace=True)
  File "/home/ipvzero/Nornir/.venv/lib/python3.10/site-packages/nornir/core/task.py", line 174, in run
    raise NornirSubTaskError(task=run_task, result=r)
nornir.core.exceptions.NornirSubTaskError: Subtask: napalm_configure (failed)


2023-02-26 05:00:48,723 - nornir.core.task -    ERROR -      start() - Host 'R6': task 'napalm_configure' failed with traceback:
Traceback (most recent call last):
  File "/home/ipvzero/Nornir/.venv/lib/python3.10/site-packages/nornir/core/task.py", line 99, in start
    r = self.task(self, **self.params)
  File "/home/ipvzero/Nornir/.venv/lib/python3.10/site-packages/nornir_napalm/plugins/tasks/napalm_configure.py", line 43, in napalm_configure
    device.commit_config()
  File "/home/ipvzero/Nornir/.venv/lib/python3.10/site-packages/napalm/ios/ios.py", line 559, in commit_config
    output = self._commit_handler(cmd)
  File "/home/ipvzero/Nornir/.venv/lib/python3.10/site-packages/napalm/ios/ios.py", line 467, in wrapper
    return f(self, *args, **kwargs)
  File "/home/ipvzero/Nornir/.venv/lib/python3.10/site-packages/napalm/ios/ios.py", line 484, in _commit_handler
    output = self.device.send_command(cmd, expect_string=patterns)
  File "/home/ipvzero/Nornir/.venv/lib/python3.10/site-packages/netmiko/utilities.py", line 592, in wrapper_decorator
    return func(self, *args, **kwargs)
  File "/home/ipvzero/Nornir/.venv/lib/python3.10/site-packages/netmiko/base_connection.py", line 1721, in send_command
    raise ReadTimeout(msg)
netmiko.exceptions.ReadTimeout: 
Pattern not detected: '(?:[>##]\\s*$|.*all username.*confirm)' in output.

Things you might try to fix this:
1. Explicitly set your pattern using the expect_string argument.
2. Increase the read_timeout to a larger value.

You can also look at the Netmiko session_log or debug log for more information.



2023-02-26 05:00:48,723 - nornir.core.task -    ERROR -      start() - Host 'R6': task 'replace_stuff' failed with traceback:
Traceback (most recent call last):
  File "/home/ipvzero/Nornir/.venv/lib/python3.10/site-packages/nornir/core/task.py", line 99, in start
    r = self.task(self, **self.params)
  File "/home/ipvzero/Nornir/Backups-Napalm/replace_test.py", line 8, in replace_stuff
    task.run(task=napalm_configure, filename=f"backup-directory/{task.host}.txt", replace=True)
  File "/home/ipvzero/Nornir/.venv/lib/python3.10/site-packages/nornir/core/task.py", line 174, in run
    raise NornirSubTaskError(task=run_task, result=r)
nornir.core.exceptions.NornirSubTaskError: Subtask: napalm_configure (failed)


2023-02-26 05:00:49,102 - nornir.core.task -    ERROR -      start() - Host 'R5': task 'napalm_configure' failed with traceback:
Traceback (most recent call last):
  File "/home/ipvzero/Nornir/.venv/lib/python3.10/site-packages/nornir/core/task.py", line 99, in start
    r = self.task(self, **self.params)
  File "/home/ipvzero/Nornir/.venv/lib/python3.10/site-packages/nornir_napalm/plugins/tasks/napalm_configure.py", line 43, in napalm_configure
    device.commit_config()
  File "/home/ipvzero/Nornir/.venv/lib/python3.10/site-packages/napalm/ios/ios.py", line 559, in commit_config
    output = self._commit_handler(cmd)
  File "/home/ipvzero/Nornir/.venv/lib/python3.10/site-packages/napalm/ios/ios.py", line 467, in wrapper
    return f(self, *args, **kwargs)
  File "/home/ipvzero/Nornir/.venv/lib/python3.10/site-packages/napalm/ios/ios.py", line 484, in _commit_handler
    output = self.device.send_command(cmd, expect_string=patterns)
  File "/home/ipvzero/Nornir/.venv/lib/python3.10/site-packages/netmiko/utilities.py", line 592, in wrapper_decorator
    return func(self, *args, **kwargs)
  File "/home/ipvzero/Nornir/.venv/lib/python3.10/site-packages/netmiko/base_connection.py", line 1721, in send_command
    raise ReadTimeout(msg)
netmiko.exceptions.ReadTimeout: 
Pattern not detected: '(?:[>##]\\s*$|.*all username.*confirm)' in output.

Things you might try to fix this:
1. Explicitly set your pattern using the expect_string argument.
2. Increase the read_timeout to a larger value.

You can also look at the Netmiko session_log or debug log for more information.



2023-02-26 05:00:49,102 - nornir.core.task -    ERROR -      start() - Host 'R5': task 'replace_stuff' failed with traceback:
Traceback (most recent call last):
  File "/home/ipvzero/Nornir/.venv/lib/python3.10/site-packages/nornir/core/task.py", line 99, in start
    r = self.task(self, **self.params)
  File "/home/ipvzero/Nornir/Backups-Napalm/replace_test.py", line 8, in replace_stuff
    task.run(task=napalm_configure, filename=f"backup-directory/{task.host}.txt", replace=True)
  File "/home/ipvzero/Nornir/.venv/lib/python3.10/site-packages/nornir/core/task.py", line 174, in run
    raise NornirSubTaskError(task=run_task, result=r)
nornir.core.exceptions.NornirSubTaskError: Subtask: napalm_configure (failed)


2023-02-26 05:00:51,684 - nornir.core.task -    ERROR -      start() - Host 'R1': task 'napalm_configure' failed with traceback:
Traceback (most recent call last):
  File "/home/ipvzero/Nornir/.venv/lib/python3.10/site-packages/nornir/core/task.py", line 99, in start
    r = self.task(self, **self.params)
  File "/home/ipvzero/Nornir/.venv/lib/python3.10/site-packages/nornir_napalm/plugins/tasks/napalm_configure.py", line 43, in napalm_configure
    device.commit_config()
  File "/home/ipvzero/Nornir/.venv/lib/python3.10/site-packages/napalm/ios/ios.py", line 559, in commit_config
    output = self._commit_handler(cmd)
  File "/home/ipvzero/Nornir/.venv/lib/python3.10/site-packages/napalm/ios/ios.py", line 467, in wrapper
    return f(self, *args, **kwargs)
  File "/home/ipvzero/Nornir/.venv/lib/python3.10/site-packages/napalm/ios/ios.py", line 484, in _commit_handler
    output = self.device.send_command(cmd, expect_string=patterns)
  File "/home/ipvzero/Nornir/.venv/lib/python3.10/site-packages/netmiko/utilities.py", line 592, in wrapper_decorator
    return func(self, *args, **kwargs)
  File "/home/ipvzero/Nornir/.venv/lib/python3.10/site-packages/netmiko/base_connection.py", line 1721, in send_command
    raise ReadTimeout(msg)
netmiko.exceptions.ReadTimeout: 
Pattern not detected: '(?:[>##]\\s*$|.*all username.*confirm)' in output.

Things you might try to fix this:
1. Explicitly set your pattern using the expect_string argument.
2. Increase the read_timeout to a larger value.

You can also look at the Netmiko session_log or debug log for more information.



2023-02-26 05:00:51,685 - nornir.core.task -    ERROR -      start() - Host 'R1': task 'replace_stuff' failed with traceback:
Traceback (most recent call last):
  File "/home/ipvzero/Nornir/.venv/lib/python3.10/site-packages/nornir/core/task.py", line 99, in start
    r = self.task(self, **self.params)
  File "/home/ipvzero/Nornir/Backups-Napalm/replace_test.py", line 8, in replace_stuff
    task.run(task=napalm_configure, filename=f"backup-directory/{task.host}.txt", replace=True)
  File "/home/ipvzero/Nornir/.venv/lib/python3.10/site-packages/nornir/core/task.py", line 174, in run
    raise NornirSubTaskError(task=run_task, result=r)
nornir.core.exceptions.NornirSubTaskError: Subtask: napalm_configure (failed)


2023-02-26 05:00:52,442 - nornir.core.task -    ERROR -      start() - Host 'R7': task 'napalm_configure' failed with traceback:
Traceback (most recent call last):
  File "/home/ipvzero/Nornir/.venv/lib/python3.10/site-packages/nornir/core/task.py", line 99, in start
    r = self.task(self, **self.params)
  File "/home/ipvzero/Nornir/.venv/lib/python3.10/site-packages/nornir_napalm/plugins/tasks/napalm_configure.py", line 43, in napalm_configure
    device.commit_config()
  File "/home/ipvzero/Nornir/.venv/lib/python3.10/site-packages/napalm/ios/ios.py", line 559, in commit_config
    output = self._commit_handler(cmd)
  File "/home/ipvzero/Nornir/.venv/lib/python3.10/site-packages/napalm/ios/ios.py", line 467, in wrapper
    return f(self, *args, **kwargs)
  File "/home/ipvzero/Nornir/.venv/lib/python3.10/site-packages/napalm/ios/ios.py", line 484, in _commit_handler
    output = self.device.send_command(cmd, expect_string=patterns)
  File "/home/ipvzero/Nornir/.venv/lib/python3.10/site-packages/netmiko/utilities.py", line 592, in wrapper_decorator
    return func(self, *args, **kwargs)
  File "/home/ipvzero/Nornir/.venv/lib/python3.10/site-packages/netmiko/base_connection.py", line 1721, in send_command
    raise ReadTimeout(msg)
netmiko.exceptions.ReadTimeout: 
Pattern not detected: '(?:[>##]\\s*$|.*all username.*confirm)' in output.

Things you might try to fix this:
1. Explicitly set your pattern using the expect_string argument.
2. Increase the read_timeout to a larger value.

You can also look at the Netmiko session_log or debug log for more information.



2023-02-26 05:00:52,443 - nornir.core.task -    ERROR -      start() - Host 'R7': task 'replace_stuff' failed with traceback:
Traceback (most recent call last):
  File "/home/ipvzero/Nornir/.venv/lib/python3.10/site-packages/nornir/core/task.py", line 99, in start
    r = self.task(self, **self.params)
  File "/home/ipvzero/Nornir/Backups-Napalm/replace_test.py", line 8, in replace_stuff
    task.run(task=napalm_configure, filename=f"backup-directory/{task.host}.txt", replace=True)
  File "/home/ipvzero/Nornir/.venv/lib/python3.10/site-packages/nornir/core/task.py", line 174, in run
    raise NornirSubTaskError(task=run_task, result=r)
nornir.core.exceptions.NornirSubTaskError: Subtask: napalm_configure (failed)


2023-02-26 05:05:56,334 -  nornir.core -     INFO -        run() - Running task 'replace_stuff' with args {} on 4 hosts
2023-02-26 05:06:09,830 - nornir.core.task -    ERROR -      start() - Host 'R1': task 'napalm_configure' failed with traceback:
Traceback (most recent call last):
  File "/home/ipvzero/Nornir/.venv/lib/python3.10/site-packages/nornir/core/task.py", line 99, in start
    r = self.task(self, **self.params)
  File "/home/ipvzero/Nornir/.venv/lib/python3.10/site-packages/nornir_napalm/plugins/tasks/napalm_configure.py", line 43, in napalm_configure
    device.commit_config()
  File "/home/ipvzero/Nornir/.venv/lib/python3.10/site-packages/napalm/ios/ios.py", line 573, in commit_config
    raise ReplaceConfigException(msg)
napalm.base.exceptions.ReplaceConfigException: napalm-ios replace() requires Cisco 'archive' feature to be enabled

2023-02-26 05:06:09,830 - nornir.core.task -    ERROR -      start() - Host 'R1': task 'replace_stuff' failed with traceback:
Traceback (most recent call last):
  File "/home/ipvzero/Nornir/.venv/lib/python3.10/site-packages/nornir/core/task.py", line 99, in start
    r = self.task(self, **self.params)
  File "/home/ipvzero/Nornir/Backups-Napalm/replace_test.py", line 8, in replace_stuff
    task.run(task=napalm_configure, filename=f"backup-directory/{task.host}.txt", replace=True)
  File "/home/ipvzero/Nornir/.venv/lib/python3.10/site-packages/nornir/core/task.py", line 174, in run
    raise NornirSubTaskError(task=run_task, result=r)
nornir.core.exceptions.NornirSubTaskError: Subtask: napalm_configure (failed)


2023-02-26 05:06:17,564 - nornir.core.task -    ERROR -      start() - Host 'R2': task 'napalm_configure' failed with traceback:
Traceback (most recent call last):
  File "/home/ipvzero/Nornir/.venv/lib/python3.10/site-packages/nornir/core/task.py", line 99, in start
    r = self.task(self, **self.params)
  File "/home/ipvzero/Nornir/.venv/lib/python3.10/site-packages/nornir_napalm/plugins/tasks/napalm_configure.py", line 43, in napalm_configure
    device.commit_config()
  File "/home/ipvzero/Nornir/.venv/lib/python3.10/site-packages/napalm/ios/ios.py", line 559, in commit_config
    output = self._commit_handler(cmd)
  File "/home/ipvzero/Nornir/.venv/lib/python3.10/site-packages/napalm/ios/ios.py", line 467, in wrapper
    return f(self, *args, **kwargs)
  File "/home/ipvzero/Nornir/.venv/lib/python3.10/site-packages/napalm/ios/ios.py", line 484, in _commit_handler
    output = self.device.send_command(cmd, expect_string=patterns)
  File "/home/ipvzero/Nornir/.venv/lib/python3.10/site-packages/netmiko/utilities.py", line 592, in wrapper_decorator
    return func(self, *args, **kwargs)
  File "/home/ipvzero/Nornir/.venv/lib/python3.10/site-packages/netmiko/base_connection.py", line 1721, in send_command
    raise ReadTimeout(msg)
netmiko.exceptions.ReadTimeout: 
Pattern not detected: '(?:[>##]\\s*$|.*all username.*confirm)' in output.

Things you might try to fix this:
1. Explicitly set your pattern using the expect_string argument.
2. Increase the read_timeout to a larger value.

You can also look at the Netmiko session_log or debug log for more information.



2023-02-26 05:06:17,565 - nornir.core.task -    ERROR -      start() - Host 'R2': task 'replace_stuff' failed with traceback:
Traceback (most recent call last):
  File "/home/ipvzero/Nornir/.venv/lib/python3.10/site-packages/nornir/core/task.py", line 99, in start
    r = self.task(self, **self.params)
  File "/home/ipvzero/Nornir/Backups-Napalm/replace_test.py", line 8, in replace_stuff
    task.run(task=napalm_configure, filename=f"backup-directory/{task.host}.txt", replace=True)
  File "/home/ipvzero/Nornir/.venv/lib/python3.10/site-packages/nornir/core/task.py", line 174, in run
    raise NornirSubTaskError(task=run_task, result=r)
nornir.core.exceptions.NornirSubTaskError: Subtask: napalm_configure (failed)


2023-02-26 05:06:18,340 - nornir.core.task -    ERROR -      start() - Host 'R3': task 'napalm_configure' failed with traceback:
Traceback (most recent call last):
  File "/home/ipvzero/Nornir/.venv/lib/python3.10/site-packages/nornir/core/task.py", line 99, in start
    r = self.task(self, **self.params)
  File "/home/ipvzero/Nornir/.venv/lib/python3.10/site-packages/nornir_napalm/plugins/tasks/napalm_configure.py", line 43, in napalm_configure
    device.commit_config()
  File "/home/ipvzero/Nornir/.venv/lib/python3.10/site-packages/napalm/ios/ios.py", line 559, in commit_config
    output = self._commit_handler(cmd)
  File "/home/ipvzero/Nornir/.venv/lib/python3.10/site-packages/napalm/ios/ios.py", line 467, in wrapper
    return f(self, *args, **kwargs)
  File "/home/ipvzero/Nornir/.venv/lib/python3.10/site-packages/napalm/ios/ios.py", line 484, in _commit_handler
    output = self.device.send_command(cmd, expect_string=patterns)
  File "/home/ipvzero/Nornir/.venv/lib/python3.10/site-packages/netmiko/utilities.py", line 592, in wrapper_decorator
    return func(self, *args, **kwargs)
  File "/home/ipvzero/Nornir/.venv/lib/python3.10/site-packages/netmiko/base_connection.py", line 1721, in send_command
    raise ReadTimeout(msg)
netmiko.exceptions.ReadTimeout: 
Pattern not detected: '(?:[>##]\\s*$|.*all username.*confirm)' in output.

Things you might try to fix this:
1. Explicitly set your pattern using the expect_string argument.
2. Increase the read_timeout to a larger value.

You can also look at the Netmiko session_log or debug log for more information.



2023-02-26 05:06:18,341 - nornir.core.task -    ERROR -      start() - Host 'R3': task 'replace_stuff' failed with traceback:
Traceback (most recent call last):
  File "/home/ipvzero/Nornir/.venv/lib/python3.10/site-packages/nornir/core/task.py", line 99, in start
    r = self.task(self, **self.params)
  File "/home/ipvzero/Nornir/Backups-Napalm/replace_test.py", line 8, in replace_stuff
    task.run(task=napalm_configure, filename=f"backup-directory/{task.host}.txt", replace=True)
  File "/home/ipvzero/Nornir/.venv/lib/python3.10/site-packages/nornir/core/task.py", line 174, in run
    raise NornirSubTaskError(task=run_task, result=r)
nornir.core.exceptions.NornirSubTaskError: Subtask: napalm_configure (failed)


2023-02-26 05:06:18,675 - nornir.core.task -    ERROR -      start() - Host 'R4': task 'napalm_configure' failed with traceback:
Traceback (most recent call last):
  File "/home/ipvzero/Nornir/.venv/lib/python3.10/site-packages/nornir/core/task.py", line 99, in start
    r = self.task(self, **self.params)
  File "/home/ipvzero/Nornir/.venv/lib/python3.10/site-packages/nornir_napalm/plugins/tasks/napalm_configure.py", line 43, in napalm_configure
    device.commit_config()
  File "/home/ipvzero/Nornir/.venv/lib/python3.10/site-packages/napalm/ios/ios.py", line 559, in commit_config
    output = self._commit_handler(cmd)
  File "/home/ipvzero/Nornir/.venv/lib/python3.10/site-packages/napalm/ios/ios.py", line 467, in wrapper
    return f(self, *args, **kwargs)
  File "/home/ipvzero/Nornir/.venv/lib/python3.10/site-packages/napalm/ios/ios.py", line 484, in _commit_handler
    output = self.device.send_command(cmd, expect_string=patterns)
  File "/home/ipvzero/Nornir/.venv/lib/python3.10/site-packages/netmiko/utilities.py", line 592, in wrapper_decorator
    return func(self, *args, **kwargs)
  File "/home/ipvzero/Nornir/.venv/lib/python3.10/site-packages/netmiko/base_connection.py", line 1721, in send_command
    raise ReadTimeout(msg)
netmiko.exceptions.ReadTimeout: 
Pattern not detected: '(?:[>##]\\s*$|.*all username.*confirm)' in output.

Things you might try to fix this:
1. Explicitly set your pattern using the expect_string argument.
2. Increase the read_timeout to a larger value.

You can also look at the Netmiko session_log or debug log for more information.



2023-02-26 05:06:18,675 - nornir.core.task -    ERROR -      start() - Host 'R4': task 'replace_stuff' failed with traceback:
Traceback (most recent call last):
  File "/home/ipvzero/Nornir/.venv/lib/python3.10/site-packages/nornir/core/task.py", line 99, in start
    r = self.task(self, **self.params)
  File "/home/ipvzero/Nornir/Backups-Napalm/replace_test.py", line 8, in replace_stuff
    task.run(task=napalm_configure, filename=f"backup-directory/{task.host}.txt", replace=True)
  File "/home/ipvzero/Nornir/.venv/lib/python3.10/site-packages/nornir/core/task.py", line 174, in run
    raise NornirSubTaskError(task=run_task, result=r)
nornir.core.exceptions.NornirSubTaskError: Subtask: napalm_configure (failed)


2023-02-26 05:10:23,449 -  nornir.core -     INFO -        run() - Running task 'replace_stuff' with args {} on 4 hosts
2023-02-26 05:10:37,273 - nornir.core.task -    ERROR -      start() - Host 'R1': task 'napalm_configure' failed with traceback:
Traceback (most recent call last):
  File "/home/ipvzero/Nornir/.venv/lib/python3.10/site-packages/nornir/core/task.py", line 99, in start
    r = self.task(self, **self.params)
  File "/home/ipvzero/Nornir/.venv/lib/python3.10/site-packages/nornir_napalm/plugins/tasks/napalm_configure.py", line 43, in napalm_configure
    device.commit_config()
  File "/home/ipvzero/Nornir/.venv/lib/python3.10/site-packages/napalm/ios/ios.py", line 573, in commit_config
    raise ReplaceConfigException(msg)
napalm.base.exceptions.ReplaceConfigException: napalm-ios replace() requires Cisco 'archive' feature to be enabled

2023-02-26 05:10:37,273 - nornir.core.task -    ERROR -      start() - Host 'R1': task 'replace_stuff' failed with traceback:
Traceback (most recent call last):
  File "/home/ipvzero/Nornir/.venv/lib/python3.10/site-packages/nornir/core/task.py", line 99, in start
    r = self.task(self, **self.params)
  File "/home/ipvzero/Nornir/Backups-Napalm/replace_test.py", line 8, in replace_stuff
    task.run(task=napalm_configure, filename=f"backup-directory/{task.host}.txt", replace=True)
  File "/home/ipvzero/Nornir/.venv/lib/python3.10/site-packages/nornir/core/task.py", line 174, in run
    raise NornirSubTaskError(task=run_task, result=r)
nornir.core.exceptions.NornirSubTaskError: Subtask: napalm_configure (failed)


2023-02-26 05:10:47,737 - nornir.core.task -    ERROR -      start() - Host 'R2': task 'napalm_configure' failed with traceback:
Traceback (most recent call last):
  File "/home/ipvzero/Nornir/.venv/lib/python3.10/site-packages/nornir/core/task.py", line 99, in start
    r = self.task(self, **self.params)
  File "/home/ipvzero/Nornir/.venv/lib/python3.10/site-packages/nornir_napalm/plugins/tasks/napalm_configure.py", line 43, in napalm_configure
    device.commit_config()
  File "/home/ipvzero/Nornir/.venv/lib/python3.10/site-packages/napalm/ios/ios.py", line 559, in commit_config
    output = self._commit_handler(cmd)
  File "/home/ipvzero/Nornir/.venv/lib/python3.10/site-packages/napalm/ios/ios.py", line 467, in wrapper
    return f(self, *args, **kwargs)
  File "/home/ipvzero/Nornir/.venv/lib/python3.10/site-packages/napalm/ios/ios.py", line 484, in _commit_handler
    output = self.device.send_command(cmd, expect_string=patterns)
  File "/home/ipvzero/Nornir/.venv/lib/python3.10/site-packages/netmiko/utilities.py", line 592, in wrapper_decorator
    return func(self, *args, **kwargs)
  File "/home/ipvzero/Nornir/.venv/lib/python3.10/site-packages/netmiko/base_connection.py", line 1721, in send_command
    raise ReadTimeout(msg)
netmiko.exceptions.ReadTimeout: 
Pattern not detected: '(?:[>##]\\s*$|.*all username.*confirm)' in output.

Things you might try to fix this:
1. Explicitly set your pattern using the expect_string argument.
2. Increase the read_timeout to a larger value.

You can also look at the Netmiko session_log or debug log for more information.



2023-02-26 05:10:47,738 - nornir.core.task -    ERROR -      start() - Host 'R2': task 'replace_stuff' failed with traceback:
Traceback (most recent call last):
  File "/home/ipvzero/Nornir/.venv/lib/python3.10/site-packages/nornir/core/task.py", line 99, in start
    r = self.task(self, **self.params)
  File "/home/ipvzero/Nornir/Backups-Napalm/replace_test.py", line 8, in replace_stuff
    task.run(task=napalm_configure, filename=f"backup-directory/{task.host}.txt", replace=True)
  File "/home/ipvzero/Nornir/.venv/lib/python3.10/site-packages/nornir/core/task.py", line 174, in run
    raise NornirSubTaskError(task=run_task, result=r)
nornir.core.exceptions.NornirSubTaskError: Subtask: napalm_configure (failed)


2023-02-26 05:10:47,810 - nornir.core.task -    ERROR -      start() - Host 'R4': task 'napalm_configure' failed with traceback:
Traceback (most recent call last):
  File "/home/ipvzero/Nornir/.venv/lib/python3.10/site-packages/nornir/core/task.py", line 99, in start
    r = self.task(self, **self.params)
  File "/home/ipvzero/Nornir/.venv/lib/python3.10/site-packages/nornir_napalm/plugins/tasks/napalm_configure.py", line 43, in napalm_configure
    device.commit_config()
  File "/home/ipvzero/Nornir/.venv/lib/python3.10/site-packages/napalm/ios/ios.py", line 559, in commit_config
    output = self._commit_handler(cmd)
  File "/home/ipvzero/Nornir/.venv/lib/python3.10/site-packages/napalm/ios/ios.py", line 467, in wrapper
    return f(self, *args, **kwargs)
  File "/home/ipvzero/Nornir/.venv/lib/python3.10/site-packages/napalm/ios/ios.py", line 484, in _commit_handler
    output = self.device.send_command(cmd, expect_string=patterns)
  File "/home/ipvzero/Nornir/.venv/lib/python3.10/site-packages/netmiko/utilities.py", line 592, in wrapper_decorator
    return func(self, *args, **kwargs)
  File "/home/ipvzero/Nornir/.venv/lib/python3.10/site-packages/netmiko/base_connection.py", line 1721, in send_command
    raise ReadTimeout(msg)
netmiko.exceptions.ReadTimeout: 
Pattern not detected: '(?:[>##]\\s*$|.*all username.*confirm)' in output.

Things you might try to fix this:
1. Explicitly set your pattern using the expect_string argument.
2. Increase the read_timeout to a larger value.

You can also look at the Netmiko session_log or debug log for more information.



2023-02-26 05:10:47,811 - nornir.core.task -    ERROR -      start() - Host 'R4': task 'replace_stuff' failed with traceback:
Traceback (most recent call last):
  File "/home/ipvzero/Nornir/.venv/lib/python3.10/site-packages/nornir/core/task.py", line 99, in start
    r = self.task(self, **self.params)
  File "/home/ipvzero/Nornir/Backups-Napalm/replace_test.py", line 8, in replace_stuff
    task.run(task=napalm_configure, filename=f"backup-directory/{task.host}.txt", replace=True)
  File "/home/ipvzero/Nornir/.venv/lib/python3.10/site-packages/nornir/core/task.py", line 174, in run
    raise NornirSubTaskError(task=run_task, result=r)
nornir.core.exceptions.NornirSubTaskError: Subtask: napalm_configure (failed)


2023-02-26 05:10:50,140 - nornir.core.task -    ERROR -      start() - Host 'R3': task 'napalm_configure' failed with traceback:
Traceback (most recent call last):
  File "/home/ipvzero/Nornir/.venv/lib/python3.10/site-packages/nornir/core/task.py", line 99, in start
    r = self.task(self, **self.params)
  File "/home/ipvzero/Nornir/.venv/lib/python3.10/site-packages/nornir_napalm/plugins/tasks/napalm_configure.py", line 43, in napalm_configure
    device.commit_config()
  File "/home/ipvzero/Nornir/.venv/lib/python3.10/site-packages/napalm/ios/ios.py", line 559, in commit_config
    output = self._commit_handler(cmd)
  File "/home/ipvzero/Nornir/.venv/lib/python3.10/site-packages/napalm/ios/ios.py", line 467, in wrapper
    return f(self, *args, **kwargs)
  File "/home/ipvzero/Nornir/.venv/lib/python3.10/site-packages/napalm/ios/ios.py", line 484, in _commit_handler
    output = self.device.send_command(cmd, expect_string=patterns)
  File "/home/ipvzero/Nornir/.venv/lib/python3.10/site-packages/netmiko/utilities.py", line 592, in wrapper_decorator
    return func(self, *args, **kwargs)
  File "/home/ipvzero/Nornir/.venv/lib/python3.10/site-packages/netmiko/base_connection.py", line 1721, in send_command
    raise ReadTimeout(msg)
netmiko.exceptions.ReadTimeout: 
Pattern not detected: '(?:[>##]\\s*$|.*all username.*confirm)' in output.

Things you might try to fix this:
1. Explicitly set your pattern using the expect_string argument.
2. Increase the read_timeout to a larger value.

You can also look at the Netmiko session_log or debug log for more information.



2023-02-26 05:10:50,140 - nornir.core.task -    ERROR -      start() - Host 'R3': task 'replace_stuff' failed with traceback:
Traceback (most recent call last):
  File "/home/ipvzero/Nornir/.venv/lib/python3.10/site-packages/nornir/core/task.py", line 99, in start
    r = self.task(self, **self.params)
  File "/home/ipvzero/Nornir/Backups-Napalm/replace_test.py", line 8, in replace_stuff
    task.run(task=napalm_configure, filename=f"backup-directory/{task.host}.txt", replace=True)
  File "/home/ipvzero/Nornir/.venv/lib/python3.10/site-packages/nornir/core/task.py", line 174, in run
    raise NornirSubTaskError(task=run_task, result=r)
nornir.core.exceptions.NornirSubTaskError: Subtask: napalm_configure (failed)


2023-02-26 05:12:06,998 -  nornir.core -     INFO -        run() - Running task 'replace_stuff' with args {} on 4 hosts
2023-02-26 05:12:18,894 - nornir.core.task -    ERROR -      start() - Host 'R3': task 'napalm_configure' failed with traceback:
Traceback (most recent call last):
  File "/home/ipvzero/Nornir/.venv/lib/python3.10/site-packages/nornir/core/task.py", line 99, in start
    r = self.task(self, **self.params)
  File "/home/ipvzero/Nornir/.venv/lib/python3.10/site-packages/nornir_napalm/plugins/tasks/napalm_configure.py", line 43, in napalm_configure
    device.commit_config()
  File "/home/ipvzero/Nornir/.venv/lib/python3.10/site-packages/napalm/ios/ios.py", line 573, in commit_config
    raise ReplaceConfigException(msg)
napalm.base.exceptions.ReplaceConfigException: napalm-ios replace() requires Cisco 'archive' feature to be enabled

2023-02-26 05:12:18,895 - nornir.core.task -    ERROR -      start() - Host 'R3': task 'replace_stuff' failed with traceback:
Traceback (most recent call last):
  File "/home/ipvzero/Nornir/.venv/lib/python3.10/site-packages/nornir/core/task.py", line 99, in start
    r = self.task(self, **self.params)
  File "/home/ipvzero/Nornir/Backups-Napalm/replace_test.py", line 8, in replace_stuff
    task.run(task=napalm_configure, filename=f"backup-directory/{task.host}.txt", replace=True)
  File "/home/ipvzero/Nornir/.venv/lib/python3.10/site-packages/nornir/core/task.py", line 174, in run
    raise NornirSubTaskError(task=run_task, result=r)
nornir.core.exceptions.NornirSubTaskError: Subtask: napalm_configure (failed)


2023-02-26 05:12:20,224 - nornir.core.task -    ERROR -      start() - Host 'R1': task 'napalm_configure' failed with traceback:
Traceback (most recent call last):
  File "/home/ipvzero/Nornir/.venv/lib/python3.10/site-packages/nornir/core/task.py", line 99, in start
    r = self.task(self, **self.params)
  File "/home/ipvzero/Nornir/.venv/lib/python3.10/site-packages/nornir_napalm/plugins/tasks/napalm_configure.py", line 43, in napalm_configure
    device.commit_config()
  File "/home/ipvzero/Nornir/.venv/lib/python3.10/site-packages/napalm/ios/ios.py", line 573, in commit_config
    raise ReplaceConfigException(msg)
napalm.base.exceptions.ReplaceConfigException: napalm-ios replace() requires Cisco 'archive' feature to be enabled

2023-02-26 05:12:20,225 - nornir.core.task -    ERROR -      start() - Host 'R1': task 'replace_stuff' failed with traceback:
Traceback (most recent call last):
  File "/home/ipvzero/Nornir/.venv/lib/python3.10/site-packages/nornir/core/task.py", line 99, in start
    r = self.task(self, **self.params)
  File "/home/ipvzero/Nornir/Backups-Napalm/replace_test.py", line 8, in replace_stuff
    task.run(task=napalm_configure, filename=f"backup-directory/{task.host}.txt", replace=True)
  File "/home/ipvzero/Nornir/.venv/lib/python3.10/site-packages/nornir/core/task.py", line 174, in run
    raise NornirSubTaskError(task=run_task, result=r)
nornir.core.exceptions.NornirSubTaskError: Subtask: napalm_configure (failed)


2023-02-26 05:12:29,047 - nornir.core.task -    ERROR -      start() - Host 'R4': task 'napalm_configure' failed with traceback:
Traceback (most recent call last):
  File "/home/ipvzero/Nornir/.venv/lib/python3.10/site-packages/nornir/core/task.py", line 99, in start
    r = self.task(self, **self.params)
  File "/home/ipvzero/Nornir/.venv/lib/python3.10/site-packages/nornir_napalm/plugins/tasks/napalm_configure.py", line 43, in napalm_configure
    device.commit_config()
  File "/home/ipvzero/Nornir/.venv/lib/python3.10/site-packages/napalm/ios/ios.py", line 559, in commit_config
    output = self._commit_handler(cmd)
  File "/home/ipvzero/Nornir/.venv/lib/python3.10/site-packages/napalm/ios/ios.py", line 467, in wrapper
    return f(self, *args, **kwargs)
  File "/home/ipvzero/Nornir/.venv/lib/python3.10/site-packages/napalm/ios/ios.py", line 484, in _commit_handler
    output = self.device.send_command(cmd, expect_string=patterns)
  File "/home/ipvzero/Nornir/.venv/lib/python3.10/site-packages/netmiko/utilities.py", line 592, in wrapper_decorator
    return func(self, *args, **kwargs)
  File "/home/ipvzero/Nornir/.venv/lib/python3.10/site-packages/netmiko/base_connection.py", line 1721, in send_command
    raise ReadTimeout(msg)
netmiko.exceptions.ReadTimeout: 
Pattern not detected: '(?:[>##]\\s*$|.*all username.*confirm)' in output.

Things you might try to fix this:
1. Explicitly set your pattern using the expect_string argument.
2. Increase the read_timeout to a larger value.

You can also look at the Netmiko session_log or debug log for more information.



2023-02-26 05:12:29,047 - nornir.core.task -    ERROR -      start() - Host 'R4': task 'replace_stuff' failed with traceback:
Traceback (most recent call last):
  File "/home/ipvzero/Nornir/.venv/lib/python3.10/site-packages/nornir/core/task.py", line 99, in start
    r = self.task(self, **self.params)
  File "/home/ipvzero/Nornir/Backups-Napalm/replace_test.py", line 8, in replace_stuff
    task.run(task=napalm_configure, filename=f"backup-directory/{task.host}.txt", replace=True)
  File "/home/ipvzero/Nornir/.venv/lib/python3.10/site-packages/nornir/core/task.py", line 174, in run
    raise NornirSubTaskError(task=run_task, result=r)
nornir.core.exceptions.NornirSubTaskError: Subtask: napalm_configure (failed)


2023-02-26 05:12:30,614 - nornir.core.task -    ERROR -      start() - Host 'R2': task 'napalm_configure' failed with traceback:
Traceback (most recent call last):
  File "/home/ipvzero/Nornir/.venv/lib/python3.10/site-packages/nornir/core/task.py", line 99, in start
    r = self.task(self, **self.params)
  File "/home/ipvzero/Nornir/.venv/lib/python3.10/site-packages/nornir_napalm/plugins/tasks/napalm_configure.py", line 43, in napalm_configure
    device.commit_config()
  File "/home/ipvzero/Nornir/.venv/lib/python3.10/site-packages/napalm/ios/ios.py", line 559, in commit_config
    output = self._commit_handler(cmd)
  File "/home/ipvzero/Nornir/.venv/lib/python3.10/site-packages/napalm/ios/ios.py", line 467, in wrapper
    return f(self, *args, **kwargs)
  File "/home/ipvzero/Nornir/.venv/lib/python3.10/site-packages/napalm/ios/ios.py", line 484, in _commit_handler
    output = self.device.send_command(cmd, expect_string=patterns)
  File "/home/ipvzero/Nornir/.venv/lib/python3.10/site-packages/netmiko/utilities.py", line 592, in wrapper_decorator
    return func(self, *args, **kwargs)
  File "/home/ipvzero/Nornir/.venv/lib/python3.10/site-packages/netmiko/base_connection.py", line 1721, in send_command
    raise ReadTimeout(msg)
netmiko.exceptions.ReadTimeout: 
Pattern not detected: '(?:[>##]\\s*$|.*all username.*confirm)' in output.

Things you might try to fix this:
1. Explicitly set your pattern using the expect_string argument.
2. Increase the read_timeout to a larger value.

You can also look at the Netmiko session_log or debug log for more information.



2023-02-26 05:12:30,614 - nornir.core.task -    ERROR -      start() - Host 'R2': task 'replace_stuff' failed with traceback:
Traceback (most recent call last):
  File "/home/ipvzero/Nornir/.venv/lib/python3.10/site-packages/nornir/core/task.py", line 99, in start
    r = self.task(self, **self.params)
  File "/home/ipvzero/Nornir/Backups-Napalm/replace_test.py", line 8, in replace_stuff
    task.run(task=napalm_configure, filename=f"backup-directory/{task.host}.txt", replace=True)
  File "/home/ipvzero/Nornir/.venv/lib/python3.10/site-packages/nornir/core/task.py", line 174, in run
    raise NornirSubTaskError(task=run_task, result=r)
nornir.core.exceptions.NornirSubTaskError: Subtask: napalm_configure (failed)


2023-02-26 06:00:50,803 -  nornir.core -     INFO -        run() - Running task 'replace_stuff' with args {} on 4 hosts
2023-02-26 06:01:10,877 - nornir.core.task -    ERROR -      start() - Host 'R4': task 'napalm_configure' failed with traceback:
Traceback (most recent call last):
  File "/home/ipvzero/Nornir/.venv/lib/python3.10/site-packages/nornir/core/task.py", line 99, in start
    r = self.task(self, **self.params)
  File "/home/ipvzero/Nornir/.venv/lib/python3.10/site-packages/nornir_napalm/plugins/tasks/napalm_configure.py", line 36, in napalm_configure
    diff = device.compare_config()
  File "/home/ipvzero/Nornir/.venv/lib/python3.10/site-packages/napalm/ios/ios.py", line 421, in compare_config
    diff = self.device.send_command(cmd)
  File "/home/ipvzero/Nornir/.venv/lib/python3.10/site-packages/netmiko/utilities.py", line 592, in wrapper_decorator
    return func(self, *args, **kwargs)
  File "/home/ipvzero/Nornir/.venv/lib/python3.10/site-packages/netmiko/base_connection.py", line 1721, in send_command
    raise ReadTimeout(msg)
netmiko.exceptions.ReadTimeout: 
Pattern not detected: 'R4\\#' in output.

Things you might try to fix this:
1. Explicitly set your pattern using the expect_string argument.
2. Increase the read_timeout to a larger value.

You can also look at the Netmiko session_log or debug log for more information.



2023-02-26 06:01:10,878 - nornir.core.task -    ERROR -      start() - Host 'R4': task 'replace_stuff' failed with traceback:
Traceback (most recent call last):
  File "/home/ipvzero/Nornir/.venv/lib/python3.10/site-packages/nornir/core/task.py", line 99, in start
    r = self.task(self, **self.params)
  File "/home/ipvzero/Nornir/Backups-Napalm/replace_test.py", line 8, in replace_stuff
    task.run(task=napalm_configure, filename=f"backup-directory/{task.host}.txt", replace=True)
  File "/home/ipvzero/Nornir/.venv/lib/python3.10/site-packages/nornir/core/task.py", line 174, in run
    raise NornirSubTaskError(task=run_task, result=r)
nornir.core.exceptions.NornirSubTaskError: Subtask: napalm_configure (failed)


2023-02-26 06:01:10,877 - nornir.core.task -    ERROR -      start() - Host 'R2': task 'napalm_configure' failed with traceback:
Traceback (most recent call last):
  File "/home/ipvzero/Nornir/.venv/lib/python3.10/site-packages/nornir/core/task.py", line 99, in start
    r = self.task(self, **self.params)
  File "/home/ipvzero/Nornir/.venv/lib/python3.10/site-packages/nornir_napalm/plugins/tasks/napalm_configure.py", line 36, in napalm_configure
    diff = device.compare_config()
  File "/home/ipvzero/Nornir/.venv/lib/python3.10/site-packages/napalm/ios/ios.py", line 421, in compare_config
    diff = self.device.send_command(cmd)
  File "/home/ipvzero/Nornir/.venv/lib/python3.10/site-packages/netmiko/utilities.py", line 592, in wrapper_decorator
    return func(self, *args, **kwargs)
  File "/home/ipvzero/Nornir/.venv/lib/python3.10/site-packages/netmiko/base_connection.py", line 1721, in send_command
    raise ReadTimeout(msg)
netmiko.exceptions.ReadTimeout: 
Pattern not detected: 'R2\\#' in output.

Things you might try to fix this:
1. Explicitly set your pattern using the expect_string argument.
2. Increase the read_timeout to a larger value.

You can also look at the Netmiko session_log or debug log for more information.



2023-02-26 06:01:10,878 - nornir.core.task -    ERROR -      start() - Host 'R2': task 'replace_stuff' failed with traceback:
Traceback (most recent call last):
  File "/home/ipvzero/Nornir/.venv/lib/python3.10/site-packages/nornir/core/task.py", line 99, in start
    r = self.task(self, **self.params)
  File "/home/ipvzero/Nornir/Backups-Napalm/replace_test.py", line 8, in replace_stuff
    task.run(task=napalm_configure, filename=f"backup-directory/{task.host}.txt", replace=True)
  File "/home/ipvzero/Nornir/.venv/lib/python3.10/site-packages/nornir/core/task.py", line 174, in run
    raise NornirSubTaskError(task=run_task, result=r)
nornir.core.exceptions.NornirSubTaskError: Subtask: napalm_configure (failed)


2023-02-26 06:01:23,917 - nornir.core.task -    ERROR -      start() - Host 'R1': task 'napalm_configure' failed with traceback:
Traceback (most recent call last):
  File "/home/ipvzero/Nornir/.venv/lib/python3.10/site-packages/nornir/core/task.py", line 99, in start
    r = self.task(self, **self.params)
  File "/home/ipvzero/Nornir/.venv/lib/python3.10/site-packages/nornir_napalm/plugins/tasks/napalm_configure.py", line 43, in napalm_configure
    device.commit_config()
  File "/home/ipvzero/Nornir/.venv/lib/python3.10/site-packages/napalm/ios/ios.py", line 573, in commit_config
    raise ReplaceConfigException(msg)
napalm.base.exceptions.ReplaceConfigException: napalm-ios replace() requires Cisco 'archive' feature to be enabled

2023-02-26 06:01:23,917 - nornir.core.task -    ERROR -      start() - Host 'R1': task 'replace_stuff' failed with traceback:
Traceback (most recent call last):
  File "/home/ipvzero/Nornir/.venv/lib/python3.10/site-packages/nornir/core/task.py", line 99, in start
    r = self.task(self, **self.params)
  File "/home/ipvzero/Nornir/Backups-Napalm/replace_test.py", line 8, in replace_stuff
    task.run(task=napalm_configure, filename=f"backup-directory/{task.host}.txt", replace=True)
  File "/home/ipvzero/Nornir/.venv/lib/python3.10/site-packages/nornir/core/task.py", line 174, in run
    raise NornirSubTaskError(task=run_task, result=r)
nornir.core.exceptions.NornirSubTaskError: Subtask: napalm_configure (failed)


2023-02-26 06:01:25,550 - nornir.core.task -    ERROR -      start() - Host 'R3': task 'napalm_configure' failed with traceback:
Traceback (most recent call last):
  File "/home/ipvzero/Nornir/.venv/lib/python3.10/site-packages/nornir/core/task.py", line 99, in start
    r = self.task(self, **self.params)
  File "/home/ipvzero/Nornir/.venv/lib/python3.10/site-packages/nornir_napalm/plugins/tasks/napalm_configure.py", line 43, in napalm_configure
    device.commit_config()
  File "/home/ipvzero/Nornir/.venv/lib/python3.10/site-packages/napalm/ios/ios.py", line 573, in commit_config
    raise ReplaceConfigException(msg)
napalm.base.exceptions.ReplaceConfigException: napalm-ios replace() requires Cisco 'archive' feature to be enabled

2023-02-26 06:01:25,551 - nornir.core.task -    ERROR -      start() - Host 'R3': task 'replace_stuff' failed with traceback:
Traceback (most recent call last):
  File "/home/ipvzero/Nornir/.venv/lib/python3.10/site-packages/nornir/core/task.py", line 99, in start
    r = self.task(self, **self.params)
  File "/home/ipvzero/Nornir/Backups-Napalm/replace_test.py", line 8, in replace_stuff
    task.run(task=napalm_configure, filename=f"backup-directory/{task.host}.txt", replace=True)
  File "/home/ipvzero/Nornir/.venv/lib/python3.10/site-packages/nornir/core/task.py", line 174, in run
    raise NornirSubTaskError(task=run_task, result=r)
nornir.core.exceptions.NornirSubTaskError: Subtask: napalm_configure (failed)


2023-02-26 06:02:37,515 -  nornir.core -     INFO -        run() - Running task 'replace_stuff' with args {} on 4 hosts
2023-02-26 06:02:48,050 - nornir.core.task -    ERROR -      start() - Host 'R4': task 'napalm_configure' failed with traceback:
Traceback (most recent call last):
  File "/home/ipvzero/Nornir/.venv/lib/python3.10/site-packages/nornir/core/task.py", line 99, in start
    r = self.task(self, **self.params)
  File "/home/ipvzero/Nornir/.venv/lib/python3.10/site-packages/nornir_napalm/plugins/tasks/napalm_configure.py", line 43, in napalm_configure
    device.commit_config()
  File "/home/ipvzero/Nornir/.venv/lib/python3.10/site-packages/napalm/ios/ios.py", line 573, in commit_config
    raise ReplaceConfigException(msg)
napalm.base.exceptions.ReplaceConfigException: napalm-ios replace() requires Cisco 'archive' feature to be enabled

2023-02-26 06:02:48,050 - nornir.core.task -    ERROR -      start() - Host 'R4': task 'replace_stuff' failed with traceback:
Traceback (most recent call last):
  File "/home/ipvzero/Nornir/.venv/lib/python3.10/site-packages/nornir/core/task.py", line 99, in start
    r = self.task(self, **self.params)
  File "/home/ipvzero/Nornir/Backups-Napalm/replace_test.py", line 8, in replace_stuff
    task.run(task=napalm_configure, filename=f"backup-directory/{task.host}.txt", replace=True)
  File "/home/ipvzero/Nornir/.venv/lib/python3.10/site-packages/nornir/core/task.py", line 174, in run
    raise NornirSubTaskError(task=run_task, result=r)
nornir.core.exceptions.NornirSubTaskError: Subtask: napalm_configure (failed)


2023-02-26 06:02:48,964 - nornir.core.task -    ERROR -      start() - Host 'R2': task 'napalm_configure' failed with traceback:
Traceback (most recent call last):
  File "/home/ipvzero/Nornir/.venv/lib/python3.10/site-packages/nornir/core/task.py", line 99, in start
    r = self.task(self, **self.params)
  File "/home/ipvzero/Nornir/.venv/lib/python3.10/site-packages/nornir_napalm/plugins/tasks/napalm_configure.py", line 43, in napalm_configure
    device.commit_config()
  File "/home/ipvzero/Nornir/.venv/lib/python3.10/site-packages/napalm/ios/ios.py", line 573, in commit_config
    raise ReplaceConfigException(msg)
napalm.base.exceptions.ReplaceConfigException: napalm-ios replace() requires Cisco 'archive' feature to be enabled

2023-02-26 06:02:48,964 - nornir.core.task -    ERROR -      start() - Host 'R2': task 'replace_stuff' failed with traceback:
Traceback (most recent call last):
  File "/home/ipvzero/Nornir/.venv/lib/python3.10/site-packages/nornir/core/task.py", line 99, in start
    r = self.task(self, **self.params)
  File "/home/ipvzero/Nornir/Backups-Napalm/replace_test.py", line 8, in replace_stuff
    task.run(task=napalm_configure, filename=f"backup-directory/{task.host}.txt", replace=True)
  File "/home/ipvzero/Nornir/.venv/lib/python3.10/site-packages/nornir/core/task.py", line 174, in run
    raise NornirSubTaskError(task=run_task, result=r)
nornir.core.exceptions.NornirSubTaskError: Subtask: napalm_configure (failed)


2023-02-26 06:02:49,773 - nornir.core.task -    ERROR -      start() - Host 'R3': task 'napalm_configure' failed with traceback:
Traceback (most recent call last):
  File "/home/ipvzero/Nornir/.venv/lib/python3.10/site-packages/nornir/core/task.py", line 99, in start
    r = self.task(self, **self.params)
  File "/home/ipvzero/Nornir/.venv/lib/python3.10/site-packages/nornir_napalm/plugins/tasks/napalm_configure.py", line 43, in napalm_configure
    device.commit_config()
  File "/home/ipvzero/Nornir/.venv/lib/python3.10/site-packages/napalm/ios/ios.py", line 573, in commit_config
    raise ReplaceConfigException(msg)
napalm.base.exceptions.ReplaceConfigException: napalm-ios replace() requires Cisco 'archive' feature to be enabled

2023-02-26 06:02:49,774 - nornir.core.task -    ERROR -      start() - Host 'R3': task 'replace_stuff' failed with traceback:
Traceback (most recent call last):
  File "/home/ipvzero/Nornir/.venv/lib/python3.10/site-packages/nornir/core/task.py", line 99, in start
    r = self.task(self, **self.params)
  File "/home/ipvzero/Nornir/Backups-Napalm/replace_test.py", line 8, in replace_stuff
    task.run(task=napalm_configure, filename=f"backup-directory/{task.host}.txt", replace=True)
  File "/home/ipvzero/Nornir/.venv/lib/python3.10/site-packages/nornir/core/task.py", line 174, in run
    raise NornirSubTaskError(task=run_task, result=r)
nornir.core.exceptions.NornirSubTaskError: Subtask: napalm_configure (failed)


2023-02-26 06:02:50,302 - nornir.core.task -    ERROR -      start() - Host 'R1': task 'napalm_configure' failed with traceback:
Traceback (most recent call last):
  File "/home/ipvzero/Nornir/.venv/lib/python3.10/site-packages/nornir/core/task.py", line 99, in start
    r = self.task(self, **self.params)
  File "/home/ipvzero/Nornir/.venv/lib/python3.10/site-packages/nornir_napalm/plugins/tasks/napalm_configure.py", line 43, in napalm_configure
    device.commit_config()
  File "/home/ipvzero/Nornir/.venv/lib/python3.10/site-packages/napalm/ios/ios.py", line 573, in commit_config
    raise ReplaceConfigException(msg)
napalm.base.exceptions.ReplaceConfigException: napalm-ios replace() requires Cisco 'archive' feature to be enabled

2023-02-26 06:02:50,302 - nornir.core.task -    ERROR -      start() - Host 'R1': task 'replace_stuff' failed with traceback:
Traceback (most recent call last):
  File "/home/ipvzero/Nornir/.venv/lib/python3.10/site-packages/nornir/core/task.py", line 99, in start
    r = self.task(self, **self.params)
  File "/home/ipvzero/Nornir/Backups-Napalm/replace_test.py", line 8, in replace_stuff
    task.run(task=napalm_configure, filename=f"backup-directory/{task.host}.txt", replace=True)
  File "/home/ipvzero/Nornir/.venv/lib/python3.10/site-packages/nornir/core/task.py", line 174, in run
    raise NornirSubTaskError(task=run_task, result=r)
nornir.core.exceptions.NornirSubTaskError: Subtask: napalm_configure (failed)


2023-02-26 06:03:06,121 -  nornir.core -     INFO -        run() - Running task 'test' with args {} on 4 hosts
2023-02-26 06:03:15,137 -  nornir.core -     INFO -        run() - Running task 'replace_stuff' with args {} on 4 hosts
2023-02-26 06:03:38,906 - nornir.core.task -    ERROR -      start() - Host 'R2': task 'napalm_configure' failed with traceback:
Traceback (most recent call last):
  File "/home/ipvzero/Nornir/.venv/lib/python3.10/site-packages/nornir/core/task.py", line 99, in start
    r = self.task(self, **self.params)
  File "/home/ipvzero/Nornir/.venv/lib/python3.10/site-packages/nornir_napalm/plugins/tasks/napalm_configure.py", line 43, in napalm_configure
    device.commit_config()
  File "/home/ipvzero/Nornir/.venv/lib/python3.10/site-packages/napalm/ios/ios.py", line 559, in commit_config
    output = self._commit_handler(cmd)
  File "/home/ipvzero/Nornir/.venv/lib/python3.10/site-packages/napalm/ios/ios.py", line 467, in wrapper
    return f(self, *args, **kwargs)
  File "/home/ipvzero/Nornir/.venv/lib/python3.10/site-packages/napalm/ios/ios.py", line 484, in _commit_handler
    output = self.device.send_command(cmd, expect_string=patterns)
  File "/home/ipvzero/Nornir/.venv/lib/python3.10/site-packages/netmiko/utilities.py", line 592, in wrapper_decorator
    return func(self, *args, **kwargs)
  File "/home/ipvzero/Nornir/.venv/lib/python3.10/site-packages/netmiko/base_connection.py", line 1721, in send_command
    raise ReadTimeout(msg)
netmiko.exceptions.ReadTimeout: 
Pattern not detected: '(?:[>##]\\s*$|.*all username.*confirm)' in output.

Things you might try to fix this:
1. Explicitly set your pattern using the expect_string argument.
2. Increase the read_timeout to a larger value.

You can also look at the Netmiko session_log or debug log for more information.



2023-02-26 06:03:38,906 - nornir.core.task -    ERROR -      start() - Host 'R2': task 'replace_stuff' failed with traceback:
Traceback (most recent call last):
  File "/home/ipvzero/Nornir/.venv/lib/python3.10/site-packages/nornir/core/task.py", line 99, in start
    r = self.task(self, **self.params)
  File "/home/ipvzero/Nornir/Backups-Napalm/replace_test.py", line 8, in replace_stuff
    task.run(task=napalm_configure, filename=f"backup-directory/{task.host}.txt", replace=True)
  File "/home/ipvzero/Nornir/.venv/lib/python3.10/site-packages/nornir/core/task.py", line 174, in run
    raise NornirSubTaskError(task=run_task, result=r)
nornir.core.exceptions.NornirSubTaskError: Subtask: napalm_configure (failed)


2023-02-26 06:03:39,235 - nornir.core.task -    ERROR -      start() - Host 'R4': task 'napalm_configure' failed with traceback:
Traceback (most recent call last):
  File "/home/ipvzero/Nornir/.venv/lib/python3.10/site-packages/nornir/core/task.py", line 99, in start
    r = self.task(self, **self.params)
  File "/home/ipvzero/Nornir/.venv/lib/python3.10/site-packages/nornir_napalm/plugins/tasks/napalm_configure.py", line 43, in napalm_configure
    device.commit_config()
  File "/home/ipvzero/Nornir/.venv/lib/python3.10/site-packages/napalm/ios/ios.py", line 559, in commit_config
    output = self._commit_handler(cmd)
  File "/home/ipvzero/Nornir/.venv/lib/python3.10/site-packages/napalm/ios/ios.py", line 467, in wrapper
    return f(self, *args, **kwargs)
  File "/home/ipvzero/Nornir/.venv/lib/python3.10/site-packages/napalm/ios/ios.py", line 484, in _commit_handler
    output = self.device.send_command(cmd, expect_string=patterns)
  File "/home/ipvzero/Nornir/.venv/lib/python3.10/site-packages/netmiko/utilities.py", line 592, in wrapper_decorator
    return func(self, *args, **kwargs)
  File "/home/ipvzero/Nornir/.venv/lib/python3.10/site-packages/netmiko/base_connection.py", line 1721, in send_command
    raise ReadTimeout(msg)
netmiko.exceptions.ReadTimeout: 
Pattern not detected: '(?:[>##]\\s*$|.*all username.*confirm)' in output.

Things you might try to fix this:
1. Explicitly set your pattern using the expect_string argument.
2. Increase the read_timeout to a larger value.

You can also look at the Netmiko session_log or debug log for more information.



2023-02-26 06:03:39,235 - nornir.core.task -    ERROR -      start() - Host 'R4': task 'replace_stuff' failed with traceback:
Traceback (most recent call last):
  File "/home/ipvzero/Nornir/.venv/lib/python3.10/site-packages/nornir/core/task.py", line 99, in start
    r = self.task(self, **self.params)
  File "/home/ipvzero/Nornir/Backups-Napalm/replace_test.py", line 8, in replace_stuff
    task.run(task=napalm_configure, filename=f"backup-directory/{task.host}.txt", replace=True)
  File "/home/ipvzero/Nornir/.venv/lib/python3.10/site-packages/nornir/core/task.py", line 174, in run
    raise NornirSubTaskError(task=run_task, result=r)
nornir.core.exceptions.NornirSubTaskError: Subtask: napalm_configure (failed)


2023-02-26 06:03:39,995 - nornir.core.task -    ERROR -      start() - Host 'R1': task 'napalm_configure' failed with traceback:
Traceback (most recent call last):
  File "/home/ipvzero/Nornir/.venv/lib/python3.10/site-packages/nornir/core/task.py", line 99, in start
    r = self.task(self, **self.params)
  File "/home/ipvzero/Nornir/.venv/lib/python3.10/site-packages/nornir_napalm/plugins/tasks/napalm_configure.py", line 43, in napalm_configure
    device.commit_config()
  File "/home/ipvzero/Nornir/.venv/lib/python3.10/site-packages/napalm/ios/ios.py", line 559, in commit_config
    output = self._commit_handler(cmd)
  File "/home/ipvzero/Nornir/.venv/lib/python3.10/site-packages/napalm/ios/ios.py", line 467, in wrapper
    return f(self, *args, **kwargs)
  File "/home/ipvzero/Nornir/.venv/lib/python3.10/site-packages/napalm/ios/ios.py", line 484, in _commit_handler
    output = self.device.send_command(cmd, expect_string=patterns)
  File "/home/ipvzero/Nornir/.venv/lib/python3.10/site-packages/netmiko/utilities.py", line 592, in wrapper_decorator
    return func(self, *args, **kwargs)
  File "/home/ipvzero/Nornir/.venv/lib/python3.10/site-packages/netmiko/base_connection.py", line 1721, in send_command
    raise ReadTimeout(msg)
netmiko.exceptions.ReadTimeout: 
Pattern not detected: '(?:[>##]\\s*$|.*all username.*confirm)' in output.

Things you might try to fix this:
1. Explicitly set your pattern using the expect_string argument.
2. Increase the read_timeout to a larger value.

You can also look at the Netmiko session_log or debug log for more information.



2023-02-26 06:03:39,995 - nornir.core.task -    ERROR -      start() - Host 'R1': task 'replace_stuff' failed with traceback:
Traceback (most recent call last):
  File "/home/ipvzero/Nornir/.venv/lib/python3.10/site-packages/nornir/core/task.py", line 99, in start
    r = self.task(self, **self.params)
  File "/home/ipvzero/Nornir/Backups-Napalm/replace_test.py", line 8, in replace_stuff
    task.run(task=napalm_configure, filename=f"backup-directory/{task.host}.txt", replace=True)
  File "/home/ipvzero/Nornir/.venv/lib/python3.10/site-packages/nornir/core/task.py", line 174, in run
    raise NornirSubTaskError(task=run_task, result=r)
nornir.core.exceptions.NornirSubTaskError: Subtask: napalm_configure (failed)


2023-02-26 06:03:40,906 - nornir.core.task -    ERROR -      start() - Host 'R3': task 'napalm_configure' failed with traceback:
Traceback (most recent call last):
  File "/home/ipvzero/Nornir/.venv/lib/python3.10/site-packages/nornir/core/task.py", line 99, in start
    r = self.task(self, **self.params)
  File "/home/ipvzero/Nornir/.venv/lib/python3.10/site-packages/nornir_napalm/plugins/tasks/napalm_configure.py", line 43, in napalm_configure
    device.commit_config()
  File "/home/ipvzero/Nornir/.venv/lib/python3.10/site-packages/napalm/ios/ios.py", line 559, in commit_config
    output = self._commit_handler(cmd)
  File "/home/ipvzero/Nornir/.venv/lib/python3.10/site-packages/napalm/ios/ios.py", line 467, in wrapper
    return f(self, *args, **kwargs)
  File "/home/ipvzero/Nornir/.venv/lib/python3.10/site-packages/napalm/ios/ios.py", line 484, in _commit_handler
    output = self.device.send_command(cmd, expect_string=patterns)
  File "/home/ipvzero/Nornir/.venv/lib/python3.10/site-packages/netmiko/utilities.py", line 592, in wrapper_decorator
    return func(self, *args, **kwargs)
  File "/home/ipvzero/Nornir/.venv/lib/python3.10/site-packages/netmiko/base_connection.py", line 1721, in send_command
    raise ReadTimeout(msg)
netmiko.exceptions.ReadTimeout: 
Pattern not detected: '(?:[>##]\\s*$|.*all username.*confirm)' in output.

Things you might try to fix this:
1. Explicitly set your pattern using the expect_string argument.
2. Increase the read_timeout to a larger value.

You can also look at the Netmiko session_log or debug log for more information.



2023-02-26 06:03:40,906 - nornir.core.task -    ERROR -      start() - Host 'R3': task 'replace_stuff' failed with traceback:
Traceback (most recent call last):
  File "/home/ipvzero/Nornir/.venv/lib/python3.10/site-packages/nornir/core/task.py", line 99, in start
    r = self.task(self, **self.params)
  File "/home/ipvzero/Nornir/Backups-Napalm/replace_test.py", line 8, in replace_stuff
    task.run(task=napalm_configure, filename=f"backup-directory/{task.host}.txt", replace=True)
  File "/home/ipvzero/Nornir/.venv/lib/python3.10/site-packages/nornir/core/task.py", line 174, in run
    raise NornirSubTaskError(task=run_task, result=r)
nornir.core.exceptions.NornirSubTaskError: Subtask: napalm_configure (failed)


2023-02-26 06:16:36,092 -  nornir.core -     INFO -        run() - Running task 'replace_stuff' with args {} on 4 hosts
2023-02-26 06:16:47,994 - nornir.core.task -    ERROR -      start() - Host 'R3': task 'napalm_configure' failed with traceback:
Traceback (most recent call last):
  File "/home/ipvzero/Nornir/.venv/lib/python3.10/site-packages/nornir/core/task.py", line 99, in start
    r = self.task(self, **self.params)
  File "/home/ipvzero/Nornir/.venv/lib/python3.10/site-packages/nornir_napalm/plugins/tasks/napalm_configure.py", line 43, in napalm_configure
    device.commit_config()
  File "/home/ipvzero/Nornir/.venv/lib/python3.10/site-packages/napalm/ios/ios.py", line 573, in commit_config
    raise ReplaceConfigException(msg)
napalm.base.exceptions.ReplaceConfigException: napalm-ios replace() requires Cisco 'archive' feature to be enabled

2023-02-26 06:16:47,995 - nornir.core.task -    ERROR -      start() - Host 'R3': task 'replace_stuff' failed with traceback:
Traceback (most recent call last):
  File "/home/ipvzero/Nornir/.venv/lib/python3.10/site-packages/nornir/core/task.py", line 99, in start
    r = self.task(self, **self.params)
  File "/home/ipvzero/Nornir/Backups-Napalm/replace_test.py", line 8, in replace_stuff
    task.run(task=napalm_configure, filename=f"backup-directory/{task.host}.txt", replace=True)
  File "/home/ipvzero/Nornir/.venv/lib/python3.10/site-packages/nornir/core/task.py", line 174, in run
    raise NornirSubTaskError(task=run_task, result=r)
nornir.core.exceptions.NornirSubTaskError: Subtask: napalm_configure (failed)


2023-02-26 06:16:58,456 - nornir.core.task -    ERROR -      start() - Host 'R4': task 'napalm_configure' failed with traceback:
Traceback (most recent call last):
  File "/home/ipvzero/Nornir/.venv/lib/python3.10/site-packages/nornir/core/task.py", line 99, in start
    r = self.task(self, **self.params)
  File "/home/ipvzero/Nornir/.venv/lib/python3.10/site-packages/nornir_napalm/plugins/tasks/napalm_configure.py", line 43, in napalm_configure
    device.commit_config()
  File "/home/ipvzero/Nornir/.venv/lib/python3.10/site-packages/napalm/ios/ios.py", line 559, in commit_config
    output = self._commit_handler(cmd)
  File "/home/ipvzero/Nornir/.venv/lib/python3.10/site-packages/napalm/ios/ios.py", line 467, in wrapper
    return f(self, *args, **kwargs)
  File "/home/ipvzero/Nornir/.venv/lib/python3.10/site-packages/napalm/ios/ios.py", line 484, in _commit_handler
    output = self.device.send_command(cmd, expect_string=patterns)
  File "/home/ipvzero/Nornir/.venv/lib/python3.10/site-packages/netmiko/utilities.py", line 592, in wrapper_decorator
    return func(self, *args, **kwargs)
  File "/home/ipvzero/Nornir/.venv/lib/python3.10/site-packages/netmiko/base_connection.py", line 1721, in send_command
    raise ReadTimeout(msg)
netmiko.exceptions.ReadTimeout: 
Pattern not detected: '(?:[>##]\\s*$|.*all username.*confirm)' in output.

Things you might try to fix this:
1. Explicitly set your pattern using the expect_string argument.
2. Increase the read_timeout to a larger value.

You can also look at the Netmiko session_log or debug log for more information.



2023-02-26 06:16:58,456 - nornir.core.task -    ERROR -      start() - Host 'R4': task 'replace_stuff' failed with traceback:
Traceback (most recent call last):
  File "/home/ipvzero/Nornir/.venv/lib/python3.10/site-packages/nornir/core/task.py", line 99, in start
    r = self.task(self, **self.params)
  File "/home/ipvzero/Nornir/Backups-Napalm/replace_test.py", line 8, in replace_stuff
    task.run(task=napalm_configure, filename=f"backup-directory/{task.host}.txt", replace=True)
  File "/home/ipvzero/Nornir/.venv/lib/python3.10/site-packages/nornir/core/task.py", line 174, in run
    raise NornirSubTaskError(task=run_task, result=r)
nornir.core.exceptions.NornirSubTaskError: Subtask: napalm_configure (failed)


2023-02-26 06:16:58,842 - nornir.core.task -    ERROR -      start() - Host 'R1': task 'napalm_configure' failed with traceback:
Traceback (most recent call last):
  File "/home/ipvzero/Nornir/.venv/lib/python3.10/site-packages/nornir/core/task.py", line 99, in start
    r = self.task(self, **self.params)
  File "/home/ipvzero/Nornir/.venv/lib/python3.10/site-packages/nornir_napalm/plugins/tasks/napalm_configure.py", line 43, in napalm_configure
    device.commit_config()
  File "/home/ipvzero/Nornir/.venv/lib/python3.10/site-packages/napalm/ios/ios.py", line 559, in commit_config
    output = self._commit_handler(cmd)
  File "/home/ipvzero/Nornir/.venv/lib/python3.10/site-packages/napalm/ios/ios.py", line 467, in wrapper
    return f(self, *args, **kwargs)
  File "/home/ipvzero/Nornir/.venv/lib/python3.10/site-packages/napalm/ios/ios.py", line 484, in _commit_handler
    output = self.device.send_command(cmd, expect_string=patterns)
  File "/home/ipvzero/Nornir/.venv/lib/python3.10/site-packages/netmiko/utilities.py", line 592, in wrapper_decorator
    return func(self, *args, **kwargs)
  File "/home/ipvzero/Nornir/.venv/lib/python3.10/site-packages/netmiko/base_connection.py", line 1721, in send_command
    raise ReadTimeout(msg)
netmiko.exceptions.ReadTimeout: 
Pattern not detected: '(?:[>##]\\s*$|.*all username.*confirm)' in output.

Things you might try to fix this:
1. Explicitly set your pattern using the expect_string argument.
2. Increase the read_timeout to a larger value.

You can also look at the Netmiko session_log or debug log for more information.



2023-02-26 06:16:58,842 - nornir.core.task -    ERROR -      start() - Host 'R1': task 'replace_stuff' failed with traceback:
Traceback (most recent call last):
  File "/home/ipvzero/Nornir/.venv/lib/python3.10/site-packages/nornir/core/task.py", line 99, in start
    r = self.task(self, **self.params)
  File "/home/ipvzero/Nornir/Backups-Napalm/replace_test.py", line 8, in replace_stuff
    task.run(task=napalm_configure, filename=f"backup-directory/{task.host}.txt", replace=True)
  File "/home/ipvzero/Nornir/.venv/lib/python3.10/site-packages/nornir/core/task.py", line 174, in run
    raise NornirSubTaskError(task=run_task, result=r)
nornir.core.exceptions.NornirSubTaskError: Subtask: napalm_configure (failed)


2023-02-26 06:16:58,936 - nornir.core.task -    ERROR -      start() - Host 'R2': task 'napalm_configure' failed with traceback:
Traceback (most recent call last):
  File "/home/ipvzero/Nornir/.venv/lib/python3.10/site-packages/nornir/core/task.py", line 99, in start
    r = self.task(self, **self.params)
  File "/home/ipvzero/Nornir/.venv/lib/python3.10/site-packages/nornir_napalm/plugins/tasks/napalm_configure.py", line 43, in napalm_configure
    device.commit_config()
  File "/home/ipvzero/Nornir/.venv/lib/python3.10/site-packages/napalm/ios/ios.py", line 559, in commit_config
    output = self._commit_handler(cmd)
  File "/home/ipvzero/Nornir/.venv/lib/python3.10/site-packages/napalm/ios/ios.py", line 467, in wrapper
    return f(self, *args, **kwargs)
  File "/home/ipvzero/Nornir/.venv/lib/python3.10/site-packages/napalm/ios/ios.py", line 484, in _commit_handler
    output = self.device.send_command(cmd, expect_string=patterns)
  File "/home/ipvzero/Nornir/.venv/lib/python3.10/site-packages/netmiko/utilities.py", line 592, in wrapper_decorator
    return func(self, *args, **kwargs)
  File "/home/ipvzero/Nornir/.venv/lib/python3.10/site-packages/netmiko/base_connection.py", line 1721, in send_command
    raise ReadTimeout(msg)
netmiko.exceptions.ReadTimeout: 
Pattern not detected: '(?:[>##]\\s*$|.*all username.*confirm)' in output.

Things you might try to fix this:
1. Explicitly set your pattern using the expect_string argument.
2. Increase the read_timeout to a larger value.

You can also look at the Netmiko session_log or debug log for more information.



2023-02-26 06:16:58,936 - nornir.core.task -    ERROR -      start() - Host 'R2': task 'replace_stuff' failed with traceback:
Traceback (most recent call last):
  File "/home/ipvzero/Nornir/.venv/lib/python3.10/site-packages/nornir/core/task.py", line 99, in start
    r = self.task(self, **self.params)
  File "/home/ipvzero/Nornir/Backups-Napalm/replace_test.py", line 8, in replace_stuff
    task.run(task=napalm_configure, filename=f"backup-directory/{task.host}.txt", replace=True)
  File "/home/ipvzero/Nornir/.venv/lib/python3.10/site-packages/nornir/core/task.py", line 174, in run
    raise NornirSubTaskError(task=run_task, result=r)
nornir.core.exceptions.NornirSubTaskError: Subtask: napalm_configure (failed)


2023-02-26 06:17:34,358 -  nornir.core -     INFO -        run() - Running task 'replace_stuff' with args {} on 4 hosts
2023-02-26 06:17:46,537 - nornir.core.task -    ERROR -      start() - Host 'R3': task 'napalm_configure' failed with traceback:
Traceback (most recent call last):
  File "/home/ipvzero/Nornir/.venv/lib/python3.10/site-packages/nornir/core/task.py", line 99, in start
    r = self.task(self, **self.params)
  File "/home/ipvzero/Nornir/.venv/lib/python3.10/site-packages/nornir_napalm/plugins/tasks/napalm_configure.py", line 43, in napalm_configure
    device.commit_config()
  File "/home/ipvzero/Nornir/.venv/lib/python3.10/site-packages/napalm/ios/ios.py", line 573, in commit_config
    raise ReplaceConfigException(msg)
napalm.base.exceptions.ReplaceConfigException: napalm-ios replace() requires Cisco 'archive' feature to be enabled

2023-02-26 06:17:46,538 - nornir.core.task -    ERROR -      start() - Host 'R3': task 'replace_stuff' failed with traceback:
Traceback (most recent call last):
  File "/home/ipvzero/Nornir/.venv/lib/python3.10/site-packages/nornir/core/task.py", line 99, in start
    r = self.task(self, **self.params)
  File "/home/ipvzero/Nornir/Backups-Napalm/replace_test.py", line 8, in replace_stuff
    task.run(task=napalm_configure, filename=f"backup-directory/{task.host}.txt", replace=True)
  File "/home/ipvzero/Nornir/.venv/lib/python3.10/site-packages/nornir/core/task.py", line 174, in run
    raise NornirSubTaskError(task=run_task, result=r)
nornir.core.exceptions.NornirSubTaskError: Subtask: napalm_configure (failed)


2023-02-26 06:17:56,282 - nornir.core.task -    ERROR -      start() - Host 'R4': task 'napalm_configure' failed with traceback:
Traceback (most recent call last):
  File "/home/ipvzero/Nornir/.venv/lib/python3.10/site-packages/nornir/core/task.py", line 99, in start
    r = self.task(self, **self.params)
  File "/home/ipvzero/Nornir/.venv/lib/python3.10/site-packages/nornir_napalm/plugins/tasks/napalm_configure.py", line 43, in napalm_configure
    device.commit_config()
  File "/home/ipvzero/Nornir/.venv/lib/python3.10/site-packages/napalm/ios/ios.py", line 559, in commit_config
    output = self._commit_handler(cmd)
  File "/home/ipvzero/Nornir/.venv/lib/python3.10/site-packages/napalm/ios/ios.py", line 467, in wrapper
    return f(self, *args, **kwargs)
  File "/home/ipvzero/Nornir/.venv/lib/python3.10/site-packages/napalm/ios/ios.py", line 484, in _commit_handler
    output = self.device.send_command(cmd, expect_string=patterns)
  File "/home/ipvzero/Nornir/.venv/lib/python3.10/site-packages/netmiko/utilities.py", line 592, in wrapper_decorator
    return func(self, *args, **kwargs)
  File "/home/ipvzero/Nornir/.venv/lib/python3.10/site-packages/netmiko/base_connection.py", line 1721, in send_command
    raise ReadTimeout(msg)
netmiko.exceptions.ReadTimeout: 
Pattern not detected: '(?:[>##]\\s*$|.*all username.*confirm)' in output.

Things you might try to fix this:
1. Explicitly set your pattern using the expect_string argument.
2. Increase the read_timeout to a larger value.

You can also look at the Netmiko session_log or debug log for more information.



2023-02-26 06:17:56,283 - nornir.core.task -    ERROR -      start() - Host 'R4': task 'replace_stuff' failed with traceback:
Traceback (most recent call last):
  File "/home/ipvzero/Nornir/.venv/lib/python3.10/site-packages/nornir/core/task.py", line 99, in start
    r = self.task(self, **self.params)
  File "/home/ipvzero/Nornir/Backups-Napalm/replace_test.py", line 8, in replace_stuff
    task.run(task=napalm_configure, filename=f"backup-directory/{task.host}.txt", replace=True)
  File "/home/ipvzero/Nornir/.venv/lib/python3.10/site-packages/nornir/core/task.py", line 174, in run
    raise NornirSubTaskError(task=run_task, result=r)
nornir.core.exceptions.NornirSubTaskError: Subtask: napalm_configure (failed)


2023-02-26 06:17:56,840 - nornir.core.task -    ERROR -      start() - Host 'R1': task 'napalm_configure' failed with traceback:
Traceback (most recent call last):
  File "/home/ipvzero/Nornir/.venv/lib/python3.10/site-packages/nornir/core/task.py", line 99, in start
    r = self.task(self, **self.params)
  File "/home/ipvzero/Nornir/.venv/lib/python3.10/site-packages/nornir_napalm/plugins/tasks/napalm_configure.py", line 43, in napalm_configure
    device.commit_config()
  File "/home/ipvzero/Nornir/.venv/lib/python3.10/site-packages/napalm/ios/ios.py", line 559, in commit_config
    output = self._commit_handler(cmd)
  File "/home/ipvzero/Nornir/.venv/lib/python3.10/site-packages/napalm/ios/ios.py", line 467, in wrapper
    return f(self, *args, **kwargs)
  File "/home/ipvzero/Nornir/.venv/lib/python3.10/site-packages/napalm/ios/ios.py", line 484, in _commit_handler
    output = self.device.send_command(cmd, expect_string=patterns)
  File "/home/ipvzero/Nornir/.venv/lib/python3.10/site-packages/netmiko/utilities.py", line 592, in wrapper_decorator
    return func(self, *args, **kwargs)
  File "/home/ipvzero/Nornir/.venv/lib/python3.10/site-packages/netmiko/base_connection.py", line 1721, in send_command
    raise ReadTimeout(msg)
netmiko.exceptions.ReadTimeout: 
Pattern not detected: '(?:[>##]\\s*$|.*all username.*confirm)' in output.

Things you might try to fix this:
1. Explicitly set your pattern using the expect_string argument.
2. Increase the read_timeout to a larger value.

You can also look at the Netmiko session_log or debug log for more information.



2023-02-26 06:17:56,840 - nornir.core.task -    ERROR -      start() - Host 'R1': task 'replace_stuff' failed with traceback:
Traceback (most recent call last):
  File "/home/ipvzero/Nornir/.venv/lib/python3.10/site-packages/nornir/core/task.py", line 99, in start
    r = self.task(self, **self.params)
  File "/home/ipvzero/Nornir/Backups-Napalm/replace_test.py", line 8, in replace_stuff
    task.run(task=napalm_configure, filename=f"backup-directory/{task.host}.txt", replace=True)
  File "/home/ipvzero/Nornir/.venv/lib/python3.10/site-packages/nornir/core/task.py", line 174, in run
    raise NornirSubTaskError(task=run_task, result=r)
nornir.core.exceptions.NornirSubTaskError: Subtask: napalm_configure (failed)


2023-02-26 06:17:57,094 - nornir.core.task -    ERROR -      start() - Host 'R2': task 'napalm_configure' failed with traceback:
Traceback (most recent call last):
  File "/home/ipvzero/Nornir/.venv/lib/python3.10/site-packages/nornir/core/task.py", line 99, in start
    r = self.task(self, **self.params)
  File "/home/ipvzero/Nornir/.venv/lib/python3.10/site-packages/nornir_napalm/plugins/tasks/napalm_configure.py", line 43, in napalm_configure
    device.commit_config()
  File "/home/ipvzero/Nornir/.venv/lib/python3.10/site-packages/napalm/ios/ios.py", line 559, in commit_config
    output = self._commit_handler(cmd)
  File "/home/ipvzero/Nornir/.venv/lib/python3.10/site-packages/napalm/ios/ios.py", line 467, in wrapper
    return f(self, *args, **kwargs)
  File "/home/ipvzero/Nornir/.venv/lib/python3.10/site-packages/napalm/ios/ios.py", line 484, in _commit_handler
    output = self.device.send_command(cmd, expect_string=patterns)
  File "/home/ipvzero/Nornir/.venv/lib/python3.10/site-packages/netmiko/utilities.py", line 592, in wrapper_decorator
    return func(self, *args, **kwargs)
  File "/home/ipvzero/Nornir/.venv/lib/python3.10/site-packages/netmiko/base_connection.py", line 1721, in send_command
    raise ReadTimeout(msg)
netmiko.exceptions.ReadTimeout: 
Pattern not detected: '(?:[>##]\\s*$|.*all username.*confirm)' in output.

Things you might try to fix this:
1. Explicitly set your pattern using the expect_string argument.
2. Increase the read_timeout to a larger value.

You can also look at the Netmiko session_log or debug log for more information.



2023-02-26 06:17:57,094 - nornir.core.task -    ERROR -      start() - Host 'R2': task 'replace_stuff' failed with traceback:
Traceback (most recent call last):
  File "/home/ipvzero/Nornir/.venv/lib/python3.10/site-packages/nornir/core/task.py", line 99, in start
    r = self.task(self, **self.params)
  File "/home/ipvzero/Nornir/Backups-Napalm/replace_test.py", line 8, in replace_stuff
    task.run(task=napalm_configure, filename=f"backup-directory/{task.host}.txt", replace=True)
  File "/home/ipvzero/Nornir/.venv/lib/python3.10/site-packages/nornir/core/task.py", line 174, in run
    raise NornirSubTaskError(task=run_task, result=r)
nornir.core.exceptions.NornirSubTaskError: Subtask: napalm_configure (failed)


2023-02-26 06:19:10,587 -  nornir.core -     INFO -        run() - Running task 'replace_stuff' with args {} on 4 hosts
2023-02-26 06:19:22,779 - nornir.core.task -    ERROR -      start() - Host 'R3': task 'napalm_configure' failed with traceback:
Traceback (most recent call last):
  File "/home/ipvzero/Nornir/.venv/lib/python3.10/site-packages/nornir/core/task.py", line 99, in start
    r = self.task(self, **self.params)
  File "/home/ipvzero/Nornir/.venv/lib/python3.10/site-packages/nornir_napalm/plugins/tasks/napalm_configure.py", line 43, in napalm_configure
    device.commit_config()
  File "/home/ipvzero/Nornir/.venv/lib/python3.10/site-packages/napalm/ios/ios.py", line 573, in commit_config
    raise ReplaceConfigException(msg)
napalm.base.exceptions.ReplaceConfigException: napalm-ios replace() requires Cisco 'archive' feature to be enabled

2023-02-26 06:19:22,779 - nornir.core.task -    ERROR -      start() - Host 'R3': task 'replace_stuff' failed with traceback:
Traceback (most recent call last):
  File "/home/ipvzero/Nornir/.venv/lib/python3.10/site-packages/nornir/core/task.py", line 99, in start
    r = self.task(self, **self.params)
  File "/home/ipvzero/Nornir/Backups-Napalm/replace_test.py", line 8, in replace_stuff
    task.run(task=napalm_configure, filename=f"backup-directory/{task.host}.txt", replace=True)
  File "/home/ipvzero/Nornir/.venv/lib/python3.10/site-packages/nornir/core/task.py", line 174, in run
    raise NornirSubTaskError(task=run_task, result=r)
nornir.core.exceptions.NornirSubTaskError: Subtask: napalm_configure (failed)


2023-02-26 06:19:32,637 - nornir.core.task -    ERROR -      start() - Host 'R4': task 'napalm_configure' failed with traceback:
Traceback (most recent call last):
  File "/home/ipvzero/Nornir/.venv/lib/python3.10/site-packages/nornir/core/task.py", line 99, in start
    r = self.task(self, **self.params)
  File "/home/ipvzero/Nornir/.venv/lib/python3.10/site-packages/nornir_napalm/plugins/tasks/napalm_configure.py", line 43, in napalm_configure
    device.commit_config()
  File "/home/ipvzero/Nornir/.venv/lib/python3.10/site-packages/napalm/ios/ios.py", line 559, in commit_config
    output = self._commit_handler(cmd)
  File "/home/ipvzero/Nornir/.venv/lib/python3.10/site-packages/napalm/ios/ios.py", line 467, in wrapper
    return f(self, *args, **kwargs)
  File "/home/ipvzero/Nornir/.venv/lib/python3.10/site-packages/napalm/ios/ios.py", line 484, in _commit_handler
    output = self.device.send_command(cmd, expect_string=patterns)
  File "/home/ipvzero/Nornir/.venv/lib/python3.10/site-packages/netmiko/utilities.py", line 592, in wrapper_decorator
    return func(self, *args, **kwargs)
  File "/home/ipvzero/Nornir/.venv/lib/python3.10/site-packages/netmiko/base_connection.py", line 1721, in send_command
    raise ReadTimeout(msg)
netmiko.exceptions.ReadTimeout: 
Pattern not detected: '(?:[>##]\\s*$|.*all username.*confirm)' in output.

Things you might try to fix this:
1. Explicitly set your pattern using the expect_string argument.
2. Increase the read_timeout to a larger value.

You can also look at the Netmiko session_log or debug log for more information.



2023-02-26 06:19:32,637 - nornir.core.task -    ERROR -      start() - Host 'R4': task 'replace_stuff' failed with traceback:
Traceback (most recent call last):
  File "/home/ipvzero/Nornir/.venv/lib/python3.10/site-packages/nornir/core/task.py", line 99, in start
    r = self.task(self, **self.params)
  File "/home/ipvzero/Nornir/Backups-Napalm/replace_test.py", line 8, in replace_stuff
    task.run(task=napalm_configure, filename=f"backup-directory/{task.host}.txt", replace=True)
  File "/home/ipvzero/Nornir/.venv/lib/python3.10/site-packages/nornir/core/task.py", line 174, in run
    raise NornirSubTaskError(task=run_task, result=r)
nornir.core.exceptions.NornirSubTaskError: Subtask: napalm_configure (failed)


2023-02-26 06:19:32,639 - nornir.core.task -    ERROR -      start() - Host 'R1': task 'napalm_configure' failed with traceback:
Traceback (most recent call last):
  File "/home/ipvzero/Nornir/.venv/lib/python3.10/site-packages/nornir/core/task.py", line 99, in start
    r = self.task(self, **self.params)
  File "/home/ipvzero/Nornir/.venv/lib/python3.10/site-packages/nornir_napalm/plugins/tasks/napalm_configure.py", line 43, in napalm_configure
    device.commit_config()
  File "/home/ipvzero/Nornir/.venv/lib/python3.10/site-packages/napalm/ios/ios.py", line 559, in commit_config
    output = self._commit_handler(cmd)
  File "/home/ipvzero/Nornir/.venv/lib/python3.10/site-packages/napalm/ios/ios.py", line 467, in wrapper
    return f(self, *args, **kwargs)
  File "/home/ipvzero/Nornir/.venv/lib/python3.10/site-packages/napalm/ios/ios.py", line 484, in _commit_handler
    output = self.device.send_command(cmd, expect_string=patterns)
  File "/home/ipvzero/Nornir/.venv/lib/python3.10/site-packages/netmiko/utilities.py", line 592, in wrapper_decorator
    return func(self, *args, **kwargs)
  File "/home/ipvzero/Nornir/.venv/lib/python3.10/site-packages/netmiko/base_connection.py", line 1721, in send_command
    raise ReadTimeout(msg)
netmiko.exceptions.ReadTimeout: 
Pattern not detected: '(?:[>##]\\s*$|.*all username.*confirm)' in output.

Things you might try to fix this:
1. Explicitly set your pattern using the expect_string argument.
2. Increase the read_timeout to a larger value.

You can also look at the Netmiko session_log or debug log for more information.



2023-02-26 06:19:32,639 - nornir.core.task -    ERROR -      start() - Host 'R1': task 'replace_stuff' failed with traceback:
Traceback (most recent call last):
  File "/home/ipvzero/Nornir/.venv/lib/python3.10/site-packages/nornir/core/task.py", line 99, in start
    r = self.task(self, **self.params)
  File "/home/ipvzero/Nornir/Backups-Napalm/replace_test.py", line 8, in replace_stuff
    task.run(task=napalm_configure, filename=f"backup-directory/{task.host}.txt", replace=True)
  File "/home/ipvzero/Nornir/.venv/lib/python3.10/site-packages/nornir/core/task.py", line 174, in run
    raise NornirSubTaskError(task=run_task, result=r)
nornir.core.exceptions.NornirSubTaskError: Subtask: napalm_configure (failed)


2023-02-26 06:19:34,321 - nornir.core.task -    ERROR -      start() - Host 'R2': task 'napalm_configure' failed with traceback:
Traceback (most recent call last):
  File "/home/ipvzero/Nornir/.venv/lib/python3.10/site-packages/nornir/core/task.py", line 99, in start
    r = self.task(self, **self.params)
  File "/home/ipvzero/Nornir/.venv/lib/python3.10/site-packages/nornir_napalm/plugins/tasks/napalm_configure.py", line 43, in napalm_configure
    device.commit_config()
  File "/home/ipvzero/Nornir/.venv/lib/python3.10/site-packages/napalm/ios/ios.py", line 559, in commit_config
    output = self._commit_handler(cmd)
  File "/home/ipvzero/Nornir/.venv/lib/python3.10/site-packages/napalm/ios/ios.py", line 467, in wrapper
    return f(self, *args, **kwargs)
  File "/home/ipvzero/Nornir/.venv/lib/python3.10/site-packages/napalm/ios/ios.py", line 484, in _commit_handler
    output = self.device.send_command(cmd, expect_string=patterns)
  File "/home/ipvzero/Nornir/.venv/lib/python3.10/site-packages/netmiko/utilities.py", line 592, in wrapper_decorator
    return func(self, *args, **kwargs)
  File "/home/ipvzero/Nornir/.venv/lib/python3.10/site-packages/netmiko/base_connection.py", line 1721, in send_command
    raise ReadTimeout(msg)
netmiko.exceptions.ReadTimeout: 
Pattern not detected: '(?:[>##]\\s*$|.*all username.*confirm)' in output.

Things you might try to fix this:
1. Explicitly set your pattern using the expect_string argument.
2. Increase the read_timeout to a larger value.

You can also look at the Netmiko session_log or debug log for more information.



2023-02-26 06:19:34,322 - nornir.core.task -    ERROR -      start() - Host 'R2': task 'replace_stuff' failed with traceback:
Traceback (most recent call last):
  File "/home/ipvzero/Nornir/.venv/lib/python3.10/site-packages/nornir/core/task.py", line 99, in start
    r = self.task(self, **self.params)
  File "/home/ipvzero/Nornir/Backups-Napalm/replace_test.py", line 8, in replace_stuff
    task.run(task=napalm_configure, filename=f"backup-directory/{task.host}.txt", replace=True)
  File "/home/ipvzero/Nornir/.venv/lib/python3.10/site-packages/nornir/core/task.py", line 174, in run
    raise NornirSubTaskError(task=run_task, result=r)
nornir.core.exceptions.NornirSubTaskError: Subtask: napalm_configure (failed)


2023-02-26 06:29:58,444 -  nornir.core -     INFO -        run() - Running task 'backup_configurations' with args {} on 4 hosts
2023-02-26 06:36:22,602 -  nornir.core -     INFO -        run() - Running task 'backup_configurations' with args {} on 4 hosts
2023-02-26 06:36:35,669 -  nornir.core -     INFO -        run() - Running task 'replace_stuff' with args {} on 4 hosts
2023-02-26 06:47:34,403 -  nornir.core -     INFO -        run() - Running task 'replace_stuff' with args {} on 4 hosts
2023-02-26 06:47:52,994 - nornir.core.task -    ERROR -      start() - Host 'R3': task 'napalm_configure' failed with traceback:
Traceback (most recent call last):
  File "/home/ipvzero/Nornir/.venv/lib/python3.10/site-packages/nornir/core/task.py", line 99, in start
    r = self.task(self, **self.params)
  File "/home/ipvzero/Nornir/.venv/lib/python3.10/site-packages/nornir_napalm/plugins/tasks/napalm_configure.py", line 43, in napalm_configure
    device.commit_config()
  File "/home/ipvzero/Nornir/.venv/lib/python3.10/site-packages/napalm/ios/ios.py", line 573, in commit_config
    raise ReplaceConfigException(msg)
napalm.base.exceptions.ReplaceConfigException: napalm-ios replace() requires Cisco 'archive' feature to be enabled

2023-02-26 06:47:52,994 - nornir.core.task -    ERROR -      start() - Host 'R3': task 'replace_stuff' failed with traceback:
Traceback (most recent call last):
  File "/home/ipvzero/Nornir/.venv/lib/python3.10/site-packages/nornir/core/task.py", line 99, in start
    r = self.task(self, **self.params)
  File "/home/ipvzero/Nornir/Backups-Napalm/replace_test.py", line 8, in replace_stuff
    task.run(task=napalm_configure, filename=f"backup-directory/{task.host}.txt", replace=True)
  File "/home/ipvzero/Nornir/.venv/lib/python3.10/site-packages/nornir/core/task.py", line 174, in run
    raise NornirSubTaskError(task=run_task, result=r)
nornir.core.exceptions.NornirSubTaskError: Subtask: napalm_configure (failed)


2023-02-26 06:48:06,815 -  nornir.core -     INFO -        run() - Running task 'test' with args {} on 4 hosts
2023-02-26 06:48:17,108 -  nornir.core -     INFO -        run() - Running task 'replace_stuff' with args {} on 4 hosts
2023-02-26 06:51:23,139 -  nornir.core -     INFO -        run() - Running task 'replace_stuff' with args {} on 4 hosts
2023-02-26 06:52:47,853 -  nornir.core -     INFO -        run() - Running task 'replace_stuff' with args {} on 4 hosts
2023-02-26 06:55:13,132 -  nornir.core -     INFO -        run() - Running task 'backup_configurations' with args {} on 4 hosts
2023-02-26 06:56:50,639 -  nornir.core -     INFO -        run() - Running task 'backup_configurations' with args {} on 4 hosts
2023-02-26 06:57:01,203 -  nornir.core -     INFO -        run() - Running task 'replace_stuff' with args {} on 4 hosts
2023-02-26 06:57:32,062 - nornir.core.task -    ERROR -      start() - Host 'R4': task 'napalm_configure' failed with traceback:
Traceback (most recent call last):
  File "/home/ipvzero/Nornir/.venv/lib/python3.10/site-packages/nornir/core/task.py", line 99, in start
    r = self.task(self, **self.params)
  File "/home/ipvzero/Nornir/.venv/lib/python3.10/site-packages/nornir_napalm/plugins/tasks/napalm_configure.py", line 43, in napalm_configure
    device.commit_config()
  File "/home/ipvzero/Nornir/.venv/lib/python3.10/site-packages/napalm/ios/ios.py", line 559, in commit_config
    output = self._commit_handler(cmd)
  File "/home/ipvzero/Nornir/.venv/lib/python3.10/site-packages/napalm/ios/ios.py", line 467, in wrapper
    return f(self, *args, **kwargs)
  File "/home/ipvzero/Nornir/.venv/lib/python3.10/site-packages/napalm/ios/ios.py", line 484, in _commit_handler
    output = self.device.send_command(cmd, expect_string=patterns)
  File "/home/ipvzero/Nornir/.venv/lib/python3.10/site-packages/netmiko/utilities.py", line 592, in wrapper_decorator
    return func(self, *args, **kwargs)
  File "/home/ipvzero/Nornir/.venv/lib/python3.10/site-packages/netmiko/base_connection.py", line 1721, in send_command
    raise ReadTimeout(msg)
netmiko.exceptions.ReadTimeout: 
Pattern not detected: '(?:[>##]\\s*$|.*all username.*confirm)' in output.

Things you might try to fix this:
1. Explicitly set your pattern using the expect_string argument.
2. Increase the read_timeout to a larger value.

You can also look at the Netmiko session_log or debug log for more information.



2023-02-26 06:57:32,062 - nornir.core.task -    ERROR -      start() - Host 'R4': task 'replace_stuff' failed with traceback:
Traceback (most recent call last):
  File "/home/ipvzero/Nornir/.venv/lib/python3.10/site-packages/nornir/core/task.py", line 99, in start
    r = self.task(self, **self.params)
  File "/home/ipvzero/Nornir/Backups-Napalm/replace_test.py", line 8, in replace_stuff
    task.run(task=napalm_configure, filename=f"backup-directory/{task.host}.txt", replace=True)
  File "/home/ipvzero/Nornir/.venv/lib/python3.10/site-packages/nornir/core/task.py", line 174, in run
    raise NornirSubTaskError(task=run_task, result=r)
nornir.core.exceptions.NornirSubTaskError: Subtask: napalm_configure (failed)


2023-02-26 18:16:43,730 -  nornir.core -     INFO -        run() - Running task 'test' with args {} on 4 hosts
2023-02-26 18:18:45,340 -  nornir.core -     INFO -        run() - Running task 'replace_stuff' with args {} on 4 hosts
2023-02-26 18:19:04,749 - nornir.core.task -    ERROR -      start() - Host 'R3': task 'napalm_configure' failed with traceback:
Traceback (most recent call last):
  File "/home/ipvzero/Nornir/.venv/lib/python3.10/site-packages/nornir/core/task.py", line 99, in start
    r = self.task(self, **self.params)
  File "/home/ipvzero/Nornir/.venv/lib/python3.10/site-packages/nornir_napalm/plugins/tasks/napalm_configure.py", line 43, in napalm_configure
    device.commit_config()
  File "/home/ipvzero/Nornir/.venv/lib/python3.10/site-packages/napalm/ios/ios.py", line 573, in commit_config
    raise ReplaceConfigException(msg)
napalm.base.exceptions.ReplaceConfigException: napalm-ios replace() requires Cisco 'archive' feature to be enabled

2023-02-26 18:19:04,750 - nornir.core.task -    ERROR -      start() - Host 'R3': task 'replace_stuff' failed with traceback:
Traceback (most recent call last):
  File "/home/ipvzero/Nornir/.venv/lib/python3.10/site-packages/nornir/core/task.py", line 99, in start
    r = self.task(self, **self.params)
  File "/home/ipvzero/Nornir/Backups-Napalm/replace_test.py", line 11, in replace_stuff
    task.run(task=napalm_configure, filename=f"backup-directory/{task.host}.txt", replace=True)
  File "/home/ipvzero/Nornir/.venv/lib/python3.10/site-packages/nornir/core/task.py", line 174, in run
    raise NornirSubTaskError(task=run_task, result=r)
nornir.core.exceptions.NornirSubTaskError: Subtask: napalm_configure (failed)


2023-02-26 18:19:09,081 - nornir.core.task -    ERROR -      start() - Host 'R4': task 'napalm_configure' failed with traceback:
Traceback (most recent call last):
  File "/home/ipvzero/Nornir/.venv/lib/python3.10/site-packages/nornir/core/task.py", line 99, in start
    r = self.task(self, **self.params)
  File "/home/ipvzero/Nornir/.venv/lib/python3.10/site-packages/nornir_napalm/plugins/tasks/napalm_configure.py", line 43, in napalm_configure
    device.commit_config()
  File "/home/ipvzero/Nornir/.venv/lib/python3.10/site-packages/napalm/ios/ios.py", line 559, in commit_config
    output = self._commit_handler(cmd)
  File "/home/ipvzero/Nornir/.venv/lib/python3.10/site-packages/napalm/ios/ios.py", line 467, in wrapper
    return f(self, *args, **kwargs)
  File "/home/ipvzero/Nornir/.venv/lib/python3.10/site-packages/napalm/ios/ios.py", line 484, in _commit_handler
    output = self.device.send_command(cmd, expect_string=patterns)
  File "/home/ipvzero/Nornir/.venv/lib/python3.10/site-packages/netmiko/utilities.py", line 592, in wrapper_decorator
    return func(self, *args, **kwargs)
  File "/home/ipvzero/Nornir/.venv/lib/python3.10/site-packages/netmiko/base_connection.py", line 1721, in send_command
    raise ReadTimeout(msg)
netmiko.exceptions.ReadTimeout: 
Pattern not detected: '(?:[>##]\\s*$|.*all username.*confirm)' in output.

Things you might try to fix this:
1. Explicitly set your pattern using the expect_string argument.
2. Increase the read_timeout to a larger value.

You can also look at the Netmiko session_log or debug log for more information.



2023-02-26 18:19:09,082 - nornir.core.task -    ERROR -      start() - Host 'R4': task 'replace_stuff' failed with traceback:
Traceback (most recent call last):
  File "/home/ipvzero/Nornir/.venv/lib/python3.10/site-packages/nornir/core/task.py", line 99, in start
    r = self.task(self, **self.params)
  File "/home/ipvzero/Nornir/Backups-Napalm/replace_test.py", line 11, in replace_stuff
    task.run(task=napalm_configure, filename=f"backup-directory/{task.host}.txt", replace=True)
  File "/home/ipvzero/Nornir/.venv/lib/python3.10/site-packages/nornir/core/task.py", line 174, in run
    raise NornirSubTaskError(task=run_task, result=r)
nornir.core.exceptions.NornirSubTaskError: Subtask: napalm_configure (failed)


2023-02-26 18:19:12,976 - nornir.core.task -    ERROR -      start() - Host 'R1': task 'napalm_configure' failed with traceback:
Traceback (most recent call last):
  File "/home/ipvzero/Nornir/.venv/lib/python3.10/site-packages/nornir/core/task.py", line 99, in start
    r = self.task(self, **self.params)
  File "/home/ipvzero/Nornir/.venv/lib/python3.10/site-packages/nornir_napalm/plugins/tasks/napalm_configure.py", line 43, in napalm_configure
    device.commit_config()
  File "/home/ipvzero/Nornir/.venv/lib/python3.10/site-packages/napalm/ios/ios.py", line 559, in commit_config
    output = self._commit_handler(cmd)
  File "/home/ipvzero/Nornir/.venv/lib/python3.10/site-packages/napalm/ios/ios.py", line 467, in wrapper
    return f(self, *args, **kwargs)
  File "/home/ipvzero/Nornir/.venv/lib/python3.10/site-packages/napalm/ios/ios.py", line 484, in _commit_handler
    output = self.device.send_command(cmd, expect_string=patterns)
  File "/home/ipvzero/Nornir/.venv/lib/python3.10/site-packages/netmiko/utilities.py", line 592, in wrapper_decorator
    return func(self, *args, **kwargs)
  File "/home/ipvzero/Nornir/.venv/lib/python3.10/site-packages/netmiko/base_connection.py", line 1721, in send_command
    raise ReadTimeout(msg)
netmiko.exceptions.ReadTimeout: 
Pattern not detected: '(?:[>##]\\s*$|.*all username.*confirm)' in output.

Things you might try to fix this:
1. Explicitly set your pattern using the expect_string argument.
2. Increase the read_timeout to a larger value.

You can also look at the Netmiko session_log or debug log for more information.



2023-02-26 18:19:12,977 - nornir.core.task -    ERROR -      start() - Host 'R1': task 'replace_stuff' failed with traceback:
Traceback (most recent call last):
  File "/home/ipvzero/Nornir/.venv/lib/python3.10/site-packages/nornir/core/task.py", line 99, in start
    r = self.task(self, **self.params)
  File "/home/ipvzero/Nornir/Backups-Napalm/replace_test.py", line 11, in replace_stuff
    task.run(task=napalm_configure, filename=f"backup-directory/{task.host}.txt", replace=True)
  File "/home/ipvzero/Nornir/.venv/lib/python3.10/site-packages/nornir/core/task.py", line 174, in run
    raise NornirSubTaskError(task=run_task, result=r)
nornir.core.exceptions.NornirSubTaskError: Subtask: napalm_configure (failed)


2023-02-26 18:30:47,078 -  nornir.core -     INFO -        run() - Running task 'replace_stuff' with args {} on 4 hosts
2023-02-26 18:30:59,535 - nornir.core.task -    ERROR -      start() - Host 'R3': task 'napalm_configure' failed with traceback:
Traceback (most recent call last):
  File "/home/ipvzero/Nornir/.venv/lib/python3.10/site-packages/nornir/core/task.py", line 99, in start
    r = self.task(self, **self.params)
  File "/home/ipvzero/Nornir/.venv/lib/python3.10/site-packages/nornir_napalm/plugins/tasks/napalm_configure.py", line 43, in napalm_configure
    device.commit_config()
  File "/home/ipvzero/Nornir/.venv/lib/python3.10/site-packages/napalm/ios/ios.py", line 573, in commit_config
    raise ReplaceConfigException(msg)
napalm.base.exceptions.ReplaceConfigException: napalm-ios replace() requires Cisco 'archive' feature to be enabled

2023-02-26 18:30:59,536 - nornir.core.task -    ERROR -      start() - Host 'R3': task 'replace_stuff' failed with traceback:
Traceback (most recent call last):
  File "/home/ipvzero/Nornir/.venv/lib/python3.10/site-packages/nornir/core/task.py", line 99, in start
    r = self.task(self, **self.params)
  File "/home/ipvzero/Nornir/Backups-Napalm/replace_test.py", line 11, in replace_stuff
    task.run(task=napalm_configure, filename=f"backup-directory/{task.host}.txt", replace=True)
  File "/home/ipvzero/Nornir/.venv/lib/python3.10/site-packages/nornir/core/task.py", line 174, in run
    raise NornirSubTaskError(task=run_task, result=r)
nornir.core.exceptions.NornirSubTaskError: Subtask: napalm_configure (failed)


2023-02-26 18:37:36,333 -  nornir.core -     INFO -        run() - Running task 'replace_stuff' with args {} on 4 hosts
2023-02-26 18:37:50,630 - nornir.core.task -    ERROR -      start() - Host 'R3': task 'napalm_configure' failed with traceback:
Traceback (most recent call last):
  File "/home/ipvzero/Nornir/.venv/lib/python3.10/site-packages/nornir/core/task.py", line 99, in start
    r = self.task(self, **self.params)
  File "/home/ipvzero/Nornir/.venv/lib/python3.10/site-packages/nornir_napalm/plugins/tasks/napalm_configure.py", line 43, in napalm_configure
    device.commit_config()
  File "/home/ipvzero/Nornir/.venv/lib/python3.10/site-packages/napalm/ios/ios.py", line 573, in commit_config
    raise ReplaceConfigException(msg)
napalm.base.exceptions.ReplaceConfigException: napalm-ios replace() requires Cisco 'archive' feature to be enabled

2023-02-26 18:37:50,631 - nornir.core.task -    ERROR -      start() - Host 'R3': task 'replace_stuff' failed with traceback:
Traceback (most recent call last):
  File "/home/ipvzero/Nornir/.venv/lib/python3.10/site-packages/nornir/core/task.py", line 99, in start
    r = self.task(self, **self.params)
  File "/home/ipvzero/Nornir/Backups-Napalm/replace_test.py", line 11, in replace_stuff
    task.run(task=napalm_configure, filename=f"backup-directory/{task.host}.txt", replace=True)
  File "/home/ipvzero/Nornir/.venv/lib/python3.10/site-packages/nornir/core/task.py", line 174, in run
    raise NornirSubTaskError(task=run_task, result=r)
nornir.core.exceptions.NornirSubTaskError: Subtask: napalm_configure (failed)


2023-02-26 18:39:48,947 -  nornir.core -     INFO -        run() - Running task 'backup_configurations' with args {} on 4 hosts
2023-02-26 18:44:04,111 -  nornir.core -     INFO -        run() - Running task 'test' with args {} on 1 hosts
2023-02-26 18:46:35,875 -  nornir.core -     INFO -        run() - Running task 'backup_configurations' with args {} on 4 hosts
2023-02-26 18:47:41,777 -  nornir.core -     INFO -        run() - Running task 'replace_stuff' with args {} on 4 hosts
