2023-03-14 05:34:50,936 -  nornir.core -     INFO -        run() - Running task 'load_vars' with args {} on 4 hosts
2023-03-14 05:34:50,952 - nornir.core.task -    ERROR -      start() - Host 'HUB (R1)': task 'load_yaml' failed with traceback:
Traceback (most recent call last):
  File "/home/ipvzero/Nornir/.venv/lib/python3.10/site-packages/nornir/core/task.py", line 99, in start
    r = self.task(self, **self.params)
  File "/home/ipvzero/Nornir/.venv/lib/python3.10/site-packages/nornir_utils/plugins/tasks/data/load_yaml.py", line 24, in load_yaml
    with open(file, "r") as f:
FileNotFoundError: [Errno 2] No such file or directory: './host_vars/.HUB (R1).yaml'

2023-03-14 05:34:50,952 - nornir.core.task -    ERROR -      start() - Host 'SPOKE1 (R2?)': task 'load_yaml' failed with traceback:
Traceback (most recent call last):
  File "/home/ipvzero/Nornir/.venv/lib/python3.10/site-packages/nornir/core/task.py", line 99, in start
    r = self.task(self, **self.params)
  File "/home/ipvzero/Nornir/.venv/lib/python3.10/site-packages/nornir_utils/plugins/tasks/data/load_yaml.py", line 24, in load_yaml
    with open(file, "r") as f:
FileNotFoundError: [Errno 2] No such file or directory: './host_vars/.SPOKE1 (R2?).yaml'

2023-03-14 05:34:50,953 - nornir.core.task -    ERROR -      start() - Host 'HUB (R1)': task 'load_vars' failed with traceback:
Traceback (most recent call last):
  File "/home/ipvzero/Nornir/.venv/lib/python3.10/site-packages/nornir/core/task.py", line 99, in start
    r = self.task(self, **self.params)
  File "/home/ipvzero/Nornir/DMVPN/deploy_dmvpn.py", line 15, in load_vars
    data = task.run(task=load_yaml, file=f"./host_vars/.{task.host}.yaml")
  File "/home/ipvzero/Nornir/.venv/lib/python3.10/site-packages/nornir/core/task.py", line 174, in run
    raise NornirSubTaskError(task=run_task, result=r)
nornir.core.exceptions.NornirSubTaskError: Subtask: load_yaml (failed)


2023-03-14 05:34:50,953 - nornir.core.task -    ERROR -      start() - Host 'SPOKE2 (R3?)': task 'load_yaml' failed with traceback:
Traceback (most recent call last):
  File "/home/ipvzero/Nornir/.venv/lib/python3.10/site-packages/nornir/core/task.py", line 99, in start
    r = self.task(self, **self.params)
  File "/home/ipvzero/Nornir/.venv/lib/python3.10/site-packages/nornir_utils/plugins/tasks/data/load_yaml.py", line 24, in load_yaml
    with open(file, "r") as f:
FileNotFoundError: [Errno 2] No such file or directory: './host_vars/.SPOKE2 (R3?).yaml'

2023-03-14 05:34:50,954 - nornir.core.task -    ERROR -      start() - Host 'SPOKE2 (R3?)': task 'load_vars' failed with traceback:
Traceback (most recent call last):
  File "/home/ipvzero/Nornir/.venv/lib/python3.10/site-packages/nornir/core/task.py", line 99, in start
    r = self.task(self, **self.params)
  File "/home/ipvzero/Nornir/DMVPN/deploy_dmvpn.py", line 15, in load_vars
    data = task.run(task=load_yaml, file=f"./host_vars/.{task.host}.yaml")
  File "/home/ipvzero/Nornir/.venv/lib/python3.10/site-packages/nornir/core/task.py", line 174, in run
    raise NornirSubTaskError(task=run_task, result=r)
nornir.core.exceptions.NornirSubTaskError: Subtask: load_yaml (failed)


2023-03-14 05:34:50,953 - nornir.core.task -    ERROR -      start() - Host 'SPOKE1 (R2?)': task 'load_vars' failed with traceback:
Traceback (most recent call last):
  File "/home/ipvzero/Nornir/.venv/lib/python3.10/site-packages/nornir/core/task.py", line 99, in start
    r = self.task(self, **self.params)
  File "/home/ipvzero/Nornir/DMVPN/deploy_dmvpn.py", line 15, in load_vars
    data = task.run(task=load_yaml, file=f"./host_vars/.{task.host}.yaml")
  File "/home/ipvzero/Nornir/.venv/lib/python3.10/site-packages/nornir/core/task.py", line 174, in run
    raise NornirSubTaskError(task=run_task, result=r)
nornir.core.exceptions.NornirSubTaskError: Subtask: load_yaml (failed)


2023-03-14 05:34:50,953 - nornir.core.task -    ERROR -      start() - Host 'SPOKE3 (R3?)': task 'load_yaml' failed with traceback:
Traceback (most recent call last):
  File "/home/ipvzero/Nornir/.venv/lib/python3.10/site-packages/nornir/core/task.py", line 99, in start
    r = self.task(self, **self.params)
  File "/home/ipvzero/Nornir/.venv/lib/python3.10/site-packages/nornir_utils/plugins/tasks/data/load_yaml.py", line 24, in load_yaml
    with open(file, "r") as f:
FileNotFoundError: [Errno 2] No such file or directory: './host_vars/.SPOKE3 (R3?).yaml'

2023-03-14 05:34:50,954 - nornir.core.task -    ERROR -      start() - Host 'SPOKE3 (R3?)': task 'load_vars' failed with traceback:
Traceback (most recent call last):
  File "/home/ipvzero/Nornir/.venv/lib/python3.10/site-packages/nornir/core/task.py", line 99, in start
    r = self.task(self, **self.params)
  File "/home/ipvzero/Nornir/DMVPN/deploy_dmvpn.py", line 15, in load_vars
    data = task.run(task=load_yaml, file=f"./host_vars/.{task.host}.yaml")
  File "/home/ipvzero/Nornir/.venv/lib/python3.10/site-packages/nornir/core/task.py", line 174, in run
    raise NornirSubTaskError(task=run_task, result=r)
nornir.core.exceptions.NornirSubTaskError: Subtask: load_yaml (failed)


2023-03-14 05:36:19,329 -  nornir.core -     INFO -        run() - Running task 'load_vars' with args {} on 4 hosts
2023-03-14 05:36:19,330 - nornir.core.task -    ERROR -      start() - Host 'HUB': task 'load_yaml' failed with traceback:
Traceback (most recent call last):
  File "/home/ipvzero/Nornir/.venv/lib/python3.10/site-packages/nornir/core/task.py", line 99, in start
    r = self.task(self, **self.params)
  File "/home/ipvzero/Nornir/.venv/lib/python3.10/site-packages/nornir_utils/plugins/tasks/data/load_yaml.py", line 24, in load_yaml
    with open(file, "r") as f:
FileNotFoundError: [Errno 2] No such file or directory: './host_vars/.HUB.yaml'

2023-03-14 05:36:19,331 - nornir.core.task -    ERROR -      start() - Host 'SPOKE1': task 'load_yaml' failed with traceback:
Traceback (most recent call last):
  File "/home/ipvzero/Nornir/.venv/lib/python3.10/site-packages/nornir/core/task.py", line 99, in start
    r = self.task(self, **self.params)
  File "/home/ipvzero/Nornir/.venv/lib/python3.10/site-packages/nornir_utils/plugins/tasks/data/load_yaml.py", line 24, in load_yaml
    with open(file, "r") as f:
FileNotFoundError: [Errno 2] No such file or directory: './host_vars/.SPOKE1.yaml'

2023-03-14 05:36:19,331 - nornir.core.task -    ERROR -      start() - Host 'HUB': task 'load_vars' failed with traceback:
Traceback (most recent call last):
  File "/home/ipvzero/Nornir/.venv/lib/python3.10/site-packages/nornir/core/task.py", line 99, in start
    r = self.task(self, **self.params)
  File "/home/ipvzero/Nornir/DMVPN/deploy_dmvpn.py", line 15, in load_vars
    data = task.run(task=load_yaml, file=f"./host_vars/.{task.host}.yaml")
  File "/home/ipvzero/Nornir/.venv/lib/python3.10/site-packages/nornir/core/task.py", line 174, in run
    raise NornirSubTaskError(task=run_task, result=r)
nornir.core.exceptions.NornirSubTaskError: Subtask: load_yaml (failed)


2023-03-14 05:36:19,331 - nornir.core.task -    ERROR -      start() - Host 'SPOKE1': task 'load_vars' failed with traceback:
Traceback (most recent call last):
  File "/home/ipvzero/Nornir/.venv/lib/python3.10/site-packages/nornir/core/task.py", line 99, in start
    r = self.task(self, **self.params)
  File "/home/ipvzero/Nornir/DMVPN/deploy_dmvpn.py", line 15, in load_vars
    data = task.run(task=load_yaml, file=f"./host_vars/.{task.host}.yaml")
  File "/home/ipvzero/Nornir/.venv/lib/python3.10/site-packages/nornir/core/task.py", line 174, in run
    raise NornirSubTaskError(task=run_task, result=r)
nornir.core.exceptions.NornirSubTaskError: Subtask: load_yaml (failed)


2023-03-14 05:36:19,332 - nornir.core.task -    ERROR -      start() - Host 'SPOKE3': task 'load_yaml' failed with traceback:
Traceback (most recent call last):
  File "/home/ipvzero/Nornir/.venv/lib/python3.10/site-packages/nornir/core/task.py", line 99, in start
    r = self.task(self, **self.params)
  File "/home/ipvzero/Nornir/.venv/lib/python3.10/site-packages/nornir_utils/plugins/tasks/data/load_yaml.py", line 24, in load_yaml
    with open(file, "r") as f:
FileNotFoundError: [Errno 2] No such file or directory: './host_vars/.SPOKE3.yaml'

2023-03-14 05:36:19,332 - nornir.core.task -    ERROR -      start() - Host 'SPOKE2': task 'load_yaml' failed with traceback:
Traceback (most recent call last):
  File "/home/ipvzero/Nornir/.venv/lib/python3.10/site-packages/nornir/core/task.py", line 99, in start
    r = self.task(self, **self.params)
  File "/home/ipvzero/Nornir/.venv/lib/python3.10/site-packages/nornir_utils/plugins/tasks/data/load_yaml.py", line 24, in load_yaml
    with open(file, "r") as f:
FileNotFoundError: [Errno 2] No such file or directory: './host_vars/.SPOKE2.yaml'

2023-03-14 05:36:19,332 - nornir.core.task -    ERROR -      start() - Host 'SPOKE3': task 'load_vars' failed with traceback:
Traceback (most recent call last):
  File "/home/ipvzero/Nornir/.venv/lib/python3.10/site-packages/nornir/core/task.py", line 99, in start
    r = self.task(self, **self.params)
  File "/home/ipvzero/Nornir/DMVPN/deploy_dmvpn.py", line 15, in load_vars
    data = task.run(task=load_yaml, file=f"./host_vars/.{task.host}.yaml")
  File "/home/ipvzero/Nornir/.venv/lib/python3.10/site-packages/nornir/core/task.py", line 174, in run
    raise NornirSubTaskError(task=run_task, result=r)
nornir.core.exceptions.NornirSubTaskError: Subtask: load_yaml (failed)


2023-03-14 05:36:19,333 - nornir.core.task -    ERROR -      start() - Host 'SPOKE2': task 'load_vars' failed with traceback:
Traceback (most recent call last):
  File "/home/ipvzero/Nornir/.venv/lib/python3.10/site-packages/nornir/core/task.py", line 99, in start
    r = self.task(self, **self.params)
  File "/home/ipvzero/Nornir/DMVPN/deploy_dmvpn.py", line 15, in load_vars
    data = task.run(task=load_yaml, file=f"./host_vars/.{task.host}.yaml")
  File "/home/ipvzero/Nornir/.venv/lib/python3.10/site-packages/nornir/core/task.py", line 174, in run
    raise NornirSubTaskError(task=run_task, result=r)
nornir.core.exceptions.NornirSubTaskError: Subtask: load_yaml (failed)


2023-03-14 05:37:12,006 -  nornir.core -     INFO -        run() - Running task 'load_vars' with args {} on 4 hosts
2023-03-14 05:37:12,007 - nornir.core.task -    ERROR -      start() - Host 'HUB': task 'load_yaml' failed with traceback:
Traceback (most recent call last):
  File "/home/ipvzero/Nornir/.venv/lib/python3.10/site-packages/nornir/core/task.py", line 99, in start
    r = self.task(self, **self.params)
  File "/home/ipvzero/Nornir/.venv/lib/python3.10/site-packages/nornir_utils/plugins/tasks/data/load_yaml.py", line 24, in load_yaml
    with open(file, "r") as f:
FileNotFoundError: [Errno 2] No such file or directory: './group_vars/all.yaml'

2023-03-14 05:37:12,008 - nornir.core.task -    ERROR -      start() - Host 'HUB': task 'load_vars' failed with traceback:
Traceback (most recent call last):
  File "/home/ipvzero/Nornir/.venv/lib/python3.10/site-packages/nornir/core/task.py", line 99, in start
    r = self.task(self, **self.params)
  File "/home/ipvzero/Nornir/DMVPN/deploy_dmvpn.py", line 17, in load_vars
    group_data = task.run(task=load_yaml, file="./group_vars/all.yaml")
  File "/home/ipvzero/Nornir/.venv/lib/python3.10/site-packages/nornir/core/task.py", line 174, in run
    raise NornirSubTaskError(task=run_task, result=r)
nornir.core.exceptions.NornirSubTaskError: Subtask: load_yaml (failed)


2023-03-14 05:37:12,009 - nornir.core.task -    ERROR -      start() - Host 'SPOKE2': task 'load_yaml' failed with traceback:
Traceback (most recent call last):
  File "/home/ipvzero/Nornir/.venv/lib/python3.10/site-packages/nornir/core/task.py", line 99, in start
    r = self.task(self, **self.params)
  File "/home/ipvzero/Nornir/.venv/lib/python3.10/site-packages/nornir_utils/plugins/tasks/data/load_yaml.py", line 24, in load_yaml
    with open(file, "r") as f:
FileNotFoundError: [Errno 2] No such file or directory: './group_vars/all.yaml'

2023-03-14 05:37:12,009 - nornir.core.task -    ERROR -      start() - Host 'SPOKE2': task 'load_vars' failed with traceback:
Traceback (most recent call last):
  File "/home/ipvzero/Nornir/.venv/lib/python3.10/site-packages/nornir/core/task.py", line 99, in start
    r = self.task(self, **self.params)
  File "/home/ipvzero/Nornir/DMVPN/deploy_dmvpn.py", line 17, in load_vars
    group_data = task.run(task=load_yaml, file="./group_vars/all.yaml")
  File "/home/ipvzero/Nornir/.venv/lib/python3.10/site-packages/nornir/core/task.py", line 174, in run
    raise NornirSubTaskError(task=run_task, result=r)
nornir.core.exceptions.NornirSubTaskError: Subtask: load_yaml (failed)


2023-03-14 05:37:12,010 - nornir.core.task -    ERROR -      start() - Host 'SPOKE1': task 'load_yaml' failed with traceback:
Traceback (most recent call last):
  File "/home/ipvzero/Nornir/.venv/lib/python3.10/site-packages/nornir/core/task.py", line 99, in start
    r = self.task(self, **self.params)
  File "/home/ipvzero/Nornir/.venv/lib/python3.10/site-packages/nornir_utils/plugins/tasks/data/load_yaml.py", line 24, in load_yaml
    with open(file, "r") as f:
FileNotFoundError: [Errno 2] No such file or directory: './group_vars/all.yaml'

2023-03-14 05:37:12,011 - nornir.core.task -    ERROR -      start() - Host 'SPOKE1': task 'load_vars' failed with traceback:
Traceback (most recent call last):
  File "/home/ipvzero/Nornir/.venv/lib/python3.10/site-packages/nornir/core/task.py", line 99, in start
    r = self.task(self, **self.params)
  File "/home/ipvzero/Nornir/DMVPN/deploy_dmvpn.py", line 17, in load_vars
    group_data = task.run(task=load_yaml, file="./group_vars/all.yaml")
  File "/home/ipvzero/Nornir/.venv/lib/python3.10/site-packages/nornir/core/task.py", line 174, in run
    raise NornirSubTaskError(task=run_task, result=r)
nornir.core.exceptions.NornirSubTaskError: Subtask: load_yaml (failed)


2023-03-14 05:37:12,011 - nornir.core.task -    ERROR -      start() - Host 'SPOKE3': task 'load_yaml' failed with traceback:
Traceback (most recent call last):
  File "/home/ipvzero/Nornir/.venv/lib/python3.10/site-packages/nornir/core/task.py", line 99, in start
    r = self.task(self, **self.params)
  File "/home/ipvzero/Nornir/.venv/lib/python3.10/site-packages/nornir_utils/plugins/tasks/data/load_yaml.py", line 24, in load_yaml
    with open(file, "r") as f:
FileNotFoundError: [Errno 2] No such file or directory: './group_vars/all.yaml'

2023-03-14 05:37:12,012 - nornir.core.task -    ERROR -      start() - Host 'SPOKE3': task 'load_vars' failed with traceback:
Traceback (most recent call last):
  File "/home/ipvzero/Nornir/.venv/lib/python3.10/site-packages/nornir/core/task.py", line 99, in start
    r = self.task(self, **self.params)
  File "/home/ipvzero/Nornir/DMVPN/deploy_dmvpn.py", line 17, in load_vars
    group_data = task.run(task=load_yaml, file="./group_vars/all.yaml")
  File "/home/ipvzero/Nornir/.venv/lib/python3.10/site-packages/nornir/core/task.py", line 174, in run
    raise NornirSubTaskError(task=run_task, result=r)
nornir.core.exceptions.NornirSubTaskError: Subtask: load_yaml (failed)


2023-03-14 05:38:13,251 -  nornir.core -     INFO -        run() - Running task 'load_vars' with args {} on 4 hosts
2023-03-14 05:38:13,258 - nornir.core.task -    ERROR -      start() - Host 'SPOKE1': task 'Pushing VRF Commands' failed with traceback:
Traceback (most recent call last):
  File "/home/ipvzero/Nornir/.venv/lib/python3.10/site-packages/nornir/core/task.py", line 99, in start
    r = self.task(self, **self.params)
TypeError: send_configs() got an unexpected keyword argument 'config'

2023-03-14 05:38:13,259 - nornir.core.task -    ERROR -      start() - Host 'HUB': task 'Pushing VRF Commands' failed with traceback:
Traceback (most recent call last):
  File "/home/ipvzero/Nornir/.venv/lib/python3.10/site-packages/nornir/core/task.py", line 99, in start
    r = self.task(self, **self.params)
TypeError: send_configs() got an unexpected keyword argument 'config'

2023-03-14 05:38:13,259 - nornir.core.task -    ERROR -      start() - Host 'SPOKE1': task 'load_vars' failed with traceback:
Traceback (most recent call last):
  File "/home/ipvzero/Nornir/.venv/lib/python3.10/site-packages/nornir/core/task.py", line 99, in start
    r = self.task(self, **self.params)
  File "/home/ipvzero/Nornir/DMVPN/deploy_dmvpn.py", line 19, in load_vars
    config_vrf(task)
  File "/home/ipvzero/Nornir/DMVPN/deploy_dmvpn.py", line 35, in config_vrf
    task.run(
  File "/home/ipvzero/Nornir/.venv/lib/python3.10/site-packages/nornir/core/task.py", line 174, in run
    raise NornirSubTaskError(task=run_task, result=r)
nornir.core.exceptions.NornirSubTaskError: Subtask: Pushing VRF Commands (failed)


2023-03-14 05:38:13,262 - nornir.core.task -    ERROR -      start() - Host 'SPOKE2': task 'Pushing VRF Commands' failed with traceback:
Traceback (most recent call last):
  File "/home/ipvzero/Nornir/.venv/lib/python3.10/site-packages/nornir/core/task.py", line 99, in start
    r = self.task(self, **self.params)
TypeError: send_configs() got an unexpected keyword argument 'config'

2023-03-14 05:38:13,263 - nornir.core.task -    ERROR -      start() - Host 'HUB': task 'load_vars' failed with traceback:
Traceback (most recent call last):
  File "/home/ipvzero/Nornir/.venv/lib/python3.10/site-packages/nornir/core/task.py", line 99, in start
    r = self.task(self, **self.params)
  File "/home/ipvzero/Nornir/DMVPN/deploy_dmvpn.py", line 19, in load_vars
    config_vrf(task)
  File "/home/ipvzero/Nornir/DMVPN/deploy_dmvpn.py", line 35, in config_vrf
    task.run(
  File "/home/ipvzero/Nornir/.venv/lib/python3.10/site-packages/nornir/core/task.py", line 174, in run
    raise NornirSubTaskError(task=run_task, result=r)
nornir.core.exceptions.NornirSubTaskError: Subtask: Pushing VRF Commands (failed)


2023-03-14 05:38:13,263 - nornir.core.task -    ERROR -      start() - Host 'SPOKE2': task 'load_vars' failed with traceback:
Traceback (most recent call last):
  File "/home/ipvzero/Nornir/.venv/lib/python3.10/site-packages/nornir/core/task.py", line 99, in start
    r = self.task(self, **self.params)
  File "/home/ipvzero/Nornir/DMVPN/deploy_dmvpn.py", line 19, in load_vars
    config_vrf(task)
  File "/home/ipvzero/Nornir/DMVPN/deploy_dmvpn.py", line 35, in config_vrf
    task.run(
  File "/home/ipvzero/Nornir/.venv/lib/python3.10/site-packages/nornir/core/task.py", line 174, in run
    raise NornirSubTaskError(task=run_task, result=r)
nornir.core.exceptions.NornirSubTaskError: Subtask: Pushing VRF Commands (failed)


2023-03-14 05:38:13,265 - nornir.core.task -    ERROR -      start() - Host 'SPOKE3': task 'Pushing VRF Commands' failed with traceback:
Traceback (most recent call last):
  File "/home/ipvzero/Nornir/.venv/lib/python3.10/site-packages/nornir/core/task.py", line 99, in start
    r = self.task(self, **self.params)
TypeError: send_configs() got an unexpected keyword argument 'config'

2023-03-14 05:38:13,265 - nornir.core.task -    ERROR -      start() - Host 'SPOKE3': task 'load_vars' failed with traceback:
Traceback (most recent call last):
  File "/home/ipvzero/Nornir/.venv/lib/python3.10/site-packages/nornir/core/task.py", line 99, in start
    r = self.task(self, **self.params)
  File "/home/ipvzero/Nornir/DMVPN/deploy_dmvpn.py", line 19, in load_vars
    config_vrf(task)
  File "/home/ipvzero/Nornir/DMVPN/deploy_dmvpn.py", line 35, in config_vrf
    task.run(
  File "/home/ipvzero/Nornir/.venv/lib/python3.10/site-packages/nornir/core/task.py", line 174, in run
    raise NornirSubTaskError(task=run_task, result=r)
nornir.core.exceptions.NornirSubTaskError: Subtask: Pushing VRF Commands (failed)


2023-03-14 05:48:46,820 -  nornir.core -     INFO -        run() - Running task 'load_vars' with args {} on 4 hosts
2023-03-14 05:48:46,829 - nornir.core.task -    ERROR -      start() - Host 'SPOKE1': task 'Pushing VRF Commands' failed with traceback:
Traceback (most recent call last):
  File "/home/ipvzero/Nornir/.venv/lib/python3.10/site-packages/nornir/core/task.py", line 99, in start
    r = self.task(self, **self.params)
TypeError: send_configs() got an unexpected keyword argument 'config'

2023-03-14 05:48:46,829 - nornir.core.task -    ERROR -      start() - Host 'HUB': task 'Pushing VRF Commands' failed with traceback:
Traceback (most recent call last):
  File "/home/ipvzero/Nornir/.venv/lib/python3.10/site-packages/nornir/core/task.py", line 99, in start
    r = self.task(self, **self.params)
TypeError: send_configs() got an unexpected keyword argument 'config'

2023-03-14 05:48:46,830 - nornir.core.task -    ERROR -      start() - Host 'SPOKE1': task 'load_vars' failed with traceback:
Traceback (most recent call last):
  File "/home/ipvzero/Nornir/.venv/lib/python3.10/site-packages/nornir/core/task.py", line 99, in start
    r = self.task(self, **self.params)
  File "/home/ipvzero/Nornir/DMVPN/deploy_dmvpn.py", line 19, in load_vars
    config_vrf(task)
  File "/home/ipvzero/Nornir/DMVPN/deploy_dmvpn.py", line 35, in config_vrf
    task.run(
  File "/home/ipvzero/Nornir/.venv/lib/python3.10/site-packages/nornir/core/task.py", line 174, in run
    raise NornirSubTaskError(task=run_task, result=r)
nornir.core.exceptions.NornirSubTaskError: Subtask: Pushing VRF Commands (failed)


2023-03-14 05:48:46,832 - nornir.core.task -    ERROR -      start() - Host 'SPOKE3': task 'Pushing VRF Commands' failed with traceback:
Traceback (most recent call last):
  File "/home/ipvzero/Nornir/.venv/lib/python3.10/site-packages/nornir/core/task.py", line 99, in start
    r = self.task(self, **self.params)
TypeError: send_configs() got an unexpected keyword argument 'config'

2023-03-14 05:48:46,834 - nornir.core.task -    ERROR -      start() - Host 'SPOKE2': task 'Pushing VRF Commands' failed with traceback:
Traceback (most recent call last):
  File "/home/ipvzero/Nornir/.venv/lib/python3.10/site-packages/nornir/core/task.py", line 99, in start
    r = self.task(self, **self.params)
TypeError: send_configs() got an unexpected keyword argument 'config'

2023-03-14 05:48:46,835 - nornir.core.task -    ERROR -      start() - Host 'HUB': task 'load_vars' failed with traceback:
Traceback (most recent call last):
  File "/home/ipvzero/Nornir/.venv/lib/python3.10/site-packages/nornir/core/task.py", line 99, in start
    r = self.task(self, **self.params)
  File "/home/ipvzero/Nornir/DMVPN/deploy_dmvpn.py", line 19, in load_vars
    config_vrf(task)
  File "/home/ipvzero/Nornir/DMVPN/deploy_dmvpn.py", line 35, in config_vrf
    task.run(
  File "/home/ipvzero/Nornir/.venv/lib/python3.10/site-packages/nornir/core/task.py", line 174, in run
    raise NornirSubTaskError(task=run_task, result=r)
nornir.core.exceptions.NornirSubTaskError: Subtask: Pushing VRF Commands (failed)


2023-03-14 05:48:46,835 - nornir.core.task -    ERROR -      start() - Host 'SPOKE3': task 'load_vars' failed with traceback:
Traceback (most recent call last):
  File "/home/ipvzero/Nornir/.venv/lib/python3.10/site-packages/nornir/core/task.py", line 99, in start
    r = self.task(self, **self.params)
  File "/home/ipvzero/Nornir/DMVPN/deploy_dmvpn.py", line 19, in load_vars
    config_vrf(task)
  File "/home/ipvzero/Nornir/DMVPN/deploy_dmvpn.py", line 35, in config_vrf
    task.run(
  File "/home/ipvzero/Nornir/.venv/lib/python3.10/site-packages/nornir/core/task.py", line 174, in run
    raise NornirSubTaskError(task=run_task, result=r)
nornir.core.exceptions.NornirSubTaskError: Subtask: Pushing VRF Commands (failed)


2023-03-14 05:48:46,835 - nornir.core.task -    ERROR -      start() - Host 'SPOKE2': task 'load_vars' failed with traceback:
Traceback (most recent call last):
  File "/home/ipvzero/Nornir/.venv/lib/python3.10/site-packages/nornir/core/task.py", line 99, in start
    r = self.task(self, **self.params)
  File "/home/ipvzero/Nornir/DMVPN/deploy_dmvpn.py", line 19, in load_vars
    config_vrf(task)
  File "/home/ipvzero/Nornir/DMVPN/deploy_dmvpn.py", line 35, in config_vrf
    task.run(
  File "/home/ipvzero/Nornir/.venv/lib/python3.10/site-packages/nornir/core/task.py", line 174, in run
    raise NornirSubTaskError(task=run_task, result=r)
nornir.core.exceptions.NornirSubTaskError: Subtask: Pushing VRF Commands (failed)


2023-03-14 05:54:15,949 -  nornir.core -     INFO -        run() - Running task 'load_vars' with args {} on 4 hosts
2023-03-14 05:54:16,154 - nornir.core.task -    ERROR -      start() - Host 'SPOKE3': task 'Pushing VRF Commands' failed with traceback:
Traceback (most recent call last):
  File "/home/ipvzero/Nornir/.venv/lib/python3.10/site-packages/nornir/core/task.py", line 99, in start
    r = self.task(self, **self.params)
  File "/home/ipvzero/Nornir/.venv/lib/python3.10/site-packages/nornir_scrapli/tasks/core/send_configs.py", line 58, in send_configs
    scrapli_conn = task.host.get_connection("scrapli", task.nornir.config)
  File "/home/ipvzero/Nornir/.venv/lib/python3.10/site-packages/nornir/core/inventory.py", line 494, in get_connection
    self.open_connection(
  File "/home/ipvzero/Nornir/.venv/lib/python3.10/site-packages/nornir/core/inventory.py", line 546, in open_connection
    conn_obj.open(
  File "/home/ipvzero/Nornir/.venv/lib/python3.10/site-packages/nornir_scrapli/connection.py", line 105, in open
    connection.open()
  File "/home/ipvzero/Nornir/.venv/lib/python3.10/site-packages/scrapli/driver/base/sync_driver.py", line 88, in open
    self.channel.channel_authenticate_ssh(
  File "/home/ipvzero/Nornir/.venv/lib/python3.10/site-packages/scrapli/decorators.py", line 216, in decorate
    return _multiprocessing_timeout(
  File "/home/ipvzero/Nornir/.venv/lib/python3.10/site-packages/scrapli/decorators.py", line 113, in _multiprocessing_timeout
    return future.result()
  File "/usr/lib/python3.10/concurrent/futures/_base.py", line 451, in result
    return self.__get_result()
  File "/usr/lib/python3.10/concurrent/futures/_base.py", line 403, in __get_result
    raise self._exception
  File "/usr/lib/python3.10/concurrent/futures/thread.py", line 58, in run
    result = self.fn(*self.args, **self.kwargs)
  File "/home/ipvzero/Nornir/.venv/lib/python3.10/site-packages/scrapli/channel/sync_channel.py", line 290, in channel_authenticate_ssh
    self._ssh_message_handler(output=authenticate_buf)
  File "/home/ipvzero/Nornir/.venv/lib/python3.10/site-packages/scrapli/channel/base_channel.py", line 432, in _ssh_message_handler
    raise ScrapliAuthenticationFailed(msg)
scrapli.exceptions.ScrapliAuthenticationFailed: Host key verification failed

2023-03-14 05:54:16,154 - nornir.core.task -    ERROR -      start() - Host 'SPOKE3': task 'load_vars' failed with traceback:
Traceback (most recent call last):
  File "/home/ipvzero/Nornir/.venv/lib/python3.10/site-packages/nornir/core/task.py", line 99, in start
    r = self.task(self, **self.params)
  File "/home/ipvzero/Nornir/DMVPN/deploy_dmvpn.py", line 19, in load_vars
    config_vrf(task)
  File "/home/ipvzero/Nornir/DMVPN/deploy_dmvpn.py", line 35, in config_vrf
    task.run(
  File "/home/ipvzero/Nornir/.venv/lib/python3.10/site-packages/nornir/core/task.py", line 174, in run
    raise NornirSubTaskError(task=run_task, result=r)
nornir.core.exceptions.NornirSubTaskError: Subtask: Pushing VRF Commands (failed)


2023-03-14 05:54:20,418 - nornir.core.task -    ERROR -      start() - Host 'SPOKE1': task 'Pushing VRF Commands' failed with traceback:
Traceback (most recent call last):
  File "/home/ipvzero/Nornir/.venv/lib/python3.10/site-packages/nornir/core/task.py", line 99, in start
    r = self.task(self, **self.params)
  File "/home/ipvzero/Nornir/.venv/lib/python3.10/site-packages/nornir_scrapli/tasks/core/send_configs.py", line 58, in send_configs
    scrapli_conn = task.host.get_connection("scrapli", task.nornir.config)
  File "/home/ipvzero/Nornir/.venv/lib/python3.10/site-packages/nornir/core/inventory.py", line 494, in get_connection
    self.open_connection(
  File "/home/ipvzero/Nornir/.venv/lib/python3.10/site-packages/nornir/core/inventory.py", line 546, in open_connection
    conn_obj.open(
  File "/home/ipvzero/Nornir/.venv/lib/python3.10/site-packages/nornir_scrapli/connection.py", line 105, in open
    connection.open()
  File "/home/ipvzero/Nornir/.venv/lib/python3.10/site-packages/scrapli/driver/base/sync_driver.py", line 88, in open
    self.channel.channel_authenticate_ssh(
  File "/home/ipvzero/Nornir/.venv/lib/python3.10/site-packages/scrapli/decorators.py", line 216, in decorate
    return _multiprocessing_timeout(
  File "/home/ipvzero/Nornir/.venv/lib/python3.10/site-packages/scrapli/decorators.py", line 113, in _multiprocessing_timeout
    return future.result()
  File "/usr/lib/python3.10/concurrent/futures/_base.py", line 451, in result
    return self.__get_result()
  File "/usr/lib/python3.10/concurrent/futures/_base.py", line 403, in __get_result
    raise self._exception
  File "/usr/lib/python3.10/concurrent/futures/thread.py", line 58, in run
    result = self.fn(*self.args, **self.kwargs)
  File "/home/ipvzero/Nornir/.venv/lib/python3.10/site-packages/scrapli/channel/sync_channel.py", line 302, in channel_authenticate_ssh
    raise ScrapliAuthenticationFailed(msg)
scrapli.exceptions.ScrapliAuthenticationFailed: password prompt seen more than once, assuming auth failed

2023-03-14 05:54:20,419 - nornir.core.task -    ERROR -      start() - Host 'SPOKE1': task 'load_vars' failed with traceback:
Traceback (most recent call last):
  File "/home/ipvzero/Nornir/.venv/lib/python3.10/site-packages/nornir/core/task.py", line 99, in start
    r = self.task(self, **self.params)
  File "/home/ipvzero/Nornir/DMVPN/deploy_dmvpn.py", line 19, in load_vars
    config_vrf(task)
  File "/home/ipvzero/Nornir/DMVPN/deploy_dmvpn.py", line 35, in config_vrf
    task.run(
  File "/home/ipvzero/Nornir/.venv/lib/python3.10/site-packages/nornir/core/task.py", line 174, in run
    raise NornirSubTaskError(task=run_task, result=r)
nornir.core.exceptions.NornirSubTaskError: Subtask: Pushing VRF Commands (failed)


2023-03-14 05:54:20,601 - nornir.core.task -    ERROR -      start() - Host 'SPOKE2': task 'Pushing VRF Commands' failed with traceback:
Traceback (most recent call last):
  File "/home/ipvzero/Nornir/.venv/lib/python3.10/site-packages/nornir/core/task.py", line 99, in start
    r = self.task(self, **self.params)
  File "/home/ipvzero/Nornir/.venv/lib/python3.10/site-packages/nornir_scrapli/tasks/core/send_configs.py", line 58, in send_configs
    scrapli_conn = task.host.get_connection("scrapli", task.nornir.config)
  File "/home/ipvzero/Nornir/.venv/lib/python3.10/site-packages/nornir/core/inventory.py", line 494, in get_connection
    self.open_connection(
  File "/home/ipvzero/Nornir/.venv/lib/python3.10/site-packages/nornir/core/inventory.py", line 546, in open_connection
    conn_obj.open(
  File "/home/ipvzero/Nornir/.venv/lib/python3.10/site-packages/nornir_scrapli/connection.py", line 105, in open
    connection.open()
  File "/home/ipvzero/Nornir/.venv/lib/python3.10/site-packages/scrapli/driver/base/sync_driver.py", line 88, in open
    self.channel.channel_authenticate_ssh(
  File "/home/ipvzero/Nornir/.venv/lib/python3.10/site-packages/scrapli/decorators.py", line 216, in decorate
    return _multiprocessing_timeout(
  File "/home/ipvzero/Nornir/.venv/lib/python3.10/site-packages/scrapli/decorators.py", line 113, in _multiprocessing_timeout
    return future.result()
  File "/usr/lib/python3.10/concurrent/futures/_base.py", line 451, in result
    return self.__get_result()
  File "/usr/lib/python3.10/concurrent/futures/_base.py", line 403, in __get_result
    raise self._exception
  File "/usr/lib/python3.10/concurrent/futures/thread.py", line 58, in run
    result = self.fn(*self.args, **self.kwargs)
  File "/home/ipvzero/Nornir/.venv/lib/python3.10/site-packages/scrapli/channel/sync_channel.py", line 302, in channel_authenticate_ssh
    raise ScrapliAuthenticationFailed(msg)
scrapli.exceptions.ScrapliAuthenticationFailed: password prompt seen more than once, assuming auth failed

2023-03-14 05:54:20,601 - nornir.core.task -    ERROR -      start() - Host 'SPOKE2': task 'load_vars' failed with traceback:
Traceback (most recent call last):
  File "/home/ipvzero/Nornir/.venv/lib/python3.10/site-packages/nornir/core/task.py", line 99, in start
    r = self.task(self, **self.params)
  File "/home/ipvzero/Nornir/DMVPN/deploy_dmvpn.py", line 19, in load_vars
    config_vrf(task)
  File "/home/ipvzero/Nornir/DMVPN/deploy_dmvpn.py", line 35, in config_vrf
    task.run(
  File "/home/ipvzero/Nornir/.venv/lib/python3.10/site-packages/nornir/core/task.py", line 174, in run
    raise NornirSubTaskError(task=run_task, result=r)
nornir.core.exceptions.NornirSubTaskError: Subtask: Pushing VRF Commands (failed)


2023-03-14 05:54:20,632 - nornir.core.task -    ERROR -      start() - Host 'HUB': task 'Pushing VRF Commands' failed with traceback:
Traceback (most recent call last):
  File "/home/ipvzero/Nornir/.venv/lib/python3.10/site-packages/nornir/core/task.py", line 99, in start
    r = self.task(self, **self.params)
  File "/home/ipvzero/Nornir/.venv/lib/python3.10/site-packages/nornir_scrapli/tasks/core/send_configs.py", line 58, in send_configs
    scrapli_conn = task.host.get_connection("scrapli", task.nornir.config)
  File "/home/ipvzero/Nornir/.venv/lib/python3.10/site-packages/nornir/core/inventory.py", line 494, in get_connection
    self.open_connection(
  File "/home/ipvzero/Nornir/.venv/lib/python3.10/site-packages/nornir/core/inventory.py", line 546, in open_connection
    conn_obj.open(
  File "/home/ipvzero/Nornir/.venv/lib/python3.10/site-packages/nornir_scrapli/connection.py", line 105, in open
    connection.open()
  File "/home/ipvzero/Nornir/.venv/lib/python3.10/site-packages/scrapli/driver/base/sync_driver.py", line 88, in open
    self.channel.channel_authenticate_ssh(
  File "/home/ipvzero/Nornir/.venv/lib/python3.10/site-packages/scrapli/decorators.py", line 216, in decorate
    return _multiprocessing_timeout(
  File "/home/ipvzero/Nornir/.venv/lib/python3.10/site-packages/scrapli/decorators.py", line 113, in _multiprocessing_timeout
    return future.result()
  File "/usr/lib/python3.10/concurrent/futures/_base.py", line 451, in result
    return self.__get_result()
  File "/usr/lib/python3.10/concurrent/futures/_base.py", line 403, in __get_result
    raise self._exception
  File "/usr/lib/python3.10/concurrent/futures/thread.py", line 58, in run
    result = self.fn(*self.args, **self.kwargs)
  File "/home/ipvzero/Nornir/.venv/lib/python3.10/site-packages/scrapli/channel/sync_channel.py", line 302, in channel_authenticate_ssh
    raise ScrapliAuthenticationFailed(msg)
scrapli.exceptions.ScrapliAuthenticationFailed: password prompt seen more than once, assuming auth failed

2023-03-14 05:54:20,632 - nornir.core.task -    ERROR -      start() - Host 'HUB': task 'load_vars' failed with traceback:
Traceback (most recent call last):
  File "/home/ipvzero/Nornir/.venv/lib/python3.10/site-packages/nornir/core/task.py", line 99, in start
    r = self.task(self, **self.params)
  File "/home/ipvzero/Nornir/DMVPN/deploy_dmvpn.py", line 19, in load_vars
    config_vrf(task)
  File "/home/ipvzero/Nornir/DMVPN/deploy_dmvpn.py", line 35, in config_vrf
    task.run(
  File "/home/ipvzero/Nornir/.venv/lib/python3.10/site-packages/nornir/core/task.py", line 174, in run
    raise NornirSubTaskError(task=run_task, result=r)
nornir.core.exceptions.NornirSubTaskError: Subtask: Pushing VRF Commands (failed)


2023-03-14 05:55:20,780 -  nornir.core -     INFO -        run() - Running task 'load_vars' with args {} on 4 hosts
2023-03-14 05:55:25,262 - nornir.core.task -    ERROR -      start() - Host 'SPOKE2': task 'Pushing VRF Commands' failed with traceback:
Traceback (most recent call last):
  File "/home/ipvzero/Nornir/.venv/lib/python3.10/site-packages/nornir/core/task.py", line 99, in start
    r = self.task(self, **self.params)
  File "/home/ipvzero/Nornir/.venv/lib/python3.10/site-packages/nornir_scrapli/tasks/core/send_configs.py", line 58, in send_configs
    scrapli_conn = task.host.get_connection("scrapli", task.nornir.config)
  File "/home/ipvzero/Nornir/.venv/lib/python3.10/site-packages/nornir/core/inventory.py", line 494, in get_connection
    self.open_connection(
  File "/home/ipvzero/Nornir/.venv/lib/python3.10/site-packages/nornir/core/inventory.py", line 546, in open_connection
    conn_obj.open(
  File "/home/ipvzero/Nornir/.venv/lib/python3.10/site-packages/nornir_scrapli/connection.py", line 105, in open
    connection.open()
  File "/home/ipvzero/Nornir/.venv/lib/python3.10/site-packages/scrapli/driver/base/sync_driver.py", line 88, in open
    self.channel.channel_authenticate_ssh(
  File "/home/ipvzero/Nornir/.venv/lib/python3.10/site-packages/scrapli/decorators.py", line 216, in decorate
    return _multiprocessing_timeout(
  File "/home/ipvzero/Nornir/.venv/lib/python3.10/site-packages/scrapli/decorators.py", line 113, in _multiprocessing_timeout
    return future.result()
  File "/usr/lib/python3.10/concurrent/futures/_base.py", line 451, in result
    return self.__get_result()
  File "/usr/lib/python3.10/concurrent/futures/_base.py", line 403, in __get_result
    raise self._exception
  File "/usr/lib/python3.10/concurrent/futures/thread.py", line 58, in run
    result = self.fn(*self.args, **self.kwargs)
  File "/home/ipvzero/Nornir/.venv/lib/python3.10/site-packages/scrapli/channel/sync_channel.py", line 302, in channel_authenticate_ssh
    raise ScrapliAuthenticationFailed(msg)
scrapli.exceptions.ScrapliAuthenticationFailed: password prompt seen more than once, assuming auth failed

2023-03-14 05:55:25,263 - nornir.core.task -    ERROR -      start() - Host 'SPOKE2': task 'load_vars' failed with traceback:
Traceback (most recent call last):
  File "/home/ipvzero/Nornir/.venv/lib/python3.10/site-packages/nornir/core/task.py", line 99, in start
    r = self.task(self, **self.params)
  File "/home/ipvzero/Nornir/DMVPN/deploy_dmvpn.py", line 19, in load_vars
    config_vrf(task)
  File "/home/ipvzero/Nornir/DMVPN/deploy_dmvpn.py", line 35, in config_vrf
    task.run(
  File "/home/ipvzero/Nornir/.venv/lib/python3.10/site-packages/nornir/core/task.py", line 174, in run
    raise NornirSubTaskError(task=run_task, result=r)
nornir.core.exceptions.NornirSubTaskError: Subtask: Pushing VRF Commands (failed)


2023-03-14 05:55:25,272 - nornir.core.task -    ERROR -      start() - Host 'SPOKE3': task 'Pushing VRF Commands' failed with traceback:
Traceback (most recent call last):
  File "/home/ipvzero/Nornir/.venv/lib/python3.10/site-packages/nornir/core/task.py", line 99, in start
    r = self.task(self, **self.params)
  File "/home/ipvzero/Nornir/.venv/lib/python3.10/site-packages/nornir_scrapli/tasks/core/send_configs.py", line 58, in send_configs
    scrapli_conn = task.host.get_connection("scrapli", task.nornir.config)
  File "/home/ipvzero/Nornir/.venv/lib/python3.10/site-packages/nornir/core/inventory.py", line 494, in get_connection
    self.open_connection(
  File "/home/ipvzero/Nornir/.venv/lib/python3.10/site-packages/nornir/core/inventory.py", line 546, in open_connection
    conn_obj.open(
  File "/home/ipvzero/Nornir/.venv/lib/python3.10/site-packages/nornir_scrapli/connection.py", line 105, in open
    connection.open()
  File "/home/ipvzero/Nornir/.venv/lib/python3.10/site-packages/scrapli/driver/base/sync_driver.py", line 88, in open
    self.channel.channel_authenticate_ssh(
  File "/home/ipvzero/Nornir/.venv/lib/python3.10/site-packages/scrapli/decorators.py", line 216, in decorate
    return _multiprocessing_timeout(
  File "/home/ipvzero/Nornir/.venv/lib/python3.10/site-packages/scrapli/decorators.py", line 113, in _multiprocessing_timeout
    return future.result()
  File "/usr/lib/python3.10/concurrent/futures/_base.py", line 451, in result
    return self.__get_result()
  File "/usr/lib/python3.10/concurrent/futures/_base.py", line 403, in __get_result
    raise self._exception
  File "/usr/lib/python3.10/concurrent/futures/thread.py", line 58, in run
    result = self.fn(*self.args, **self.kwargs)
  File "/home/ipvzero/Nornir/.venv/lib/python3.10/site-packages/scrapli/channel/sync_channel.py", line 302, in channel_authenticate_ssh
    raise ScrapliAuthenticationFailed(msg)
scrapli.exceptions.ScrapliAuthenticationFailed: password prompt seen more than once, assuming auth failed

2023-03-14 05:55:25,273 - nornir.core.task -    ERROR -      start() - Host 'SPOKE3': task 'load_vars' failed with traceback:
Traceback (most recent call last):
  File "/home/ipvzero/Nornir/.venv/lib/python3.10/site-packages/nornir/core/task.py", line 99, in start
    r = self.task(self, **self.params)
  File "/home/ipvzero/Nornir/DMVPN/deploy_dmvpn.py", line 19, in load_vars
    config_vrf(task)
  File "/home/ipvzero/Nornir/DMVPN/deploy_dmvpn.py", line 35, in config_vrf
    task.run(
  File "/home/ipvzero/Nornir/.venv/lib/python3.10/site-packages/nornir/core/task.py", line 174, in run
    raise NornirSubTaskError(task=run_task, result=r)
nornir.core.exceptions.NornirSubTaskError: Subtask: Pushing VRF Commands (failed)


2023-03-14 05:55:25,281 - nornir.core.task -    ERROR -      start() - Host 'HUB': task 'Pushing VRF Commands' failed with traceback:
Traceback (most recent call last):
  File "/home/ipvzero/Nornir/.venv/lib/python3.10/site-packages/nornir/core/task.py", line 99, in start
    r = self.task(self, **self.params)
  File "/home/ipvzero/Nornir/.venv/lib/python3.10/site-packages/nornir_scrapli/tasks/core/send_configs.py", line 58, in send_configs
    scrapli_conn = task.host.get_connection("scrapli", task.nornir.config)
  File "/home/ipvzero/Nornir/.venv/lib/python3.10/site-packages/nornir/core/inventory.py", line 494, in get_connection
    self.open_connection(
  File "/home/ipvzero/Nornir/.venv/lib/python3.10/site-packages/nornir/core/inventory.py", line 546, in open_connection
    conn_obj.open(
  File "/home/ipvzero/Nornir/.venv/lib/python3.10/site-packages/nornir_scrapli/connection.py", line 105, in open
    connection.open()
  File "/home/ipvzero/Nornir/.venv/lib/python3.10/site-packages/scrapli/driver/base/sync_driver.py", line 88, in open
    self.channel.channel_authenticate_ssh(
  File "/home/ipvzero/Nornir/.venv/lib/python3.10/site-packages/scrapli/decorators.py", line 216, in decorate
    return _multiprocessing_timeout(
  File "/home/ipvzero/Nornir/.venv/lib/python3.10/site-packages/scrapli/decorators.py", line 113, in _multiprocessing_timeout
    return future.result()
  File "/usr/lib/python3.10/concurrent/futures/_base.py", line 451, in result
    return self.__get_result()
  File "/usr/lib/python3.10/concurrent/futures/_base.py", line 403, in __get_result
    raise self._exception
  File "/usr/lib/python3.10/concurrent/futures/thread.py", line 58, in run
    result = self.fn(*self.args, **self.kwargs)
  File "/home/ipvzero/Nornir/.venv/lib/python3.10/site-packages/scrapli/channel/sync_channel.py", line 302, in channel_authenticate_ssh
    raise ScrapliAuthenticationFailed(msg)
scrapli.exceptions.ScrapliAuthenticationFailed: password prompt seen more than once, assuming auth failed

2023-03-14 05:55:25,282 - nornir.core.task -    ERROR -      start() - Host 'HUB': task 'load_vars' failed with traceback:
Traceback (most recent call last):
  File "/home/ipvzero/Nornir/.venv/lib/python3.10/site-packages/nornir/core/task.py", line 99, in start
    r = self.task(self, **self.params)
  File "/home/ipvzero/Nornir/DMVPN/deploy_dmvpn.py", line 19, in load_vars
    config_vrf(task)
  File "/home/ipvzero/Nornir/DMVPN/deploy_dmvpn.py", line 35, in config_vrf
    task.run(
  File "/home/ipvzero/Nornir/.venv/lib/python3.10/site-packages/nornir/core/task.py", line 174, in run
    raise NornirSubTaskError(task=run_task, result=r)
nornir.core.exceptions.NornirSubTaskError: Subtask: Pushing VRF Commands (failed)


2023-03-14 05:55:25,414 - nornir.core.task -    ERROR -      start() - Host 'SPOKE1': task 'Pushing VRF Commands' failed with traceback:
Traceback (most recent call last):
  File "/home/ipvzero/Nornir/.venv/lib/python3.10/site-packages/nornir/core/task.py", line 99, in start
    r = self.task(self, **self.params)
  File "/home/ipvzero/Nornir/.venv/lib/python3.10/site-packages/nornir_scrapli/tasks/core/send_configs.py", line 58, in send_configs
    scrapli_conn = task.host.get_connection("scrapli", task.nornir.config)
  File "/home/ipvzero/Nornir/.venv/lib/python3.10/site-packages/nornir/core/inventory.py", line 494, in get_connection
    self.open_connection(
  File "/home/ipvzero/Nornir/.venv/lib/python3.10/site-packages/nornir/core/inventory.py", line 546, in open_connection
    conn_obj.open(
  File "/home/ipvzero/Nornir/.venv/lib/python3.10/site-packages/nornir_scrapli/connection.py", line 105, in open
    connection.open()
  File "/home/ipvzero/Nornir/.venv/lib/python3.10/site-packages/scrapli/driver/base/sync_driver.py", line 88, in open
    self.channel.channel_authenticate_ssh(
  File "/home/ipvzero/Nornir/.venv/lib/python3.10/site-packages/scrapli/decorators.py", line 216, in decorate
    return _multiprocessing_timeout(
  File "/home/ipvzero/Nornir/.venv/lib/python3.10/site-packages/scrapli/decorators.py", line 113, in _multiprocessing_timeout
    return future.result()
  File "/usr/lib/python3.10/concurrent/futures/_base.py", line 451, in result
    return self.__get_result()
  File "/usr/lib/python3.10/concurrent/futures/_base.py", line 403, in __get_result
    raise self._exception
  File "/usr/lib/python3.10/concurrent/futures/thread.py", line 58, in run
    result = self.fn(*self.args, **self.kwargs)
  File "/home/ipvzero/Nornir/.venv/lib/python3.10/site-packages/scrapli/channel/sync_channel.py", line 302, in channel_authenticate_ssh
    raise ScrapliAuthenticationFailed(msg)
scrapli.exceptions.ScrapliAuthenticationFailed: password prompt seen more than once, assuming auth failed

2023-03-14 05:55:25,414 - nornir.core.task -    ERROR -      start() - Host 'SPOKE1': task 'load_vars' failed with traceback:
Traceback (most recent call last):
  File "/home/ipvzero/Nornir/.venv/lib/python3.10/site-packages/nornir/core/task.py", line 99, in start
    r = self.task(self, **self.params)
  File "/home/ipvzero/Nornir/DMVPN/deploy_dmvpn.py", line 19, in load_vars
    config_vrf(task)
  File "/home/ipvzero/Nornir/DMVPN/deploy_dmvpn.py", line 35, in config_vrf
    task.run(
  File "/home/ipvzero/Nornir/.venv/lib/python3.10/site-packages/nornir/core/task.py", line 174, in run
    raise NornirSubTaskError(task=run_task, result=r)
nornir.core.exceptions.NornirSubTaskError: Subtask: Pushing VRF Commands (failed)


2023-03-14 05:56:33,452 -  nornir.core -     INFO -        run() - Running task 'load_vars' with args {} on 4 hosts
2023-03-14 05:56:35,076 - nornir.core.task -    ERROR -      start() - Host 'SPOKE3': task 'Building DMVPN Configuration' failed with traceback:
Traceback (most recent call last):
  File "/home/ipvzero/Nornir/.venv/lib/python3.10/site-packages/nornir/core/task.py", line 99, in start
    r = self.task(self, **self.params)
  File "/home/ipvzero/Nornir/.venv/lib/python3.10/site-packages/nornir_jinja2/plugins/tasks/template_file.py", line 42, in template_file
    t = env.get_template(template)
  File "/home/ipvzero/Nornir/.venv/lib/python3.10/site-packages/jinja2/environment.py", line 1010, in get_template
    return self._load_template(name, globals)
  File "/home/ipvzero/Nornir/.venv/lib/python3.10/site-packages/jinja2/environment.py", line 969, in _load_template
    template = self.loader.load(self, name, self.make_globals(globals))
  File "/home/ipvzero/Nornir/.venv/lib/python3.10/site-packages/jinja2/loaders.py", line 138, in load
    code = environment.compile(source, name, filename)
  File "/home/ipvzero/Nornir/.venv/lib/python3.10/site-packages/jinja2/environment.py", line 768, in compile
    self.handle_exception(source=source_hint)
  File "/home/ipvzero/Nornir/.venv/lib/python3.10/site-packages/jinja2/environment.py", line 936, in handle_exception
    raise rewrite_traceback_stack(source=source)
  File "templates/dmvpn.j2", line 16, in template
    {% if host.facts.dmvpn.type = "Hub" %}
jinja2.exceptions.TemplateSyntaxError: expected token 'end of statement block', got '='

2023-03-14 05:56:35,077 - nornir.core.task -    ERROR -      start() - Host 'SPOKE3': task 'load_vars' failed with traceback:
Traceback (most recent call last):
  File "/home/ipvzero/Nornir/.venv/lib/python3.10/site-packages/nornir/core/task.py", line 99, in start
    r = self.task(self, **self.params)
  File "/home/ipvzero/Nornir/DMVPN/deploy_dmvpn.py", line 24, in load_vars
    config_vrf(task)
  File "/home/ipvzero/Nornir/DMVPN/deploy_dmvpn.py", line 43, in config_vrf
    config_dmvpn(task)
  File "/home/ipvzero/Nornir/DMVPN/deploy_dmvpn.py", line 51, in config_dmvpn
    dmvpn_template = task.run(
  File "/home/ipvzero/Nornir/.venv/lib/python3.10/site-packages/nornir/core/task.py", line 174, in run
    raise NornirSubTaskError(task=run_task, result=r)
nornir.core.exceptions.NornirSubTaskError: Subtask: Building DMVPN Configuration (failed)


2023-03-14 05:56:35,236 - nornir.core.task -    ERROR -      start() - Host 'SPOKE2': task 'Building DMVPN Configuration' failed with traceback:
Traceback (most recent call last):
  File "/home/ipvzero/Nornir/.venv/lib/python3.10/site-packages/nornir/core/task.py", line 99, in start
    r = self.task(self, **self.params)
  File "/home/ipvzero/Nornir/.venv/lib/python3.10/site-packages/nornir_jinja2/plugins/tasks/template_file.py", line 42, in template_file
    t = env.get_template(template)
  File "/home/ipvzero/Nornir/.venv/lib/python3.10/site-packages/jinja2/environment.py", line 1010, in get_template
    return self._load_template(name, globals)
  File "/home/ipvzero/Nornir/.venv/lib/python3.10/site-packages/jinja2/environment.py", line 969, in _load_template
    template = self.loader.load(self, name, self.make_globals(globals))
  File "/home/ipvzero/Nornir/.venv/lib/python3.10/site-packages/jinja2/loaders.py", line 138, in load
    code = environment.compile(source, name, filename)
  File "/home/ipvzero/Nornir/.venv/lib/python3.10/site-packages/jinja2/environment.py", line 768, in compile
    self.handle_exception(source=source_hint)
  File "/home/ipvzero/Nornir/.venv/lib/python3.10/site-packages/jinja2/environment.py", line 936, in handle_exception
    raise rewrite_traceback_stack(source=source)
  File "templates/dmvpn.j2", line 16, in template
    {% if host.facts.dmvpn.type = "Hub" %}
jinja2.exceptions.TemplateSyntaxError: expected token 'end of statement block', got '='

2023-03-14 05:56:35,236 - nornir.core.task -    ERROR -      start() - Host 'SPOKE2': task 'load_vars' failed with traceback:
Traceback (most recent call last):
  File "/home/ipvzero/Nornir/.venv/lib/python3.10/site-packages/nornir/core/task.py", line 99, in start
    r = self.task(self, **self.params)
  File "/home/ipvzero/Nornir/DMVPN/deploy_dmvpn.py", line 24, in load_vars
    config_vrf(task)
  File "/home/ipvzero/Nornir/DMVPN/deploy_dmvpn.py", line 43, in config_vrf
    config_dmvpn(task)
  File "/home/ipvzero/Nornir/DMVPN/deploy_dmvpn.py", line 51, in config_dmvpn
    dmvpn_template = task.run(
  File "/home/ipvzero/Nornir/.venv/lib/python3.10/site-packages/nornir/core/task.py", line 174, in run
    raise NornirSubTaskError(task=run_task, result=r)
nornir.core.exceptions.NornirSubTaskError: Subtask: Building DMVPN Configuration (failed)


2023-03-14 05:56:35,262 - nornir.core.task -    ERROR -      start() - Host 'HUB': task 'Building DMVPN Configuration' failed with traceback:
Traceback (most recent call last):
  File "/home/ipvzero/Nornir/.venv/lib/python3.10/site-packages/nornir/core/task.py", line 99, in start
    r = self.task(self, **self.params)
  File "/home/ipvzero/Nornir/.venv/lib/python3.10/site-packages/nornir_jinja2/plugins/tasks/template_file.py", line 42, in template_file
    t = env.get_template(template)
  File "/home/ipvzero/Nornir/.venv/lib/python3.10/site-packages/jinja2/environment.py", line 1010, in get_template
    return self._load_template(name, globals)
  File "/home/ipvzero/Nornir/.venv/lib/python3.10/site-packages/jinja2/environment.py", line 969, in _load_template
    template = self.loader.load(self, name, self.make_globals(globals))
  File "/home/ipvzero/Nornir/.venv/lib/python3.10/site-packages/jinja2/loaders.py", line 138, in load
    code = environment.compile(source, name, filename)
  File "/home/ipvzero/Nornir/.venv/lib/python3.10/site-packages/jinja2/environment.py", line 768, in compile
    self.handle_exception(source=source_hint)
  File "/home/ipvzero/Nornir/.venv/lib/python3.10/site-packages/jinja2/environment.py", line 936, in handle_exception
    raise rewrite_traceback_stack(source=source)
  File "templates/dmvpn.j2", line 16, in template
    {% if host.facts.dmvpn.type = "Hub" %}
jinja2.exceptions.TemplateSyntaxError: expected token 'end of statement block', got '='

2023-03-14 05:56:35,263 - nornir.core.task -    ERROR -      start() - Host 'HUB': task 'load_vars' failed with traceback:
Traceback (most recent call last):
  File "/home/ipvzero/Nornir/.venv/lib/python3.10/site-packages/nornir/core/task.py", line 99, in start
    r = self.task(self, **self.params)
  File "/home/ipvzero/Nornir/DMVPN/deploy_dmvpn.py", line 24, in load_vars
    config_vrf(task)
  File "/home/ipvzero/Nornir/DMVPN/deploy_dmvpn.py", line 43, in config_vrf
    config_dmvpn(task)
  File "/home/ipvzero/Nornir/DMVPN/deploy_dmvpn.py", line 51, in config_dmvpn
    dmvpn_template = task.run(
  File "/home/ipvzero/Nornir/.venv/lib/python3.10/site-packages/nornir/core/task.py", line 174, in run
    raise NornirSubTaskError(task=run_task, result=r)
nornir.core.exceptions.NornirSubTaskError: Subtask: Building DMVPN Configuration (failed)


2023-03-14 05:56:35,270 - nornir.core.task -    ERROR -      start() - Host 'SPOKE1': task 'Building DMVPN Configuration' failed with traceback:
Traceback (most recent call last):
  File "/home/ipvzero/Nornir/.venv/lib/python3.10/site-packages/nornir/core/task.py", line 99, in start
    r = self.task(self, **self.params)
  File "/home/ipvzero/Nornir/.venv/lib/python3.10/site-packages/nornir_jinja2/plugins/tasks/template_file.py", line 42, in template_file
    t = env.get_template(template)
  File "/home/ipvzero/Nornir/.venv/lib/python3.10/site-packages/jinja2/environment.py", line 1010, in get_template
    return self._load_template(name, globals)
  File "/home/ipvzero/Nornir/.venv/lib/python3.10/site-packages/jinja2/environment.py", line 969, in _load_template
    template = self.loader.load(self, name, self.make_globals(globals))
  File "/home/ipvzero/Nornir/.venv/lib/python3.10/site-packages/jinja2/loaders.py", line 138, in load
    code = environment.compile(source, name, filename)
  File "/home/ipvzero/Nornir/.venv/lib/python3.10/site-packages/jinja2/environment.py", line 768, in compile
    self.handle_exception(source=source_hint)
  File "/home/ipvzero/Nornir/.venv/lib/python3.10/site-packages/jinja2/environment.py", line 936, in handle_exception
    raise rewrite_traceback_stack(source=source)
  File "templates/dmvpn.j2", line 16, in template
    {% if host.facts.dmvpn.type = "Hub" %}
jinja2.exceptions.TemplateSyntaxError: expected token 'end of statement block', got '='

2023-03-14 05:56:35,271 - nornir.core.task -    ERROR -      start() - Host 'SPOKE1': task 'load_vars' failed with traceback:
Traceback (most recent call last):
  File "/home/ipvzero/Nornir/.venv/lib/python3.10/site-packages/nornir/core/task.py", line 99, in start
    r = self.task(self, **self.params)
  File "/home/ipvzero/Nornir/DMVPN/deploy_dmvpn.py", line 24, in load_vars
    config_vrf(task)
  File "/home/ipvzero/Nornir/DMVPN/deploy_dmvpn.py", line 43, in config_vrf
    config_dmvpn(task)
  File "/home/ipvzero/Nornir/DMVPN/deploy_dmvpn.py", line 51, in config_dmvpn
    dmvpn_template = task.run(
  File "/home/ipvzero/Nornir/.venv/lib/python3.10/site-packages/nornir/core/task.py", line 174, in run
    raise NornirSubTaskError(task=run_task, result=r)
nornir.core.exceptions.NornirSubTaskError: Subtask: Building DMVPN Configuration (failed)


2023-03-14 05:58:27,856 -  nornir.core -     INFO -        run() - Running task 'load_vars' with args {} on 4 hosts
2023-03-14 05:58:29,386 - nornir.core.task -    ERROR -      start() - Host 'HUB': task 'Building DMVPN Configuration' failed with traceback:
Traceback (most recent call last):
  File "/home/ipvzero/Nornir/.venv/lib/python3.10/site-packages/nornir/core/task.py", line 99, in start
    r = self.task(self, **self.params)
  File "/home/ipvzero/Nornir/.venv/lib/python3.10/site-packages/nornir_jinja2/plugins/tasks/template_file.py", line 42, in template_file
    t = env.get_template(template)
  File "/home/ipvzero/Nornir/.venv/lib/python3.10/site-packages/jinja2/environment.py", line 1010, in get_template
    return self._load_template(name, globals)
  File "/home/ipvzero/Nornir/.venv/lib/python3.10/site-packages/jinja2/environment.py", line 969, in _load_template
    template = self.loader.load(self, name, self.make_globals(globals))
  File "/home/ipvzero/Nornir/.venv/lib/python3.10/site-packages/jinja2/loaders.py", line 138, in load
    code = environment.compile(source, name, filename)
  File "/home/ipvzero/Nornir/.venv/lib/python3.10/site-packages/jinja2/environment.py", line 768, in compile
    self.handle_exception(source=source_hint)
  File "/home/ipvzero/Nornir/.venv/lib/python3.10/site-packages/jinja2/environment.py", line 936, in handle_exception
    raise rewrite_traceback_stack(source=source)
  File "templates/dmvpn.j2", line 36, in template
    ip nhrp map {{ host.group_facts.dmvpn.hub.tunnel_ip }} {{ host.group_facts.dmvpn.hub.global_ip %}}
jinja2.exceptions.TemplateSyntaxError: unexpected 'end of print statement'

2023-03-14 05:58:29,387 - nornir.core.task -    ERROR -      start() - Host 'HUB': task 'load_vars' failed with traceback:
Traceback (most recent call last):
  File "/home/ipvzero/Nornir/.venv/lib/python3.10/site-packages/nornir/core/task.py", line 99, in start
    r = self.task(self, **self.params)
  File "/home/ipvzero/Nornir/DMVPN/deploy_dmvpn.py", line 24, in load_vars
    config_vrf(task)
  File "/home/ipvzero/Nornir/DMVPN/deploy_dmvpn.py", line 43, in config_vrf
    config_dmvpn(task)
  File "/home/ipvzero/Nornir/DMVPN/deploy_dmvpn.py", line 51, in config_dmvpn
    dmvpn_template = task.run(
  File "/home/ipvzero/Nornir/.venv/lib/python3.10/site-packages/nornir/core/task.py", line 174, in run
    raise NornirSubTaskError(task=run_task, result=r)
nornir.core.exceptions.NornirSubTaskError: Subtask: Building DMVPN Configuration (failed)


2023-03-14 05:58:29,606 - nornir.core.task -    ERROR -      start() - Host 'SPOKE2': task 'Building DMVPN Configuration' failed with traceback:
Traceback (most recent call last):
  File "/home/ipvzero/Nornir/.venv/lib/python3.10/site-packages/nornir/core/task.py", line 99, in start
    r = self.task(self, **self.params)
  File "/home/ipvzero/Nornir/.venv/lib/python3.10/site-packages/nornir_jinja2/plugins/tasks/template_file.py", line 42, in template_file
    t = env.get_template(template)
  File "/home/ipvzero/Nornir/.venv/lib/python3.10/site-packages/jinja2/environment.py", line 1010, in get_template
    return self._load_template(name, globals)
  File "/home/ipvzero/Nornir/.venv/lib/python3.10/site-packages/jinja2/environment.py", line 969, in _load_template
    template = self.loader.load(self, name, self.make_globals(globals))
  File "/home/ipvzero/Nornir/.venv/lib/python3.10/site-packages/jinja2/loaders.py", line 138, in load
    code = environment.compile(source, name, filename)
  File "/home/ipvzero/Nornir/.venv/lib/python3.10/site-packages/jinja2/environment.py", line 768, in compile
    self.handle_exception(source=source_hint)
  File "/home/ipvzero/Nornir/.venv/lib/python3.10/site-packages/jinja2/environment.py", line 936, in handle_exception
    raise rewrite_traceback_stack(source=source)
  File "templates/dmvpn.j2", line 36, in template
    ip nhrp map {{ host.group_facts.dmvpn.hub.tunnel_ip }} {{ host.group_facts.dmvpn.hub.global_ip %}}
jinja2.exceptions.TemplateSyntaxError: unexpected 'end of print statement'

2023-03-14 05:58:29,607 - nornir.core.task -    ERROR -      start() - Host 'SPOKE2': task 'load_vars' failed with traceback:
Traceback (most recent call last):
  File "/home/ipvzero/Nornir/.venv/lib/python3.10/site-packages/nornir/core/task.py", line 99, in start
    r = self.task(self, **self.params)
  File "/home/ipvzero/Nornir/DMVPN/deploy_dmvpn.py", line 24, in load_vars
    config_vrf(task)
  File "/home/ipvzero/Nornir/DMVPN/deploy_dmvpn.py", line 43, in config_vrf
    config_dmvpn(task)
  File "/home/ipvzero/Nornir/DMVPN/deploy_dmvpn.py", line 51, in config_dmvpn
    dmvpn_template = task.run(
  File "/home/ipvzero/Nornir/.venv/lib/python3.10/site-packages/nornir/core/task.py", line 174, in run
    raise NornirSubTaskError(task=run_task, result=r)
nornir.core.exceptions.NornirSubTaskError: Subtask: Building DMVPN Configuration (failed)


2023-03-14 05:58:29,654 - nornir.core.task -    ERROR -      start() - Host 'SPOKE1': task 'Building DMVPN Configuration' failed with traceback:
Traceback (most recent call last):
  File "/home/ipvzero/Nornir/.venv/lib/python3.10/site-packages/nornir/core/task.py", line 99, in start
    r = self.task(self, **self.params)
  File "/home/ipvzero/Nornir/.venv/lib/python3.10/site-packages/nornir_jinja2/plugins/tasks/template_file.py", line 42, in template_file
    t = env.get_template(template)
  File "/home/ipvzero/Nornir/.venv/lib/python3.10/site-packages/jinja2/environment.py", line 1010, in get_template
    return self._load_template(name, globals)
  File "/home/ipvzero/Nornir/.venv/lib/python3.10/site-packages/jinja2/environment.py", line 969, in _load_template
    template = self.loader.load(self, name, self.make_globals(globals))
  File "/home/ipvzero/Nornir/.venv/lib/python3.10/site-packages/jinja2/loaders.py", line 138, in load
    code = environment.compile(source, name, filename)
  File "/home/ipvzero/Nornir/.venv/lib/python3.10/site-packages/jinja2/environment.py", line 768, in compile
    self.handle_exception(source=source_hint)
  File "/home/ipvzero/Nornir/.venv/lib/python3.10/site-packages/jinja2/environment.py", line 936, in handle_exception
    raise rewrite_traceback_stack(source=source)
  File "templates/dmvpn.j2", line 36, in template
    ip nhrp map {{ host.group_facts.dmvpn.hub.tunnel_ip }} {{ host.group_facts.dmvpn.hub.global_ip %}}
jinja2.exceptions.TemplateSyntaxError: unexpected 'end of print statement'

2023-03-14 05:58:29,654 - nornir.core.task -    ERROR -      start() - Host 'SPOKE1': task 'load_vars' failed with traceback:
Traceback (most recent call last):
  File "/home/ipvzero/Nornir/.venv/lib/python3.10/site-packages/nornir/core/task.py", line 99, in start
    r = self.task(self, **self.params)
  File "/home/ipvzero/Nornir/DMVPN/deploy_dmvpn.py", line 24, in load_vars
    config_vrf(task)
  File "/home/ipvzero/Nornir/DMVPN/deploy_dmvpn.py", line 43, in config_vrf
    config_dmvpn(task)
  File "/home/ipvzero/Nornir/DMVPN/deploy_dmvpn.py", line 51, in config_dmvpn
    dmvpn_template = task.run(
  File "/home/ipvzero/Nornir/.venv/lib/python3.10/site-packages/nornir/core/task.py", line 174, in run
    raise NornirSubTaskError(task=run_task, result=r)
nornir.core.exceptions.NornirSubTaskError: Subtask: Building DMVPN Configuration (failed)


2023-03-14 05:58:29,691 - nornir.core.task -    ERROR -      start() - Host 'SPOKE3': task 'Building DMVPN Configuration' failed with traceback:
Traceback (most recent call last):
  File "/home/ipvzero/Nornir/.venv/lib/python3.10/site-packages/nornir/core/task.py", line 99, in start
    r = self.task(self, **self.params)
  File "/home/ipvzero/Nornir/.venv/lib/python3.10/site-packages/nornir_jinja2/plugins/tasks/template_file.py", line 42, in template_file
    t = env.get_template(template)
  File "/home/ipvzero/Nornir/.venv/lib/python3.10/site-packages/jinja2/environment.py", line 1010, in get_template
    return self._load_template(name, globals)
  File "/home/ipvzero/Nornir/.venv/lib/python3.10/site-packages/jinja2/environment.py", line 969, in _load_template
    template = self.loader.load(self, name, self.make_globals(globals))
  File "/home/ipvzero/Nornir/.venv/lib/python3.10/site-packages/jinja2/loaders.py", line 138, in load
    code = environment.compile(source, name, filename)
  File "/home/ipvzero/Nornir/.venv/lib/python3.10/site-packages/jinja2/environment.py", line 768, in compile
    self.handle_exception(source=source_hint)
  File "/home/ipvzero/Nornir/.venv/lib/python3.10/site-packages/jinja2/environment.py", line 936, in handle_exception
    raise rewrite_traceback_stack(source=source)
  File "templates/dmvpn.j2", line 36, in template
    ip nhrp map {{ host.group_facts.dmvpn.hub.tunnel_ip }} {{ host.group_facts.dmvpn.hub.global_ip %}}
jinja2.exceptions.TemplateSyntaxError: unexpected 'end of print statement'

2023-03-14 05:58:29,692 - nornir.core.task -    ERROR -      start() - Host 'SPOKE3': task 'load_vars' failed with traceback:
Traceback (most recent call last):
  File "/home/ipvzero/Nornir/.venv/lib/python3.10/site-packages/nornir/core/task.py", line 99, in start
    r = self.task(self, **self.params)
  File "/home/ipvzero/Nornir/DMVPN/deploy_dmvpn.py", line 24, in load_vars
    config_vrf(task)
  File "/home/ipvzero/Nornir/DMVPN/deploy_dmvpn.py", line 43, in config_vrf
    config_dmvpn(task)
  File "/home/ipvzero/Nornir/DMVPN/deploy_dmvpn.py", line 51, in config_dmvpn
    dmvpn_template = task.run(
  File "/home/ipvzero/Nornir/.venv/lib/python3.10/site-packages/nornir/core/task.py", line 174, in run
    raise NornirSubTaskError(task=run_task, result=r)
nornir.core.exceptions.NornirSubTaskError: Subtask: Building DMVPN Configuration (failed)


2023-03-14 06:00:17,786 -  nornir.core -     INFO -        run() - Running task 'load_vars' with args {} on 4 hosts
2023-03-14 06:00:19,662 - nornir.core.task -    ERROR -      start() - Host 'SPOKE3': task 'Building DMVPN Configuration' failed with traceback:
Traceback (most recent call last):
  File "/home/ipvzero/Nornir/.venv/lib/python3.10/site-packages/nornir/core/task.py", line 99, in start
    r = self.task(self, **self.params)
  File "/home/ipvzero/Nornir/.venv/lib/python3.10/site-packages/nornir_jinja2/plugins/tasks/template_file.py", line 43, in template_file
    text = t.render(host=task.host, **kwargs)
  File "/home/ipvzero/Nornir/.venv/lib/python3.10/site-packages/jinja2/environment.py", line 1301, in render
    self.environment.handle_exception()
  File "/home/ipvzero/Nornir/.venv/lib/python3.10/site-packages/jinja2/environment.py", line 936, in handle_exception
    raise rewrite_traceback_stack(source=source)
  File "templates/dmvpn.j2", line 29, in top-level template code
    ip address {{ host.facts.dmvpn.tunnel_ip }}
jinja2.exceptions.UndefinedError: 'dict object' has no attribute 'tunnel_ip'

2023-03-14 06:00:19,664 - nornir.core.task -    ERROR -      start() - Host 'SPOKE3': task 'load_vars' failed with traceback:
Traceback (most recent call last):
  File "/home/ipvzero/Nornir/.venv/lib/python3.10/site-packages/nornir/core/task.py", line 99, in start
    r = self.task(self, **self.params)
  File "/home/ipvzero/Nornir/DMVPN/deploy_dmvpn.py", line 24, in load_vars
    config_vrf(task)
  File "/home/ipvzero/Nornir/DMVPN/deploy_dmvpn.py", line 43, in config_vrf
    config_dmvpn(task)
  File "/home/ipvzero/Nornir/DMVPN/deploy_dmvpn.py", line 51, in config_dmvpn
    dmvpn_template = task.run(
  File "/home/ipvzero/Nornir/.venv/lib/python3.10/site-packages/nornir/core/task.py", line 174, in run
    raise NornirSubTaskError(task=run_task, result=r)
nornir.core.exceptions.NornirSubTaskError: Subtask: Building DMVPN Configuration (failed)


2023-03-14 06:00:19,754 - nornir.core.task -    ERROR -      start() - Host 'SPOKE1': task 'Building DMVPN Configuration' failed with traceback:
Traceback (most recent call last):
  File "/home/ipvzero/Nornir/.venv/lib/python3.10/site-packages/nornir/core/task.py", line 99, in start
    r = self.task(self, **self.params)
  File "/home/ipvzero/Nornir/.venv/lib/python3.10/site-packages/nornir_jinja2/plugins/tasks/template_file.py", line 43, in template_file
    text = t.render(host=task.host, **kwargs)
  File "/home/ipvzero/Nornir/.venv/lib/python3.10/site-packages/jinja2/environment.py", line 1301, in render
    self.environment.handle_exception()
  File "/home/ipvzero/Nornir/.venv/lib/python3.10/site-packages/jinja2/environment.py", line 936, in handle_exception
    raise rewrite_traceback_stack(source=source)
  File "templates/dmvpn.j2", line 29, in top-level template code
    ip address {{ host.facts.dmvpn.tunnel_ip }}
jinja2.exceptions.UndefinedError: 'dict object' has no attribute 'tunnel_ip'

2023-03-14 06:00:19,756 - nornir.core.task -    ERROR -      start() - Host 'SPOKE1': task 'load_vars' failed with traceback:
Traceback (most recent call last):
  File "/home/ipvzero/Nornir/.venv/lib/python3.10/site-packages/nornir/core/task.py", line 99, in start
    r = self.task(self, **self.params)
  File "/home/ipvzero/Nornir/DMVPN/deploy_dmvpn.py", line 24, in load_vars
    config_vrf(task)
  File "/home/ipvzero/Nornir/DMVPN/deploy_dmvpn.py", line 43, in config_vrf
    config_dmvpn(task)
  File "/home/ipvzero/Nornir/DMVPN/deploy_dmvpn.py", line 51, in config_dmvpn
    dmvpn_template = task.run(
  File "/home/ipvzero/Nornir/.venv/lib/python3.10/site-packages/nornir/core/task.py", line 174, in run
    raise NornirSubTaskError(task=run_task, result=r)
nornir.core.exceptions.NornirSubTaskError: Subtask: Building DMVPN Configuration (failed)


2023-03-14 06:00:19,788 - nornir.core.task -    ERROR -      start() - Host 'SPOKE2': task 'Building DMVPN Configuration' failed with traceback:
Traceback (most recent call last):
  File "/home/ipvzero/Nornir/.venv/lib/python3.10/site-packages/nornir/core/task.py", line 99, in start
    r = self.task(self, **self.params)
  File "/home/ipvzero/Nornir/.venv/lib/python3.10/site-packages/nornir_jinja2/plugins/tasks/template_file.py", line 43, in template_file
    text = t.render(host=task.host, **kwargs)
  File "/home/ipvzero/Nornir/.venv/lib/python3.10/site-packages/jinja2/environment.py", line 1301, in render
    self.environment.handle_exception()
  File "/home/ipvzero/Nornir/.venv/lib/python3.10/site-packages/jinja2/environment.py", line 936, in handle_exception
    raise rewrite_traceback_stack(source=source)
  File "templates/dmvpn.j2", line 29, in top-level template code
    ip address {{ host.facts.dmvpn.tunnel_ip }}
jinja2.exceptions.UndefinedError: 'dict object' has no attribute 'tunnel_ip'

2023-03-14 06:00:19,789 - nornir.core.task -    ERROR -      start() - Host 'SPOKE2': task 'load_vars' failed with traceback:
Traceback (most recent call last):
  File "/home/ipvzero/Nornir/.venv/lib/python3.10/site-packages/nornir/core/task.py", line 99, in start
    r = self.task(self, **self.params)
  File "/home/ipvzero/Nornir/DMVPN/deploy_dmvpn.py", line 24, in load_vars
    config_vrf(task)
  File "/home/ipvzero/Nornir/DMVPN/deploy_dmvpn.py", line 43, in config_vrf
    config_dmvpn(task)
  File "/home/ipvzero/Nornir/DMVPN/deploy_dmvpn.py", line 51, in config_dmvpn
    dmvpn_template = task.run(
  File "/home/ipvzero/Nornir/.venv/lib/python3.10/site-packages/nornir/core/task.py", line 174, in run
    raise NornirSubTaskError(task=run_task, result=r)
nornir.core.exceptions.NornirSubTaskError: Subtask: Building DMVPN Configuration (failed)


2023-03-14 06:00:22,688 - nornir.core.task -    ERROR -      start() - Host 'HUB': task 'load_vars' failed with traceback:
Traceback (most recent call last):
  File "/home/ipvzero/Nornir/.venv/lib/python3.10/site-packages/nornir/core/task.py", line 99, in start
    r = self.task(self, **self.params)
  File "/home/ipvzero/Nornir/DMVPN/deploy_dmvpn.py", line 24, in load_vars
    config_vrf(task)
  File "/home/ipvzero/Nornir/DMVPN/deploy_dmvpn.py", line 43, in config_vrf
    config_dmvpn(task)
  File "/home/ipvzero/Nornir/DMVPN/deploy_dmvpn.py", line 60, in config_dmvpn
    task.run(
  File "/home/ipvzero/Nornir/.venv/lib/python3.10/site-packages/nornir/core/task.py", line 174, in run
    raise NornirSubTaskError(task=run_task, result=r)
nornir.core.exceptions.NornirSubTaskError: Subtask: Pushing DMVPN Commands (failed)


2023-03-15 04:27:18,759 -  nornir.core -     INFO -        run() - Running task 'load_vars' with args {} on 4 hosts
2023-03-15 04:27:20,425 - nornir.core.task -    ERROR -      start() - Host 'SPOKE2': task 'Building DMVPN Configuration' failed with traceback:
Traceback (most recent call last):
  File "/home/ipvzero/Nornir/.venv/lib/python3.10/site-packages/nornir/core/task.py", line 99, in start
    r = self.task(self, **self.params)
  File "/home/ipvzero/Nornir/.venv/lib/python3.10/site-packages/nornir_jinja2/plugins/tasks/template_file.py", line 43, in template_file
    text = t.render(host=task.host, **kwargs)
  File "/home/ipvzero/Nornir/.venv/lib/python3.10/site-packages/jinja2/environment.py", line 1301, in render
    self.environment.handle_exception()
  File "/home/ipvzero/Nornir/.venv/lib/python3.10/site-packages/jinja2/environment.py", line 936, in handle_exception
    raise rewrite_traceback_stack(source=source)
  File "templates/dmvpn.j2", line 29, in top-level template code
    ip address {{ host.facts.dmvpn.tunnel_ip }}
jinja2.exceptions.UndefinedError: 'dict object' has no attribute 'tunnel_ip'

2023-03-15 04:27:20,426 - nornir.core.task -    ERROR -      start() - Host 'SPOKE2': task 'load_vars' failed with traceback:
Traceback (most recent call last):
  File "/home/ipvzero/Nornir/.venv/lib/python3.10/site-packages/nornir/core/task.py", line 99, in start
    r = self.task(self, **self.params)
  File "/home/ipvzero/Nornir/DMVPN/deploy_dmvpn.py", line 24, in load_vars
    config_vrf(task)
  File "/home/ipvzero/Nornir/DMVPN/deploy_dmvpn.py", line 43, in config_vrf
    config_dmvpn(task)
  File "/home/ipvzero/Nornir/DMVPN/deploy_dmvpn.py", line 51, in config_dmvpn
    dmvpn_template = task.run(
  File "/home/ipvzero/Nornir/.venv/lib/python3.10/site-packages/nornir/core/task.py", line 174, in run
    raise NornirSubTaskError(task=run_task, result=r)
nornir.core.exceptions.NornirSubTaskError: Subtask: Building DMVPN Configuration (failed)


2023-03-15 04:27:20,763 - nornir.core.task -    ERROR -      start() - Host 'SPOKE1': task 'Building DMVPN Configuration' failed with traceback:
Traceback (most recent call last):
  File "/home/ipvzero/Nornir/.venv/lib/python3.10/site-packages/nornir/core/task.py", line 99, in start
    r = self.task(self, **self.params)
  File "/home/ipvzero/Nornir/.venv/lib/python3.10/site-packages/nornir_jinja2/plugins/tasks/template_file.py", line 43, in template_file
    text = t.render(host=task.host, **kwargs)
  File "/home/ipvzero/Nornir/.venv/lib/python3.10/site-packages/jinja2/environment.py", line 1301, in render
    self.environment.handle_exception()
  File "/home/ipvzero/Nornir/.venv/lib/python3.10/site-packages/jinja2/environment.py", line 936, in handle_exception
    raise rewrite_traceback_stack(source=source)
  File "templates/dmvpn.j2", line 29, in top-level template code
    ip address {{ host.facts.dmvpn.tunnel_ip }}
jinja2.exceptions.UndefinedError: 'dict object' has no attribute 'tunnel_ip'

2023-03-15 04:27:20,763 - nornir.core.task -    ERROR -      start() - Host 'SPOKE1': task 'load_vars' failed with traceback:
Traceback (most recent call last):
  File "/home/ipvzero/Nornir/.venv/lib/python3.10/site-packages/nornir/core/task.py", line 99, in start
    r = self.task(self, **self.params)
  File "/home/ipvzero/Nornir/DMVPN/deploy_dmvpn.py", line 24, in load_vars
    config_vrf(task)
  File "/home/ipvzero/Nornir/DMVPN/deploy_dmvpn.py", line 43, in config_vrf
    config_dmvpn(task)
  File "/home/ipvzero/Nornir/DMVPN/deploy_dmvpn.py", line 51, in config_dmvpn
    dmvpn_template = task.run(
  File "/home/ipvzero/Nornir/.venv/lib/python3.10/site-packages/nornir/core/task.py", line 174, in run
    raise NornirSubTaskError(task=run_task, result=r)
nornir.core.exceptions.NornirSubTaskError: Subtask: Building DMVPN Configuration (failed)


2023-03-15 04:27:20,858 - nornir.core.task -    ERROR -      start() - Host 'SPOKE3': task 'Building DMVPN Configuration' failed with traceback:
Traceback (most recent call last):
  File "/home/ipvzero/Nornir/.venv/lib/python3.10/site-packages/nornir/core/task.py", line 99, in start
    r = self.task(self, **self.params)
  File "/home/ipvzero/Nornir/.venv/lib/python3.10/site-packages/nornir_jinja2/plugins/tasks/template_file.py", line 43, in template_file
    text = t.render(host=task.host, **kwargs)
  File "/home/ipvzero/Nornir/.venv/lib/python3.10/site-packages/jinja2/environment.py", line 1301, in render
    self.environment.handle_exception()
  File "/home/ipvzero/Nornir/.venv/lib/python3.10/site-packages/jinja2/environment.py", line 936, in handle_exception
    raise rewrite_traceback_stack(source=source)
  File "templates/dmvpn.j2", line 29, in top-level template code
    ip address {{ host.facts.dmvpn.tunnel_ip }}
jinja2.exceptions.UndefinedError: 'dict object' has no attribute 'tunnel_ip'

2023-03-15 04:27:20,859 - nornir.core.task -    ERROR -      start() - Host 'SPOKE3': task 'load_vars' failed with traceback:
Traceback (most recent call last):
  File "/home/ipvzero/Nornir/.venv/lib/python3.10/site-packages/nornir/core/task.py", line 99, in start
    r = self.task(self, **self.params)
  File "/home/ipvzero/Nornir/DMVPN/deploy_dmvpn.py", line 24, in load_vars
    config_vrf(task)
  File "/home/ipvzero/Nornir/DMVPN/deploy_dmvpn.py", line 43, in config_vrf
    config_dmvpn(task)
  File "/home/ipvzero/Nornir/DMVPN/deploy_dmvpn.py", line 51, in config_dmvpn
    dmvpn_template = task.run(
  File "/home/ipvzero/Nornir/.venv/lib/python3.10/site-packages/nornir/core/task.py", line 174, in run
    raise NornirSubTaskError(task=run_task, result=r)
nornir.core.exceptions.NornirSubTaskError: Subtask: Building DMVPN Configuration (failed)


2023-03-15 04:27:24,070 - nornir.core.task -    ERROR -      start() - Host 'HUB': task 'load_vars' failed with traceback:
Traceback (most recent call last):
  File "/home/ipvzero/Nornir/.venv/lib/python3.10/site-packages/nornir/core/task.py", line 99, in start
    r = self.task(self, **self.params)
  File "/home/ipvzero/Nornir/DMVPN/deploy_dmvpn.py", line 24, in load_vars
    config_vrf(task)
  File "/home/ipvzero/Nornir/DMVPN/deploy_dmvpn.py", line 43, in config_vrf
    config_dmvpn(task)
  File "/home/ipvzero/Nornir/DMVPN/deploy_dmvpn.py", line 60, in config_dmvpn
    task.run(
  File "/home/ipvzero/Nornir/.venv/lib/python3.10/site-packages/nornir/core/task.py", line 174, in run
    raise NornirSubTaskError(task=run_task, result=r)
nornir.core.exceptions.NornirSubTaskError: Subtask: Pushing DMVPN Commands (failed)


2023-03-15 04:49:56,705 -  nornir.core -     INFO -        run() - Running task 'load_vars' with args {} on 4 hosts
2023-03-15 04:49:58,377 - nornir.core.task -    ERROR -      start() - Host 'SPOKE1': task 'Building DMVPN Configuration' failed with traceback:
Traceback (most recent call last):
  File "/home/ipvzero/Nornir/.venv/lib/python3.10/site-packages/nornir/core/task.py", line 99, in start
    r = self.task(self, **self.params)
  File "/home/ipvzero/Nornir/.venv/lib/python3.10/site-packages/nornir_jinja2/plugins/tasks/template_file.py", line 43, in template_file
    text = t.render(host=task.host, **kwargs)
  File "/home/ipvzero/Nornir/.venv/lib/python3.10/site-packages/jinja2/environment.py", line 1301, in render
    self.environment.handle_exception()
  File "/home/ipvzero/Nornir/.venv/lib/python3.10/site-packages/jinja2/environment.py", line 936, in handle_exception
    raise rewrite_traceback_stack(source=source)
  File "templates/dmvpn.j2", line 29, in top-level template code
    ip address {{ host.facts.dmvpn.tunnel_ip }}
jinja2.exceptions.UndefinedError: 'dict object' has no attribute 'tunnel_ip'

2023-03-15 04:49:58,378 - nornir.core.task -    ERROR -      start() - Host 'SPOKE3': task 'Building DMVPN Configuration' failed with traceback:
Traceback (most recent call last):
  File "/home/ipvzero/Nornir/.venv/lib/python3.10/site-packages/nornir/core/task.py", line 99, in start
    r = self.task(self, **self.params)
  File "/home/ipvzero/Nornir/.venv/lib/python3.10/site-packages/nornir_jinja2/plugins/tasks/template_file.py", line 43, in template_file
    text = t.render(host=task.host, **kwargs)
  File "/home/ipvzero/Nornir/.venv/lib/python3.10/site-packages/jinja2/environment.py", line 1301, in render
    self.environment.handle_exception()
  File "/home/ipvzero/Nornir/.venv/lib/python3.10/site-packages/jinja2/environment.py", line 936, in handle_exception
    raise rewrite_traceback_stack(source=source)
  File "templates/dmvpn.j2", line 29, in top-level template code
    ip address {{ host.facts.dmvpn.tunnel_ip }}
jinja2.exceptions.UndefinedError: 'dict object' has no attribute 'tunnel_ip'

2023-03-15 04:49:58,380 - nornir.core.task -    ERROR -      start() - Host 'SPOKE1': task 'load_vars' failed with traceback:
Traceback (most recent call last):
  File "/home/ipvzero/Nornir/.venv/lib/python3.10/site-packages/nornir/core/task.py", line 99, in start
    r = self.task(self, **self.params)
  File "/home/ipvzero/Nornir/DMVPN/deploy_dmvpn.py", line 24, in load_vars
    config_vrf(task)
  File "/home/ipvzero/Nornir/DMVPN/deploy_dmvpn.py", line 43, in config_vrf
    config_dmvpn(task)
  File "/home/ipvzero/Nornir/DMVPN/deploy_dmvpn.py", line 51, in config_dmvpn
    dmvpn_template = task.run(
  File "/home/ipvzero/Nornir/.venv/lib/python3.10/site-packages/nornir/core/task.py", line 174, in run
    raise NornirSubTaskError(task=run_task, result=r)
nornir.core.exceptions.NornirSubTaskError: Subtask: Building DMVPN Configuration (failed)


2023-03-15 04:49:58,380 - nornir.core.task -    ERROR -      start() - Host 'SPOKE3': task 'load_vars' failed with traceback:
Traceback (most recent call last):
  File "/home/ipvzero/Nornir/.venv/lib/python3.10/site-packages/nornir/core/task.py", line 99, in start
    r = self.task(self, **self.params)
  File "/home/ipvzero/Nornir/DMVPN/deploy_dmvpn.py", line 24, in load_vars
    config_vrf(task)
  File "/home/ipvzero/Nornir/DMVPN/deploy_dmvpn.py", line 43, in config_vrf
    config_dmvpn(task)
  File "/home/ipvzero/Nornir/DMVPN/deploy_dmvpn.py", line 51, in config_dmvpn
    dmvpn_template = task.run(
  File "/home/ipvzero/Nornir/.venv/lib/python3.10/site-packages/nornir/core/task.py", line 174, in run
    raise NornirSubTaskError(task=run_task, result=r)
nornir.core.exceptions.NornirSubTaskError: Subtask: Building DMVPN Configuration (failed)


2023-03-15 04:49:58,570 - nornir.core.task -    ERROR -      start() - Host 'SPOKE2': task 'Building DMVPN Configuration' failed with traceback:
Traceback (most recent call last):
  File "/home/ipvzero/Nornir/.venv/lib/python3.10/site-packages/nornir/core/task.py", line 99, in start
    r = self.task(self, **self.params)
  File "/home/ipvzero/Nornir/.venv/lib/python3.10/site-packages/nornir_jinja2/plugins/tasks/template_file.py", line 43, in template_file
    text = t.render(host=task.host, **kwargs)
  File "/home/ipvzero/Nornir/.venv/lib/python3.10/site-packages/jinja2/environment.py", line 1301, in render
    self.environment.handle_exception()
  File "/home/ipvzero/Nornir/.venv/lib/python3.10/site-packages/jinja2/environment.py", line 936, in handle_exception
    raise rewrite_traceback_stack(source=source)
  File "templates/dmvpn.j2", line 29, in top-level template code
    ip address {{ host.facts.dmvpn.tunnel_ip }}
jinja2.exceptions.UndefinedError: 'dict object' has no attribute 'tunnel_ip'

2023-03-15 04:49:58,570 - nornir.core.task -    ERROR -      start() - Host 'SPOKE2': task 'load_vars' failed with traceback:
Traceback (most recent call last):
  File "/home/ipvzero/Nornir/.venv/lib/python3.10/site-packages/nornir/core/task.py", line 99, in start
    r = self.task(self, **self.params)
  File "/home/ipvzero/Nornir/DMVPN/deploy_dmvpn.py", line 24, in load_vars
    config_vrf(task)
  File "/home/ipvzero/Nornir/DMVPN/deploy_dmvpn.py", line 43, in config_vrf
    config_dmvpn(task)
  File "/home/ipvzero/Nornir/DMVPN/deploy_dmvpn.py", line 51, in config_dmvpn
    dmvpn_template = task.run(
  File "/home/ipvzero/Nornir/.venv/lib/python3.10/site-packages/nornir/core/task.py", line 174, in run
    raise NornirSubTaskError(task=run_task, result=r)
nornir.core.exceptions.NornirSubTaskError: Subtask: Building DMVPN Configuration (failed)


2023-03-15 04:50:01,630 - nornir.core.task -    ERROR -      start() - Host 'HUB': task 'load_vars' failed with traceback:
Traceback (most recent call last):
  File "/home/ipvzero/Nornir/.venv/lib/python3.10/site-packages/nornir/core/task.py", line 99, in start
    r = self.task(self, **self.params)
  File "/home/ipvzero/Nornir/DMVPN/deploy_dmvpn.py", line 24, in load_vars
    config_vrf(task)
  File "/home/ipvzero/Nornir/DMVPN/deploy_dmvpn.py", line 43, in config_vrf
    config_dmvpn(task)
  File "/home/ipvzero/Nornir/DMVPN/deploy_dmvpn.py", line 60, in config_dmvpn
    task.run(
  File "/home/ipvzero/Nornir/.venv/lib/python3.10/site-packages/nornir/core/task.py", line 174, in run
    raise NornirSubTaskError(task=run_task, result=r)
nornir.core.exceptions.NornirSubTaskError: Subtask: Pushing DMVPN Commands (failed)


2023-03-15 04:57:21,131 -  nornir.core -     INFO -        run() - Running task 'load_vars' with args {} on 4 hosts
2023-03-15 04:57:29,014 - nornir.core.task -    ERROR -      start() - Host 'HUB': task 'load_vars' failed with traceback:
Traceback (most recent call last):
  File "/home/ipvzero/Nornir/.venv/lib/python3.10/site-packages/nornir/core/task.py", line 99, in start
    r = self.task(self, **self.params)
  File "/home/ipvzero/Nornir/DMVPN/deploy_dmvpn.py", line 24, in load_vars
    config_vrf(task)
  File "/home/ipvzero/Nornir/DMVPN/deploy_dmvpn.py", line 43, in config_vrf
    config_dmvpn(task)
  File "/home/ipvzero/Nornir/DMVPN/deploy_dmvpn.py", line 60, in config_dmvpn
    task.run(
  File "/home/ipvzero/Nornir/.venv/lib/python3.10/site-packages/nornir/core/task.py", line 174, in run
    raise NornirSubTaskError(task=run_task, result=r)
nornir.core.exceptions.NornirSubTaskError: Subtask: Pushing DMVPN Commands (failed)


2023-03-15 05:07:38,920 -  nornir.core -     INFO -        run() - Running task 'load_vars' with args {} on 4 hosts
2023-03-15 05:07:46,442 - nornir.core.task -    ERROR -      start() - Host 'HUB': task 'load_vars' failed with traceback:
Traceback (most recent call last):
  File "/home/ipvzero/Nornir/.venv/lib/python3.10/site-packages/nornir/core/task.py", line 99, in start
    r = self.task(self, **self.params)
  File "/home/ipvzero/Nornir/DMVPN/deploy_dmvpn.py", line 24, in load_vars
    config_vrf(task)
  File "/home/ipvzero/Nornir/DMVPN/deploy_dmvpn.py", line 43, in config_vrf
    config_dmvpn(task)
  File "/home/ipvzero/Nornir/DMVPN/deploy_dmvpn.py", line 60, in config_dmvpn
    task.run(
  File "/home/ipvzero/Nornir/.venv/lib/python3.10/site-packages/nornir/core/task.py", line 174, in run
    raise NornirSubTaskError(task=run_task, result=r)
nornir.core.exceptions.NornirSubTaskError: Subtask: Pushing DMVPN Commands (failed)


2023-03-15 05:12:58,329 -  nornir.core -     INFO -        run() - Running task 'load_vars' with args {} on 4 hosts
2023-03-15 05:13:06,280 - nornir.core.task -    ERROR -      start() - Host 'HUB': task 'load_vars' failed with traceback:
Traceback (most recent call last):
  File "/home/ipvzero/Nornir/.venv/lib/python3.10/site-packages/nornir/core/task.py", line 99, in start
    r = self.task(self, **self.params)
  File "/home/ipvzero/Nornir/DMVPN/deploy_dmvpn.py", line 24, in load_vars
    config_vrf(task)
  File "/home/ipvzero/Nornir/DMVPN/deploy_dmvpn.py", line 43, in config_vrf
    config_dmvpn(task)
  File "/home/ipvzero/Nornir/DMVPN/deploy_dmvpn.py", line 60, in config_dmvpn
    task.run(
  File "/home/ipvzero/Nornir/.venv/lib/python3.10/site-packages/nornir/core/task.py", line 174, in run
    raise NornirSubTaskError(task=run_task, result=r)
nornir.core.exceptions.NornirSubTaskError: Subtask: Pushing DMVPN Commands (failed)


