2023-02-15 06:04:03,221 -  nornir.core -     INFO -        run() - Running task 'pull_info' with args {} on 7 hosts
2023-02-15 06:04:03,223 - nornir.core.task -    ERROR -      start() - Host 'R1(Tigerwoods)': task 'send_command' failed with traceback:
Traceback (most recent call last):
  File "/home/ipvzero/Nornir/.venv/lib/python3.10/site-packages/nornir/core/task.py", line 99, in start
    r = self.task(self, **self.params)
TypeError: send_command() got an unexpected keyword argument 'commands'

2023-02-15 06:04:03,224 - nornir.core.task -    ERROR -      start() - Host 'R1(Tigerwoods)': task 'pull_info' failed with traceback:
Traceback (most recent call last):
  File "/home/ipvzero/Nornir/.venv/lib/python3.10/site-packages/nornir/core/task.py", line 99, in start
    r = self.task(self, **self.params)
  File "/home/ipvzero/Nornir/Tools/mach-hunter.py", line 11, in pull_info
    interface_result = task.run(task=send_command, commands="show interfaces")
  File "/home/ipvzero/Nornir/.venv/lib/python3.10/site-packages/nornir/core/task.py", line 174, in run
    raise NornirSubTaskError(task=run_task, result=r)
nornir.core.exceptions.NornirSubTaskError: Subtask: send_command (failed)


2023-02-15 06:04:03,224 - nornir.core.task -    ERROR -      start() - Host 'R2(MerylStreep)': task 'send_command' failed with traceback:
Traceback (most recent call last):
  File "/home/ipvzero/Nornir/.venv/lib/python3.10/site-packages/nornir/core/task.py", line 99, in start
    r = self.task(self, **self.params)
TypeError: send_command() got an unexpected keyword argument 'commands'

2023-02-15 06:04:03,224 - nornir.core.task -    ERROR -      start() - Host 'R2(MerylStreep)': task 'pull_info' failed with traceback:
Traceback (most recent call last):
  File "/home/ipvzero/Nornir/.venv/lib/python3.10/site-packages/nornir/core/task.py", line 99, in start
    r = self.task(self, **self.params)
  File "/home/ipvzero/Nornir/Tools/mach-hunter.py", line 11, in pull_info
    interface_result = task.run(task=send_command, commands="show interfaces")
  File "/home/ipvzero/Nornir/.venv/lib/python3.10/site-packages/nornir/core/task.py", line 174, in run
    raise NornirSubTaskError(task=run_task, result=r)
nornir.core.exceptions.NornirSubTaskError: Subtask: send_command (failed)


2023-02-15 06:04:03,225 - nornir.core.task -    ERROR -      start() - Host 'R3(AndyMurray)': task 'send_command' failed with traceback:
Traceback (most recent call last):
  File "/home/ipvzero/Nornir/.venv/lib/python3.10/site-packages/nornir/core/task.py", line 99, in start
    r = self.task(self, **self.params)
TypeError: send_command() got an unexpected keyword argument 'commands'

2023-02-15 06:04:03,225 - nornir.core.task -    ERROR -      start() - Host 'R3(AndyMurray)': task 'pull_info' failed with traceback:
Traceback (most recent call last):
  File "/home/ipvzero/Nornir/.venv/lib/python3.10/site-packages/nornir/core/task.py", line 99, in start
    r = self.task(self, **self.params)
  File "/home/ipvzero/Nornir/Tools/mach-hunter.py", line 11, in pull_info
    interface_result = task.run(task=send_command, commands="show interfaces")
  File "/home/ipvzero/Nornir/.venv/lib/python3.10/site-packages/nornir/core/task.py", line 174, in run
    raise NornirSubTaskError(task=run_task, result=r)
nornir.core.exceptions.NornirSubTaskError: Subtask: send_command (failed)


2023-02-15 06:04:03,225 - nornir.core.task -    ERROR -      start() - Host 'R4(Harambe)': task 'send_command' failed with traceback:
Traceback (most recent call last):
  File "/home/ipvzero/Nornir/.venv/lib/python3.10/site-packages/nornir/core/task.py", line 99, in start
    r = self.task(self, **self.params)
TypeError: send_command() got an unexpected keyword argument 'commands'

2023-02-15 06:04:03,226 - nornir.core.task -    ERROR -      start() - Host 'R4(Harambe)': task 'pull_info' failed with traceback:
Traceback (most recent call last):
  File "/home/ipvzero/Nornir/.venv/lib/python3.10/site-packages/nornir/core/task.py", line 99, in start
    r = self.task(self, **self.params)
  File "/home/ipvzero/Nornir/Tools/mach-hunter.py", line 11, in pull_info
    interface_result = task.run(task=send_command, commands="show interfaces")
  File "/home/ipvzero/Nornir/.venv/lib/python3.10/site-packages/nornir/core/task.py", line 174, in run
    raise NornirSubTaskError(task=run_task, result=r)
nornir.core.exceptions.NornirSubTaskError: Subtask: send_command (failed)


2023-02-15 06:04:03,226 - nornir.core.task -    ERROR -      start() - Host 'R5(MarieCurie)': task 'send_command' failed with traceback:
Traceback (most recent call last):
  File "/home/ipvzero/Nornir/.venv/lib/python3.10/site-packages/nornir/core/task.py", line 99, in start
    r = self.task(self, **self.params)
TypeError: send_command() got an unexpected keyword argument 'commands'

2023-02-15 06:04:03,226 - nornir.core.task -    ERROR -      start() - Host 'R5(MarieCurie)': task 'pull_info' failed with traceback:
Traceback (most recent call last):
  File "/home/ipvzero/Nornir/.venv/lib/python3.10/site-packages/nornir/core/task.py", line 99, in start
    r = self.task(self, **self.params)
  File "/home/ipvzero/Nornir/Tools/mach-hunter.py", line 11, in pull_info
    interface_result = task.run(task=send_command, commands="show interfaces")
  File "/home/ipvzero/Nornir/.venv/lib/python3.10/site-packages/nornir/core/task.py", line 174, in run
    raise NornirSubTaskError(task=run_task, result=r)
nornir.core.exceptions.NornirSubTaskError: Subtask: send_command (failed)


2023-02-15 06:04:03,226 - nornir.core.task -    ERROR -      start() - Host 'R6(NalaCat)': task 'send_command' failed with traceback:
Traceback (most recent call last):
  File "/home/ipvzero/Nornir/.venv/lib/python3.10/site-packages/nornir/core/task.py", line 99, in start
    r = self.task(self, **self.params)
TypeError: send_command() got an unexpected keyword argument 'commands'

2023-02-15 06:04:03,226 - nornir.core.task -    ERROR -      start() - Host 'R6(NalaCat)': task 'pull_info' failed with traceback:
Traceback (most recent call last):
  File "/home/ipvzero/Nornir/.venv/lib/python3.10/site-packages/nornir/core/task.py", line 99, in start
    r = self.task(self, **self.params)
  File "/home/ipvzero/Nornir/Tools/mach-hunter.py", line 11, in pull_info
    interface_result = task.run(task=send_command, commands="show interfaces")
  File "/home/ipvzero/Nornir/.venv/lib/python3.10/site-packages/nornir/core/task.py", line 174, in run
    raise NornirSubTaskError(task=run_task, result=r)
nornir.core.exceptions.NornirSubTaskError: Subtask: send_command (failed)


2023-02-15 06:04:03,227 - nornir.core.task -    ERROR -      start() - Host 'R7(RogerFederer)': task 'send_command' failed with traceback:
Traceback (most recent call last):
  File "/home/ipvzero/Nornir/.venv/lib/python3.10/site-packages/nornir/core/task.py", line 99, in start
    r = self.task(self, **self.params)
TypeError: send_command() got an unexpected keyword argument 'commands'

2023-02-15 06:04:03,227 - nornir.core.task -    ERROR -      start() - Host 'R7(RogerFederer)': task 'pull_info' failed with traceback:
Traceback (most recent call last):
  File "/home/ipvzero/Nornir/.venv/lib/python3.10/site-packages/nornir/core/task.py", line 99, in start
    r = self.task(self, **self.params)
  File "/home/ipvzero/Nornir/Tools/mach-hunter.py", line 11, in pull_info
    interface_result = task.run(task=send_command, commands="show interfaces")
  File "/home/ipvzero/Nornir/.venv/lib/python3.10/site-packages/nornir/core/task.py", line 174, in run
    raise NornirSubTaskError(task=run_task, result=r)
nornir.core.exceptions.NornirSubTaskError: Subtask: send_command (failed)


2023-02-15 06:04:57,941 -  nornir.core -     INFO -        run() - Running task 'pull_info' with args {} on 7 hosts
2023-02-15 06:04:57,942 - nornir.core.task -    ERROR -      start() - Host 'R1(Tigerwoods)': task 'send_command' failed with traceback:
Traceback (most recent call last):
  File "/home/ipvzero/Nornir/.venv/lib/python3.10/site-packages/nornir/core/task.py", line 99, in start
    r = self.task(self, **self.params)
TypeError: send_command() got an unexpected keyword argument 'commands'

2023-02-15 06:04:57,942 - nornir.core.task -    ERROR -      start() - Host 'R1(Tigerwoods)': task 'pull_info' failed with traceback:
Traceback (most recent call last):
  File "/home/ipvzero/Nornir/.venv/lib/python3.10/site-packages/nornir/core/task.py", line 99, in start
    r = self.task(self, **self.params)
  File "/home/ipvzero/Nornir/Tools/mach-hunter.py", line 11, in pull_info
    interface_result = task.run(task=send_command, commands="show interfaces")
  File "/home/ipvzero/Nornir/.venv/lib/python3.10/site-packages/nornir/core/task.py", line 174, in run
    raise NornirSubTaskError(task=run_task, result=r)
nornir.core.exceptions.NornirSubTaskError: Subtask: send_command (failed)


2023-02-15 06:04:57,942 - nornir.core.task -    ERROR -      start() - Host 'R2(MerylStreep)': task 'send_command' failed with traceback:
Traceback (most recent call last):
  File "/home/ipvzero/Nornir/.venv/lib/python3.10/site-packages/nornir/core/task.py", line 99, in start
    r = self.task(self, **self.params)
TypeError: send_command() got an unexpected keyword argument 'commands'

2023-02-15 06:04:57,942 - nornir.core.task -    ERROR -      start() - Host 'R2(MerylStreep)': task 'pull_info' failed with traceback:
Traceback (most recent call last):
  File "/home/ipvzero/Nornir/.venv/lib/python3.10/site-packages/nornir/core/task.py", line 99, in start
    r = self.task(self, **self.params)
  File "/home/ipvzero/Nornir/Tools/mach-hunter.py", line 11, in pull_info
    interface_result = task.run(task=send_command, commands="show interfaces")
  File "/home/ipvzero/Nornir/.venv/lib/python3.10/site-packages/nornir/core/task.py", line 174, in run
    raise NornirSubTaskError(task=run_task, result=r)
nornir.core.exceptions.NornirSubTaskError: Subtask: send_command (failed)


2023-02-15 06:04:57,943 - nornir.core.task -    ERROR -      start() - Host 'R3(AndyMurray)': task 'send_command' failed with traceback:
Traceback (most recent call last):
  File "/home/ipvzero/Nornir/.venv/lib/python3.10/site-packages/nornir/core/task.py", line 99, in start
    r = self.task(self, **self.params)
TypeError: send_command() got an unexpected keyword argument 'commands'

2023-02-15 06:04:57,943 - nornir.core.task -    ERROR -      start() - Host 'R3(AndyMurray)': task 'pull_info' failed with traceback:
Traceback (most recent call last):
  File "/home/ipvzero/Nornir/.venv/lib/python3.10/site-packages/nornir/core/task.py", line 99, in start
    r = self.task(self, **self.params)
  File "/home/ipvzero/Nornir/Tools/mach-hunter.py", line 11, in pull_info
    interface_result = task.run(task=send_command, commands="show interfaces")
  File "/home/ipvzero/Nornir/.venv/lib/python3.10/site-packages/nornir/core/task.py", line 174, in run
    raise NornirSubTaskError(task=run_task, result=r)
nornir.core.exceptions.NornirSubTaskError: Subtask: send_command (failed)


2023-02-15 06:04:57,943 - nornir.core.task -    ERROR -      start() - Host 'R4(Harambe)': task 'send_command' failed with traceback:
Traceback (most recent call last):
  File "/home/ipvzero/Nornir/.venv/lib/python3.10/site-packages/nornir/core/task.py", line 99, in start
    r = self.task(self, **self.params)
TypeError: send_command() got an unexpected keyword argument 'commands'

2023-02-15 06:04:57,943 - nornir.core.task -    ERROR -      start() - Host 'R4(Harambe)': task 'pull_info' failed with traceback:
Traceback (most recent call last):
  File "/home/ipvzero/Nornir/.venv/lib/python3.10/site-packages/nornir/core/task.py", line 99, in start
    r = self.task(self, **self.params)
  File "/home/ipvzero/Nornir/Tools/mach-hunter.py", line 11, in pull_info
    interface_result = task.run(task=send_command, commands="show interfaces")
  File "/home/ipvzero/Nornir/.venv/lib/python3.10/site-packages/nornir/core/task.py", line 174, in run
    raise NornirSubTaskError(task=run_task, result=r)
nornir.core.exceptions.NornirSubTaskError: Subtask: send_command (failed)


2023-02-15 06:04:57,943 - nornir.core.task -    ERROR -      start() - Host 'R5(MarieCurie)': task 'send_command' failed with traceback:
Traceback (most recent call last):
  File "/home/ipvzero/Nornir/.venv/lib/python3.10/site-packages/nornir/core/task.py", line 99, in start
    r = self.task(self, **self.params)
TypeError: send_command() got an unexpected keyword argument 'commands'

2023-02-15 06:04:57,944 - nornir.core.task -    ERROR -      start() - Host 'R5(MarieCurie)': task 'pull_info' failed with traceback:
Traceback (most recent call last):
  File "/home/ipvzero/Nornir/.venv/lib/python3.10/site-packages/nornir/core/task.py", line 99, in start
    r = self.task(self, **self.params)
  File "/home/ipvzero/Nornir/Tools/mach-hunter.py", line 11, in pull_info
    interface_result = task.run(task=send_command, commands="show interfaces")
  File "/home/ipvzero/Nornir/.venv/lib/python3.10/site-packages/nornir/core/task.py", line 174, in run
    raise NornirSubTaskError(task=run_task, result=r)
nornir.core.exceptions.NornirSubTaskError: Subtask: send_command (failed)


2023-02-15 06:04:57,944 - nornir.core.task -    ERROR -      start() - Host 'R6(NalaCat)': task 'send_command' failed with traceback:
Traceback (most recent call last):
  File "/home/ipvzero/Nornir/.venv/lib/python3.10/site-packages/nornir/core/task.py", line 99, in start
    r = self.task(self, **self.params)
TypeError: send_command() got an unexpected keyword argument 'commands'

2023-02-15 06:04:57,944 - nornir.core.task -    ERROR -      start() - Host 'R6(NalaCat)': task 'pull_info' failed with traceback:
Traceback (most recent call last):
  File "/home/ipvzero/Nornir/.venv/lib/python3.10/site-packages/nornir/core/task.py", line 99, in start
    r = self.task(self, **self.params)
  File "/home/ipvzero/Nornir/Tools/mach-hunter.py", line 11, in pull_info
    interface_result = task.run(task=send_command, commands="show interfaces")
  File "/home/ipvzero/Nornir/.venv/lib/python3.10/site-packages/nornir/core/task.py", line 174, in run
    raise NornirSubTaskError(task=run_task, result=r)
nornir.core.exceptions.NornirSubTaskError: Subtask: send_command (failed)


2023-02-15 06:04:57,944 - nornir.core.task -    ERROR -      start() - Host 'R7(RogerFederer)': task 'send_command' failed with traceback:
Traceback (most recent call last):
  File "/home/ipvzero/Nornir/.venv/lib/python3.10/site-packages/nornir/core/task.py", line 99, in start
    r = self.task(self, **self.params)
TypeError: send_command() got an unexpected keyword argument 'commands'

2023-02-15 06:04:57,944 - nornir.core.task -    ERROR -      start() - Host 'R7(RogerFederer)': task 'pull_info' failed with traceback:
Traceback (most recent call last):
  File "/home/ipvzero/Nornir/.venv/lib/python3.10/site-packages/nornir/core/task.py", line 99, in start
    r = self.task(self, **self.params)
  File "/home/ipvzero/Nornir/Tools/mach-hunter.py", line 11, in pull_info
    interface_result = task.run(task=send_command, commands="show interfaces")
  File "/home/ipvzero/Nornir/.venv/lib/python3.10/site-packages/nornir/core/task.py", line 174, in run
    raise NornirSubTaskError(task=run_task, result=r)
nornir.core.exceptions.NornirSubTaskError: Subtask: send_command (failed)


2023-02-15 06:09:24,581 -  nornir.core -     INFO -        run() - Running task 'pull_info' with args {} on 7 hosts
2023-02-15 12:03:43,139 -  nornir.core -     INFO -        run() - Running task 'pull_info' with args {} on 7 hosts
2023-02-15 12:07:56,579 -  nornir.core -     INFO -        run() - Running task 'pull_info' with args {} on 7 hosts
2023-02-15 12:16:23,163 -  nornir.core -     INFO -        run() - Running task 'pull_info' with args {} on 7 hosts
2023-02-15 12:18:19,764 -  nornir.core -     INFO -        run() - Running task 'pull_info' with args {} on 7 hosts
2023-02-15 12:18:53,898 -  nornir.core -     INFO -        run() - Running task 'pull_info' with args {} on 7 hosts
2023-02-15 12:20:33,516 -  nornir.core -     INFO -        run() - Running task 'pull_info' with args {} on 7 hosts
2023-02-15 12:20:36,172 - nornir.core.task -    ERROR -      start() - Host 'R4': task 'pull_info' failed with traceback:
Traceback (most recent call last):
  File "/home/ipvzero/Nornir/.venv/lib/python3.10/site-packages/nornir/core/task.py", line 99, in start
    r = self.task(self, **self.params)
  File "/home/ipvzero/Nornir/Tools/mac-hunter.py", line 17, in pull_info
    mac_addr = interfaces[interface]["mac_address"]
KeyError: 'mac_address'

2023-02-15 12:25:10,779 -  nornir.core -     INFO -        run() - Running task 'pull_info' with args {} on 7 hosts
2023-02-15 12:25:13,661 - nornir.core.task -    ERROR -      start() - Host 'R4': task 'pull_info' failed with traceback:
Traceback (most recent call last):
  File "/home/ipvzero/Nornir/.venv/lib/python3.10/site-packages/nornir/core/task.py", line 99, in start
    r = self.task(self, **self.params)
  File "/home/ipvzero/Nornir/Tools/mac-hunter.py", line 17, in pull_info
    mac_addr = interfaces[interface]["mac_address"]
KeyError: 'mac_address'

2023-02-15 12:27:17,026 -  nornir.core -     INFO -        run() - Running task 'pull_info' with args {} on 7 hosts
2023-02-15 12:27:19,913 - nornir.core.task -    ERROR -      start() - Host 'R4': task 'pull_info' failed with traceback:
Traceback (most recent call last):
  File "/home/ipvzero/Nornir/.venv/lib/python3.10/site-packages/nornir/core/task.py", line 99, in start
    r = self.task(self, **self.params)
  File "/home/ipvzero/Nornir/Tools/mac-hunter.py", line 17, in pull_info
    mac_addr = interfaces[interface]["mac_address"]
KeyError: 'mac_address'

2023-02-16 04:46:03,713 -  nornir.core -     INFO -        run() - Running task 'pull_info' with args {} on 7 hosts
2023-02-16 04:46:06,974 - nornir.core.task -    ERROR -      start() - Host 'R4': task 'pull_info' failed with traceback:
Traceback (most recent call last):
  File "/home/ipvzero/Nornir/.venv/lib/python3.10/site-packages/nornir/core/task.py", line 99, in start
    r = self.task(self, **self.params)
  File "/home/ipvzero/Nornir/Tools/mac-hunter1.py", line 22, in pull_info
    print_info(task, intf)
  File "/home/ipvzero/Nornir/Tools/mac-hunter1.py", line 35, in print_info
    print(f"Connected to {device_id} on its interface {port_id}")
NameError: name 'device_id' is not defined

2023-02-16 04:46:30,199 -  nornir.core -     INFO -        run() - Running task 'pull_info' with args {} on 7 hosts
2023-02-16 04:46:33,057 - nornir.core.task -    ERROR -      start() - Host 'R4': task 'pull_info' failed with traceback:
Traceback (most recent call last):
  File "/home/ipvzero/Nornir/.venv/lib/python3.10/site-packages/nornir/core/task.py", line 99, in start
    r = self.task(self, **self.params)
  File "/home/ipvzero/Nornir/Tools/mac-hunter1.py", line 22, in pull_info
    print_info(task, intf)
  File "/home/ipvzero/Nornir/Tools/mac-hunter1.py", line 35, in print_info
    print(f"Connected to {device_id} on its interface {port_id}")
NameError: name 'device_id' is not defined

2023-02-16 04:49:25,998 -  nornir.core -     INFO -        run() - Running task 'pull_info' with args {} on 7 hosts
2023-02-16 04:49:28,761 - nornir.core.task -    ERROR -      start() - Host 'R4': task 'pull_info' failed with traceback:
Traceback (most recent call last):
  File "/home/ipvzero/Nornir/.venv/lib/python3.10/site-packages/nornir/core/task.py", line 99, in start
    r = self.task(self, **self.params)
  File "/home/ipvzero/Nornir/Tools/mac-hunter1.py", line 22, in pull_info
    print_info(task, intf)
  File "/home/ipvzero/Nornir/Tools/mac-hunter1.py", line 35, in print_info
    print(f"Connected to {device_id} on its interface {port_id}")
NameError: name 'device_id' is not defined

2023-02-16 04:51:28,478 -  nornir.core -     INFO -        run() - Running task 'pull_info' with args {} on 7 hosts
2023-02-16 04:51:31,069 - nornir.core.task -    ERROR -      start() - Host 'R4': task 'pull_info' failed with traceback:
Traceback (most recent call last):
  File "/home/ipvzero/Nornir/.venv/lib/python3.10/site-packages/nornir/core/task.py", line 99, in start
    r = self.task(self, **self.params)
  File "/home/ipvzero/Nornir/Tools/mac-hunter1.py", line 17, in pull_info
    mac_addr = interfaces[interface]["mac_address"]
KeyError: 'mac_address'

2023-02-16 05:03:53,869 -  nornir.core -     INFO -        run() - Running task 'pull_info' with args {} on 7 hosts
2023-02-16 05:03:56,608 - nornir.core.task -    ERROR -      start() - Host 'R4': task 'pull_info' failed with traceback:
Traceback (most recent call last):
  File "/home/ipvzero/Nornir/.venv/lib/python3.10/site-packages/nornir/core/task.py", line 99, in start
    r = self.task(self, **self.params)
  File "/home/ipvzero/Nornir/Tools/mac-hunter2.py", line 17, in pull_info
    mac_addr = interfaces[interface]["mac_address"]
KeyError: 'mac_address'

2023-02-16 05:05:43,438 -  nornir.core -     INFO -        run() - Running task 'pull_info' with args {} on 7 hosts
2023-02-16 05:05:46,698 - nornir.core.task -    ERROR -      start() - Host 'R4': task 'pull_info' failed with traceback:
Traceback (most recent call last):
  File "/home/ipvzero/Nornir/.venv/lib/python3.10/site-packages/nornir/core/task.py", line 99, in start
    r = self.task(self, **self.params)
  File "/home/ipvzero/Nornir/Tools/mac-hunter2.py", line 17, in pull_info
    mac_addr = interfaces[interface]["mac_address"]
KeyError: 'mac_address'

2023-02-16 05:10:55,893 -  nornir.core -     INFO -        run() - Running task 'pull_info' with args {} on 7 hosts
2023-02-16 05:10:59,047 - nornir.core.task -    ERROR -      start() - Host 'R4': task 'pull_info' failed with traceback:
Traceback (most recent call last):
  File "/home/ipvzero/Nornir/.venv/lib/python3.10/site-packages/nornir/core/task.py", line 99, in start
    r = self.task(self, **self.params)
  File "/home/ipvzero/Nornir/Tools/mac-hunter2.py", line 17, in pull_info
    mac_addr = interfaces[interface]["mac_address"]
KeyError: 'mac_address'

2023-02-16 05:12:34,293 -  nornir.core -     INFO -        run() - Running task 'pull_info' with args {} on 7 hosts
2023-02-16 05:12:38,193 - nornir.core.task -    ERROR -      start() - Host 'R4': task 'pull_info' failed with traceback:
Traceback (most recent call last):
  File "/home/ipvzero/Nornir/.venv/lib/python3.10/site-packages/nornir/core/task.py", line 99, in start
    r = self.task(self, **self.params)
  File "/home/ipvzero/Nornir/Tools/mac-hunter1.py", line 17, in pull_info
    mac_addr = interfaces[interface]["mac_address"]
KeyError: 'mac_address'

2023-02-16 05:18:16,524 -  nornir.core -     INFO -        run() - Running task 'pull_info' with args {} on 7 hosts
2023-02-16 05:18:19,357 - nornir.core.task -    ERROR -      start() - Host 'R4': task 'pull_info' failed with traceback:
Traceback (most recent call last):
  File "/home/ipvzero/Nornir/.venv/lib/python3.10/site-packages/nornir/core/task.py", line 99, in start
    r = self.task(self, **self.params)
  File "/home/ipvzero/Nornir/Tools/mac-hunter2.py", line 17, in pull_info
    mac_addr = interfaces[interface]["mac_address"]
KeyError: 'mac_address'

2023-02-16 05:27:53,092 -  nornir.core -     INFO -        run() - Running task 'pull_info' with args {} on 7 hosts
2023-02-16 05:27:56,150 - nornir.core.task -    ERROR -      start() - Host 'R4': task 'pull_info' failed with traceback:
Traceback (most recent call last):
  File "/home/ipvzero/Nornir/.venv/lib/python3.10/site-packages/nornir/core/task.py", line 99, in start
    r = self.task(self, **self.params)
  File "/home/ipvzero/Nornir/Tools/mac-hunter2.py", line 17, in pull_info
    mac_addr = interfaces[interface]["mac_address"]
KeyError: 'mac_address'

2023-02-16 05:28:56,988 -  nornir.core -     INFO -        run() - Running task 'pull_info' with args {} on 7 hosts
2023-02-16 05:29:00,194 - nornir.core.task -    ERROR -      start() - Host 'R4': task 'pull_info' failed with traceback:
Traceback (most recent call last):
  File "/home/ipvzero/Nornir/.venv/lib/python3.10/site-packages/nornir/core/task.py", line 99, in start
    r = self.task(self, **self.params)
  File "/home/ipvzero/Nornir/Tools/mac-hunter2.py", line 17, in pull_info
    mac_addr = interfaces[interface]["mac_address"]
KeyError: 'mac_address'

2023-02-16 05:31:33,579 -  nornir.core -     INFO -        run() - Running task 'pull_info' with args {} on 7 hosts
2023-02-16 05:31:36,528 - nornir.core.task -    ERROR -      start() - Host 'R4': task 'pull_info' failed with traceback:
Traceback (most recent call last):
  File "/home/ipvzero/Nornir/.venv/lib/python3.10/site-packages/nornir/core/task.py", line 99, in start
    r = self.task(self, **self.params)
  File "/home/ipvzero/Nornir/Tools/mac-hunter2.py", line 17, in pull_info
    mac_addr = interfaces[interface]["mac_address"]
KeyError: 'mac_address'

2023-02-16 05:42:11,042 -  nornir.core -     INFO -        run() - Running task 'pull_info' with args {} on 7 hosts
2023-02-16 05:42:14,208 - nornir.core.task -    ERROR -      start() - Host 'R4': task 'pull_info' failed with traceback:
Traceback (most recent call last):
  File "/home/ipvzero/Nornir/.venv/lib/python3.10/site-packages/nornir/core/task.py", line 99, in start
    r = self.task(self, **self.params)
  File "/home/ipvzero/Nornir/Tools/mac-hunter2.py", line 17, in pull_info
    mac_addr = interfaces[interface]["mac_address"]
KeyError: 'mac_address'

2023-02-16 05:50:30,171 -  nornir.core -     INFO -        run() - Running task 'pull_info' with args {} on 7 hosts
2023-02-16 05:50:33,091 - nornir.core.task -    ERROR -      start() - Host 'R4': task 'pull_info' failed with traceback:
Traceback (most recent call last):
  File "/home/ipvzero/Nornir/.venv/lib/python3.10/site-packages/nornir/core/task.py", line 99, in start
    r = self.task(self, **self.params)
  File "/home/ipvzero/Nornir/Tools/mac-hunter3.py", line 19, in pull_info
    mac_addr = interfaces[interface]["mac_address"]
KeyError: 'mac_address'

2023-02-16 05:50:46,851 -  nornir.core -     INFO -        run() - Running task 'pull_info' with args {} on 7 hosts
2023-02-16 05:50:49,838 - nornir.core.task -    ERROR -      start() - Host 'R4': task 'pull_info' failed with traceback:
Traceback (most recent call last):
  File "/home/ipvzero/Nornir/.venv/lib/python3.10/site-packages/nornir/core/task.py", line 99, in start
    r = self.task(self, **self.params)
  File "/home/ipvzero/Nornir/Tools/mac-hunter3.py", line 19, in pull_info
    mac_addr = interfaces[interface]["mac_address"]
KeyError: 'mac_address'

2023-02-16 05:52:37,797 -  nornir.core -     INFO -        run() - Running task 'pull_info' with args {} on 7 hosts
2023-02-16 05:52:40,988 - nornir.core.task -    ERROR -      start() - Host 'R4': task 'pull_info' failed with traceback:
Traceback (most recent call last):
  File "/home/ipvzero/Nornir/.venv/lib/python3.10/site-packages/nornir/core/task.py", line 99, in start
    r = self.task(self, **self.params)
  File "/home/ipvzero/Nornir/Tools/mac-hunter3.py", line 19, in pull_info
    mac_addr = interfaces[interface]["mac_address"]
KeyError: 'mac_address'

2023-02-16 05:52:52,203 -  nornir.core -     INFO -        run() - Running task 'pull_info' with args {} on 7 hosts
2023-02-16 05:52:54,945 - nornir.core.task -    ERROR -      start() - Host 'R4': task 'pull_info' failed with traceback:
Traceback (most recent call last):
  File "/home/ipvzero/Nornir/.venv/lib/python3.10/site-packages/nornir/core/task.py", line 99, in start
    r = self.task(self, **self.params)
  File "/home/ipvzero/Nornir/Tools/mac-hunter3.py", line 19, in pull_info
    mac_addr = interfaces[interface]["mac_address"]
KeyError: 'mac_address'

2023-02-16 15:38:10,320 -  nornir.core -     INFO -        run() - Running task 'pull_info' with args {} on 7 hosts
2023-02-16 15:38:13,751 - nornir.core.task -    ERROR -      start() - Host 'R4': task 'pull_info' failed with traceback:
Traceback (most recent call last):
  File "/home/ipvzero/Nornir/.venv/lib/python3.10/site-packages/nornir/core/task.py", line 99, in start
    r = self.task(self, **self.params)
  File "/home/ipvzero/Nornir/Tools/mac-hunter3.py", line 19, in pull_info
    mac_addr = interfaces[interface]["mac_address"]
KeyError: 'mac_address'

2023-02-16 15:38:14,022 - nornir.core.task -    ERROR -      start() - Host 'R2': task 'pull_info' failed with traceback:
Traceback (most recent call last):
  File "/home/ipvzero/Nornir/.venv/lib/python3.10/site-packages/nornir/core/task.py", line 99, in start
    r = self.task(self, **self.params)
  File "/home/ipvzero/Nornir/Tools/mac-hunter3.py", line 25, in pull_info
    print_info(task, intf)
  File "/home/ipvzero/Nornir/Tools/mac-hunter3.py", line 53, in print_info
    print(f"Connected to {port_id} on {dev_id}")
UnboundLocalError: local variable 'port_id' referenced before assignment

2023-02-16 15:38:45,792 -  nornir.core -     INFO -        run() - Running task 'pull_info' with args {} on 7 hosts
2023-02-16 15:38:48,476 - nornir.core.task -    ERROR -      start() - Host 'R4': task 'pull_info' failed with traceback:
Traceback (most recent call last):
  File "/home/ipvzero/Nornir/.venv/lib/python3.10/site-packages/nornir/core/task.py", line 99, in start
    r = self.task(self, **self.params)
  File "/home/ipvzero/Nornir/Tools/mac-hunter3.py", line 19, in pull_info
    mac_addr = interfaces[interface]["mac_address"]
KeyError: 'mac_address'

2023-02-16 15:38:48,823 - nornir.core.task -    ERROR -      start() - Host 'R2': task 'pull_info' failed with traceback:
Traceback (most recent call last):
  File "/home/ipvzero/Nornir/.venv/lib/python3.10/site-packages/nornir/core/task.py", line 99, in start
    r = self.task(self, **self.params)
  File "/home/ipvzero/Nornir/Tools/mac-hunter3.py", line 25, in pull_info
    print_info(task, intf)
  File "/home/ipvzero/Nornir/Tools/mac-hunter3.py", line 53, in print_info
    print(f"Connected to {port_id} on {dev_id}")
UnboundLocalError: local variable 'port_id' referenced before assignment

2023-02-16 15:39:20,166 -  nornir.core -     INFO -        run() - Running task 'pull_info' with args {} on 7 hosts
2023-02-16 15:39:23,358 - nornir.core.task -    ERROR -      start() - Host 'R4': task 'pull_info' failed with traceback:
Traceback (most recent call last):
  File "/home/ipvzero/Nornir/.venv/lib/python3.10/site-packages/nornir/core/task.py", line 99, in start
    r = self.task(self, **self.params)
  File "/home/ipvzero/Nornir/Tools/mac-hunter3.py", line 19, in pull_info
    mac_addr = interfaces[interface]["mac_address"]
KeyError: 'mac_address'

2023-02-16 15:39:23,579 - nornir.core.task -    ERROR -      start() - Host 'R2': task 'pull_info' failed with traceback:
Traceback (most recent call last):
  File "/home/ipvzero/Nornir/.venv/lib/python3.10/site-packages/nornir/core/task.py", line 99, in start
    r = self.task(self, **self.params)
  File "/home/ipvzero/Nornir/Tools/mac-hunter3.py", line 25, in pull_info
    print_info(task, intf)
  File "/home/ipvzero/Nornir/Tools/mac-hunter3.py", line 53, in print_info
    print(f"Connected to {port_id} on {dev_id}")
UnboundLocalError: local variable 'port_id' referenced before assignment

2023-02-16 15:41:18,880 -  nornir.core -     INFO -        run() - Running task 'pull_info' with args {} on 7 hosts
2023-02-16 15:41:21,593 - nornir.core.task -    ERROR -      start() - Host 'R4': task 'pull_info' failed with traceback:
Traceback (most recent call last):
  File "/home/ipvzero/Nornir/.venv/lib/python3.10/site-packages/nornir/core/task.py", line 99, in start
    r = self.task(self, **self.params)
  File "/home/ipvzero/Nornir/Tools/mac-hunter4.py", line 19, in pull_info
    mac_addr = interfaces[interface]["mac_address"]
KeyError: 'mac_address'

2023-02-16 15:41:21,862 - nornir.core.task -    ERROR -      start() - Host 'R2': task 'pull_info' failed with traceback:
Traceback (most recent call last):
  File "/home/ipvzero/Nornir/.venv/lib/python3.10/site-packages/nornir/core/task.py", line 99, in start
    r = self.task(self, **self.params)
  File "/home/ipvzero/Nornir/Tools/mac-hunter4.py", line 25, in pull_info
    print_info(task, intf)
  File "/home/ipvzero/Nornir/Tools/mac-hunter4.py", line 53, in print_info
    print(f"Connected to {port_id} on {dev_id}")
UnboundLocalError: local variable 'port_id' referenced before assignment

2023-02-16 15:51:04,272 -  nornir.core -     INFO -        run() - Running task 'pull_info' with args {} on 7 hosts
2023-02-16 15:51:07,356 - nornir.core.task -    ERROR -      start() - Host 'R2': task 'pull_info' failed with traceback:
Traceback (most recent call last):
  File "/home/ipvzero/Nornir/.venv/lib/python3.10/site-packages/nornir/core/task.py", line 99, in start
    r = self.task(self, **self.params)
  File "/home/ipvzero/Nornir/Tools/mac-hunter4.py", line 25, in pull_info
    print_info(task, intf)
  File "/home/ipvzero/Nornir/Tools/mac-hunter4.py", line 53, in print_info
    print(f"Connected to {port_id} on {dev_id}")
UnboundLocalError: local variable 'port_id' referenced before assignment

2023-02-16 15:54:56,360 -  nornir.core -     INFO -        run() - Running task 'pull_info' with args {} on 7 hosts
2023-02-16 15:56:24,753 -  nornir.core -     INFO -        run() - Running task 'pull_info' with args {} on 7 hosts
2023-02-16 15:56:27,628 - nornir.core.task -    ERROR -      start() - Host 'R2': task 'pull_info' failed with traceback:
Traceback (most recent call last):
  File "/home/ipvzero/Nornir/.venv/lib/python3.10/site-packages/nornir/core/task.py", line 99, in start
    r = self.task(self, **self.params)
  File "/home/ipvzero/Nornir/Tools/mac-hunter4.py", line 19, in pull_info
    mac_addr = interfaces[interface]["mac_address"]
KeyError: 'mac_address'

2023-02-16 15:58:20,011 -  nornir.core -     INFO -        run() - Running task 'pull_info' with args {} on 7 hosts
2023-02-16 15:58:22,919 - nornir.core.task -    ERROR -      start() - Host 'R2': task 'pull_info' failed with traceback:
Traceback (most recent call last):
  File "/home/ipvzero/Nornir/.venv/lib/python3.10/site-packages/nornir/core/task.py", line 99, in start
    r = self.task(self, **self.params)
  File "/home/ipvzero/Nornir/Tools/mac-hunter4.py", line 19, in pull_info
    mac_addr = interfaces[interface]["mac_address"]
KeyError: 'mac_address'

2023-02-16 16:05:18,705 -  nornir.core -     INFO -        run() - Running task 'pull_info' with args {} on 7 hosts
2023-02-16 21:25:32,570 -  nornir.core -     INFO -        run() - Running task 'pull_info' with args {} on 7 hosts
2023-02-16 21:26:33,977 -  nornir.core -     INFO -        run() - Running task 'pull_info' with args {} on 7 hosts
2023-02-16 21:28:00,913 -  nornir.core -     INFO -        run() - Running task 'pull_info' with args {} on 7 hosts
2023-02-16 21:28:49,113 -  nornir.core -     INFO -        run() - Running task 'pull_info' with args {} on 7 hosts
2023-02-16 21:29:20,915 -  nornir.core -     INFO -        run() - Running task 'pull_info' with args {} on 7 hosts
2023-02-16 21:46:22,091 -  nornir.core -     INFO -        run() - Running task 'get_ip' with args {} on 7 hosts
2023-02-16 21:47:30,767 -  nornir.core -     INFO -        run() - Running task 'get_ip' with args {} on 7 hosts
2023-02-17 04:34:13,979 -  nornir.core -     INFO -        run() - Running task 'get_ip' with args {} on 7 hosts
2023-02-17 04:37:09,373 -  nornir.core -     INFO -        run() - Running task 'get_ip' with args {} on 7 hosts
2023-02-17 04:42:08,950 -  nornir.core -     INFO -        run() - Running task 'get_ip' with args {} on 7 hosts
2023-02-17 04:42:11,523 - nornir.core.task -    ERROR -      start() - Host 'R7': task 'get_ip' failed with traceback:
Traceback (most recent call last):
  File "/home/ipvzero/Nornir/.venv/lib/python3.10/site-packages/nornir/core/task.py", line 99, in start
    r = self.task(self, **self.params)
  File "/home/ipvzero/Nornir/Tools/ip-hunter.py", line 14, in get_ip
    ip_key = interfaces[intf]["ipv4"]
KeyError: 'ipv4'

2023-02-17 04:42:11,638 - nornir.core.task -    ERROR -      start() - Host 'R6': task 'get_ip' failed with traceback:
Traceback (most recent call last):
  File "/home/ipvzero/Nornir/.venv/lib/python3.10/site-packages/nornir/core/task.py", line 99, in start
    r = self.task(self, **self.params)
  File "/home/ipvzero/Nornir/Tools/ip-hunter.py", line 14, in get_ip
    ip_key = interfaces[intf]["ipv4"]
KeyError: 'ipv4'

2023-02-17 04:42:11,640 - nornir.core.task -    ERROR -      start() - Host 'R1': task 'get_ip' failed with traceback:
Traceback (most recent call last):
  File "/home/ipvzero/Nornir/.venv/lib/python3.10/site-packages/nornir/core/task.py", line 99, in start
    r = self.task(self, **self.params)
  File "/home/ipvzero/Nornir/Tools/ip-hunter.py", line 14, in get_ip
    ip_key = interfaces[intf]["ipv4"]
KeyError: 'ipv4'

2023-02-17 04:42:11,641 - nornir.core.task -    ERROR -      start() - Host 'R4': task 'get_ip' failed with traceback:
Traceback (most recent call last):
  File "/home/ipvzero/Nornir/.venv/lib/python3.10/site-packages/nornir/core/task.py", line 99, in start
    r = self.task(self, **self.params)
  File "/home/ipvzero/Nornir/Tools/ip-hunter.py", line 14, in get_ip
    ip_key = interfaces[intf]["ipv4"]
KeyError: 'ipv4'

2023-02-17 04:42:11,641 - nornir.core.task -    ERROR -      start() - Host 'R3': task 'get_ip' failed with traceback:
Traceback (most recent call last):
  File "/home/ipvzero/Nornir/.venv/lib/python3.10/site-packages/nornir/core/task.py", line 99, in start
    r = self.task(self, **self.params)
  File "/home/ipvzero/Nornir/Tools/ip-hunter.py", line 14, in get_ip
    ip_key = interfaces[intf]["ipv4"]
KeyError: 'ipv4'

2023-02-17 04:42:11,645 - nornir.core.task -    ERROR -      start() - Host 'R5': task 'get_ip' failed with traceback:
Traceback (most recent call last):
  File "/home/ipvzero/Nornir/.venv/lib/python3.10/site-packages/nornir/core/task.py", line 99, in start
    r = self.task(self, **self.params)
  File "/home/ipvzero/Nornir/Tools/ip-hunter.py", line 14, in get_ip
    ip_key = interfaces[intf]["ipv4"]
KeyError: 'ipv4'

2023-02-17 04:42:11,645 - nornir.core.task -    ERROR -      start() - Host 'R2': task 'get_ip' failed with traceback:
Traceback (most recent call last):
  File "/home/ipvzero/Nornir/.venv/lib/python3.10/site-packages/nornir/core/task.py", line 99, in start
    r = self.task(self, **self.params)
  File "/home/ipvzero/Nornir/Tools/ip-hunter.py", line 14, in get_ip
    ip_key = interfaces[intf]["ipv4"]
KeyError: 'ipv4'

2023-02-17 04:44:45,764 -  nornir.core -     INFO -        run() - Running task 'get_ip' with args {} on 7 hosts
2023-02-17 04:44:48,614 - nornir.core.task -    ERROR -      start() - Host 'R6': task 'get_ip' failed with traceback:
Traceback (most recent call last):
  File "/home/ipvzero/Nornir/.venv/lib/python3.10/site-packages/nornir/core/task.py", line 99, in start
    r = self.task(self, **self.params)
  File "/home/ipvzero/Nornir/Tools/ip-hunter.py", line 14, in get_ip
    ip_key = interfaces[intf]["ipv4"]
KeyError: 'ipv4'

2023-02-17 04:44:48,614 - nornir.core.task -    ERROR -      start() - Host 'R2': task 'get_ip' failed with traceback:
Traceback (most recent call last):
  File "/home/ipvzero/Nornir/.venv/lib/python3.10/site-packages/nornir/core/task.py", line 99, in start
    r = self.task(self, **self.params)
  File "/home/ipvzero/Nornir/Tools/ip-hunter.py", line 14, in get_ip
    ip_key = interfaces[intf]["ipv4"]
KeyError: 'ipv4'

2023-02-17 04:44:48,616 - nornir.core.task -    ERROR -      start() - Host 'R1': task 'get_ip' failed with traceback:
Traceback (most recent call last):
  File "/home/ipvzero/Nornir/.venv/lib/python3.10/site-packages/nornir/core/task.py", line 99, in start
    r = self.task(self, **self.params)
  File "/home/ipvzero/Nornir/Tools/ip-hunter.py", line 14, in get_ip
    ip_key = interfaces[intf]["ipv4"]
KeyError: 'ipv4'

2023-02-17 04:44:48,617 - nornir.core.task -    ERROR -      start() - Host 'R7': task 'get_ip' failed with traceback:
Traceback (most recent call last):
  File "/home/ipvzero/Nornir/.venv/lib/python3.10/site-packages/nornir/core/task.py", line 99, in start
    r = self.task(self, **self.params)
  File "/home/ipvzero/Nornir/Tools/ip-hunter.py", line 14, in get_ip
    ip_key = interfaces[intf]["ipv4"]
KeyError: 'ipv4'

2023-02-17 04:44:48,617 - nornir.core.task -    ERROR -      start() - Host 'R5': task 'get_ip' failed with traceback:
Traceback (most recent call last):
  File "/home/ipvzero/Nornir/.venv/lib/python3.10/site-packages/nornir/core/task.py", line 99, in start
    r = self.task(self, **self.params)
  File "/home/ipvzero/Nornir/Tools/ip-hunter.py", line 14, in get_ip
    ip_key = interfaces[intf]["ipv4"]
KeyError: 'ipv4'

2023-02-17 04:44:48,618 - nornir.core.task -    ERROR -      start() - Host 'R4': task 'get_ip' failed with traceback:
Traceback (most recent call last):
  File "/home/ipvzero/Nornir/.venv/lib/python3.10/site-packages/nornir/core/task.py", line 99, in start
    r = self.task(self, **self.params)
  File "/home/ipvzero/Nornir/Tools/ip-hunter.py", line 14, in get_ip
    ip_key = interfaces[intf]["ipv4"]
KeyError: 'ipv4'

2023-02-17 04:44:48,620 - nornir.core.task -    ERROR -      start() - Host 'R3': task 'get_ip' failed with traceback:
Traceback (most recent call last):
  File "/home/ipvzero/Nornir/.venv/lib/python3.10/site-packages/nornir/core/task.py", line 99, in start
    r = self.task(self, **self.params)
  File "/home/ipvzero/Nornir/Tools/ip-hunter.py", line 14, in get_ip
    ip_key = interfaces[intf]["ipv4"]
KeyError: 'ipv4'

2023-02-17 04:49:52,337 -  nornir.core -     INFO -        run() - Running task 'get_ip' with args {} on 7 hosts
2023-02-17 04:49:55,312 - nornir.core.task -    ERROR -      start() - Host 'R6': task 'get_ip' failed with traceback:
Traceback (most recent call last):
  File "/home/ipvzero/Nornir/.venv/lib/python3.10/site-packages/nornir/core/task.py", line 99, in start
    r = self.task(self, **self.params)
  File "/home/ipvzero/Nornir/Tools/ip-hunter.py", line 14, in get_ip
    ip_key = interfaces[intf]["ipv4"]
KeyError: 'ipv4'

2023-02-17 04:49:55,312 - nornir.core.task -    ERROR -      start() - Host 'R1': task 'get_ip' failed with traceback:
Traceback (most recent call last):
  File "/home/ipvzero/Nornir/.venv/lib/python3.10/site-packages/nornir/core/task.py", line 99, in start
    r = self.task(self, **self.params)
  File "/home/ipvzero/Nornir/Tools/ip-hunter.py", line 14, in get_ip
    ip_key = interfaces[intf]["ipv4"]
KeyError: 'ipv4'

2023-02-17 04:49:55,313 - nornir.core.task -    ERROR -      start() - Host 'R7': task 'get_ip' failed with traceback:
Traceback (most recent call last):
  File "/home/ipvzero/Nornir/.venv/lib/python3.10/site-packages/nornir/core/task.py", line 99, in start
    r = self.task(self, **self.params)
  File "/home/ipvzero/Nornir/Tools/ip-hunter.py", line 14, in get_ip
    ip_key = interfaces[intf]["ipv4"]
KeyError: 'ipv4'

2023-02-17 04:49:55,313 - nornir.core.task -    ERROR -      start() - Host 'R4': task 'get_ip' failed with traceback:
Traceback (most recent call last):
  File "/home/ipvzero/Nornir/.venv/lib/python3.10/site-packages/nornir/core/task.py", line 99, in start
    r = self.task(self, **self.params)
  File "/home/ipvzero/Nornir/Tools/ip-hunter.py", line 14, in get_ip
    ip_key = interfaces[intf]["ipv4"]
KeyError: 'ipv4'

2023-02-17 04:49:55,314 - nornir.core.task -    ERROR -      start() - Host 'R2': task 'get_ip' failed with traceback:
Traceback (most recent call last):
  File "/home/ipvzero/Nornir/.venv/lib/python3.10/site-packages/nornir/core/task.py", line 99, in start
    r = self.task(self, **self.params)
  File "/home/ipvzero/Nornir/Tools/ip-hunter.py", line 14, in get_ip
    ip_key = interfaces[intf]["ipv4"]
KeyError: 'ipv4'

2023-02-17 04:49:55,314 - nornir.core.task -    ERROR -      start() - Host 'R5': task 'get_ip' failed with traceback:
Traceback (most recent call last):
  File "/home/ipvzero/Nornir/.venv/lib/python3.10/site-packages/nornir/core/task.py", line 99, in start
    r = self.task(self, **self.params)
  File "/home/ipvzero/Nornir/Tools/ip-hunter.py", line 14, in get_ip
    ip_key = interfaces[intf]["ipv4"]
KeyError: 'ipv4'

2023-02-17 04:49:55,315 - nornir.core.task -    ERROR -      start() - Host 'R3': task 'get_ip' failed with traceback:
Traceback (most recent call last):
  File "/home/ipvzero/Nornir/.venv/lib/python3.10/site-packages/nornir/core/task.py", line 99, in start
    r = self.task(self, **self.params)
  File "/home/ipvzero/Nornir/Tools/ip-hunter.py", line 14, in get_ip
    ip_key = interfaces[intf]["ipv4"]
KeyError: 'ipv4'

2023-02-17 04:53:51,811 -  nornir.core -     INFO -        run() - Running task 'get_ip' with args {} on 7 hosts
2023-02-17 04:53:54,811 - nornir.core.task -    ERROR -      start() - Host 'R6': task 'get_ip' failed with traceback:
Traceback (most recent call last):
  File "/home/ipvzero/Nornir/.venv/lib/python3.10/site-packages/nornir/core/task.py", line 99, in start
    r = self.task(self, **self.params)
  File "/home/ipvzero/Nornir/Tools/ip-hunter.py", line 14, in get_ip
    ip_key = interfaces[intf]["ipv4"]
KeyError: 'ipv4'

2023-02-17 04:53:54,812 - nornir.core.task -    ERROR -      start() - Host 'R1': task 'get_ip' failed with traceback:
Traceback (most recent call last):
  File "/home/ipvzero/Nornir/.venv/lib/python3.10/site-packages/nornir/core/task.py", line 99, in start
    r = self.task(self, **self.params)
  File "/home/ipvzero/Nornir/Tools/ip-hunter.py", line 14, in get_ip
    ip_key = interfaces[intf]["ipv4"]
KeyError: 'ipv4'

2023-02-17 04:53:54,812 - nornir.core.task -    ERROR -      start() - Host 'R2': task 'get_ip' failed with traceback:
Traceback (most recent call last):
  File "/home/ipvzero/Nornir/.venv/lib/python3.10/site-packages/nornir/core/task.py", line 99, in start
    r = self.task(self, **self.params)
  File "/home/ipvzero/Nornir/Tools/ip-hunter.py", line 14, in get_ip
    ip_key = interfaces[intf]["ipv4"]
KeyError: 'ipv4'

2023-02-17 04:53:54,813 - nornir.core.task -    ERROR -      start() - Host 'R5': task 'get_ip' failed with traceback:
Traceback (most recent call last):
  File "/home/ipvzero/Nornir/.venv/lib/python3.10/site-packages/nornir/core/task.py", line 99, in start
    r = self.task(self, **self.params)
  File "/home/ipvzero/Nornir/Tools/ip-hunter.py", line 14, in get_ip
    ip_key = interfaces[intf]["ipv4"]
KeyError: 'ipv4'

2023-02-17 04:53:54,815 - nornir.core.task -    ERROR -      start() - Host 'R3': task 'get_ip' failed with traceback:
Traceback (most recent call last):
  File "/home/ipvzero/Nornir/.venv/lib/python3.10/site-packages/nornir/core/task.py", line 99, in start
    r = self.task(self, **self.params)
  File "/home/ipvzero/Nornir/Tools/ip-hunter.py", line 14, in get_ip
    ip_key = interfaces[intf]["ipv4"]
KeyError: 'ipv4'

2023-02-17 04:53:54,815 - nornir.core.task -    ERROR -      start() - Host 'R7': task 'get_ip' failed with traceback:
Traceback (most recent call last):
  File "/home/ipvzero/Nornir/.venv/lib/python3.10/site-packages/nornir/core/task.py", line 99, in start
    r = self.task(self, **self.params)
  File "/home/ipvzero/Nornir/Tools/ip-hunter.py", line 14, in get_ip
    ip_key = interfaces[intf]["ipv4"]
KeyError: 'ipv4'

2023-02-17 04:53:54,816 - nornir.core.task -    ERROR -      start() - Host 'R4': task 'get_ip' failed with traceback:
Traceback (most recent call last):
  File "/home/ipvzero/Nornir/.venv/lib/python3.10/site-packages/nornir/core/task.py", line 99, in start
    r = self.task(self, **self.params)
  File "/home/ipvzero/Nornir/Tools/ip-hunter.py", line 14, in get_ip
    ip_key = interfaces[intf]["ipv4"]
KeyError: 'ipv4'

2023-02-17 05:07:13,159 -  nornir.core -     INFO -        run() - Running task 'get_ip' with args {} on 7 hosts
2023-02-17 05:10:25,927 -  nornir.core -     INFO -        run() - Running task 'get_ip' with args {} on 7 hosts
2023-02-17 05:16:15,860 -  nornir.core -     INFO -        run() - Running task 'get_ip' with args {} on 7 hosts
2023-02-17 05:38:14,608 -  nornir.core -     INFO -        run() - Running task 'get_ip' with args {} on 7 hosts
2023-02-17 05:38:51,961 -  nornir.core -     INFO -        run() - Running task 'get_ip' with args {} on 7 hosts
2023-02-17 05:41:25,519 -  nornir.core -     INFO -        run() - Running task 'get_ip' with args {} on 7 hosts
2023-02-17 20:51:54,116 -  nornir.core -     INFO -        run() - Running task 'get_ip' with args {} on 7 hosts
2023-02-17 20:51:58,464 -  nornir.core -     INFO -        run() - Running task 'locate_ip' with args {} on 7 hosts
2023-02-17 20:51:59,538 - nornir.core.task -    ERROR -      start() - Host 'R3': task 'locate_ip' failed with traceback:
Traceback (most recent call last):
  File "/home/ipvzero/Nornir/.venv/lib/python3.10/site-packages/nornir/core/task.py", line 99, in start
    r = self.task(self, **self.params)
  File "/home/ipvzero/Nornir/Tools/ip-hunter1.py", line 36, in locate_ip
    task.host["verfacts"] = version.result.scrapli_response.textfsm_parse_output()#binding to "verfacts" and running textfsm parser.
NameError: name 'version' is not defined

2023-02-17 20:51:59,559 - nornir.core.task -    ERROR -      start() - Host 'R4': task 'locate_ip' failed with traceback:
Traceback (most recent call last):
  File "/home/ipvzero/Nornir/.venv/lib/python3.10/site-packages/nornir/core/task.py", line 99, in start
    r = self.task(self, **self.params)
  File "/home/ipvzero/Nornir/Tools/ip-hunter1.py", line 36, in locate_ip
    task.host["verfacts"] = version.result.scrapli_response.textfsm_parse_output()#binding to "verfacts" and running textfsm parser.
NameError: name 'version' is not defined

2023-02-17 20:51:59,587 - nornir.core.task -    ERROR -      start() - Host 'R6': task 'locate_ip' failed with traceback:
Traceback (most recent call last):
  File "/home/ipvzero/Nornir/.venv/lib/python3.10/site-packages/nornir/core/task.py", line 99, in start
    r = self.task(self, **self.params)
  File "/home/ipvzero/Nornir/Tools/ip-hunter1.py", line 36, in locate_ip
    task.host["verfacts"] = version.result.scrapli_response.textfsm_parse_output()#binding to "verfacts" and running textfsm parser.
NameError: name 'version' is not defined

2023-02-17 20:51:59,651 - nornir.core.task -    ERROR -      start() - Host 'R5': task 'locate_ip' failed with traceback:
Traceback (most recent call last):
  File "/home/ipvzero/Nornir/.venv/lib/python3.10/site-packages/nornir/core/task.py", line 99, in start
    r = self.task(self, **self.params)
  File "/home/ipvzero/Nornir/Tools/ip-hunter1.py", line 36, in locate_ip
    task.host["verfacts"] = version.result.scrapli_response.textfsm_parse_output()#binding to "verfacts" and running textfsm parser.
NameError: name 'version' is not defined

2023-02-17 20:51:59,779 - nornir.core.task -    ERROR -      start() - Host 'R2': task 'locate_ip' failed with traceback:
Traceback (most recent call last):
  File "/home/ipvzero/Nornir/.venv/lib/python3.10/site-packages/nornir/core/task.py", line 99, in start
    r = self.task(self, **self.params)
  File "/home/ipvzero/Nornir/Tools/ip-hunter1.py", line 36, in locate_ip
    task.host["verfacts"] = version.result.scrapli_response.textfsm_parse_output()#binding to "verfacts" and running textfsm parser.
NameError: name 'version' is not defined

2023-02-17 20:51:59,789 - nornir.core.task -    ERROR -      start() - Host 'R1': task 'locate_ip' failed with traceback:
Traceback (most recent call last):
  File "/home/ipvzero/Nornir/.venv/lib/python3.10/site-packages/nornir/core/task.py", line 99, in start
    r = self.task(self, **self.params)
  File "/home/ipvzero/Nornir/Tools/ip-hunter1.py", line 36, in locate_ip
    task.host["verfacts"] = version.result.scrapli_response.textfsm_parse_output()#binding to "verfacts" and running textfsm parser.
NameError: name 'version' is not defined

2023-02-17 20:51:59,823 - nornir.core.task -    ERROR -      start() - Host 'R7': task 'locate_ip' failed with traceback:
Traceback (most recent call last):
  File "/home/ipvzero/Nornir/.venv/lib/python3.10/site-packages/nornir/core/task.py", line 99, in start
    r = self.task(self, **self.params)
  File "/home/ipvzero/Nornir/Tools/ip-hunter1.py", line 36, in locate_ip
    task.host["verfacts"] = version.result.scrapli_response.textfsm_parse_output()#binding to "verfacts" and running textfsm parser.
NameError: name 'version' is not defined

2023-02-17 21:15:54,637 -  nornir.core -     INFO -        run() - Running task 'get_ip' with args {} on 7 hosts
2023-02-17 21:15:57,516 -  nornir.core -     INFO -        run() - Running task 'locate_ip' with args {} on 7 hosts
2023-02-17 21:15:58,764 - nornir.core.task -    ERROR -      start() - Host 'R5': task 'locate_ip' failed with traceback:
Traceback (most recent call last):
  File "/home/ipvzero/Nornir/.venv/lib/python3.10/site-packages/nornir/core/task.py", line 99, in start
    r = self.task(self, **self.params)
  File "/home/ipvzero/Nornir/Tools/ip-hunter1.py", line 36, in locate_ip
    task.host["verfacts"] = version.result.scrapli_response.textfsm_parse_output()#binding to "verfacts" and running textfsm parser.
NameError: name 'version' is not defined

2023-02-17 21:15:58,779 - nornir.core.task -    ERROR -      start() - Host 'R6': task 'locate_ip' failed with traceback:
Traceback (most recent call last):
  File "/home/ipvzero/Nornir/.venv/lib/python3.10/site-packages/nornir/core/task.py", line 99, in start
    r = self.task(self, **self.params)
  File "/home/ipvzero/Nornir/Tools/ip-hunter1.py", line 36, in locate_ip
    task.host["verfacts"] = version.result.scrapli_response.textfsm_parse_output()#binding to "verfacts" and running textfsm parser.
NameError: name 'version' is not defined

2023-02-17 21:15:58,821 - nornir.core.task -    ERROR -      start() - Host 'R1': task 'locate_ip' failed with traceback:
Traceback (most recent call last):
  File "/home/ipvzero/Nornir/.venv/lib/python3.10/site-packages/nornir/core/task.py", line 99, in start
    r = self.task(self, **self.params)
  File "/home/ipvzero/Nornir/Tools/ip-hunter1.py", line 36, in locate_ip
    task.host["verfacts"] = version.result.scrapli_response.textfsm_parse_output()#binding to "verfacts" and running textfsm parser.
NameError: name 'version' is not defined

2023-02-17 21:15:58,853 - nornir.core.task -    ERROR -      start() - Host 'R3': task 'locate_ip' failed with traceback:
Traceback (most recent call last):
  File "/home/ipvzero/Nornir/.venv/lib/python3.10/site-packages/nornir/core/task.py", line 99, in start
    r = self.task(self, **self.params)
  File "/home/ipvzero/Nornir/Tools/ip-hunter1.py", line 36, in locate_ip
    task.host["verfacts"] = version.result.scrapli_response.textfsm_parse_output()#binding to "verfacts" and running textfsm parser.
NameError: name 'version' is not defined

2023-02-17 21:15:58,895 - nornir.core.task -    ERROR -      start() - Host 'R7': task 'locate_ip' failed with traceback:
Traceback (most recent call last):
  File "/home/ipvzero/Nornir/.venv/lib/python3.10/site-packages/nornir/core/task.py", line 99, in start
    r = self.task(self, **self.params)
  File "/home/ipvzero/Nornir/Tools/ip-hunter1.py", line 36, in locate_ip
    task.host["verfacts"] = version.result.scrapli_response.textfsm_parse_output()#binding to "verfacts" and running textfsm parser.
NameError: name 'version' is not defined

2023-02-17 21:15:58,901 - nornir.core.task -    ERROR -      start() - Host 'R4': task 'locate_ip' failed with traceback:
Traceback (most recent call last):
  File "/home/ipvzero/Nornir/.venv/lib/python3.10/site-packages/nornir/core/task.py", line 99, in start
    r = self.task(self, **self.params)
  File "/home/ipvzero/Nornir/Tools/ip-hunter1.py", line 36, in locate_ip
    task.host["verfacts"] = version.result.scrapli_response.textfsm_parse_output()#binding to "verfacts" and running textfsm parser.
NameError: name 'version' is not defined

2023-02-17 21:15:58,936 - nornir.core.task -    ERROR -      start() - Host 'R2': task 'locate_ip' failed with traceback:
Traceback (most recent call last):
  File "/home/ipvzero/Nornir/.venv/lib/python3.10/site-packages/nornir/core/task.py", line 99, in start
    r = self.task(self, **self.params)
  File "/home/ipvzero/Nornir/Tools/ip-hunter1.py", line 36, in locate_ip
    task.host["verfacts"] = version.result.scrapli_response.textfsm_parse_output()#binding to "verfacts" and running textfsm parser.
NameError: name 'version' is not defined

2023-02-17 21:31:18,086 -  nornir.core -     INFO -        run() - Running task 'get_ip' with args {} on 7 hosts
2023-02-17 21:31:21,493 -  nornir.core -     INFO -        run() - Running task 'locate_ip' with args {} on 7 hosts
2023-02-17 21:31:22,835 - nornir.core.task -    ERROR -      start() - Host 'R1': task 'locate_ip' failed with traceback:
Traceback (most recent call last):
  File "/home/ipvzero/Nornir/.venv/lib/python3.10/site-packages/nornir/core/task.py", line 99, in start
    r = self.task(self, **self.params)
  File "/home/ipvzero/Nornir/Tools/ip-hunter1.py", line 36, in locate_ip
    task.host["verfacts"] = version.result.scrapli_response.textfsm_parse_output()#binding to "verfacts" and running textfsm parser.
NameError: name 'version' is not defined

2023-02-17 21:31:22,878 - nornir.core.task -    ERROR -      start() - Host 'R4': task 'locate_ip' failed with traceback:
Traceback (most recent call last):
  File "/home/ipvzero/Nornir/.venv/lib/python3.10/site-packages/nornir/core/task.py", line 99, in start
    r = self.task(self, **self.params)
  File "/home/ipvzero/Nornir/Tools/ip-hunter1.py", line 36, in locate_ip
    task.host["verfacts"] = version.result.scrapli_response.textfsm_parse_output()#binding to "verfacts" and running textfsm parser.
NameError: name 'version' is not defined

2023-02-17 21:31:22,887 - nornir.core.task -    ERROR -      start() - Host 'R5': task 'locate_ip' failed with traceback:
Traceback (most recent call last):
  File "/home/ipvzero/Nornir/.venv/lib/python3.10/site-packages/nornir/core/task.py", line 99, in start
    r = self.task(self, **self.params)
  File "/home/ipvzero/Nornir/Tools/ip-hunter1.py", line 36, in locate_ip
    task.host["verfacts"] = version.result.scrapli_response.textfsm_parse_output()#binding to "verfacts" and running textfsm parser.
NameError: name 'version' is not defined

2023-02-17 21:31:22,903 - nornir.core.task -    ERROR -      start() - Host 'R6': task 'locate_ip' failed with traceback:
Traceback (most recent call last):
  File "/home/ipvzero/Nornir/.venv/lib/python3.10/site-packages/nornir/core/task.py", line 99, in start
    r = self.task(self, **self.params)
  File "/home/ipvzero/Nornir/Tools/ip-hunter1.py", line 36, in locate_ip
    task.host["verfacts"] = version.result.scrapli_response.textfsm_parse_output()#binding to "verfacts" and running textfsm parser.
NameError: name 'version' is not defined

2023-02-17 21:31:22,904 - nornir.core.task -    ERROR -      start() - Host 'R7': task 'locate_ip' failed with traceback:
Traceback (most recent call last):
  File "/home/ipvzero/Nornir/.venv/lib/python3.10/site-packages/nornir/core/task.py", line 99, in start
    r = self.task(self, **self.params)
  File "/home/ipvzero/Nornir/Tools/ip-hunter1.py", line 36, in locate_ip
    task.host["verfacts"] = version.result.scrapli_response.textfsm_parse_output()#binding to "verfacts" and running textfsm parser.
NameError: name 'version' is not defined

2023-02-17 21:31:22,906 - nornir.core.task -    ERROR -      start() - Host 'R2': task 'locate_ip' failed with traceback:
Traceback (most recent call last):
  File "/home/ipvzero/Nornir/.venv/lib/python3.10/site-packages/nornir/core/task.py", line 99, in start
    r = self.task(self, **self.params)
  File "/home/ipvzero/Nornir/Tools/ip-hunter1.py", line 36, in locate_ip
    task.host["verfacts"] = version.result.scrapli_response.textfsm_parse_output()#binding to "verfacts" and running textfsm parser.
NameError: name 'version' is not defined

2023-02-17 21:31:22,912 - nornir.core.task -    ERROR -      start() - Host 'R3': task 'locate_ip' failed with traceback:
Traceback (most recent call last):
  File "/home/ipvzero/Nornir/.venv/lib/python3.10/site-packages/nornir/core/task.py", line 99, in start
    r = self.task(self, **self.params)
  File "/home/ipvzero/Nornir/Tools/ip-hunter1.py", line 36, in locate_ip
    task.host["verfacts"] = version.result.scrapli_response.textfsm_parse_output()#binding to "verfacts" and running textfsm parser.
NameError: name 'version' is not defined

2023-02-17 21:33:04,388 -  nornir.core -     INFO -        run() - Running task 'get_ip' with args {} on 7 hosts
2023-02-17 21:33:06,662 - nornir.core.task -    ERROR -      start() - Host 'R7': task 'get_ip' failed with traceback:
Traceback (most recent call last):
  File "/home/ipvzero/Nornir/.venv/lib/python3.10/site-packages/nornir/core/task.py", line 99, in start
    r = self.task(self, **self.params)
  File "/home/ipvzero/Nornir/Tools/ip-hunter.py", line 14, in get_ip
    ip_key = interfaces[intf]["ipv4"]
KeyError: 'ipv4'

2023-02-17 21:33:06,692 - nornir.core.task -    ERROR -      start() - Host 'R2': task 'get_ip' failed with traceback:
Traceback (most recent call last):
  File "/home/ipvzero/Nornir/.venv/lib/python3.10/site-packages/nornir/core/task.py", line 99, in start
    r = self.task(self, **self.params)
  File "/home/ipvzero/Nornir/Tools/ip-hunter.py", line 14, in get_ip
    ip_key = interfaces[intf]["ipv4"]
KeyError: 'ipv4'

2023-02-17 21:33:06,740 - nornir.core.task -    ERROR -      start() - Host 'R5': task 'get_ip' failed with traceback:
Traceback (most recent call last):
  File "/home/ipvzero/Nornir/.venv/lib/python3.10/site-packages/nornir/core/task.py", line 99, in start
    r = self.task(self, **self.params)
  File "/home/ipvzero/Nornir/Tools/ip-hunter.py", line 14, in get_ip
    ip_key = interfaces[intf]["ipv4"]
KeyError: 'ipv4'

2023-02-17 21:33:06,740 - nornir.core.task -    ERROR -      start() - Host 'R1': task 'get_ip' failed with traceback:
Traceback (most recent call last):
  File "/home/ipvzero/Nornir/.venv/lib/python3.10/site-packages/nornir/core/task.py", line 99, in start
    r = self.task(self, **self.params)
  File "/home/ipvzero/Nornir/Tools/ip-hunter.py", line 14, in get_ip
    ip_key = interfaces[intf]["ipv4"]
KeyError: 'ipv4'

2023-02-17 21:33:06,741 - nornir.core.task -    ERROR -      start() - Host 'R3': task 'get_ip' failed with traceback:
Traceback (most recent call last):
  File "/home/ipvzero/Nornir/.venv/lib/python3.10/site-packages/nornir/core/task.py", line 99, in start
    r = self.task(self, **self.params)
  File "/home/ipvzero/Nornir/Tools/ip-hunter.py", line 14, in get_ip
    ip_key = interfaces[intf]["ipv4"]
KeyError: 'ipv4'

2023-02-17 21:33:06,741 - nornir.core.task -    ERROR -      start() - Host 'R6': task 'get_ip' failed with traceback:
Traceback (most recent call last):
  File "/home/ipvzero/Nornir/.venv/lib/python3.10/site-packages/nornir/core/task.py", line 99, in start
    r = self.task(self, **self.params)
  File "/home/ipvzero/Nornir/Tools/ip-hunter.py", line 14, in get_ip
    ip_key = interfaces[intf]["ipv4"]
KeyError: 'ipv4'

2023-02-17 21:43:05,383 -  nornir.core -     INFO -        run() - Running task 'get_ip' with args {} on 7 hosts
2023-02-17 21:47:16,316 -  nornir.core -     INFO -        run() - Running task 'get_ip' with args {} on 7 hosts
2023-02-17 21:47:19,212 - nornir.core.task -    ERROR -      start() - Host 'R7': task 'get_ip' failed with traceback:
Traceback (most recent call last):
  File "/home/ipvzero/Nornir/.venv/lib/python3.10/site-packages/nornir/core/task.py", line 99, in start
    r = self.task(self, **self.params)
  File "/home/ipvzero/Nornir/Tools/ip-hunter.py", line 14, in get_ip
    ip_key = interfaces[intf]["ipv4"]
KeyError: 'ipv4'

2023-02-17 21:47:19,214 - nornir.core.task -    ERROR -      start() - Host 'R5': task 'get_ip' failed with traceback:
Traceback (most recent call last):
  File "/home/ipvzero/Nornir/.venv/lib/python3.10/site-packages/nornir/core/task.py", line 99, in start
    r = self.task(self, **self.params)
  File "/home/ipvzero/Nornir/Tools/ip-hunter.py", line 14, in get_ip
    ip_key = interfaces[intf]["ipv4"]
KeyError: 'ipv4'

2023-02-17 21:47:19,214 - nornir.core.task -    ERROR -      start() - Host 'R1': task 'get_ip' failed with traceback:
Traceback (most recent call last):
  File "/home/ipvzero/Nornir/.venv/lib/python3.10/site-packages/nornir/core/task.py", line 99, in start
    r = self.task(self, **self.params)
  File "/home/ipvzero/Nornir/Tools/ip-hunter.py", line 14, in get_ip
    ip_key = interfaces[intf]["ipv4"]
KeyError: 'ipv4'

2023-02-17 21:47:19,215 - nornir.core.task -    ERROR -      start() - Host 'R3': task 'get_ip' failed with traceback:
Traceback (most recent call last):
  File "/home/ipvzero/Nornir/.venv/lib/python3.10/site-packages/nornir/core/task.py", line 99, in start
    r = self.task(self, **self.params)
  File "/home/ipvzero/Nornir/Tools/ip-hunter.py", line 14, in get_ip
    ip_key = interfaces[intf]["ipv4"]
KeyError: 'ipv4'

2023-02-17 21:47:19,216 - nornir.core.task -    ERROR -      start() - Host 'R6': task 'get_ip' failed with traceback:
Traceback (most recent call last):
  File "/home/ipvzero/Nornir/.venv/lib/python3.10/site-packages/nornir/core/task.py", line 99, in start
    r = self.task(self, **self.params)
  File "/home/ipvzero/Nornir/Tools/ip-hunter.py", line 14, in get_ip
    ip_key = interfaces[intf]["ipv4"]
KeyError: 'ipv4'

2023-02-17 21:47:19,219 - nornir.core.task -    ERROR -      start() - Host 'R2': task 'get_ip' failed with traceback:
Traceback (most recent call last):
  File "/home/ipvzero/Nornir/.venv/lib/python3.10/site-packages/nornir/core/task.py", line 99, in start
    r = self.task(self, **self.params)
  File "/home/ipvzero/Nornir/Tools/ip-hunter.py", line 14, in get_ip
    ip_key = interfaces[intf]["ipv4"]
KeyError: 'ipv4'

2023-02-17 21:50:08,615 -  nornir.core -     INFO -        run() - Running task 'get_ip' with args {} on 7 hosts
2023-02-17 21:50:11,402 - nornir.core.task -    ERROR -      start() - Host 'R6': task 'get_ip' failed with traceback:
Traceback (most recent call last):
  File "/home/ipvzero/Nornir/.venv/lib/python3.10/site-packages/nornir/core/task.py", line 99, in start
    r = self.task(self, **self.params)
  File "/home/ipvzero/Nornir/Tools/ip-hunter.py", line 14, in get_ip
    ip_key = interfaces[intf]["ipv4"]
KeyError: 'ipv4'

2023-02-17 21:50:11,403 - nornir.core.task -    ERROR -      start() - Host 'R2': task 'get_ip' failed with traceback:
Traceback (most recent call last):
  File "/home/ipvzero/Nornir/.venv/lib/python3.10/site-packages/nornir/core/task.py", line 99, in start
    r = self.task(self, **self.params)
  File "/home/ipvzero/Nornir/Tools/ip-hunter.py", line 14, in get_ip
    ip_key = interfaces[intf]["ipv4"]
KeyError: 'ipv4'

2023-02-17 21:50:11,404 - nornir.core.task -    ERROR -      start() - Host 'R1': task 'get_ip' failed with traceback:
Traceback (most recent call last):
  File "/home/ipvzero/Nornir/.venv/lib/python3.10/site-packages/nornir/core/task.py", line 99, in start
    r = self.task(self, **self.params)
  File "/home/ipvzero/Nornir/Tools/ip-hunter.py", line 14, in get_ip
    ip_key = interfaces[intf]["ipv4"]
KeyError: 'ipv4'

2023-02-17 21:50:11,407 - nornir.core.task -    ERROR -      start() - Host 'R3': task 'get_ip' failed with traceback:
Traceback (most recent call last):
  File "/home/ipvzero/Nornir/.venv/lib/python3.10/site-packages/nornir/core/task.py", line 99, in start
    r = self.task(self, **self.params)
  File "/home/ipvzero/Nornir/Tools/ip-hunter.py", line 14, in get_ip
    ip_key = interfaces[intf]["ipv4"]
KeyError: 'ipv4'

2023-02-17 21:50:11,410 - nornir.core.task -    ERROR -      start() - Host 'R7': task 'get_ip' failed with traceback:
Traceback (most recent call last):
  File "/home/ipvzero/Nornir/.venv/lib/python3.10/site-packages/nornir/core/task.py", line 99, in start
    r = self.task(self, **self.params)
  File "/home/ipvzero/Nornir/Tools/ip-hunter.py", line 14, in get_ip
    ip_key = interfaces[intf]["ipv4"]
KeyError: 'ipv4'

2023-02-17 21:50:11,411 - nornir.core.task -    ERROR -      start() - Host 'R5': task 'get_ip' failed with traceback:
Traceback (most recent call last):
  File "/home/ipvzero/Nornir/.venv/lib/python3.10/site-packages/nornir/core/task.py", line 99, in start
    r = self.task(self, **self.params)
  File "/home/ipvzero/Nornir/Tools/ip-hunter.py", line 14, in get_ip
    ip_key = interfaces[intf]["ipv4"]
KeyError: 'ipv4'

2023-02-17 21:52:41,751 -  nornir.core -     INFO -        run() - Running task 'get_ip' with args {} on 7 hosts
2023-02-17 21:52:44,749 - nornir.core.task -    ERROR -      start() - Host 'R6': task 'get_ip' failed with traceback:
Traceback (most recent call last):
  File "/home/ipvzero/Nornir/.venv/lib/python3.10/site-packages/nornir/core/task.py", line 99, in start
    r = self.task(self, **self.params)
  File "/home/ipvzero/Nornir/Tools/ip-hunter.py", line 14, in get_ip
    ip_key = interfaces[intf]["ipv4"]
KeyError: 'ipv4'

2023-02-17 21:52:44,751 - nornir.core.task -    ERROR -      start() - Host 'R1': task 'get_ip' failed with traceback:
Traceback (most recent call last):
  File "/home/ipvzero/Nornir/.venv/lib/python3.10/site-packages/nornir/core/task.py", line 99, in start
    r = self.task(self, **self.params)
  File "/home/ipvzero/Nornir/Tools/ip-hunter.py", line 14, in get_ip
    ip_key = interfaces[intf]["ipv4"]
KeyError: 'ipv4'

2023-02-17 21:52:44,751 - nornir.core.task -    ERROR -      start() - Host 'R3': task 'get_ip' failed with traceback:
Traceback (most recent call last):
  File "/home/ipvzero/Nornir/.venv/lib/python3.10/site-packages/nornir/core/task.py", line 99, in start
    r = self.task(self, **self.params)
  File "/home/ipvzero/Nornir/Tools/ip-hunter.py", line 14, in get_ip
    ip_key = interfaces[intf]["ipv4"]
KeyError: 'ipv4'

2023-02-17 21:52:44,752 - nornir.core.task -    ERROR -      start() - Host 'R7': task 'get_ip' failed with traceback:
Traceback (most recent call last):
  File "/home/ipvzero/Nornir/.venv/lib/python3.10/site-packages/nornir/core/task.py", line 99, in start
    r = self.task(self, **self.params)
  File "/home/ipvzero/Nornir/Tools/ip-hunter.py", line 14, in get_ip
    ip_key = interfaces[intf]["ipv4"]
KeyError: 'ipv4'

2023-02-17 21:52:44,753 - nornir.core.task -    ERROR -      start() - Host 'R2': task 'get_ip' failed with traceback:
Traceback (most recent call last):
  File "/home/ipvzero/Nornir/.venv/lib/python3.10/site-packages/nornir/core/task.py", line 99, in start
    r = self.task(self, **self.params)
  File "/home/ipvzero/Nornir/Tools/ip-hunter.py", line 14, in get_ip
    ip_key = interfaces[intf]["ipv4"]
KeyError: 'ipv4'

2023-02-17 21:52:44,753 - nornir.core.task -    ERROR -      start() - Host 'R5': task 'get_ip' failed with traceback:
Traceback (most recent call last):
  File "/home/ipvzero/Nornir/.venv/lib/python3.10/site-packages/nornir/core/task.py", line 99, in start
    r = self.task(self, **self.params)
  File "/home/ipvzero/Nornir/Tools/ip-hunter.py", line 14, in get_ip
    ip_key = interfaces[intf]["ipv4"]
KeyError: 'ipv4'

2023-02-17 21:55:23,760 -  nornir.core -     INFO -        run() - Running task 'get_ip' with args {} on 7 hosts
2023-02-17 21:55:26,679 -  nornir.core -     INFO -        run() - Running task 'locate_ip' with args {} on 7 hosts
2023-02-17 21:55:27,627 - nornir.core.task -    ERROR -      start() - Host 'R5': task 'locate_ip' failed with traceback:
Traceback (most recent call last):
  File "/home/ipvzero/Nornir/.venv/lib/python3.10/site-packages/nornir/core/task.py", line 99, in start
    r = self.task(self, **self.params)
  File "/home/ipvzero/Nornir/Tools/ip-hunter1.py", line 36, in locate_ip
    task.host["verfacts"] = version.result.scrapli_response.textfsm_parse_output()#binding to "verfacts" and running textfsm parser.
NameError: name 'version' is not defined

2023-02-17 21:55:27,721 - nornir.core.task -    ERROR -      start() - Host 'R4': task 'locate_ip' failed with traceback:
Traceback (most recent call last):
  File "/home/ipvzero/Nornir/.venv/lib/python3.10/site-packages/nornir/core/task.py", line 99, in start
    r = self.task(self, **self.params)
  File "/home/ipvzero/Nornir/Tools/ip-hunter1.py", line 36, in locate_ip
    task.host["verfacts"] = version.result.scrapli_response.textfsm_parse_output()#binding to "verfacts" and running textfsm parser.
NameError: name 'version' is not defined

2023-02-17 21:55:27,852 - nornir.core.task -    ERROR -      start() - Host 'R7': task 'locate_ip' failed with traceback:
Traceback (most recent call last):
  File "/home/ipvzero/Nornir/.venv/lib/python3.10/site-packages/nornir/core/task.py", line 99, in start
    r = self.task(self, **self.params)
  File "/home/ipvzero/Nornir/Tools/ip-hunter1.py", line 36, in locate_ip
    task.host["verfacts"] = version.result.scrapli_response.textfsm_parse_output()#binding to "verfacts" and running textfsm parser.
NameError: name 'version' is not defined

2023-02-17 21:55:27,953 - nornir.core.task -    ERROR -      start() - Host 'R6': task 'locate_ip' failed with traceback:
Traceback (most recent call last):
  File "/home/ipvzero/Nornir/.venv/lib/python3.10/site-packages/nornir/core/task.py", line 99, in start
    r = self.task(self, **self.params)
  File "/home/ipvzero/Nornir/Tools/ip-hunter1.py", line 36, in locate_ip
    task.host["verfacts"] = version.result.scrapli_response.textfsm_parse_output()#binding to "verfacts" and running textfsm parser.
NameError: name 'version' is not defined

2023-02-17 21:55:28,010 - nornir.core.task -    ERROR -      start() - Host 'R1': task 'locate_ip' failed with traceback:
Traceback (most recent call last):
  File "/home/ipvzero/Nornir/.venv/lib/python3.10/site-packages/nornir/core/task.py", line 99, in start
    r = self.task(self, **self.params)
  File "/home/ipvzero/Nornir/Tools/ip-hunter1.py", line 36, in locate_ip
    task.host["verfacts"] = version.result.scrapli_response.textfsm_parse_output()#binding to "verfacts" and running textfsm parser.
NameError: name 'version' is not defined

2023-02-17 21:55:28,023 - nornir.core.task -    ERROR -      start() - Host 'R3': task 'locate_ip' failed with traceback:
Traceback (most recent call last):
  File "/home/ipvzero/Nornir/.venv/lib/python3.10/site-packages/nornir/core/task.py", line 99, in start
    r = self.task(self, **self.params)
  File "/home/ipvzero/Nornir/Tools/ip-hunter1.py", line 36, in locate_ip
    task.host["verfacts"] = version.result.scrapli_response.textfsm_parse_output()#binding to "verfacts" and running textfsm parser.
NameError: name 'version' is not defined

2023-02-17 21:55:28,027 - nornir.core.task -    ERROR -      start() - Host 'R2': task 'locate_ip' failed with traceback:
Traceback (most recent call last):
  File "/home/ipvzero/Nornir/.venv/lib/python3.10/site-packages/nornir/core/task.py", line 99, in start
    r = self.task(self, **self.params)
  File "/home/ipvzero/Nornir/Tools/ip-hunter1.py", line 36, in locate_ip
    task.host["verfacts"] = version.result.scrapli_response.textfsm_parse_output()#binding to "verfacts" and running textfsm parser.
NameError: name 'version' is not defined

2023-02-17 21:57:47,490 -  nornir.core -     INFO -        run() - Running task 'get_ip' with args {} on 7 hosts
2023-02-17 21:57:49,985 -  nornir.core -     INFO -        run() - Running task 'locate_ip' with args {} on 7 hosts
2023-02-17 21:57:51,143 - nornir.core.task -    ERROR -      start() - Host 'R2': task 'locate_ip' failed with traceback:
Traceback (most recent call last):
  File "/home/ipvzero/Nornir/.venv/lib/python3.10/site-packages/nornir/core/task.py", line 99, in start
    r = self.task(self, **self.params)
  File "/home/ipvzero/Nornir/Tools/ip-hunter1.py", line 36, in locate_ip
    task.host["verfacts"] = version.result.scrapli_response.textfsm_parse_output()#binding to "verfacts" and running textfsm parser.
NameError: name 'version' is not defined

2023-02-17 21:57:51,270 - nornir.core.task -    ERROR -      start() - Host 'R4': task 'locate_ip' failed with traceback:
Traceback (most recent call last):
  File "/home/ipvzero/Nornir/.venv/lib/python3.10/site-packages/nornir/core/task.py", line 99, in start
    r = self.task(self, **self.params)
  File "/home/ipvzero/Nornir/Tools/ip-hunter1.py", line 36, in locate_ip
    task.host["verfacts"] = version.result.scrapli_response.textfsm_parse_output()#binding to "verfacts" and running textfsm parser.
NameError: name 'version' is not defined

2023-02-17 21:57:51,299 - nornir.core.task -    ERROR -      start() - Host 'R6': task 'locate_ip' failed with traceback:
Traceback (most recent call last):
  File "/home/ipvzero/Nornir/.venv/lib/python3.10/site-packages/nornir/core/task.py", line 99, in start
    r = self.task(self, **self.params)
  File "/home/ipvzero/Nornir/Tools/ip-hunter1.py", line 36, in locate_ip
    task.host["verfacts"] = version.result.scrapli_response.textfsm_parse_output()#binding to "verfacts" and running textfsm parser.
NameError: name 'version' is not defined

2023-02-17 21:57:51,304 - nornir.core.task -    ERROR -      start() - Host 'R1': task 'locate_ip' failed with traceback:
Traceback (most recent call last):
  File "/home/ipvzero/Nornir/.venv/lib/python3.10/site-packages/nornir/core/task.py", line 99, in start
    r = self.task(self, **self.params)
  File "/home/ipvzero/Nornir/Tools/ip-hunter1.py", line 36, in locate_ip
    task.host["verfacts"] = version.result.scrapli_response.textfsm_parse_output()#binding to "verfacts" and running textfsm parser.
NameError: name 'version' is not defined

2023-02-17 22:02:04,347 -  nornir.core -     INFO -        run() - Running task 'get_ip' with args {} on 7 hosts
2023-02-17 22:02:07,139 -  nornir.core -     INFO -        run() - Running task 'locate_ip' with args {} on 7 hosts
2023-02-17 22:02:08,624 - nornir.core.task -    ERROR -      start() - Host 'R6': task 'locate_ip' failed with traceback:
Traceback (most recent call last):
  File "/home/ipvzero/Nornir/.venv/lib/python3.10/site-packages/nornir/core/task.py", line 99, in start
    r = self.task(self, **self.params)
  File "/home/ipvzero/Nornir/Tools/ip-hunter1.py", line 37, in locate_ip
    task.host["verfacts"] = version.result.scrapli_response.textfsm_parse_output()#binding to "verfacts" and running textfsm parser.
NameError: name 'version' is not defined

2023-02-17 22:02:08,664 - nornir.core.task -    ERROR -      start() - Host 'R2': task 'locate_ip' failed with traceback:
Traceback (most recent call last):
  File "/home/ipvzero/Nornir/.venv/lib/python3.10/site-packages/nornir/core/task.py", line 99, in start
    r = self.task(self, **self.params)
  File "/home/ipvzero/Nornir/Tools/ip-hunter1.py", line 37, in locate_ip
    task.host["verfacts"] = version.result.scrapli_response.textfsm_parse_output()#binding to "verfacts" and running textfsm parser.
NameError: name 'version' is not defined

2023-02-17 22:02:08,689 - nornir.core.task -    ERROR -      start() - Host 'R4': task 'locate_ip' failed with traceback:
Traceback (most recent call last):
  File "/home/ipvzero/Nornir/.venv/lib/python3.10/site-packages/nornir/core/task.py", line 99, in start
    r = self.task(self, **self.params)
  File "/home/ipvzero/Nornir/Tools/ip-hunter1.py", line 37, in locate_ip
    task.host["verfacts"] = version.result.scrapli_response.textfsm_parse_output()#binding to "verfacts" and running textfsm parser.
NameError: name 'version' is not defined

2023-02-17 22:02:08,713 - nornir.core.task -    ERROR -      start() - Host 'R1': task 'locate_ip' failed with traceback:
Traceback (most recent call last):
  File "/home/ipvzero/Nornir/.venv/lib/python3.10/site-packages/nornir/core/task.py", line 99, in start
    r = self.task(self, **self.params)
  File "/home/ipvzero/Nornir/Tools/ip-hunter1.py", line 37, in locate_ip
    task.host["verfacts"] = version.result.scrapli_response.textfsm_parse_output()#binding to "verfacts" and running textfsm parser.
NameError: name 'version' is not defined

2023-02-17 22:05:45,406 -  nornir.core -     INFO -        run() - Running task 'get_ip' with args {} on 7 hosts
2023-02-17 22:05:48,000 -  nornir.core -     INFO -        run() - Running task 'locate_ip' with args {} on 7 hosts
2023-02-17 22:06:21,000 -  nornir.core -     INFO -        run() - Running task 'get_ip' with args {} on 7 hosts
2023-02-17 22:06:23,802 -  nornir.core -     INFO -        run() - Running task 'locate_ip' with args {} on 7 hosts
2023-02-17 22:09:46,815 -  nornir.core -     INFO -        run() - Running task 'get_ip' with args {} on 7 hosts
2023-02-17 22:09:49,510 -  nornir.core -     INFO -        run() - Running task 'locate_ip' with args {} on 7 hosts
2023-02-17 22:36:12,643 -  nornir.core -     INFO -        run() - Running task 'get_ip' with args {} on 7 hosts
2023-02-17 22:36:15,292 -  nornir.core -     INFO -        run() - Running task 'locate_ip' with args {} on 7 hosts
2023-02-17 22:36:16,585 - nornir.core.task -    ERROR -      start() - Host 'R4': task 'locate_ip' failed with traceback:
Traceback (most recent call last):
  File "/home/ipvzero/Nornir/.venv/lib/python3.10/site-packages/nornir/core/task.py", line 99, in start
    r = self.task(self, **self.params)
  File "/home/ipvzero/Nornir/Tools/ip-hunter1.py", line 38, in locate_ip
    LOCK.acquire()
NameError: name 'LOCK' is not defined

2023-02-17 22:36:16,587 - nornir.core.task -    ERROR -      start() - Host 'R1': task 'locate_ip' failed with traceback:
Traceback (most recent call last):
  File "/home/ipvzero/Nornir/.venv/lib/python3.10/site-packages/nornir/core/task.py", line 99, in start
    r = self.task(self, **self.params)
  File "/home/ipvzero/Nornir/Tools/ip-hunter1.py", line 38, in locate_ip
    LOCK.acquire()
NameError: name 'LOCK' is not defined

2023-02-17 22:36:16,587 - nornir.core.task -    ERROR -      start() - Host 'R6': task 'locate_ip' failed with traceback:
Traceback (most recent call last):
  File "/home/ipvzero/Nornir/.venv/lib/python3.10/site-packages/nornir/core/task.py", line 99, in start
    r = self.task(self, **self.params)
  File "/home/ipvzero/Nornir/Tools/ip-hunter1.py", line 38, in locate_ip
    LOCK.acquire()
NameError: name 'LOCK' is not defined

2023-02-17 22:36:16,643 - nornir.core.task -    ERROR -      start() - Host 'R2': task 'locate_ip' failed with traceback:
Traceback (most recent call last):
  File "/home/ipvzero/Nornir/.venv/lib/python3.10/site-packages/nornir/core/task.py", line 99, in start
    r = self.task(self, **self.params)
  File "/home/ipvzero/Nornir/Tools/ip-hunter1.py", line 38, in locate_ip
    LOCK.acquire()
NameError: name 'LOCK' is not defined

2023-02-17 22:41:02,365 -  nornir.core -     INFO -        run() - Running task 'get_ip' with args {} on 7 hosts
2023-02-17 22:41:05,358 -  nornir.core -     INFO -        run() - Running task 'locate_ip' with args {} on 7 hosts
2023-02-17 22:42:17,000 -  nornir.core -     INFO -        run() - Running task 'get_ip' with args {} on 7 hosts
2023-02-17 22:42:20,147 -  nornir.core -     INFO -        run() - Running task 'locate_ip' with args {} on 7 hosts
2023-02-18 05:12:38,814 -  nornir.core -     INFO -        run() - Running task 'get_ip' with args {} on 7 hosts
2023-02-18 05:12:42,147 -  nornir.core -     INFO -        run() - Running task 'locate_ip' with args {} on 7 hosts
2023-02-18 05:12:57,437 -  nornir.core -     INFO -        run() - Running task 'get_ip' with args {} on 7 hosts
2023-02-18 05:13:00,758 -  nornir.core -     INFO -        run() - Running task 'locate_ip' with args {} on 7 hosts
2023-02-18 05:13:21,469 -  nornir.core -     INFO -        run() - Running task 'get_ip' with args {} on 7 hosts
2023-02-18 05:13:24,507 -  nornir.core -     INFO -        run() - Running task 'locate_ip' with args {} on 7 hosts
2023-02-18 05:16:02,902 -  nornir.core -     INFO -        run() - Running task 'get_ip' with args {} on 2 hosts
2023-02-18 05:16:22,650 -  nornir.core -     INFO -        run() - Running task 'get_ip' with args {} on 5 hosts
2023-02-18 05:16:25,110 -  nornir.core -     INFO -        run() - Running task 'locate_ip' with args {} on 5 hosts
2023-02-18 05:17:59,878 -  nornir.core -     INFO -        run() - Running task 'get_ip' with args {} on 2 hosts
2023-02-18 05:18:22,271 -  nornir.core -     INFO -        run() - Running task 'get_ip' with args {} on 2 hosts
2023-02-18 05:18:44,319 -  nornir.core -     INFO -        run() - Running task 'get_ip' with args {} on 2 hosts
2023-02-18 05:19:01,311 -  nornir.core -     INFO -        run() - Running task 'get_ip' with args {} on 7 hosts
2023-02-18 05:19:04,309 -  nornir.core -     INFO -        run() - Running task 'locate_ip' with args {} on 7 hosts
2023-02-18 05:20:33,752 -  nornir.core -  WARNING -        run() - Task 'get_ip' has not been run – 0 hosts selected
2023-02-18 05:21:06,896 -  nornir.core -     INFO -        run() - Running task 'get_ip' with args {} on 1 hosts
2023-02-18 05:21:08,725 -  nornir.core -     INFO -        run() - Running task 'locate_ip' with args {} on 1 hosts
2023-02-20 20:49:42,239 -  nornir.core -     INFO -        run() - Running task 'get_ip' with args {} on 7 hosts
2023-02-20 20:51:22,996 -  nornir.core -     INFO -        run() - Running task 'get_ip' with args {} on 7 hosts
2023-02-20 21:02:35,687 -  nornir.core -     INFO -        run() - Running task 'get_ip' with args {} on 7 hosts
2023-02-20 21:02:38,400 -  nornir.core -     INFO -        run() - Running task 'ping_test' with args {} on 7 hosts
2023-02-20 21:02:39,034 - nornir.core.task -    ERROR -      start() - Host 'R4': task 'ping_test' failed with traceback:
Traceback (most recent call last):
  File "/home/ipvzero/Nornir/.venv/lib/python3.10/site-packages/nornir/core/task.py", line 99, in start
    r = self.task(self, **self.params)
  File "/home/ipvzero/Nornir/Tools/pinghunter.py", line 24, in ping_test
    if not "!!!" in reponse:
NameError: name 'reponse' is not defined

2023-02-20 21:02:39,157 - nornir.core.task -    ERROR -      start() - Host 'R1': task 'ping_test' failed with traceback:
Traceback (most recent call last):
  File "/home/ipvzero/Nornir/.venv/lib/python3.10/site-packages/nornir/core/task.py", line 99, in start
    r = self.task(self, **self.params)
  File "/home/ipvzero/Nornir/Tools/pinghunter.py", line 24, in ping_test
    if not "!!!" in reponse:
NameError: name 'reponse' is not defined

2023-02-20 21:02:39,188 - nornir.core.task -    ERROR -      start() - Host 'R2': task 'ping_test' failed with traceback:
Traceback (most recent call last):
  File "/home/ipvzero/Nornir/.venv/lib/python3.10/site-packages/nornir/core/task.py", line 99, in start
    r = self.task(self, **self.params)
  File "/home/ipvzero/Nornir/Tools/pinghunter.py", line 24, in ping_test
    if not "!!!" in reponse:
NameError: name 'reponse' is not defined

2023-02-20 21:02:49,130 - nornir.core.task -    ERROR -      start() - Host 'R5': task 'ping_test' failed with traceback:
Traceback (most recent call last):
  File "/home/ipvzero/Nornir/.venv/lib/python3.10/site-packages/nornir/core/task.py", line 99, in start
    r = self.task(self, **self.params)
  File "/home/ipvzero/Nornir/Tools/pinghunter.py", line 24, in ping_test
    if not "!!!" in reponse:
NameError: name 'reponse' is not defined

2023-02-20 21:02:49,178 - nornir.core.task -    ERROR -      start() - Host 'R6': task 'ping_test' failed with traceback:
Traceback (most recent call last):
  File "/home/ipvzero/Nornir/.venv/lib/python3.10/site-packages/nornir/core/task.py", line 99, in start
    r = self.task(self, **self.params)
  File "/home/ipvzero/Nornir/Tools/pinghunter.py", line 24, in ping_test
    if not "!!!" in reponse:
NameError: name 'reponse' is not defined

2023-02-20 21:02:49,224 - nornir.core.task -    ERROR -      start() - Host 'R3': task 'ping_test' failed with traceback:
Traceback (most recent call last):
  File "/home/ipvzero/Nornir/.venv/lib/python3.10/site-packages/nornir/core/task.py", line 99, in start
    r = self.task(self, **self.params)
  File "/home/ipvzero/Nornir/Tools/pinghunter.py", line 24, in ping_test
    if not "!!!" in reponse:
NameError: name 'reponse' is not defined

2023-02-20 21:02:49,303 - nornir.core.task -    ERROR -      start() - Host 'R7': task 'ping_test' failed with traceback:
Traceback (most recent call last):
  File "/home/ipvzero/Nornir/.venv/lib/python3.10/site-packages/nornir/core/task.py", line 99, in start
    r = self.task(self, **self.params)
  File "/home/ipvzero/Nornir/Tools/pinghunter.py", line 24, in ping_test
    if not "!!!" in reponse:
NameError: name 'reponse' is not defined

2023-02-20 21:06:50,291 -  nornir.core -     INFO -        run() - Running task 'get_ip' with args {} on 7 hosts
2023-02-20 21:06:52,737 -  nornir.core -     INFO -        run() - Running task 'ping_test' with args {} on 7 hosts
2023-02-20 21:06:53,348 - nornir.core.task -    ERROR -      start() - Host 'R1': task 'ping_test' failed with traceback:
Traceback (most recent call last):
  File "/home/ipvzero/Nornir/.venv/lib/python3.10/site-packages/nornir/core/task.py", line 99, in start
    r = self.task(self, **self.params)
  File "/home/ipvzero/Nornir/Tools/pinghunter.py", line 24, in ping_test
    if not "!!!" in reponse:
NameError: name 'reponse' is not defined

2023-02-20 21:06:53,365 - nornir.core.task -    ERROR -      start() - Host 'R4': task 'ping_test' failed with traceback:
Traceback (most recent call last):
  File "/home/ipvzero/Nornir/.venv/lib/python3.10/site-packages/nornir/core/task.py", line 99, in start
    r = self.task(self, **self.params)
  File "/home/ipvzero/Nornir/Tools/pinghunter.py", line 24, in ping_test
    if not "!!!" in reponse:
NameError: name 'reponse' is not defined

2023-02-20 21:06:53,368 - nornir.core.task -    ERROR -      start() - Host 'R2': task 'ping_test' failed with traceback:
Traceback (most recent call last):
  File "/home/ipvzero/Nornir/.venv/lib/python3.10/site-packages/nornir/core/task.py", line 99, in start
    r = self.task(self, **self.params)
  File "/home/ipvzero/Nornir/Tools/pinghunter.py", line 24, in ping_test
    if not "!!!" in reponse:
NameError: name 'reponse' is not defined

2023-02-20 21:07:03,287 - nornir.core.task -    ERROR -      start() - Host 'R6': task 'ping_test' failed with traceback:
Traceback (most recent call last):
  File "/home/ipvzero/Nornir/.venv/lib/python3.10/site-packages/nornir/core/task.py", line 99, in start
    r = self.task(self, **self.params)
  File "/home/ipvzero/Nornir/Tools/pinghunter.py", line 24, in ping_test
    if not "!!!" in reponse:
NameError: name 'reponse' is not defined

2023-02-20 21:07:03,396 - nornir.core.task -    ERROR -      start() - Host 'R7': task 'ping_test' failed with traceback:
Traceback (most recent call last):
  File "/home/ipvzero/Nornir/.venv/lib/python3.10/site-packages/nornir/core/task.py", line 99, in start
    r = self.task(self, **self.params)
  File "/home/ipvzero/Nornir/Tools/pinghunter.py", line 24, in ping_test
    if not "!!!" in reponse:
NameError: name 'reponse' is not defined

2023-02-20 21:07:03,426 - nornir.core.task -    ERROR -      start() - Host 'R5': task 'ping_test' failed with traceback:
Traceback (most recent call last):
  File "/home/ipvzero/Nornir/.venv/lib/python3.10/site-packages/nornir/core/task.py", line 99, in start
    r = self.task(self, **self.params)
  File "/home/ipvzero/Nornir/Tools/pinghunter.py", line 24, in ping_test
    if not "!!!" in reponse:
NameError: name 'reponse' is not defined

2023-02-20 21:07:03,448 - nornir.core.task -    ERROR -      start() - Host 'R3': task 'ping_test' failed with traceback:
Traceback (most recent call last):
  File "/home/ipvzero/Nornir/.venv/lib/python3.10/site-packages/nornir/core/task.py", line 99, in start
    r = self.task(self, **self.params)
  File "/home/ipvzero/Nornir/Tools/pinghunter.py", line 24, in ping_test
    if not "!!!" in reponse:
NameError: name 'reponse' is not defined

2023-02-20 21:07:46,903 -  nornir.core -     INFO -        run() - Running task 'get_ip' with args {} on 7 hosts
2023-02-20 21:08:02,048 - nornir.core.task -    ERROR -      start() - Host 'R2': task 'send_command' failed with traceback:
Traceback (most recent call last):
  File "/home/ipvzero/Nornir/.venv/lib/python3.10/site-packages/nornir/core/task.py", line 99, in start
    r = self.task(self, **self.params)
  File "/home/ipvzero/Nornir/.venv/lib/python3.10/site-packages/nornir_scrapli/tasks/core/send_command.py", line 36, in send_command
    scrapli_conn = task.host.get_connection("scrapli", task.nornir.config)
  File "/home/ipvzero/Nornir/.venv/lib/python3.10/site-packages/nornir/core/inventory.py", line 494, in get_connection
    self.open_connection(
  File "/home/ipvzero/Nornir/.venv/lib/python3.10/site-packages/nornir/core/inventory.py", line 546, in open_connection
    conn_obj.open(
  File "/home/ipvzero/Nornir/.venv/lib/python3.10/site-packages/nornir_scrapli/connection.py", line 105, in open
    connection.open()
  File "/home/ipvzero/Nornir/.venv/lib/python3.10/site-packages/scrapli/driver/base/sync_driver.py", line 88, in open
    self.channel.channel_authenticate_ssh(
  File "/home/ipvzero/Nornir/.venv/lib/python3.10/site-packages/scrapli/decorators.py", line 216, in decorate
    return _multiprocessing_timeout(
  File "/home/ipvzero/Nornir/.venv/lib/python3.10/site-packages/scrapli/decorators.py", line 113, in _multiprocessing_timeout
    return future.result()
  File "/usr/lib/python3.10/concurrent/futures/_base.py", line 451, in result
    return self.__get_result()
  File "/usr/lib/python3.10/concurrent/futures/_base.py", line 403, in __get_result
    raise self._exception
  File "/usr/lib/python3.10/concurrent/futures/thread.py", line 58, in run
    result = self.fn(*self.args, **self.kwargs)
  File "/home/ipvzero/Nornir/.venv/lib/python3.10/site-packages/scrapli/channel/sync_channel.py", line 290, in channel_authenticate_ssh
    self._ssh_message_handler(output=authenticate_buf)
  File "/home/ipvzero/Nornir/.venv/lib/python3.10/site-packages/scrapli/channel/base_channel.py", line 432, in _ssh_message_handler
    raise ScrapliAuthenticationFailed(msg)
scrapli.exceptions.ScrapliAuthenticationFailed: Timed out connecting to host

2023-02-20 21:08:02,048 - nornir.core.task -    ERROR -      start() - Host 'R2': task 'get_ip' failed with traceback:
Traceback (most recent call last):
  File "/home/ipvzero/Nornir/.venv/lib/python3.10/site-packages/nornir/core/task.py", line 99, in start
    r = self.task(self, **self.params)
  File "/home/ipvzero/Nornir/Tools/pinghunter.py", line 12, in get_ip
    result = task.run(task=send_command, command="show ip interface brief")
  File "/home/ipvzero/Nornir/.venv/lib/python3.10/site-packages/nornir/core/task.py", line 174, in run
    raise NornirSubTaskError(task=run_task, result=r)
nornir.core.exceptions.NornirSubTaskError: Subtask: send_command (failed)


2023-02-20 21:08:02,049 -  nornir.core -     INFO -        run() - Running task 'ping_test' with args {} on 7 hosts
2023-02-20 21:08:02,623 - nornir.core.task -    ERROR -      start() - Host 'R4': task 'ping_test' failed with traceback:
Traceback (most recent call last):
  File "/home/ipvzero/Nornir/.venv/lib/python3.10/site-packages/nornir/core/task.py", line 99, in start
    r = self.task(self, **self.params)
  File "/home/ipvzero/Nornir/Tools/pinghunter.py", line 24, in ping_test
    if not "!!!" in reponse:
NameError: name 'reponse' is not defined

2023-02-20 21:08:02,639 - nornir.core.task -    ERROR -      start() - Host 'R1': task 'ping_test' failed with traceback:
Traceback (most recent call last):
  File "/home/ipvzero/Nornir/.venv/lib/python3.10/site-packages/nornir/core/task.py", line 99, in start
    r = self.task(self, **self.params)
  File "/home/ipvzero/Nornir/Tools/pinghunter.py", line 24, in ping_test
    if not "!!!" in reponse:
NameError: name 'reponse' is not defined

2023-02-20 21:08:12,604 - nornir.core.task -    ERROR -      start() - Host 'R5': task 'ping_test' failed with traceback:
Traceback (most recent call last):
  File "/home/ipvzero/Nornir/.venv/lib/python3.10/site-packages/nornir/core/task.py", line 99, in start
    r = self.task(self, **self.params)
  File "/home/ipvzero/Nornir/Tools/pinghunter.py", line 24, in ping_test
    if not "!!!" in reponse:
NameError: name 'reponse' is not defined

2023-02-20 21:08:12,637 - nornir.core.task -    ERROR -      start() - Host 'R7': task 'ping_test' failed with traceback:
Traceback (most recent call last):
  File "/home/ipvzero/Nornir/.venv/lib/python3.10/site-packages/nornir/core/task.py", line 99, in start
    r = self.task(self, **self.params)
  File "/home/ipvzero/Nornir/Tools/pinghunter.py", line 24, in ping_test
    if not "!!!" in reponse:
NameError: name 'reponse' is not defined

2023-02-20 21:08:12,709 - nornir.core.task -    ERROR -      start() - Host 'R3': task 'ping_test' failed with traceback:
Traceback (most recent call last):
  File "/home/ipvzero/Nornir/.venv/lib/python3.10/site-packages/nornir/core/task.py", line 99, in start
    r = self.task(self, **self.params)
  File "/home/ipvzero/Nornir/Tools/pinghunter.py", line 24, in ping_test
    if not "!!!" in reponse:
NameError: name 'reponse' is not defined

2023-02-20 21:08:12,722 - nornir.core.task -    ERROR -      start() - Host 'R6': task 'ping_test' failed with traceback:
Traceback (most recent call last):
  File "/home/ipvzero/Nornir/.venv/lib/python3.10/site-packages/nornir/core/task.py", line 99, in start
    r = self.task(self, **self.params)
  File "/home/ipvzero/Nornir/Tools/pinghunter.py", line 24, in ping_test
    if not "!!!" in reponse:
NameError: name 'reponse' is not defined

2023-02-20 21:13:09,982 -  nornir.core -     INFO -        run() - Running task 'get_ip' with args {} on 7 hosts
2023-02-20 21:13:13,082 - nornir.core.task -    ERROR -      start() - Host 'R2': task 'send_command' failed with traceback:
Traceback (most recent call last):
  File "/home/ipvzero/Nornir/.venv/lib/python3.10/site-packages/nornir/core/task.py", line 99, in start
    r = self.task(self, **self.params)
  File "/home/ipvzero/Nornir/.venv/lib/python3.10/site-packages/nornir_scrapli/tasks/core/send_command.py", line 36, in send_command
    scrapli_conn = task.host.get_connection("scrapli", task.nornir.config)
  File "/home/ipvzero/Nornir/.venv/lib/python3.10/site-packages/nornir/core/inventory.py", line 494, in get_connection
    self.open_connection(
  File "/home/ipvzero/Nornir/.venv/lib/python3.10/site-packages/nornir/core/inventory.py", line 546, in open_connection
    conn_obj.open(
  File "/home/ipvzero/Nornir/.venv/lib/python3.10/site-packages/nornir_scrapli/connection.py", line 105, in open
    connection.open()
  File "/home/ipvzero/Nornir/.venv/lib/python3.10/site-packages/scrapli/driver/base/sync_driver.py", line 88, in open
    self.channel.channel_authenticate_ssh(
  File "/home/ipvzero/Nornir/.venv/lib/python3.10/site-packages/scrapli/decorators.py", line 216, in decorate
    return _multiprocessing_timeout(
  File "/home/ipvzero/Nornir/.venv/lib/python3.10/site-packages/scrapli/decorators.py", line 113, in _multiprocessing_timeout
    return future.result()
  File "/usr/lib/python3.10/concurrent/futures/_base.py", line 451, in result
    return self.__get_result()
  File "/usr/lib/python3.10/concurrent/futures/_base.py", line 403, in __get_result
    raise self._exception
  File "/usr/lib/python3.10/concurrent/futures/thread.py", line 58, in run
    result = self.fn(*self.args, **self.kwargs)
  File "/home/ipvzero/Nornir/.venv/lib/python3.10/site-packages/scrapli/channel/sync_channel.py", line 290, in channel_authenticate_ssh
    self._ssh_message_handler(output=authenticate_buf)
  File "/home/ipvzero/Nornir/.venv/lib/python3.10/site-packages/scrapli/channel/base_channel.py", line 432, in _ssh_message_handler
    raise ScrapliAuthenticationFailed(msg)
scrapli.exceptions.ScrapliAuthenticationFailed: No route to host

2023-02-20 21:13:13,082 - nornir.core.task -    ERROR -      start() - Host 'R2': task 'get_ip' failed with traceback:
Traceback (most recent call last):
  File "/home/ipvzero/Nornir/.venv/lib/python3.10/site-packages/nornir/core/task.py", line 99, in start
    r = self.task(self, **self.params)
  File "/home/ipvzero/Nornir/Tools/pinghunter.py", line 12, in get_ip
    result = task.run(task=send_command, command="show ip interface brief")
  File "/home/ipvzero/Nornir/.venv/lib/python3.10/site-packages/nornir/core/task.py", line 174, in run
    raise NornirSubTaskError(task=run_task, result=r)
nornir.core.exceptions.NornirSubTaskError: Subtask: send_command (failed)


2023-02-20 21:13:13,082 -  nornir.core -     INFO -        run() - Running task 'ping_test' with args {} on 7 hosts
2023-02-20 21:13:13,492 - nornir.core.task -    ERROR -      start() - Host 'R1': task 'ping_test' failed with traceback:
Traceback (most recent call last):
  File "/home/ipvzero/Nornir/.venv/lib/python3.10/site-packages/nornir/core/task.py", line 99, in start
    r = self.task(self, **self.params)
  File "/home/ipvzero/Nornir/Tools/pinghunter.py", line 24, in ping_test
    if not "!!!" in reponse:
NameError: name 'reponse' is not defined

2023-02-20 21:13:13,517 - nornir.core.task -    ERROR -      start() - Host 'R4': task 'ping_test' failed with traceback:
Traceback (most recent call last):
  File "/home/ipvzero/Nornir/.venv/lib/python3.10/site-packages/nornir/core/task.py", line 99, in start
    r = self.task(self, **self.params)
  File "/home/ipvzero/Nornir/Tools/pinghunter.py", line 24, in ping_test
    if not "!!!" in reponse:
NameError: name 'reponse' is not defined

2023-02-20 21:13:23,576 - nornir.core.task -    ERROR -      start() - Host 'R6': task 'ping_test' failed with traceback:
Traceback (most recent call last):
  File "/home/ipvzero/Nornir/.venv/lib/python3.10/site-packages/nornir/core/task.py", line 99, in start
    r = self.task(self, **self.params)
  File "/home/ipvzero/Nornir/Tools/pinghunter.py", line 24, in ping_test
    if not "!!!" in reponse:
NameError: name 'reponse' is not defined

2023-02-20 21:13:23,592 - nornir.core.task -    ERROR -      start() - Host 'R7': task 'ping_test' failed with traceback:
Traceback (most recent call last):
  File "/home/ipvzero/Nornir/.venv/lib/python3.10/site-packages/nornir/core/task.py", line 99, in start
    r = self.task(self, **self.params)
  File "/home/ipvzero/Nornir/Tools/pinghunter.py", line 24, in ping_test
    if not "!!!" in reponse:
NameError: name 'reponse' is not defined

2023-02-20 21:13:23,610 - nornir.core.task -    ERROR -      start() - Host 'R3': task 'ping_test' failed with traceback:
Traceback (most recent call last):
  File "/home/ipvzero/Nornir/.venv/lib/python3.10/site-packages/nornir/core/task.py", line 99, in start
    r = self.task(self, **self.params)
  File "/home/ipvzero/Nornir/Tools/pinghunter.py", line 24, in ping_test
    if not "!!!" in reponse:
NameError: name 'reponse' is not defined

2023-02-20 21:13:23,613 - nornir.core.task -    ERROR -      start() - Host 'R5': task 'ping_test' failed with traceback:
Traceback (most recent call last):
  File "/home/ipvzero/Nornir/.venv/lib/python3.10/site-packages/nornir/core/task.py", line 99, in start
    r = self.task(self, **self.params)
  File "/home/ipvzero/Nornir/Tools/pinghunter.py", line 24, in ping_test
    if not "!!!" in reponse:
NameError: name 'reponse' is not defined

2023-02-20 21:13:23,644 -  nornir.core -     INFO -        run() - Running task 'ping_test' with args {} on 7 hosts
2023-02-20 21:13:52,163 -  nornir.core -     INFO -        run() - Running task 'get_ip' with args {} on 7 hosts
2023-02-20 21:13:55,257 - nornir.core.task -    ERROR -      start() - Host 'R2': task 'send_command' failed with traceback:
Traceback (most recent call last):
  File "/home/ipvzero/Nornir/.venv/lib/python3.10/site-packages/nornir/core/task.py", line 99, in start
    r = self.task(self, **self.params)
  File "/home/ipvzero/Nornir/.venv/lib/python3.10/site-packages/nornir_scrapli/tasks/core/send_command.py", line 36, in send_command
    scrapli_conn = task.host.get_connection("scrapli", task.nornir.config)
  File "/home/ipvzero/Nornir/.venv/lib/python3.10/site-packages/nornir/core/inventory.py", line 494, in get_connection
    self.open_connection(
  File "/home/ipvzero/Nornir/.venv/lib/python3.10/site-packages/nornir/core/inventory.py", line 546, in open_connection
    conn_obj.open(
  File "/home/ipvzero/Nornir/.venv/lib/python3.10/site-packages/nornir_scrapli/connection.py", line 105, in open
    connection.open()
  File "/home/ipvzero/Nornir/.venv/lib/python3.10/site-packages/scrapli/driver/base/sync_driver.py", line 88, in open
    self.channel.channel_authenticate_ssh(
  File "/home/ipvzero/Nornir/.venv/lib/python3.10/site-packages/scrapli/decorators.py", line 216, in decorate
    return _multiprocessing_timeout(
  File "/home/ipvzero/Nornir/.venv/lib/python3.10/site-packages/scrapli/decorators.py", line 113, in _multiprocessing_timeout
    return future.result()
  File "/usr/lib/python3.10/concurrent/futures/_base.py", line 451, in result
    return self.__get_result()
  File "/usr/lib/python3.10/concurrent/futures/_base.py", line 403, in __get_result
    raise self._exception
  File "/usr/lib/python3.10/concurrent/futures/thread.py", line 58, in run
    result = self.fn(*self.args, **self.kwargs)
  File "/home/ipvzero/Nornir/.venv/lib/python3.10/site-packages/scrapli/channel/sync_channel.py", line 290, in channel_authenticate_ssh
    self._ssh_message_handler(output=authenticate_buf)
  File "/home/ipvzero/Nornir/.venv/lib/python3.10/site-packages/scrapli/channel/base_channel.py", line 432, in _ssh_message_handler
    raise ScrapliAuthenticationFailed(msg)
scrapli.exceptions.ScrapliAuthenticationFailed: No route to host

2023-02-20 21:13:55,257 - nornir.core.task -    ERROR -      start() - Host 'R2': task 'get_ip' failed with traceback:
Traceback (most recent call last):
  File "/home/ipvzero/Nornir/.venv/lib/python3.10/site-packages/nornir/core/task.py", line 99, in start
    r = self.task(self, **self.params)
  File "/home/ipvzero/Nornir/Tools/pinghunter.py", line 12, in get_ip
    result = task.run(task=send_command, command="show ip interface brief")
  File "/home/ipvzero/Nornir/.venv/lib/python3.10/site-packages/nornir/core/task.py", line 174, in run
    raise NornirSubTaskError(task=run_task, result=r)
nornir.core.exceptions.NornirSubTaskError: Subtask: send_command (failed)


2023-02-20 21:13:55,257 -  nornir.core -     INFO -        run() - Running task 'ping_test' with args {} on 7 hosts
2023-02-20 21:13:55,901 - nornir.core.task -    ERROR -      start() - Host 'R1': task 'ping_test' failed with traceback:
Traceback (most recent call last):
  File "/home/ipvzero/Nornir/.venv/lib/python3.10/site-packages/nornir/core/task.py", line 99, in start
    r = self.task(self, **self.params)
  File "/home/ipvzero/Nornir/Tools/pinghunter.py", line 24, in ping_test
    if not "!!!" in reponse:
NameError: name 'reponse' is not defined

2023-02-20 21:13:55,925 - nornir.core.task -    ERROR -      start() - Host 'R4': task 'ping_test' failed with traceback:
Traceback (most recent call last):
  File "/home/ipvzero/Nornir/.venv/lib/python3.10/site-packages/nornir/core/task.py", line 99, in start
    r = self.task(self, **self.params)
  File "/home/ipvzero/Nornir/Tools/pinghunter.py", line 24, in ping_test
    if not "!!!" in reponse:
NameError: name 'reponse' is not defined

2023-02-20 21:14:05,902 - nornir.core.task -    ERROR -      start() - Host 'R6': task 'ping_test' failed with traceback:
Traceback (most recent call last):
  File "/home/ipvzero/Nornir/.venv/lib/python3.10/site-packages/nornir/core/task.py", line 99, in start
    r = self.task(self, **self.params)
  File "/home/ipvzero/Nornir/Tools/pinghunter.py", line 24, in ping_test
    if not "!!!" in reponse:
NameError: name 'reponse' is not defined

2023-02-20 21:14:05,906 - nornir.core.task -    ERROR -      start() - Host 'R3': task 'ping_test' failed with traceback:
Traceback (most recent call last):
  File "/home/ipvzero/Nornir/.venv/lib/python3.10/site-packages/nornir/core/task.py", line 99, in start
    r = self.task(self, **self.params)
  File "/home/ipvzero/Nornir/Tools/pinghunter.py", line 24, in ping_test
    if not "!!!" in reponse:
NameError: name 'reponse' is not defined

2023-02-20 21:14:05,935 - nornir.core.task -    ERROR -      start() - Host 'R7': task 'ping_test' failed with traceback:
Traceback (most recent call last):
  File "/home/ipvzero/Nornir/.venv/lib/python3.10/site-packages/nornir/core/task.py", line 99, in start
    r = self.task(self, **self.params)
  File "/home/ipvzero/Nornir/Tools/pinghunter.py", line 24, in ping_test
    if not "!!!" in reponse:
NameError: name 'reponse' is not defined

2023-02-20 21:14:05,993 - nornir.core.task -    ERROR -      start() - Host 'R5': task 'ping_test' failed with traceback:
Traceback (most recent call last):
  File "/home/ipvzero/Nornir/.venv/lib/python3.10/site-packages/nornir/core/task.py", line 99, in start
    r = self.task(self, **self.params)
  File "/home/ipvzero/Nornir/Tools/pinghunter.py", line 24, in ping_test
    if not "!!!" in reponse:
NameError: name 'reponse' is not defined

2023-02-20 21:14:05,994 -  nornir.core -     INFO -        run() - Running task 'ping_test' with args {} on 7 hosts
2023-02-20 21:14:36,319 -  nornir.core -     INFO -        run() - Running task 'get_ip' with args {} on 7 hosts
2023-02-20 21:14:39,417 - nornir.core.task -    ERROR -      start() - Host 'R2': task 'send_command' failed with traceback:
Traceback (most recent call last):
  File "/home/ipvzero/Nornir/.venv/lib/python3.10/site-packages/nornir/core/task.py", line 99, in start
    r = self.task(self, **self.params)
  File "/home/ipvzero/Nornir/.venv/lib/python3.10/site-packages/nornir_scrapli/tasks/core/send_command.py", line 36, in send_command
    scrapli_conn = task.host.get_connection("scrapli", task.nornir.config)
  File "/home/ipvzero/Nornir/.venv/lib/python3.10/site-packages/nornir/core/inventory.py", line 494, in get_connection
    self.open_connection(
  File "/home/ipvzero/Nornir/.venv/lib/python3.10/site-packages/nornir/core/inventory.py", line 546, in open_connection
    conn_obj.open(
  File "/home/ipvzero/Nornir/.venv/lib/python3.10/site-packages/nornir_scrapli/connection.py", line 105, in open
    connection.open()
  File "/home/ipvzero/Nornir/.venv/lib/python3.10/site-packages/scrapli/driver/base/sync_driver.py", line 88, in open
    self.channel.channel_authenticate_ssh(
  File "/home/ipvzero/Nornir/.venv/lib/python3.10/site-packages/scrapli/decorators.py", line 216, in decorate
    return _multiprocessing_timeout(
  File "/home/ipvzero/Nornir/.venv/lib/python3.10/site-packages/scrapli/decorators.py", line 113, in _multiprocessing_timeout
    return future.result()
  File "/usr/lib/python3.10/concurrent/futures/_base.py", line 451, in result
    return self.__get_result()
  File "/usr/lib/python3.10/concurrent/futures/_base.py", line 403, in __get_result
    raise self._exception
  File "/usr/lib/python3.10/concurrent/futures/thread.py", line 58, in run
    result = self.fn(*self.args, **self.kwargs)
  File "/home/ipvzero/Nornir/.venv/lib/python3.10/site-packages/scrapli/channel/sync_channel.py", line 290, in channel_authenticate_ssh
    self._ssh_message_handler(output=authenticate_buf)
  File "/home/ipvzero/Nornir/.venv/lib/python3.10/site-packages/scrapli/channel/base_channel.py", line 432, in _ssh_message_handler
    raise ScrapliAuthenticationFailed(msg)
scrapli.exceptions.ScrapliAuthenticationFailed: No route to host

2023-02-20 21:14:39,417 - nornir.core.task -    ERROR -      start() - Host 'R2': task 'get_ip' failed with traceback:
Traceback (most recent call last):
  File "/home/ipvzero/Nornir/.venv/lib/python3.10/site-packages/nornir/core/task.py", line 99, in start
    r = self.task(self, **self.params)
  File "/home/ipvzero/Nornir/Tools/pinghunter.py", line 12, in get_ip
    result = task.run(task=send_command, command="show ip interface brief")
  File "/home/ipvzero/Nornir/.venv/lib/python3.10/site-packages/nornir/core/task.py", line 174, in run
    raise NornirSubTaskError(task=run_task, result=r)
nornir.core.exceptions.NornirSubTaskError: Subtask: send_command (failed)


2023-02-20 21:14:39,418 -  nornir.core -     INFO -        run() - Running task 'ping_test' with args {} on 7 hosts
2023-02-20 21:14:39,905 - nornir.core.task -    ERROR -      start() - Host 'R4': task 'ping_test' failed with traceback:
Traceback (most recent call last):
  File "/home/ipvzero/Nornir/.venv/lib/python3.10/site-packages/nornir/core/task.py", line 99, in start
    r = self.task(self, **self.params)
  File "/home/ipvzero/Nornir/Tools/pinghunter.py", line 24, in ping_test
    if not "!!!" in reponse:
NameError: name 'reponse' is not defined

2023-02-20 21:14:39,928 - nornir.core.task -    ERROR -      start() - Host 'R1': task 'ping_test' failed with traceback:
Traceback (most recent call last):
  File "/home/ipvzero/Nornir/.venv/lib/python3.10/site-packages/nornir/core/task.py", line 99, in start
    r = self.task(self, **self.params)
  File "/home/ipvzero/Nornir/Tools/pinghunter.py", line 24, in ping_test
    if not "!!!" in reponse:
NameError: name 'reponse' is not defined

2023-02-20 21:14:49,905 - nornir.core.task -    ERROR -      start() - Host 'R7': task 'ping_test' failed with traceback:
Traceback (most recent call last):
  File "/home/ipvzero/Nornir/.venv/lib/python3.10/site-packages/nornir/core/task.py", line 99, in start
    r = self.task(self, **self.params)
  File "/home/ipvzero/Nornir/Tools/pinghunter.py", line 24, in ping_test
    if not "!!!" in reponse:
NameError: name 'reponse' is not defined

2023-02-20 21:14:49,928 - nornir.core.task -    ERROR -      start() - Host 'R6': task 'ping_test' failed with traceback:
Traceback (most recent call last):
  File "/home/ipvzero/Nornir/.venv/lib/python3.10/site-packages/nornir/core/task.py", line 99, in start
    r = self.task(self, **self.params)
  File "/home/ipvzero/Nornir/Tools/pinghunter.py", line 24, in ping_test
    if not "!!!" in reponse:
NameError: name 'reponse' is not defined

2023-02-20 21:14:49,939 - nornir.core.task -    ERROR -      start() - Host 'R5': task 'ping_test' failed with traceback:
Traceback (most recent call last):
  File "/home/ipvzero/Nornir/.venv/lib/python3.10/site-packages/nornir/core/task.py", line 99, in start
    r = self.task(self, **self.params)
  File "/home/ipvzero/Nornir/Tools/pinghunter.py", line 24, in ping_test
    if not "!!!" in reponse:
NameError: name 'reponse' is not defined

2023-02-20 21:14:49,985 - nornir.core.task -    ERROR -      start() - Host 'R3': task 'ping_test' failed with traceback:
Traceback (most recent call last):
  File "/home/ipvzero/Nornir/.venv/lib/python3.10/site-packages/nornir/core/task.py", line 99, in start
    r = self.task(self, **self.params)
  File "/home/ipvzero/Nornir/Tools/pinghunter.py", line 24, in ping_test
    if not "!!!" in reponse:
NameError: name 'reponse' is not defined

2023-02-20 21:14:49,986 -  nornir.core -     INFO -        run() - Running task 'ping_test' with args {} on 7 hosts
2023-02-20 21:18:49,714 -  nornir.core -     INFO -        run() - Running task 'get_ip' with args {} on 7 hosts
2023-02-20 21:18:52,794 - nornir.core.task -    ERROR -      start() - Host 'R2': task 'send_command' failed with traceback:
Traceback (most recent call last):
  File "/home/ipvzero/Nornir/.venv/lib/python3.10/site-packages/nornir/core/task.py", line 99, in start
    r = self.task(self, **self.params)
  File "/home/ipvzero/Nornir/.venv/lib/python3.10/site-packages/nornir_scrapli/tasks/core/send_command.py", line 36, in send_command
    scrapli_conn = task.host.get_connection("scrapli", task.nornir.config)
  File "/home/ipvzero/Nornir/.venv/lib/python3.10/site-packages/nornir/core/inventory.py", line 494, in get_connection
    self.open_connection(
  File "/home/ipvzero/Nornir/.venv/lib/python3.10/site-packages/nornir/core/inventory.py", line 546, in open_connection
    conn_obj.open(
  File "/home/ipvzero/Nornir/.venv/lib/python3.10/site-packages/nornir_scrapli/connection.py", line 105, in open
    connection.open()
  File "/home/ipvzero/Nornir/.venv/lib/python3.10/site-packages/scrapli/driver/base/sync_driver.py", line 88, in open
    self.channel.channel_authenticate_ssh(
  File "/home/ipvzero/Nornir/.venv/lib/python3.10/site-packages/scrapli/decorators.py", line 216, in decorate
    return _multiprocessing_timeout(
  File "/home/ipvzero/Nornir/.venv/lib/python3.10/site-packages/scrapli/decorators.py", line 113, in _multiprocessing_timeout
    return future.result()
  File "/usr/lib/python3.10/concurrent/futures/_base.py", line 451, in result
    return self.__get_result()
  File "/usr/lib/python3.10/concurrent/futures/_base.py", line 403, in __get_result
    raise self._exception
  File "/usr/lib/python3.10/concurrent/futures/thread.py", line 58, in run
    result = self.fn(*self.args, **self.kwargs)
  File "/home/ipvzero/Nornir/.venv/lib/python3.10/site-packages/scrapli/channel/sync_channel.py", line 290, in channel_authenticate_ssh
    self._ssh_message_handler(output=authenticate_buf)
  File "/home/ipvzero/Nornir/.venv/lib/python3.10/site-packages/scrapli/channel/base_channel.py", line 432, in _ssh_message_handler
    raise ScrapliAuthenticationFailed(msg)
scrapli.exceptions.ScrapliAuthenticationFailed: No route to host

2023-02-20 21:18:52,794 - nornir.core.task -    ERROR -      start() - Host 'R2': task 'get_ip' failed with traceback:
Traceback (most recent call last):
  File "/home/ipvzero/Nornir/.venv/lib/python3.10/site-packages/nornir/core/task.py", line 99, in start
    r = self.task(self, **self.params)
  File "/home/ipvzero/Nornir/Tools/pinghunter.py", line 12, in get_ip
    result = task.run(task=send_command, command="show ip interface brief")
  File "/home/ipvzero/Nornir/.venv/lib/python3.10/site-packages/nornir/core/task.py", line 174, in run
    raise NornirSubTaskError(task=run_task, result=r)
nornir.core.exceptions.NornirSubTaskError: Subtask: send_command (failed)


2023-02-20 21:20:06,292 -  nornir.core -     INFO -        run() - Running task 'get_ip' with args {} on 7 hosts
2023-02-20 21:20:09,400 - nornir.core.task -    ERROR -      start() - Host 'R2': task 'send_command' failed with traceback:
Traceback (most recent call last):
  File "/home/ipvzero/Nornir/.venv/lib/python3.10/site-packages/nornir/core/task.py", line 99, in start
    r = self.task(self, **self.params)
  File "/home/ipvzero/Nornir/.venv/lib/python3.10/site-packages/nornir_scrapli/tasks/core/send_command.py", line 36, in send_command
    scrapli_conn = task.host.get_connection("scrapli", task.nornir.config)
  File "/home/ipvzero/Nornir/.venv/lib/python3.10/site-packages/nornir/core/inventory.py", line 494, in get_connection
    self.open_connection(
  File "/home/ipvzero/Nornir/.venv/lib/python3.10/site-packages/nornir/core/inventory.py", line 546, in open_connection
    conn_obj.open(
  File "/home/ipvzero/Nornir/.venv/lib/python3.10/site-packages/nornir_scrapli/connection.py", line 105, in open
    connection.open()
  File "/home/ipvzero/Nornir/.venv/lib/python3.10/site-packages/scrapli/driver/base/sync_driver.py", line 88, in open
    self.channel.channel_authenticate_ssh(
  File "/home/ipvzero/Nornir/.venv/lib/python3.10/site-packages/scrapli/decorators.py", line 216, in decorate
    return _multiprocessing_timeout(
  File "/home/ipvzero/Nornir/.venv/lib/python3.10/site-packages/scrapli/decorators.py", line 113, in _multiprocessing_timeout
    return future.result()
  File "/usr/lib/python3.10/concurrent/futures/_base.py", line 451, in result
    return self.__get_result()
  File "/usr/lib/python3.10/concurrent/futures/_base.py", line 403, in __get_result
    raise self._exception
  File "/usr/lib/python3.10/concurrent/futures/thread.py", line 58, in run
    result = self.fn(*self.args, **self.kwargs)
  File "/home/ipvzero/Nornir/.venv/lib/python3.10/site-packages/scrapli/channel/sync_channel.py", line 290, in channel_authenticate_ssh
    self._ssh_message_handler(output=authenticate_buf)
  File "/home/ipvzero/Nornir/.venv/lib/python3.10/site-packages/scrapli/channel/base_channel.py", line 432, in _ssh_message_handler
    raise ScrapliAuthenticationFailed(msg)
scrapli.exceptions.ScrapliAuthenticationFailed: No route to host

2023-02-20 21:20:09,401 - nornir.core.task -    ERROR -      start() - Host 'R2': task 'get_ip' failed with traceback:
Traceback (most recent call last):
  File "/home/ipvzero/Nornir/.venv/lib/python3.10/site-packages/nornir/core/task.py", line 99, in start
    r = self.task(self, **self.params)
  File "/home/ipvzero/Nornir/Tools/pinghunter.py", line 12, in get_ip
    result = task.run(task=send_command, command="show ip interface brief")
  File "/home/ipvzero/Nornir/.venv/lib/python3.10/site-packages/nornir/core/task.py", line 174, in run
    raise NornirSubTaskError(task=run_task, result=r)
nornir.core.exceptions.NornirSubTaskError: Subtask: send_command (failed)


2023-02-20 21:21:30,498 -  nornir.core -     INFO -        run() - Running task 'get_ip' with args {} on 7 hosts
2023-02-20 21:21:33,624 - nornir.core.task -    ERROR -      start() - Host 'R2': task 'send_command' failed with traceback:
Traceback (most recent call last):
  File "/home/ipvzero/Nornir/.venv/lib/python3.10/site-packages/nornir/core/task.py", line 99, in start
    r = self.task(self, **self.params)
  File "/home/ipvzero/Nornir/.venv/lib/python3.10/site-packages/nornir_scrapli/tasks/core/send_command.py", line 36, in send_command
    scrapli_conn = task.host.get_connection("scrapli", task.nornir.config)
  File "/home/ipvzero/Nornir/.venv/lib/python3.10/site-packages/nornir/core/inventory.py", line 494, in get_connection
    self.open_connection(
  File "/home/ipvzero/Nornir/.venv/lib/python3.10/site-packages/nornir/core/inventory.py", line 546, in open_connection
    conn_obj.open(
  File "/home/ipvzero/Nornir/.venv/lib/python3.10/site-packages/nornir_scrapli/connection.py", line 105, in open
    connection.open()
  File "/home/ipvzero/Nornir/.venv/lib/python3.10/site-packages/scrapli/driver/base/sync_driver.py", line 88, in open
    self.channel.channel_authenticate_ssh(
  File "/home/ipvzero/Nornir/.venv/lib/python3.10/site-packages/scrapli/decorators.py", line 216, in decorate
    return _multiprocessing_timeout(
  File "/home/ipvzero/Nornir/.venv/lib/python3.10/site-packages/scrapli/decorators.py", line 113, in _multiprocessing_timeout
    return future.result()
  File "/usr/lib/python3.10/concurrent/futures/_base.py", line 451, in result
    return self.__get_result()
  File "/usr/lib/python3.10/concurrent/futures/_base.py", line 403, in __get_result
    raise self._exception
  File "/usr/lib/python3.10/concurrent/futures/thread.py", line 58, in run
    result = self.fn(*self.args, **self.kwargs)
  File "/home/ipvzero/Nornir/.venv/lib/python3.10/site-packages/scrapli/channel/sync_channel.py", line 290, in channel_authenticate_ssh
    self._ssh_message_handler(output=authenticate_buf)
  File "/home/ipvzero/Nornir/.venv/lib/python3.10/site-packages/scrapli/channel/base_channel.py", line 432, in _ssh_message_handler
    raise ScrapliAuthenticationFailed(msg)
scrapli.exceptions.ScrapliAuthenticationFailed: No route to host

2023-02-20 21:21:33,625 - nornir.core.task -    ERROR -      start() - Host 'R2': task 'get_ip' failed with traceback:
Traceback (most recent call last):
  File "/home/ipvzero/Nornir/.venv/lib/python3.10/site-packages/nornir/core/task.py", line 99, in start
    r = self.task(self, **self.params)
  File "/home/ipvzero/Nornir/Tools/pinghunter.py", line 12, in get_ip
    result = task.run(task=send_command, command="show ip interface brief")
  File "/home/ipvzero/Nornir/.venv/lib/python3.10/site-packages/nornir/core/task.py", line 174, in run
    raise NornirSubTaskError(task=run_task, result=r)
nornir.core.exceptions.NornirSubTaskError: Subtask: send_command (failed)


2023-02-20 21:22:18,836 -  nornir.core -     INFO -        run() - Running task 'get_ip' with args {} on 7 hosts
2023-02-20 21:22:21,945 - nornir.core.task -    ERROR -      start() - Host 'R2': task 'send_command' failed with traceback:
Traceback (most recent call last):
  File "/home/ipvzero/Nornir/.venv/lib/python3.10/site-packages/nornir/core/task.py", line 99, in start
    r = self.task(self, **self.params)
  File "/home/ipvzero/Nornir/.venv/lib/python3.10/site-packages/nornir_scrapli/tasks/core/send_command.py", line 36, in send_command
    scrapli_conn = task.host.get_connection("scrapli", task.nornir.config)
  File "/home/ipvzero/Nornir/.venv/lib/python3.10/site-packages/nornir/core/inventory.py", line 494, in get_connection
    self.open_connection(
  File "/home/ipvzero/Nornir/.venv/lib/python3.10/site-packages/nornir/core/inventory.py", line 546, in open_connection
    conn_obj.open(
  File "/home/ipvzero/Nornir/.venv/lib/python3.10/site-packages/nornir_scrapli/connection.py", line 105, in open
    connection.open()
  File "/home/ipvzero/Nornir/.venv/lib/python3.10/site-packages/scrapli/driver/base/sync_driver.py", line 88, in open
    self.channel.channel_authenticate_ssh(
  File "/home/ipvzero/Nornir/.venv/lib/python3.10/site-packages/scrapli/decorators.py", line 216, in decorate
    return _multiprocessing_timeout(
  File "/home/ipvzero/Nornir/.venv/lib/python3.10/site-packages/scrapli/decorators.py", line 113, in _multiprocessing_timeout
    return future.result()
  File "/usr/lib/python3.10/concurrent/futures/_base.py", line 451, in result
    return self.__get_result()
  File "/usr/lib/python3.10/concurrent/futures/_base.py", line 403, in __get_result
    raise self._exception
  File "/usr/lib/python3.10/concurrent/futures/thread.py", line 58, in run
    result = self.fn(*self.args, **self.kwargs)
  File "/home/ipvzero/Nornir/.venv/lib/python3.10/site-packages/scrapli/channel/sync_channel.py", line 290, in channel_authenticate_ssh
    self._ssh_message_handler(output=authenticate_buf)
  File "/home/ipvzero/Nornir/.venv/lib/python3.10/site-packages/scrapli/channel/base_channel.py", line 432, in _ssh_message_handler
    raise ScrapliAuthenticationFailed(msg)
scrapli.exceptions.ScrapliAuthenticationFailed: No route to host

2023-02-20 21:22:21,946 - nornir.core.task -    ERROR -      start() - Host 'R2': task 'get_ip' failed with traceback:
Traceback (most recent call last):
  File "/home/ipvzero/Nornir/.venv/lib/python3.10/site-packages/nornir/core/task.py", line 99, in start
    r = self.task(self, **self.params)
  File "/home/ipvzero/Nornir/Tools/pinghunter.py", line 12, in get_ip
    result = task.run(task=send_command, command="show ip interface brief")
  File "/home/ipvzero/Nornir/.venv/lib/python3.10/site-packages/nornir/core/task.py", line 174, in run
    raise NornirSubTaskError(task=run_task, result=r)
nornir.core.exceptions.NornirSubTaskError: Subtask: send_command (failed)


2023-02-20 21:23:20,787 -  nornir.core -     INFO -        run() - Running task 'get_ip' with args {} on 7 hosts
2023-02-20 21:26:02,983 -  nornir.core -     INFO -        run() - Running task 'get_ip' with args {} on 7 hosts
2023-02-20 21:26:05,855 -  nornir.core -     INFO -        run() - Running task 'ping_test' with args {} on 7 hosts
2023-02-20 21:28:55,706 -  nornir.core -     INFO -        run() - Running task 'get_ip' with args {} on 4 hosts
2023-02-20 21:28:57,809 -  nornir.core -     INFO -        run() - Running task 'ping_test' with args {} on 4 hosts
2023-02-20 21:33:39,840 -  nornir.core -     INFO -        run() - Running task 'get_ip' with args {} on 4 hosts
2023-02-20 21:33:41,740 -  nornir.core -     INFO -        run() - Running task 'ping_test' with args {} on 4 hosts
2023-02-20 21:33:41,946 - nornir.core.task -    ERROR -      start() - Host 'R1': task 'ping_test' failed with traceback:
Traceback (most recent call last):
  File "/home/ipvzero/Nornir/.venv/lib/python3.10/site-packages/nornir/core/task.py", line 99, in start
    r = self.task(self, **self.params)
  File "/home/ipvzero/Nornir/Tools/pinghunter.py", line 25, in ping_test
    if not "!!!" in reponse:
NameError: name 'reponse' is not defined

2023-02-20 21:33:41,998 - nornir.core.task -    ERROR -      start() - Host 'R2': task 'ping_test' failed with traceback:
Traceback (most recent call last):
  File "/home/ipvzero/Nornir/.venv/lib/python3.10/site-packages/nornir/core/task.py", line 99, in start
    r = self.task(self, **self.params)
  File "/home/ipvzero/Nornir/Tools/pinghunter.py", line 25, in ping_test
    if not "!!!" in reponse:
NameError: name 'reponse' is not defined

2023-02-20 21:33:42,027 - nornir.core.task -    ERROR -      start() - Host 'R4': task 'ping_test' failed with traceback:
Traceback (most recent call last):
  File "/home/ipvzero/Nornir/.venv/lib/python3.10/site-packages/nornir/core/task.py", line 99, in start
    r = self.task(self, **self.params)
  File "/home/ipvzero/Nornir/Tools/pinghunter.py", line 25, in ping_test
    if not "!!!" in reponse:
NameError: name 'reponse' is not defined

2023-02-20 21:33:51,999 - nornir.core.task -    ERROR -      start() - Host 'R3': task 'ping_test' failed with traceback:
Traceback (most recent call last):
  File "/home/ipvzero/Nornir/.venv/lib/python3.10/site-packages/nornir/core/task.py", line 99, in start
    r = self.task(self, **self.params)
  File "/home/ipvzero/Nornir/Tools/pinghunter.py", line 25, in ping_test
    if not "!!!" in reponse:
NameError: name 'reponse' is not defined

2023-02-20 21:37:11,493 -  nornir.core -     INFO -        run() - Running task 'get_ip' with args {} on 4 hosts
2023-02-20 21:37:13,545 -  nornir.core -     INFO -        run() - Running task 'ping_test' with args {} on 4 hosts
2023-02-20 21:37:13,841 - nornir.core.task -    ERROR -      start() - Host 'R1': task 'ping_test' failed with traceback:
Traceback (most recent call last):
  File "/home/ipvzero/Nornir/.venv/lib/python3.10/site-packages/nornir/core/task.py", line 99, in start
    r = self.task(self, **self.params)
  File "/home/ipvzero/Nornir/Tools/pinghunter.py", line 25, in ping_test
    if not "!!!" in reponse:
NameError: name 'reponse' is not defined

2023-02-20 21:37:13,901 - nornir.core.task -    ERROR -      start() - Host 'R4': task 'ping_test' failed with traceback:
Traceback (most recent call last):
  File "/home/ipvzero/Nornir/.venv/lib/python3.10/site-packages/nornir/core/task.py", line 99, in start
    r = self.task(self, **self.params)
  File "/home/ipvzero/Nornir/Tools/pinghunter.py", line 25, in ping_test
    if not "!!!" in reponse:
NameError: name 'reponse' is not defined

2023-02-20 21:37:13,918 - nornir.core.task -    ERROR -      start() - Host 'R2': task 'ping_test' failed with traceback:
Traceback (most recent call last):
  File "/home/ipvzero/Nornir/.venv/lib/python3.10/site-packages/nornir/core/task.py", line 99, in start
    r = self.task(self, **self.params)
  File "/home/ipvzero/Nornir/Tools/pinghunter.py", line 25, in ping_test
    if not "!!!" in reponse:
NameError: name 'reponse' is not defined

2023-02-20 21:37:23,970 - nornir.core.task -    ERROR -      start() - Host 'R3': task 'ping_test' failed with traceback:
Traceback (most recent call last):
  File "/home/ipvzero/Nornir/.venv/lib/python3.10/site-packages/nornir/core/task.py", line 99, in start
    r = self.task(self, **self.params)
  File "/home/ipvzero/Nornir/Tools/pinghunter.py", line 25, in ping_test
    if not "!!!" in reponse:
NameError: name 'reponse' is not defined

2023-02-21 04:50:26,768 -  nornir.core -     INFO -        run() - Running task 'get_ip' with args {} on 4 hosts
2023-02-21 04:50:29,166 -  nornir.core -     INFO -        run() - Running task 'ping_test' with args {} on 4 hosts
2023-02-22 04:43:36,225 -  nornir.core -     INFO -        run() - Running task 'testconf' with args {} on 2 hosts
2023-02-22 04:43:36,612 - nornir.core.task -    ERROR -      start() - Host 'R1': task 'testconf' failed with traceback:
Traceback (most recent call last):
  File "/home/ipvzero/Nornir/.venv/lib/python3.10/site-packages/urllib3/connection.py", line 174, in _new_conn
    conn = connection.create_connection(
  File "/home/ipvzero/Nornir/.venv/lib/python3.10/site-packages/urllib3/util/connection.py", line 95, in create_connection
    raise err
  File "/home/ipvzero/Nornir/.venv/lib/python3.10/site-packages/urllib3/util/connection.py", line 85, in create_connection
    sock.connect(sa)
ConnectionRefusedError: [Errno 111] Connection refused

During handling of the above exception, another exception occurred:

Traceback (most recent call last):
  File "/home/ipvzero/Nornir/.venv/lib/python3.10/site-packages/urllib3/connectionpool.py", line 703, in urlopen
    httplib_response = self._make_request(
  File "/home/ipvzero/Nornir/.venv/lib/python3.10/site-packages/urllib3/connectionpool.py", line 386, in _make_request
    self._validate_conn(conn)
  File "/home/ipvzero/Nornir/.venv/lib/python3.10/site-packages/urllib3/connectionpool.py", line 1042, in _validate_conn
    conn.connect()
  File "/home/ipvzero/Nornir/.venv/lib/python3.10/site-packages/urllib3/connection.py", line 358, in connect
    self.sock = conn = self._new_conn()
  File "/home/ipvzero/Nornir/.venv/lib/python3.10/site-packages/urllib3/connection.py", line 186, in _new_conn
    raise NewConnectionError(
urllib3.exceptions.NewConnectionError: <urllib3.connection.HTTPSConnection object at 0x7f66e7765f90>: Failed to establish a new connection: [Errno 111] Connection refused

During handling of the above exception, another exception occurred:

Traceback (most recent call last):
  File "/home/ipvzero/Nornir/.venv/lib/python3.10/site-packages/requests/adapters.py", line 489, in send
    resp = conn.urlopen(
  File "/home/ipvzero/Nornir/.venv/lib/python3.10/site-packages/urllib3/connectionpool.py", line 787, in urlopen
    retries = retries.increment(
  File "/home/ipvzero/Nornir/.venv/lib/python3.10/site-packages/urllib3/util/retry.py", line 592, in increment
    raise MaxRetryError(_pool, url, error or ResponseError(cause))
urllib3.exceptions.MaxRetryError: HTTPSConnectionPool(host='192.168.179.130', port=443): Max retries exceeded with url: /restconf/data/ospf-oper-data (Caused by NewConnectionError('<urllib3.connection.HTTPSConnection object at 0x7f66e7765f90>: Failed to establish a new connection: [Errno 111] Connection refused'))

During handling of the above exception, another exception occurred:

Traceback (most recent call last):
  File "/home/ipvzero/Nornir/.venv/lib/python3.10/site-packages/nornir/core/task.py", line 99, in start
    r = self.task(self, **self.params)
  File "/home/ipvzero/Nornir/Tools/requests-test.py", line 12, in testconf
    response = requests.get(url=url, headers=headers, auth=(f"{task.host.username}", f"{task.host.password}"), verify=False)
  File "/home/ipvzero/Nornir/.venv/lib/python3.10/site-packages/requests/api.py", line 73, in get
    return request("get", url, params=params, **kwargs)
  File "/home/ipvzero/Nornir/.venv/lib/python3.10/site-packages/requests/api.py", line 59, in request
    return session.request(method=method, url=url, **kwargs)
  File "/home/ipvzero/Nornir/.venv/lib/python3.10/site-packages/requests/sessions.py", line 587, in request
    resp = self.send(prep, **send_kwargs)
  File "/home/ipvzero/Nornir/.venv/lib/python3.10/site-packages/requests/sessions.py", line 701, in send
    r = adapter.send(request, **kwargs)
  File "/home/ipvzero/Nornir/.venv/lib/python3.10/site-packages/requests/adapters.py", line 565, in send
    raise ConnectionError(e, request=request)
requests.exceptions.ConnectionError: HTTPSConnectionPool(host='192.168.179.130', port=443): Max retries exceeded with url: /restconf/data/ospf-oper-data (Caused by NewConnectionError('<urllib3.connection.HTTPSConnection object at 0x7f66e7765f90>: Failed to establish a new connection: [Errno 111] Connection refused'))

2023-02-22 04:43:36,612 - nornir.core.task -    ERROR -      start() - Host 'R2': task 'testconf' failed with traceback:
Traceback (most recent call last):
  File "/home/ipvzero/Nornir/.venv/lib/python3.10/site-packages/urllib3/connection.py", line 174, in _new_conn
    conn = connection.create_connection(
  File "/home/ipvzero/Nornir/.venv/lib/python3.10/site-packages/urllib3/util/connection.py", line 95, in create_connection
    raise err
  File "/home/ipvzero/Nornir/.venv/lib/python3.10/site-packages/urllib3/util/connection.py", line 85, in create_connection
    sock.connect(sa)
ConnectionRefusedError: [Errno 111] Connection refused

During handling of the above exception, another exception occurred:

Traceback (most recent call last):
  File "/home/ipvzero/Nornir/.venv/lib/python3.10/site-packages/urllib3/connectionpool.py", line 703, in urlopen
    httplib_response = self._make_request(
  File "/home/ipvzero/Nornir/.venv/lib/python3.10/site-packages/urllib3/connectionpool.py", line 386, in _make_request
    self._validate_conn(conn)
  File "/home/ipvzero/Nornir/.venv/lib/python3.10/site-packages/urllib3/connectionpool.py", line 1042, in _validate_conn
    conn.connect()
  File "/home/ipvzero/Nornir/.venv/lib/python3.10/site-packages/urllib3/connection.py", line 358, in connect
    self.sock = conn = self._new_conn()
  File "/home/ipvzero/Nornir/.venv/lib/python3.10/site-packages/urllib3/connection.py", line 186, in _new_conn
    raise NewConnectionError(
urllib3.exceptions.NewConnectionError: <urllib3.connection.HTTPSConnection object at 0x7f66e77672e0>: Failed to establish a new connection: [Errno 111] Connection refused

During handling of the above exception, another exception occurred:

Traceback (most recent call last):
  File "/home/ipvzero/Nornir/.venv/lib/python3.10/site-packages/requests/adapters.py", line 489, in send
    resp = conn.urlopen(
  File "/home/ipvzero/Nornir/.venv/lib/python3.10/site-packages/urllib3/connectionpool.py", line 787, in urlopen
    retries = retries.increment(
  File "/home/ipvzero/Nornir/.venv/lib/python3.10/site-packages/urllib3/util/retry.py", line 592, in increment
    raise MaxRetryError(_pool, url, error or ResponseError(cause))
urllib3.exceptions.MaxRetryError: HTTPSConnectionPool(host='192.168.179.131', port=443): Max retries exceeded with url: /restconf/data/ospf-oper-data (Caused by NewConnectionError('<urllib3.connection.HTTPSConnection object at 0x7f66e77672e0>: Failed to establish a new connection: [Errno 111] Connection refused'))

During handling of the above exception, another exception occurred:

Traceback (most recent call last):
  File "/home/ipvzero/Nornir/.venv/lib/python3.10/site-packages/nornir/core/task.py", line 99, in start
    r = self.task(self, **self.params)
  File "/home/ipvzero/Nornir/Tools/requests-test.py", line 12, in testconf
    response = requests.get(url=url, headers=headers, auth=(f"{task.host.username}", f"{task.host.password}"), verify=False)
  File "/home/ipvzero/Nornir/.venv/lib/python3.10/site-packages/requests/api.py", line 73, in get
    return request("get", url, params=params, **kwargs)
  File "/home/ipvzero/Nornir/.venv/lib/python3.10/site-packages/requests/api.py", line 59, in request
    return session.request(method=method, url=url, **kwargs)
  File "/home/ipvzero/Nornir/.venv/lib/python3.10/site-packages/requests/sessions.py", line 587, in request
    resp = self.send(prep, **send_kwargs)
  File "/home/ipvzero/Nornir/.venv/lib/python3.10/site-packages/requests/sessions.py", line 701, in send
    r = adapter.send(request, **kwargs)
  File "/home/ipvzero/Nornir/.venv/lib/python3.10/site-packages/requests/adapters.py", line 565, in send
    raise ConnectionError(e, request=request)
requests.exceptions.ConnectionError: HTTPSConnectionPool(host='192.168.179.131', port=443): Max retries exceeded with url: /restconf/data/ospf-oper-data (Caused by NewConnectionError('<urllib3.connection.HTTPSConnection object at 0x7f66e77672e0>: Failed to establish a new connection: [Errno 111] Connection refused'))

2023-02-22 04:47:21,009 -  nornir.core -     INFO -        run() - Running task 'testconf' with args {} on 2 hosts
2023-02-22 04:47:21,019 - nornir.core.task -    ERROR -      start() - Host 'R1': task 'testconf' failed with traceback:
Traceback (most recent call last):
  File "/home/ipvzero/Nornir/.venv/lib/python3.10/site-packages/urllib3/connection.py", line 174, in _new_conn
    conn = connection.create_connection(
  File "/home/ipvzero/Nornir/.venv/lib/python3.10/site-packages/urllib3/util/connection.py", line 95, in create_connection
    raise err
  File "/home/ipvzero/Nornir/.venv/lib/python3.10/site-packages/urllib3/util/connection.py", line 85, in create_connection
    sock.connect(sa)
ConnectionRefusedError: [Errno 111] Connection refused

During handling of the above exception, another exception occurred:

Traceback (most recent call last):
  File "/home/ipvzero/Nornir/.venv/lib/python3.10/site-packages/urllib3/connectionpool.py", line 703, in urlopen
    httplib_response = self._make_request(
  File "/home/ipvzero/Nornir/.venv/lib/python3.10/site-packages/urllib3/connectionpool.py", line 386, in _make_request
    self._validate_conn(conn)
  File "/home/ipvzero/Nornir/.venv/lib/python3.10/site-packages/urllib3/connectionpool.py", line 1042, in _validate_conn
    conn.connect()
  File "/home/ipvzero/Nornir/.venv/lib/python3.10/site-packages/urllib3/connection.py", line 358, in connect
    self.sock = conn = self._new_conn()
  File "/home/ipvzero/Nornir/.venv/lib/python3.10/site-packages/urllib3/connection.py", line 186, in _new_conn
    raise NewConnectionError(
urllib3.exceptions.NewConnectionError: <urllib3.connection.HTTPSConnection object at 0x7f22e5365f90>: Failed to establish a new connection: [Errno 111] Connection refused

During handling of the above exception, another exception occurred:

Traceback (most recent call last):
  File "/home/ipvzero/Nornir/.venv/lib/python3.10/site-packages/requests/adapters.py", line 489, in send
    resp = conn.urlopen(
  File "/home/ipvzero/Nornir/.venv/lib/python3.10/site-packages/urllib3/connectionpool.py", line 787, in urlopen
    retries = retries.increment(
  File "/home/ipvzero/Nornir/.venv/lib/python3.10/site-packages/urllib3/util/retry.py", line 592, in increment
    raise MaxRetryError(_pool, url, error or ResponseError(cause))
urllib3.exceptions.MaxRetryError: HTTPSConnectionPool(host='192.168.179.130', port=443): Max retries exceeded with url: /restconf/data/ospf-oper-data (Caused by NewConnectionError('<urllib3.connection.HTTPSConnection object at 0x7f22e5365f90>: Failed to establish a new connection: [Errno 111] Connection refused'))

During handling of the above exception, another exception occurred:

Traceback (most recent call last):
  File "/home/ipvzero/Nornir/.venv/lib/python3.10/site-packages/nornir/core/task.py", line 99, in start
    r = self.task(self, **self.params)
  File "/home/ipvzero/Nornir/Tools/requests-test.py", line 12, in testconf
    response = requests.get(url=url, headers=headers, auth=(f"{task.host.username}", f"{task.host.password}"), verify=False)
  File "/home/ipvzero/Nornir/.venv/lib/python3.10/site-packages/requests/api.py", line 73, in get
    return request("get", url, params=params, **kwargs)
  File "/home/ipvzero/Nornir/.venv/lib/python3.10/site-packages/requests/api.py", line 59, in request
    return session.request(method=method, url=url, **kwargs)
  File "/home/ipvzero/Nornir/.venv/lib/python3.10/site-packages/requests/sessions.py", line 587, in request
    resp = self.send(prep, **send_kwargs)
  File "/home/ipvzero/Nornir/.venv/lib/python3.10/site-packages/requests/sessions.py", line 701, in send
    r = adapter.send(request, **kwargs)
  File "/home/ipvzero/Nornir/.venv/lib/python3.10/site-packages/requests/adapters.py", line 565, in send
    raise ConnectionError(e, request=request)
requests.exceptions.ConnectionError: HTTPSConnectionPool(host='192.168.179.130', port=443): Max retries exceeded with url: /restconf/data/ospf-oper-data (Caused by NewConnectionError('<urllib3.connection.HTTPSConnection object at 0x7f22e5365f90>: Failed to establish a new connection: [Errno 111] Connection refused'))

2023-02-22 04:47:21,023 - nornir.core.task -    ERROR -      start() - Host 'R3': task 'testconf' failed with traceback:
Traceback (most recent call last):
  File "/home/ipvzero/Nornir/.venv/lib/python3.10/site-packages/urllib3/connection.py", line 174, in _new_conn
    conn = connection.create_connection(
  File "/home/ipvzero/Nornir/.venv/lib/python3.10/site-packages/urllib3/util/connection.py", line 95, in create_connection
    raise err
  File "/home/ipvzero/Nornir/.venv/lib/python3.10/site-packages/urllib3/util/connection.py", line 85, in create_connection
    sock.connect(sa)
ConnectionRefusedError: [Errno 111] Connection refused

During handling of the above exception, another exception occurred:

Traceback (most recent call last):
  File "/home/ipvzero/Nornir/.venv/lib/python3.10/site-packages/urllib3/connectionpool.py", line 703, in urlopen
    httplib_response = self._make_request(
  File "/home/ipvzero/Nornir/.venv/lib/python3.10/site-packages/urllib3/connectionpool.py", line 386, in _make_request
    self._validate_conn(conn)
  File "/home/ipvzero/Nornir/.venv/lib/python3.10/site-packages/urllib3/connectionpool.py", line 1042, in _validate_conn
    conn.connect()
  File "/home/ipvzero/Nornir/.venv/lib/python3.10/site-packages/urllib3/connection.py", line 358, in connect
    self.sock = conn = self._new_conn()
  File "/home/ipvzero/Nornir/.venv/lib/python3.10/site-packages/urllib3/connection.py", line 186, in _new_conn
    raise NewConnectionError(
urllib3.exceptions.NewConnectionError: <urllib3.connection.HTTPSConnection object at 0x7f22e53672e0>: Failed to establish a new connection: [Errno 111] Connection refused

During handling of the above exception, another exception occurred:

Traceback (most recent call last):
  File "/home/ipvzero/Nornir/.venv/lib/python3.10/site-packages/requests/adapters.py", line 489, in send
    resp = conn.urlopen(
  File "/home/ipvzero/Nornir/.venv/lib/python3.10/site-packages/urllib3/connectionpool.py", line 787, in urlopen
    retries = retries.increment(
  File "/home/ipvzero/Nornir/.venv/lib/python3.10/site-packages/urllib3/util/retry.py", line 592, in increment
    raise MaxRetryError(_pool, url, error or ResponseError(cause))
urllib3.exceptions.MaxRetryError: HTTPSConnectionPool(host='192.168.179.132', port=443): Max retries exceeded with url: /restconf/data/ospf-oper-data (Caused by NewConnectionError('<urllib3.connection.HTTPSConnection object at 0x7f22e53672e0>: Failed to establish a new connection: [Errno 111] Connection refused'))

During handling of the above exception, another exception occurred:

Traceback (most recent call last):
  File "/home/ipvzero/Nornir/.venv/lib/python3.10/site-packages/nornir/core/task.py", line 99, in start
    r = self.task(self, **self.params)
  File "/home/ipvzero/Nornir/Tools/requests-test.py", line 12, in testconf
    response = requests.get(url=url, headers=headers, auth=(f"{task.host.username}", f"{task.host.password}"), verify=False)
  File "/home/ipvzero/Nornir/.venv/lib/python3.10/site-packages/requests/api.py", line 73, in get
    return request("get", url, params=params, **kwargs)
  File "/home/ipvzero/Nornir/.venv/lib/python3.10/site-packages/requests/api.py", line 59, in request
    return session.request(method=method, url=url, **kwargs)
  File "/home/ipvzero/Nornir/.venv/lib/python3.10/site-packages/requests/sessions.py", line 587, in request
    resp = self.send(prep, **send_kwargs)
  File "/home/ipvzero/Nornir/.venv/lib/python3.10/site-packages/requests/sessions.py", line 701, in send
    r = adapter.send(request, **kwargs)
  File "/home/ipvzero/Nornir/.venv/lib/python3.10/site-packages/requests/adapters.py", line 565, in send
    raise ConnectionError(e, request=request)
requests.exceptions.ConnectionError: HTTPSConnectionPool(host='192.168.179.132', port=443): Max retries exceeded with url: /restconf/data/ospf-oper-data (Caused by NewConnectionError('<urllib3.connection.HTTPSConnection object at 0x7f22e53672e0>: Failed to establish a new connection: [Errno 111] Connection refused'))

2023-02-22 05:21:28,704 -  nornir.core -     INFO -        run() - Running task 'testconf' with args {} on 2 hosts
2023-02-22 05:21:47,128 - nornir.core.task -    ERROR -      start() - Host 'R3': task 'testconf' failed with traceback:
Traceback (most recent call last):
  File "/home/ipvzero/Nornir/.venv/lib/python3.10/site-packages/urllib3/connection.py", line 174, in _new_conn
    conn = connection.create_connection(
  File "/home/ipvzero/Nornir/.venv/lib/python3.10/site-packages/urllib3/util/connection.py", line 95, in create_connection
    raise err
  File "/home/ipvzero/Nornir/.venv/lib/python3.10/site-packages/urllib3/util/connection.py", line 85, in create_connection
    sock.connect(sa)
OSError: [Errno 113] No route to host

During handling of the above exception, another exception occurred:

Traceback (most recent call last):
  File "/home/ipvzero/Nornir/.venv/lib/python3.10/site-packages/urllib3/connectionpool.py", line 703, in urlopen
    httplib_response = self._make_request(
  File "/home/ipvzero/Nornir/.venv/lib/python3.10/site-packages/urllib3/connectionpool.py", line 386, in _make_request
    self._validate_conn(conn)
  File "/home/ipvzero/Nornir/.venv/lib/python3.10/site-packages/urllib3/connectionpool.py", line 1042, in _validate_conn
    conn.connect()
  File "/home/ipvzero/Nornir/.venv/lib/python3.10/site-packages/urllib3/connection.py", line 358, in connect
    self.sock = conn = self._new_conn()
  File "/home/ipvzero/Nornir/.venv/lib/python3.10/site-packages/urllib3/connection.py", line 186, in _new_conn
    raise NewConnectionError(
urllib3.exceptions.NewConnectionError: <urllib3.connection.HTTPSConnection object at 0x7f08b01732e0>: Failed to establish a new connection: [Errno 113] No route to host

During handling of the above exception, another exception occurred:

Traceback (most recent call last):
  File "/home/ipvzero/Nornir/.venv/lib/python3.10/site-packages/requests/adapters.py", line 489, in send
    resp = conn.urlopen(
  File "/home/ipvzero/Nornir/.venv/lib/python3.10/site-packages/urllib3/connectionpool.py", line 787, in urlopen
    retries = retries.increment(
  File "/home/ipvzero/Nornir/.venv/lib/python3.10/site-packages/urllib3/util/retry.py", line 592, in increment
    raise MaxRetryError(_pool, url, error or ResponseError(cause))
urllib3.exceptions.MaxRetryError: HTTPSConnectionPool(host='192.168.179.132', port=443): Max retries exceeded with url: /restconf/data/ospf-oper-data (Caused by NewConnectionError('<urllib3.connection.HTTPSConnection object at 0x7f08b01732e0>: Failed to establish a new connection: [Errno 113] No route to host'))

During handling of the above exception, another exception occurred:

Traceback (most recent call last):
  File "/home/ipvzero/Nornir/.venv/lib/python3.10/site-packages/nornir/core/task.py", line 99, in start
    r = self.task(self, **self.params)
  File "/home/ipvzero/Nornir/Tools/requests-test.py", line 12, in testconf
    response = requests.get(url=url, headers=headers, auth=(f"{task.host.username}", f"{task.host.password}"), verify=False)
  File "/home/ipvzero/Nornir/.venv/lib/python3.10/site-packages/requests/api.py", line 73, in get
    return request("get", url, params=params, **kwargs)
  File "/home/ipvzero/Nornir/.venv/lib/python3.10/site-packages/requests/api.py", line 59, in request
    return session.request(method=method, url=url, **kwargs)
  File "/home/ipvzero/Nornir/.venv/lib/python3.10/site-packages/requests/sessions.py", line 587, in request
    resp = self.send(prep, **send_kwargs)
  File "/home/ipvzero/Nornir/.venv/lib/python3.10/site-packages/requests/sessions.py", line 701, in send
    r = adapter.send(request, **kwargs)
  File "/home/ipvzero/Nornir/.venv/lib/python3.10/site-packages/requests/adapters.py", line 565, in send
    raise ConnectionError(e, request=request)
requests.exceptions.ConnectionError: HTTPSConnectionPool(host='192.168.179.132', port=443): Max retries exceeded with url: /restconf/data/ospf-oper-data (Caused by NewConnectionError('<urllib3.connection.HTTPSConnection object at 0x7f08b01732e0>: Failed to establish a new connection: [Errno 113] No route to host'))

2023-02-22 05:22:58,241 -  nornir.core -     INFO -        run() - Running task 'testconf' with args {} on 2 hosts
2023-02-22 05:29:40,711 -  nornir.core -     INFO -        run() - Running task 'testconf' with args {} on 2 hosts
2023-02-22 05:30:25,144 -  nornir.core -     INFO -        run() - Running task 'testconf' with args {} on 2 hosts
2023-02-22 05:32:25,545 -  nornir.core -     INFO -        run() - Running task 'testconf' with args {} on 2 hosts
2023-02-22 05:37:41,794 -  nornir.core -     INFO -        run() - Running task 'get_ospf' with args {} on 2 hosts
2023-02-22 05:37:41,795 - nornir.core.task -    ERROR -      start() - Host 'CSR1': task 'get_ospf' failed with traceback:
Traceback (most recent call last):
  File "/home/ipvzero/Nornir/.venv/lib/python3.10/site-packages/nornir/core/task.py", line 99, in start
    r = self.task(self, **self.params)
  File "/home/ipvzero/Nornir/Tools/requests-test.py", line 13, in get_ospf
    ospf_send = requests.get(url=url, headers=headers, auth=(f"{task.host.username}", f"{task.host.password}"), verify=False)
NameError: name 'url' is not defined

2023-02-22 05:37:41,796 - nornir.core.task -    ERROR -      start() - Host 'CSR2': task 'get_ospf' failed with traceback:
Traceback (most recent call last):
  File "/home/ipvzero/Nornir/.venv/lib/python3.10/site-packages/nornir/core/task.py", line 99, in start
    r = self.task(self, **self.params)
  File "/home/ipvzero/Nornir/Tools/requests-test.py", line 13, in get_ospf
    ospf_send = requests.get(url=url, headers=headers, auth=(f"{task.host.username}", f"{task.host.password}"), verify=False)
NameError: name 'url' is not defined

2023-02-22 05:38:09,535 -  nornir.core -     INFO -        run() - Running task 'get_ospf' with args {} on 2 hosts
2023-02-22 05:39:30,935 -  nornir.core -     INFO -        run() - Running task 'get_ospf' with args {} on 2 hosts
2023-02-22 05:41:08,913 -  nornir.core -     INFO -        run() - Running task 'get_ospf' with args {} on 2 hosts
2023-02-22 05:46:42,263 -  nornir.core -     INFO -        run() - Running task 'get_ospf' with args {} on 2 hosts
2023-02-22 20:55:19,724 -  nornir.core -     INFO -        run() - Running task 'get_ospf' with args {} on 2 hosts
2023-02-22 21:12:40,167 -  nornir.core -     INFO -        run() - Running task 'get_ospf' with args {} on 2 hosts
2023-02-22 21:24:39,825 -  nornir.core -     INFO -        run() - Running task 'get_ospf' with args {} on 2 hosts
2023-02-22 21:26:12,613 -  nornir.core -     INFO -        run() - Running task 'get_ospf' with args {} on 2 hosts
2023-02-22 21:34:42,448 -  nornir.core -     INFO -        run() - Running task 'get_ospf' with args {} on 2 hosts
2023-02-22 21:39:04,780 -  nornir.core -     INFO -        run() - Running task 'get_ospf' with args {} on 2 hosts
2023-02-23 04:56:35,423 -  nornir.core -     INFO -        run() - Running task 'get_ospf' with args {} on 2 hosts
2023-02-23 04:56:36,233 - nornir.core.task -    ERROR -      start() - Host 'R2': task 'get_ospf' failed with traceback:
Traceback (most recent call last):
  File "/home/ipvzero/Nornir/.venv/lib/python3.10/site-packages/nornir/core/task.py", line 99, in start
    r = self.task(self, **self.params)
  File "/home/ipvzero/Nornir/Tools/requests-test.py", line 38, in get_ospf
    for instance in instances:
NameError: name 'instances' is not defined

2023-02-23 04:56:36,251 - nornir.core.task -    ERROR -      start() - Host 'R1': task 'get_ospf' failed with traceback:
Traceback (most recent call last):
  File "/home/ipvzero/Nornir/.venv/lib/python3.10/site-packages/nornir/core/task.py", line 99, in start
    r = self.task(self, **self.params)
  File "/home/ipvzero/Nornir/Tools/requests-test.py", line 38, in get_ospf
    for instance in instances:
NameError: name 'instances' is not defined

2023-02-23 04:56:59,603 -  nornir.core -     INFO -        run() - Running task 'get_ospf' with args {} on 2 hosts
2023-02-23 04:57:19,483 -  nornir.core -     INFO -        run() - Running task 'get_ospf' with args {} on 2 hosts
2023-02-23 05:04:33,291 -  nornir.core -     INFO -        run() - Running task 'get_ospf' with args {} on 2 hosts
2023-02-23 05:05:10,239 -  nornir.core -     INFO -        run() - Running task 'get_ospf' with args {} on 2 hosts
2023-02-23 05:05:40,490 -  nornir.core -     INFO -        run() - Running task 'get_ospf' with args {} on 2 hosts
2023-02-23 05:17:56,647 -  nornir.core -     INFO -        run() - Running task 'get_ospf' with args {} on 2 hosts
2023-02-23 05:19:40,054 -  nornir.core -     INFO -        run() - Running task 'get_ospf' with args {} on 2 hosts
2023-02-23 05:21:16,508 -  nornir.core -     INFO -        run() - Running task 'get_ospf' with args {} on 2 hosts
2023-02-23 05:21:59,395 -  nornir.core -     INFO -        run() - Running task 'get_ospf' with args {} on 2 hosts
2023-02-23 05:24:20,998 -  nornir.core -     INFO -        run() - Running task 'get_ospf' with args {} on 2 hosts
2023-02-23 05:25:43,588 -  nornir.core -     INFO -        run() - Running task 'get_ospf' with args {} on 2 hosts
2023-02-23 05:38:37,035 -  nornir.core -     INFO -        run() - Running task 'get_ospf' with args {} on 2 hosts
2023-02-23 05:38:37,831 -  nornir.core -     INFO -        run() - Running task 'get_cdp' with args {} on 2 hosts
2023-02-23 05:38:52,348 -  nornir.core -     INFO -        run() - Running task 'get_ospf' with args {} on 2 hosts
2023-02-23 05:38:52,960 -  nornir.core -     INFO -        run() - Running task 'get_cdp' with args {} on 2 hosts
2023-02-23 05:47:17,747 -  nornir.core -     INFO -        run() - Running task 'get_ospf' with args {} on 2 hosts
2023-02-23 05:47:18,685 -  nornir.core -     INFO -        run() - Running task 'get_cdp' with args {} on 2 hosts
2023-02-23 05:47:18,755 - nornir.core.task -    ERROR -      start() - Host 'R1': task 'get_cdp' failed with traceback:
Traceback (most recent call last):
  File "/home/ipvzero/Nornir/.venv/lib/python3.10/site-packages/nornir/core/task.py", line 99, in start
    r = self.task(self, **self.params)
  File "/home/ipvzero/Nornir/Tools/requests-test.py", line 68, in get_cdp
    for neighbor in neighbors:
NameError: name 'neighbors' is not defined

2023-02-23 05:47:18,756 - nornir.core.task -    ERROR -      start() - Host 'R2': task 'get_cdp' failed with traceback:
Traceback (most recent call last):
  File "/home/ipvzero/Nornir/.venv/lib/python3.10/site-packages/nornir/core/task.py", line 99, in start
    r = self.task(self, **self.params)
  File "/home/ipvzero/Nornir/Tools/requests-test.py", line 68, in get_cdp
    for neighbor in neighbors:
NameError: name 'neighbors' is not defined

2023-02-23 05:48:32,724 -  nornir.core -     INFO -        run() - Running task 'get_ospf' with args {} on 2 hosts
2023-02-23 05:48:33,356 -  nornir.core -     INFO -        run() - Running task 'get_cdp' with args {} on 2 hosts
2023-02-23 05:48:33,421 - nornir.core.task -    ERROR -      start() - Host 'R1': task 'get_cdp' failed with traceback:
Traceback (most recent call last):
  File "/home/ipvzero/Nornir/.venv/lib/python3.10/site-packages/nornir/core/task.py", line 99, in start
    r = self.task(self, **self.params)
  File "/home/ipvzero/Nornir/Tools/requests-test.py", line 68, in get_cdp
    for neighbor in neighbors:
NameError: name 'neighbors' is not defined

2023-02-23 05:48:33,426 - nornir.core.task -    ERROR -      start() - Host 'R2': task 'get_cdp' failed with traceback:
Traceback (most recent call last):
  File "/home/ipvzero/Nornir/.venv/lib/python3.10/site-packages/nornir/core/task.py", line 99, in start
    r = self.task(self, **self.params)
  File "/home/ipvzero/Nornir/Tools/requests-test.py", line 68, in get_cdp
    for neighbor in neighbors:
NameError: name 'neighbors' is not defined

2023-02-23 05:49:51,852 -  nornir.core -     INFO -        run() - Running task 'get_ospf' with args {} on 2 hosts
2023-02-23 05:49:52,431 -  nornir.core -     INFO -        run() - Running task 'get_cdp' with args {} on 2 hosts
2023-02-23 05:49:52,487 - nornir.core.task -    ERROR -      start() - Host 'R2': task 'get_cdp' failed with traceback:
Traceback (most recent call last):
  File "/home/ipvzero/Nornir/.venv/lib/python3.10/site-packages/nornir/core/task.py", line 99, in start
    r = self.task(self, **self.params)
  File "/home/ipvzero/Nornir/Tools/requests-test.py", line 71, in get_cdp
    port_id = neighbor["port_id"]
KeyError: 'port_id'

2023-02-23 05:49:52,494 - nornir.core.task -    ERROR -      start() - Host 'R1': task 'get_cdp' failed with traceback:
Traceback (most recent call last):
  File "/home/ipvzero/Nornir/.venv/lib/python3.10/site-packages/nornir/core/task.py", line 99, in start
    r = self.task(self, **self.params)
  File "/home/ipvzero/Nornir/Tools/requests-test.py", line 71, in get_cdp
    port_id = neighbor["port_id"]
KeyError: 'port_id'

2023-02-23 05:51:33,292 -  nornir.core -     INFO -        run() - Running task 'get_ospf' with args {} on 2 hosts
2023-02-23 05:51:33,964 -  nornir.core -     INFO -        run() - Running task 'get_cdp' with args {} on 2 hosts
2023-02-23 05:51:34,066 - nornir.core.task -    ERROR -      start() - Host 'R1': task 'get_cdp' failed with traceback:
Traceback (most recent call last):
  File "/home/ipvzero/Nornir/.venv/lib/python3.10/site-packages/nornir/core/task.py", line 99, in start
    r = self.task(self, **self.params)
  File "/home/ipvzero/Nornir/Tools/requests-test.py", line 71, in get_cdp
    port_id = neighbor["port_id"]
KeyError: 'port_id'

2023-02-23 05:51:34,085 - nornir.core.task -    ERROR -      start() - Host 'R2': task 'get_cdp' failed with traceback:
Traceback (most recent call last):
  File "/home/ipvzero/Nornir/.venv/lib/python3.10/site-packages/nornir/core/task.py", line 99, in start
    r = self.task(self, **self.params)
  File "/home/ipvzero/Nornir/Tools/requests-test.py", line 71, in get_cdp
    port_id = neighbor["port_id"]
KeyError: 'port_id'

2023-02-23 05:55:19,007 -  nornir.core -     INFO -        run() - Running task 'get_ospf' with args {} on 2 hosts
2023-02-23 05:55:19,791 -  nornir.core -     INFO -        run() - Running task 'get_cdp' with args {} on 2 hosts
2023-02-23 05:55:19,871 - nornir.core.task -    ERROR -      start() - Host 'R1': task 'get_cdp' failed with traceback:
Traceback (most recent call last):
  File "/home/ipvzero/Nornir/.venv/lib/python3.10/site-packages/nornir/core/task.py", line 99, in start
    r = self.task(self, **self.params)
  File "/home/ipvzero/Nornir/Tools/requests-test.py", line 71, in get_cdp
    port_id = neighbor["port_id"]
KeyError: 'port_id'

2023-02-23 05:55:19,877 - nornir.core.task -    ERROR -      start() - Host 'R2': task 'get_cdp' failed with traceback:
Traceback (most recent call last):
  File "/home/ipvzero/Nornir/.venv/lib/python3.10/site-packages/nornir/core/task.py", line 99, in start
    r = self.task(self, **self.params)
  File "/home/ipvzero/Nornir/Tools/requests-test.py", line 71, in get_cdp
    port_id = neighbor["port_id"]
KeyError: 'port_id'

2023-02-23 06:06:06,851 -  nornir.core -     INFO -        run() - Running task 'get_ospf' with args {} on 2 hosts
2023-02-23 06:06:07,638 -  nornir.core -     INFO -        run() - Running task 'get_cdp' with args {} on 2 hosts
2023-02-23 06:08:26,040 -  nornir.core -     INFO -        run() - Running task 'get_ospf' with args {} on 2 hosts
2023-02-23 06:08:26,711 -  nornir.core -     INFO -        run() - Running task 'get_cdp' with args {} on 2 hosts
2023-02-23 06:08:26,777 - nornir.core.task -    ERROR -      start() - Host 'R1': task 'get_cdp' failed with traceback:
Traceback (most recent call last):
  File "/home/ipvzero/Nornir/.venv/lib/python3.10/site-packages/nornir/core/task.py", line 99, in start
    r = self.task(self, **self.params)
  File "/home/ipvzero/Nornir/Tools/requests-test.py", line 71, in get_cdp
    port_id = neighbor["port_id"]
KeyError: 'port_id'

2023-02-23 06:08:26,778 - nornir.core.task -    ERROR -      start() - Host 'R2': task 'get_cdp' failed with traceback:
Traceback (most recent call last):
  File "/home/ipvzero/Nornir/.venv/lib/python3.10/site-packages/nornir/core/task.py", line 99, in start
    r = self.task(self, **self.params)
  File "/home/ipvzero/Nornir/Tools/requests-test.py", line 71, in get_cdp
    port_id = neighbor["port_id"]
KeyError: 'port_id'

2023-02-23 06:20:08,765 -  nornir.core -     INFO -        run() - Running task 'get_ospf' with args {} on 2 hosts
2023-02-23 06:20:09,436 -  nornir.core -     INFO -        run() - Running task 'get_cdp' with args {} on 2 hosts
2023-02-23 20:00:13,749 -  nornir.core -     INFO -        run() - Running task 'get_ospf' with args {} on 2 hosts
2023-02-23 20:00:14,603 -  nornir.core -     INFO -        run() - Running task 'get_cdp' with args {} on 2 hosts
2023-02-23 20:16:43,177 -  nornir.core -     INFO -        run() - Running task 'get_ospf' with args {} on 2 hosts
2023-02-23 20:16:44,069 -  nornir.core -     INFO -        run() - Running task 'get_cdp' with args {} on 2 hosts
2023-02-23 20:16:44,190 - nornir.core.task -    ERROR -      start() - Host 'R1': task 'get_cdp' failed with traceback:
Traceback (most recent call last):
  File "/home/ipvzero/Nornir/.venv/lib/python3.10/site-packages/nornir/core/task.py", line 99, in start
    r = self.task(self, **self.params)
  File "/home/ipvzero/Nornir/Tools/requests-test.py", line 73, in get_cdp
    if local_int.startswith("Gi"):
NameError: name 'local_int' is not defined

2023-02-23 20:16:44,197 - nornir.core.task -    ERROR -      start() - Host 'R2': task 'get_cdp' failed with traceback:
Traceback (most recent call last):
  File "/home/ipvzero/Nornir/.venv/lib/python3.10/site-packages/nornir/core/task.py", line 99, in start
    r = self.task(self, **self.params)
  File "/home/ipvzero/Nornir/Tools/requests-test.py", line 73, in get_cdp
    if local_int.startswith("Gi"):
NameError: name 'local_int' is not defined

2023-02-23 20:25:39,733 -  nornir.core -     INFO -        run() - Running task 'get_ospf' with args {} on 2 hosts
2023-02-23 20:25:40,474 -  nornir.core -     INFO -        run() - Running task 'get_cdp' with args {} on 2 hosts
2023-02-23 20:26:19,466 -  nornir.core -     INFO -        run() - Running task 'get_ospf' with args {} on 2 hosts
2023-02-23 20:26:20,167 -  nornir.core -     INFO -        run() - Running task 'get_cdp' with args {} on 2 hosts
2023-02-23 20:26:59,186 -  nornir.core -     INFO -        run() - Running task 'get_ospf' with args {} on 2 hosts
2023-02-23 20:26:59,916 -  nornir.core -     INFO -        run() - Running task 'get_cdp' with args {} on 2 hosts
2023-02-23 20:26:59,989 - nornir.core.task -    ERROR -      start() - Host 'R2': task 'get_cdp' failed with traceback:
Traceback (most recent call last):
  File "/home/ipvzero/Nornir/.venv/lib/python3.10/site-packages/nornir/core/task.py", line 99, in start
    r = self.task(self, **self.params)
  File "/home/ipvzero/Nornir/Tools/requests-test.py", line 75, in get_cdp
    local_ip = config_dict[R1]
NameError: name 'R1' is not defined

2023-02-23 20:26:59,993 - nornir.core.task -    ERROR -      start() - Host 'R1': task 'get_cdp' failed with traceback:
Traceback (most recent call last):
  File "/home/ipvzero/Nornir/.venv/lib/python3.10/site-packages/nornir/core/task.py", line 99, in start
    r = self.task(self, **self.params)
  File "/home/ipvzero/Nornir/Tools/requests-test.py", line 75, in get_cdp
    local_ip = config_dict[R1]
NameError: name 'R1' is not defined

2023-02-23 20:27:35,485 -  nornir.core -     INFO -        run() - Running task 'get_ospf' with args {} on 2 hosts
2023-02-23 20:27:36,100 -  nornir.core -     INFO -        run() - Running task 'get_cdp' with args {} on 2 hosts
2023-02-23 20:33:55,141 -  nornir.core -     INFO -        run() - Running task 'get_ospf' with args {} on 2 hosts
2023-02-23 20:33:55,783 -  nornir.core -     INFO -        run() - Running task 'get_cdp' with args {} on 2 hosts
2023-02-23 20:38:49,029 -  nornir.core -     INFO -        run() - Running task 'get_ospf' with args {} on 2 hosts
2023-02-23 20:38:49,693 -  nornir.core -     INFO -        run() - Running task 'get_cdp' with args {} on 2 hosts
2023-02-23 20:44:08,701 -  nornir.core -     INFO -        run() - Running task 'get_ospf' with args {} on 2 hosts
2023-02-23 20:44:09,453 -  nornir.core -     INFO -        run() - Running task 'get_cdp' with args {} on 2 hosts
2023-02-23 20:44:09,515 - nornir.core.task -    ERROR -      start() - Host 'R2': task 'get_cdp' failed with traceback:
Traceback (most recent call last):
  File "/home/ipvzero/Nornir/.venv/lib/python3.10/site-packages/nornir/core/task.py", line 99, in start
    r = self.task(self, **self.params)
  File "/home/ipvzero/Nornir/Tools/requests-test.py", line 79, in get_cdp
    local_net = ipaddress.ip_network(local_ip + "/" + local_mask, strict=False)
NameError: name 'ipaddress' is not defined

2023-02-23 20:44:09,526 - nornir.core.task -    ERROR -      start() - Host 'R1': task 'get_cdp' failed with traceback:
Traceback (most recent call last):
  File "/home/ipvzero/Nornir/.venv/lib/python3.10/site-packages/nornir/core/task.py", line 99, in start
    r = self.task(self, **self.params)
  File "/home/ipvzero/Nornir/Tools/requests-test.py", line 79, in get_cdp
    local_net = ipaddress.ip_network(local_ip + "/" + local_mask, strict=False)
NameError: name 'ipaddress' is not defined

2023-02-23 20:45:28,863 -  nornir.core -     INFO -        run() - Running task 'get_ospf' with args {} on 2 hosts
2023-02-23 20:45:29,646 -  nornir.core -     INFO -        run() - Running task 'get_cdp' with args {} on 2 hosts
2023-02-23 20:54:17,046 -  nornir.core -     INFO -        run() - Running task 'get_ospf' with args {} on 2 hosts
2023-02-23 20:54:17,738 -  nornir.core -     INFO -        run() - Running task 'get_cdp' with args {} on 2 hosts
2023-02-23 20:57:05,092 -  nornir.core -     INFO -        run() - Running task 'get_ospf' with args {} on 2 hosts
2023-02-23 20:57:05,764 -  nornir.core -     INFO -        run() - Running task 'get_cdp' with args {} on 2 hosts
2023-02-23 21:17:34,773 -  nornir.core -     INFO -        run() - Running task 'get_ospf' with args {} on 2 hosts
2023-02-23 21:17:35,443 -  nornir.core -     INFO -        run() - Running task 'get_cdp' with args {} on 2 hosts
2023-02-23 21:25:47,820 -  nornir.core -     INFO -        run() - Running task 'get_ospf' with args {} on 2 hosts
2023-02-23 21:25:48,525 -  nornir.core -     INFO -        run() - Running task 'get_cdp' with args {} on 2 hosts
2023-02-23 21:25:56,496 -  nornir.core -     INFO -        run() - Running task 'get_ospf' with args {} on 2 hosts
2023-02-23 21:25:57,072 -  nornir.core -     INFO -        run() - Running task 'get_cdp' with args {} on 2 hosts
2023-02-24 04:36:19,600 -  nornir.core -     INFO -        run() - Running task 'get_ospf' with args {} on 2 hosts
2023-02-24 04:36:20,408 -  nornir.core -     INFO -        run() - Running task 'get_cdp' with args {} on 2 hosts
2023-02-24 04:39:09,213 -  nornir.core -     INFO -        run() - Running task 'get_ospf' with args {} on 2 hosts
2023-02-24 04:39:09,956 -  nornir.core -     INFO -        run() - Running task 'get_cdp' with args {} on 2 hosts
2023-02-24 04:40:07,194 -  nornir.core -     INFO -        run() - Running task 'get_ospf' with args {} on 2 hosts
2023-02-24 04:40:07,805 -  nornir.core -     INFO -        run() - Running task 'get_cdp' with args {} on 2 hosts
2023-02-24 04:42:07,322 -  nornir.core -     INFO -        run() - Running task 'get_ospf' with args {} on 2 hosts
2023-02-24 04:42:07,982 -  nornir.core -     INFO -        run() - Running task 'get_cdp' with args {} on 2 hosts
2023-02-24 04:42:58,306 -  nornir.core -     INFO -        run() - Running task 'get_ospf' with args {} on 2 hosts
2023-02-24 04:42:58,892 -  nornir.core -     INFO -        run() - Running task 'get_cdp' with args {} on 2 hosts
2023-02-24 04:43:22,926 -  nornir.core -     INFO -        run() - Running task 'get_ospf' with args {} on 2 hosts
2023-02-24 04:43:23,590 -  nornir.core -     INFO -        run() - Running task 'get_cdp' with args {} on 2 hosts
2023-02-24 04:44:59,771 -  nornir.core -     INFO -        run() - Running task 'get_ospf' with args {} on 2 hosts
2023-02-24 04:45:00,472 -  nornir.core -     INFO -        run() - Running task 'get_cdp' with args {} on 2 hosts
2023-02-24 04:45:22,291 -  nornir.core -     INFO -        run() - Running task 'get_ospf' with args {} on 2 hosts
2023-02-24 04:45:22,918 -  nornir.core -     INFO -        run() - Running task 'get_cdp' with args {} on 2 hosts
2023-02-24 04:47:18,872 -  nornir.core -     INFO -        run() - Running task 'get_ospf' with args {} on 2 hosts
2023-02-24 04:47:19,519 -  nornir.core -     INFO -        run() - Running task 'get_cdp' with args {} on 2 hosts
2023-02-24 04:47:53,316 -  nornir.core -     INFO -        run() - Running task 'get_ospf' with args {} on 2 hosts
2023-02-24 04:47:53,924 -  nornir.core -     INFO -        run() - Running task 'get_cdp' with args {} on 2 hosts
2023-02-24 04:49:16,735 -  nornir.core -     INFO -        run() - Running task 'get_ospf' with args {} on 2 hosts
2023-02-24 04:49:17,333 -  nornir.core -     INFO -        run() - Running task 'get_cdp' with args {} on 2 hosts
2023-02-24 04:50:08,985 -  nornir.core -     INFO -        run() - Running task 'get_ospf' with args {} on 2 hosts
2023-02-24 04:50:09,589 -  nornir.core -     INFO -        run() - Running task 'get_cdp' with args {} on 2 hosts
2023-02-24 04:59:44,383 -  nornir.core -     INFO -        run() - Running task 'get_ospf' with args {} on 2 hosts
2023-02-24 04:59:45,097 -  nornir.core -     INFO -        run() - Running task 'get_cdp' with args {} on 2 hosts
2023-02-24 05:01:31,445 -  nornir.core -     INFO -        run() - Running task 'get_ospf' with args {} on 2 hosts
2023-02-24 05:01:32,092 -  nornir.core -     INFO -        run() - Running task 'get_cdp' with args {} on 2 hosts
2023-02-24 05:02:16,113 -  nornir.core -     INFO -        run() - Running task 'get_ospf' with args {} on 2 hosts
2023-02-24 05:02:16,729 -  nornir.core -     INFO -        run() - Running task 'get_cdp' with args {} on 2 hosts
2023-02-24 05:02:26,675 -  nornir.core -     INFO -        run() - Running task 'get_ospf' with args {} on 2 hosts
2023-02-24 05:02:27,310 -  nornir.core -     INFO -        run() - Running task 'get_cdp' with args {} on 2 hosts
2023-02-24 05:06:08,362 -  nornir.core -     INFO -        run() - Running task 'get_ospf' with args {} on 2 hosts
2023-02-24 05:06:09,000 -  nornir.core -     INFO -        run() - Running task 'get_cdp' with args {} on 2 hosts
2023-02-24 05:07:29,196 -  nornir.core -     INFO -        run() - Running task 'get_ospf' with args {} on 2 hosts
2023-02-24 05:07:29,890 -  nornir.core -     INFO -        run() - Running task 'get_cdp' with args {} on 2 hosts
2023-02-24 05:09:52,049 -  nornir.core -     INFO -        run() - Running task 'get_ospf' with args {} on 2 hosts
2023-02-24 05:09:52,702 -  nornir.core -     INFO -        run() - Running task 'get_cdp' with args {} on 2 hosts
2023-02-24 05:12:33,022 -  nornir.core -     INFO -        run() - Running task 'get_ospf' with args {} on 2 hosts
2023-02-24 05:12:33,736 -  nornir.core -     INFO -        run() - Running task 'get_cdp' with args {} on 2 hosts
2023-02-24 05:36:16,403 -  nornir.core -     INFO -        run() - Running task 'get_ospf' with args {} on 2 hosts
2023-02-24 05:36:17,090 -  nornir.core -     INFO -        run() - Running task 'get_cdp' with args {} on 2 hosts
2023-02-24 05:36:17,149 - nornir.core.task -    ERROR -      start() - Host 'R1': task 'get_cdp' failed with traceback:
Traceback (most recent call last):
  File "/home/ipvzero/Nornir/.venv/lib/python3.10/site-packages/nornir/core/task.py", line 99, in start
    r = self.task(self, **self.params)
  File "/home/ipvzero/Nornir/Tools/requests-test.py", line 70, in get_cdp
    dev_name = neighbor["device_name"]
KeyError: 'device_name'

2023-02-24 05:36:17,161 - nornir.core.task -    ERROR -      start() - Host 'R2': task 'get_cdp' failed with traceback:
Traceback (most recent call last):
  File "/home/ipvzero/Nornir/.venv/lib/python3.10/site-packages/nornir/core/task.py", line 99, in start
    r = self.task(self, **self.params)
  File "/home/ipvzero/Nornir/Tools/requests-test.py", line 70, in get_cdp
    dev_name = neighbor["device_name"]
KeyError: 'device_name'

2023-02-24 05:36:44,049 -  nornir.core -     INFO -        run() - Running task 'get_ospf' with args {} on 2 hosts
2023-02-24 05:36:44,689 -  nornir.core -     INFO -        run() - Running task 'get_cdp' with args {} on 2 hosts
2023-02-24 05:37:26,801 -  nornir.core -     INFO -        run() - Running task 'get_ospf' with args {} on 2 hosts
2023-02-24 05:37:27,439 -  nornir.core -     INFO -        run() - Running task 'get_cdp' with args {} on 2 hosts
2023-02-24 05:45:29,038 -  nornir.core -     INFO -        run() - Running task 'get_ospf' with args {} on 2 hosts
2023-02-24 05:45:29,741 -  nornir.core -     INFO -        run() - Running task 'get_cdp' with args {} on 2 hosts
2023-02-24 05:46:23,810 -  nornir.core -     INFO -        run() - Running task 'get_ospf' with args {} on 2 hosts
2023-02-24 05:46:24,490 -  nornir.core -     INFO -        run() - Running task 'get_cdp' with args {} on 2 hosts
2023-02-24 05:46:35,587 -  nornir.core -     INFO -        run() - Running task 'get_ospf' with args {} on 2 hosts
2023-02-24 05:46:36,200 -  nornir.core -     INFO -        run() - Running task 'get_cdp' with args {} on 2 hosts
2023-02-24 05:47:29,882 -  nornir.core -     INFO -        run() - Running task 'get_ospf' with args {} on 2 hosts
2023-02-24 05:47:30,539 -  nornir.core -     INFO -        run() - Running task 'get_cdp' with args {} on 2 hosts
2023-02-24 05:47:43,624 -  nornir.core -     INFO -        run() - Running task 'get_ospf' with args {} on 2 hosts
2023-02-24 05:47:44,279 -  nornir.core -     INFO -        run() - Running task 'get_cdp' with args {} on 2 hosts
2023-02-24 05:50:33,222 -  nornir.core -     INFO -        run() - Running task 'get_ospf' with args {} on 2 hosts
2023-02-24 05:50:33,944 -  nornir.core -     INFO -        run() - Running task 'get_cdp' with args {} on 2 hosts
2023-02-24 05:52:45,029 -  nornir.core -     INFO -        run() - Running task 'get_ospf' with args {} on 2 hosts
2023-02-24 05:52:45,729 -  nornir.core -     INFO -        run() - Running task 'get_cdp' with args {} on 2 hosts
2023-02-24 05:54:53,629 -  nornir.core -     INFO -        run() - Running task 'get_ospf' with args {} on 2 hosts
2023-02-24 05:54:54,270 -  nornir.core -     INFO -        run() - Running task 'get_cdp' with args {} on 2 hosts
2023-02-24 05:58:32,426 -  nornir.core -     INFO -        run() - Running task 'get_ospf' with args {} on 2 hosts
2023-02-24 05:58:33,068 -  nornir.core -     INFO -        run() - Running task 'get_cdp' with args {} on 2 hosts
2023-02-24 06:02:02,105 -  nornir.core -     INFO -        run() - Running task 'get_ospf' with args {} on 2 hosts
2023-02-24 06:02:02,789 -  nornir.core -     INFO -        run() - Running task 'get_cdp' with args {} on 2 hosts
2023-02-24 06:02:26,441 -  nornir.core -     INFO -        run() - Running task 'get_ospf' with args {} on 2 hosts
2023-02-24 06:02:27,191 -  nornir.core -     INFO -        run() - Running task 'get_cdp' with args {} on 2 hosts
2023-02-24 06:05:45,036 -  nornir.core -     INFO -        run() - Running task 'get_ospf' with args {} on 2 hosts
2023-02-24 06:05:45,676 -  nornir.core -     INFO -        run() - Running task 'get_cdp' with args {} on 2 hosts
2023-02-25 04:56:48,286 -  nornir.core -     INFO -        run() - Running task 'get_ospf' with args {} on 2 hosts
2023-02-25 04:56:49,101 -  nornir.core -     INFO -        run() - Running task 'get_cdp' with args {} on 2 hosts
2023-02-25 05:03:33,162 -  nornir.core -     INFO -        run() - Running task 'get_ospf' with args {} on 2 hosts
2023-02-25 05:03:33,877 -  nornir.core -     INFO -        run() - Running task 'get_cdp' with args {} on 2 hosts
2023-02-25 05:04:20,891 -  nornir.core -     INFO -        run() - Running task 'get_ospf' with args {} on 2 hosts
2023-02-25 05:04:21,514 -  nornir.core -     INFO -        run() - Running task 'get_cdp' with args {} on 2 hosts
2023-02-25 05:27:37,804 -  nornir.core -     INFO -        run() - Running task 'get_ospf' with args {} on 2 hosts
2023-02-25 05:27:38,484 -  nornir.core -     INFO -        run() - Running task 'get_cdp' with args {} on 2 hosts
2023-02-25 06:03:07,109 -  nornir.core -     INFO -        run() - Running task 'get_ospf' with args {} on 2 hosts
2023-02-25 06:03:07,885 -  nornir.core -     INFO -        run() - Running task 'get_cdp' with args {} on 2 hosts
2023-02-25 07:35:58,170 -  nornir.core -     INFO -        run() - Running task 'get_ospf' with args {} on 2 hosts
2023-02-25 07:35:58,369 - nornir.core.task -    ERROR -      start() - Host 'R1': task 'get_ospf' failed with traceback:
Traceback (most recent call last):
  File "/home/ipvzero/Nornir/.venv/lib/python3.10/site-packages/urllib3/connection.py", line 174, in _new_conn
    conn = connection.create_connection(
  File "/home/ipvzero/Nornir/.venv/lib/python3.10/site-packages/urllib3/util/connection.py", line 95, in create_connection
    raise err
  File "/home/ipvzero/Nornir/.venv/lib/python3.10/site-packages/urllib3/util/connection.py", line 85, in create_connection
    sock.connect(sa)
ConnectionRefusedError: [Errno 111] Connection refused

During handling of the above exception, another exception occurred:

Traceback (most recent call last):
  File "/home/ipvzero/Nornir/.venv/lib/python3.10/site-packages/urllib3/connectionpool.py", line 703, in urlopen
    httplib_response = self._make_request(
  File "/home/ipvzero/Nornir/.venv/lib/python3.10/site-packages/urllib3/connectionpool.py", line 386, in _make_request
    self._validate_conn(conn)
  File "/home/ipvzero/Nornir/.venv/lib/python3.10/site-packages/urllib3/connectionpool.py", line 1042, in _validate_conn
    conn.connect()
  File "/home/ipvzero/Nornir/.venv/lib/python3.10/site-packages/urllib3/connection.py", line 358, in connect
    self.sock = conn = self._new_conn()
  File "/home/ipvzero/Nornir/.venv/lib/python3.10/site-packages/urllib3/connection.py", line 186, in _new_conn
    raise NewConnectionError(
urllib3.exceptions.NewConnectionError: <urllib3.connection.HTTPSConnection object at 0x7facd2d22e00>: Failed to establish a new connection: [Errno 111] Connection refused

During handling of the above exception, another exception occurred:

Traceback (most recent call last):
  File "/home/ipvzero/Nornir/.venv/lib/python3.10/site-packages/requests/adapters.py", line 489, in send
    resp = conn.urlopen(
  File "/home/ipvzero/Nornir/.venv/lib/python3.10/site-packages/urllib3/connectionpool.py", line 787, in urlopen
    retries = retries.increment(
  File "/home/ipvzero/Nornir/.venv/lib/python3.10/site-packages/urllib3/util/retry.py", line 592, in increment
    raise MaxRetryError(_pool, url, error or ResponseError(cause))
urllib3.exceptions.MaxRetryError: HTTPSConnectionPool(host='192.168.179.130', port=443): Max retries exceeded with url: /restconf/data/ospf-oper-data (Caused by NewConnectionError('<urllib3.connection.HTTPSConnection object at 0x7facd2d22e00>: Failed to establish a new connection: [Errno 111] Connection refused'))

During handling of the above exception, another exception occurred:

Traceback (most recent call last):
  File "/home/ipvzero/Nornir/.venv/lib/python3.10/site-packages/nornir/core/task.py", line 99, in start
    r = self.task(self, **self.params)
  File "/home/ipvzero/Nornir/Tools/requests-test2.py", line 26, in get_ospf
    ospf_send = requests.get(
  File "/home/ipvzero/Nornir/.venv/lib/python3.10/site-packages/requests/api.py", line 73, in get
    return request("get", url, params=params, **kwargs)
  File "/home/ipvzero/Nornir/.venv/lib/python3.10/site-packages/requests/api.py", line 59, in request
    return session.request(method=method, url=url, **kwargs)
  File "/home/ipvzero/Nornir/.venv/lib/python3.10/site-packages/requests/sessions.py", line 587, in request
    resp = self.send(prep, **send_kwargs)
  File "/home/ipvzero/Nornir/.venv/lib/python3.10/site-packages/requests/sessions.py", line 701, in send
    r = adapter.send(request, **kwargs)
  File "/home/ipvzero/Nornir/.venv/lib/python3.10/site-packages/requests/adapters.py", line 565, in send
    raise ConnectionError(e, request=request)
requests.exceptions.ConnectionError: HTTPSConnectionPool(host='192.168.179.130', port=443): Max retries exceeded with url: /restconf/data/ospf-oper-data (Caused by NewConnectionError('<urllib3.connection.HTTPSConnection object at 0x7facd2d22e00>: Failed to establish a new connection: [Errno 111] Connection refused'))

2023-02-25 07:35:58,369 - nornir.core.task -    ERROR -      start() - Host 'R2': task 'get_ospf' failed with traceback:
Traceback (most recent call last):
  File "/home/ipvzero/Nornir/.venv/lib/python3.10/site-packages/urllib3/connection.py", line 174, in _new_conn
    conn = connection.create_connection(
  File "/home/ipvzero/Nornir/.venv/lib/python3.10/site-packages/urllib3/util/connection.py", line 95, in create_connection
    raise err
  File "/home/ipvzero/Nornir/.venv/lib/python3.10/site-packages/urllib3/util/connection.py", line 85, in create_connection
    sock.connect(sa)
ConnectionRefusedError: [Errno 111] Connection refused

During handling of the above exception, another exception occurred:

Traceback (most recent call last):
  File "/home/ipvzero/Nornir/.venv/lib/python3.10/site-packages/urllib3/connectionpool.py", line 703, in urlopen
    httplib_response = self._make_request(
  File "/home/ipvzero/Nornir/.venv/lib/python3.10/site-packages/urllib3/connectionpool.py", line 386, in _make_request
    self._validate_conn(conn)
  File "/home/ipvzero/Nornir/.venv/lib/python3.10/site-packages/urllib3/connectionpool.py", line 1042, in _validate_conn
    conn.connect()
  File "/home/ipvzero/Nornir/.venv/lib/python3.10/site-packages/urllib3/connection.py", line 358, in connect
    self.sock = conn = self._new_conn()
  File "/home/ipvzero/Nornir/.venv/lib/python3.10/site-packages/urllib3/connection.py", line 186, in _new_conn
    raise NewConnectionError(
urllib3.exceptions.NewConnectionError: <urllib3.connection.HTTPSConnection object at 0x7facd2d228f0>: Failed to establish a new connection: [Errno 111] Connection refused

During handling of the above exception, another exception occurred:

Traceback (most recent call last):
  File "/home/ipvzero/Nornir/.venv/lib/python3.10/site-packages/requests/adapters.py", line 489, in send
    resp = conn.urlopen(
  File "/home/ipvzero/Nornir/.venv/lib/python3.10/site-packages/urllib3/connectionpool.py", line 787, in urlopen
    retries = retries.increment(
  File "/home/ipvzero/Nornir/.venv/lib/python3.10/site-packages/urllib3/util/retry.py", line 592, in increment
    raise MaxRetryError(_pool, url, error or ResponseError(cause))
urllib3.exceptions.MaxRetryError: HTTPSConnectionPool(host='192.168.179.131', port=443): Max retries exceeded with url: /restconf/data/ospf-oper-data (Caused by NewConnectionError('<urllib3.connection.HTTPSConnection object at 0x7facd2d228f0>: Failed to establish a new connection: [Errno 111] Connection refused'))

During handling of the above exception, another exception occurred:

Traceback (most recent call last):
  File "/home/ipvzero/Nornir/.venv/lib/python3.10/site-packages/nornir/core/task.py", line 99, in start
    r = self.task(self, **self.params)
  File "/home/ipvzero/Nornir/Tools/requests-test2.py", line 26, in get_ospf
    ospf_send = requests.get(
  File "/home/ipvzero/Nornir/.venv/lib/python3.10/site-packages/requests/api.py", line 73, in get
    return request("get", url, params=params, **kwargs)
  File "/home/ipvzero/Nornir/.venv/lib/python3.10/site-packages/requests/api.py", line 59, in request
    return session.request(method=method, url=url, **kwargs)
  File "/home/ipvzero/Nornir/.venv/lib/python3.10/site-packages/requests/sessions.py", line 587, in request
    resp = self.send(prep, **send_kwargs)
  File "/home/ipvzero/Nornir/.venv/lib/python3.10/site-packages/requests/sessions.py", line 701, in send
    r = adapter.send(request, **kwargs)
  File "/home/ipvzero/Nornir/.venv/lib/python3.10/site-packages/requests/adapters.py", line 565, in send
    raise ConnectionError(e, request=request)
requests.exceptions.ConnectionError: HTTPSConnectionPool(host='192.168.179.131', port=443): Max retries exceeded with url: /restconf/data/ospf-oper-data (Caused by NewConnectionError('<urllib3.connection.HTTPSConnection object at 0x7facd2d228f0>: Failed to establish a new connection: [Errno 111] Connection refused'))

2023-02-25 07:35:58,370 -  nornir.core -     INFO -        run() - Running task 'get_cdp' with args {} on 2 hosts
