2023-02-11 05:14:33,271 -  nornir.core -     INFO -        run() - Running task 'random_configs' with args {'progress_bar': <tqdm.std.tqdm object at 0x7f18e690c070>} on 7 hosts
2023-02-11 05:14:33,404 - nornir.core.task -    ERROR -      start() - Host 'R1': task 'send_configs_from_file' failed with traceback:
Traceback (most recent call last):
  File "/home/ipvzero/Netbox-Demo/.venv/lib/python3.10/site-packages/nornir/core/task.py", line 99, in start
    r = self.task(self, **self.params)
  File "/home/ipvzero/Netbox-Demo/.venv/lib/python3.10/site-packages/nornir_scrapli/tasks/core/send_configs_from_file.py", line 58, in send_configs_from_file
    scrapli_conn = task.host.get_connection("scrapli", task.nornir.config)
  File "/home/ipvzero/Netbox-Demo/.venv/lib/python3.10/site-packages/nornir/core/inventory.py", line 494, in get_connection
    self.open_connection(
  File "/home/ipvzero/Netbox-Demo/.venv/lib/python3.10/site-packages/nornir/core/inventory.py", line 546, in open_connection
    conn_obj.open(
  File "/home/ipvzero/Netbox-Demo/.venv/lib/python3.10/site-packages/nornir_scrapli/connection.py", line 88, in open
    raise NornirScrapliInvalidPlatform(
nornir_scrapli.exceptions.NornirScrapliInvalidPlatform: 'platform' not provided in inventory for host `192.168.179.130`

2023-02-11 05:14:33,405 - nornir.core.task -    ERROR -      start() - Host 'R2': task 'send_configs_from_file' failed with traceback:
Traceback (most recent call last):
  File "/home/ipvzero/Netbox-Demo/.venv/lib/python3.10/site-packages/nornir/core/task.py", line 99, in start
    r = self.task(self, **self.params)
  File "/home/ipvzero/Netbox-Demo/.venv/lib/python3.10/site-packages/nornir_scrapli/tasks/core/send_configs_from_file.py", line 58, in send_configs_from_file
    scrapli_conn = task.host.get_connection("scrapli", task.nornir.config)
  File "/home/ipvzero/Netbox-Demo/.venv/lib/python3.10/site-packages/nornir/core/inventory.py", line 494, in get_connection
    self.open_connection(
  File "/home/ipvzero/Netbox-Demo/.venv/lib/python3.10/site-packages/nornir/core/inventory.py", line 546, in open_connection
    conn_obj.open(
  File "/home/ipvzero/Netbox-Demo/.venv/lib/python3.10/site-packages/nornir_scrapli/connection.py", line 88, in open
    raise NornirScrapliInvalidPlatform(
nornir_scrapli.exceptions.NornirScrapliInvalidPlatform: 'platform' not provided in inventory for host `192.168.179.131`

2023-02-11 05:14:33,405 - nornir.core.task -    ERROR -      start() - Host 'R2': task 'random_configs' failed with traceback:
Traceback (most recent call last):
  File "/home/ipvzero/Netbox-Demo/.venv/lib/python3.10/site-packages/nornir/core/task.py", line 99, in start
    r = self.task(self, **self.params)
  File "/home/ipvzero/Nornir/Progress_Bars/runbook1-progress_bar-send_config.py", line 9, in random_configs
    task.run(task=send_configs_from_file, file="conf.txt")
  File "/home/ipvzero/Netbox-Demo/.venv/lib/python3.10/site-packages/nornir/core/task.py", line 174, in run
    raise NornirSubTaskError(task=run_task, result=r)
nornir.core.exceptions.NornirSubTaskError: Subtask: send_configs_from_file (failed)


2023-02-11 05:14:33,405 - nornir.core.task -    ERROR -      start() - Host 'R3': task 'send_configs_from_file' failed with traceback:
Traceback (most recent call last):
  File "/home/ipvzero/Netbox-Demo/.venv/lib/python3.10/site-packages/nornir/core/task.py", line 99, in start
    r = self.task(self, **self.params)
  File "/home/ipvzero/Netbox-Demo/.venv/lib/python3.10/site-packages/nornir_scrapli/tasks/core/send_configs_from_file.py", line 58, in send_configs_from_file
    scrapli_conn = task.host.get_connection("scrapli", task.nornir.config)
  File "/home/ipvzero/Netbox-Demo/.venv/lib/python3.10/site-packages/nornir/core/inventory.py", line 494, in get_connection
    self.open_connection(
  File "/home/ipvzero/Netbox-Demo/.venv/lib/python3.10/site-packages/nornir/core/inventory.py", line 546, in open_connection
    conn_obj.open(
  File "/home/ipvzero/Netbox-Demo/.venv/lib/python3.10/site-packages/nornir_scrapli/connection.py", line 88, in open
    raise NornirScrapliInvalidPlatform(
nornir_scrapli.exceptions.NornirScrapliInvalidPlatform: 'platform' not provided in inventory for host `192.168.179.132`

2023-02-11 05:14:33,406 - nornir.core.task -    ERROR -      start() - Host 'R1': task 'random_configs' failed with traceback:
Traceback (most recent call last):
  File "/home/ipvzero/Netbox-Demo/.venv/lib/python3.10/site-packages/nornir/core/task.py", line 99, in start
    r = self.task(self, **self.params)
  File "/home/ipvzero/Nornir/Progress_Bars/runbook1-progress_bar-send_config.py", line 9, in random_configs
    task.run(task=send_configs_from_file, file="conf.txt")
  File "/home/ipvzero/Netbox-Demo/.venv/lib/python3.10/site-packages/nornir/core/task.py", line 174, in run
    raise NornirSubTaskError(task=run_task, result=r)
nornir.core.exceptions.NornirSubTaskError: Subtask: send_configs_from_file (failed)


2023-02-11 05:14:33,406 - nornir.core.task -    ERROR -      start() - Host 'R3': task 'random_configs' failed with traceback:
Traceback (most recent call last):
  File "/home/ipvzero/Netbox-Demo/.venv/lib/python3.10/site-packages/nornir/core/task.py", line 99, in start
    r = self.task(self, **self.params)
  File "/home/ipvzero/Nornir/Progress_Bars/runbook1-progress_bar-send_config.py", line 9, in random_configs
    task.run(task=send_configs_from_file, file="conf.txt")
  File "/home/ipvzero/Netbox-Demo/.venv/lib/python3.10/site-packages/nornir/core/task.py", line 174, in run
    raise NornirSubTaskError(task=run_task, result=r)
nornir.core.exceptions.NornirSubTaskError: Subtask: send_configs_from_file (failed)


2023-02-11 05:14:33,406 - nornir.core.task -    ERROR -      start() - Host 'R4': task 'send_configs_from_file' failed with traceback:
Traceback (most recent call last):
  File "/home/ipvzero/Netbox-Demo/.venv/lib/python3.10/site-packages/nornir/core/task.py", line 99, in start
    r = self.task(self, **self.params)
  File "/home/ipvzero/Netbox-Demo/.venv/lib/python3.10/site-packages/nornir_scrapli/tasks/core/send_configs_from_file.py", line 58, in send_configs_from_file
    scrapli_conn = task.host.get_connection("scrapli", task.nornir.config)
  File "/home/ipvzero/Netbox-Demo/.venv/lib/python3.10/site-packages/nornir/core/inventory.py", line 494, in get_connection
    self.open_connection(
  File "/home/ipvzero/Netbox-Demo/.venv/lib/python3.10/site-packages/nornir/core/inventory.py", line 546, in open_connection
    conn_obj.open(
  File "/home/ipvzero/Netbox-Demo/.venv/lib/python3.10/site-packages/nornir_scrapli/connection.py", line 88, in open
    raise NornirScrapliInvalidPlatform(
nornir_scrapli.exceptions.NornirScrapliInvalidPlatform: 'platform' not provided in inventory for host `192.168.179.133`

2023-02-11 05:14:33,407 - nornir.core.task -    ERROR -      start() - Host 'R5': task 'send_configs_from_file' failed with traceback:
Traceback (most recent call last):
  File "/home/ipvzero/Netbox-Demo/.venv/lib/python3.10/site-packages/nornir/core/task.py", line 99, in start
    r = self.task(self, **self.params)
  File "/home/ipvzero/Netbox-Demo/.venv/lib/python3.10/site-packages/nornir_scrapli/tasks/core/send_configs_from_file.py", line 58, in send_configs_from_file
    scrapli_conn = task.host.get_connection("scrapli", task.nornir.config)
  File "/home/ipvzero/Netbox-Demo/.venv/lib/python3.10/site-packages/nornir/core/inventory.py", line 494, in get_connection
    self.open_connection(
  File "/home/ipvzero/Netbox-Demo/.venv/lib/python3.10/site-packages/nornir/core/inventory.py", line 546, in open_connection
    conn_obj.open(
  File "/home/ipvzero/Netbox-Demo/.venv/lib/python3.10/site-packages/nornir_scrapli/connection.py", line 88, in open
    raise NornirScrapliInvalidPlatform(
nornir_scrapli.exceptions.NornirScrapliInvalidPlatform: 'platform' not provided in inventory for host `192.168.179.134`

2023-02-11 05:14:33,407 - nornir.core.task -    ERROR -      start() - Host 'R4': task 'random_configs' failed with traceback:
Traceback (most recent call last):
  File "/home/ipvzero/Netbox-Demo/.venv/lib/python3.10/site-packages/nornir/core/task.py", line 99, in start
    r = self.task(self, **self.params)
  File "/home/ipvzero/Nornir/Progress_Bars/runbook1-progress_bar-send_config.py", line 9, in random_configs
    task.run(task=send_configs_from_file, file="conf.txt")
  File "/home/ipvzero/Netbox-Demo/.venv/lib/python3.10/site-packages/nornir/core/task.py", line 174, in run
    raise NornirSubTaskError(task=run_task, result=r)
nornir.core.exceptions.NornirSubTaskError: Subtask: send_configs_from_file (failed)


2023-02-11 05:14:33,407 - nornir.core.task -    ERROR -      start() - Host 'R5': task 'random_configs' failed with traceback:
Traceback (most recent call last):
  File "/home/ipvzero/Netbox-Demo/.venv/lib/python3.10/site-packages/nornir/core/task.py", line 99, in start
    r = self.task(self, **self.params)
  File "/home/ipvzero/Nornir/Progress_Bars/runbook1-progress_bar-send_config.py", line 9, in random_configs
    task.run(task=send_configs_from_file, file="conf.txt")
  File "/home/ipvzero/Netbox-Demo/.venv/lib/python3.10/site-packages/nornir/core/task.py", line 174, in run
    raise NornirSubTaskError(task=run_task, result=r)
nornir.core.exceptions.NornirSubTaskError: Subtask: send_configs_from_file (failed)


2023-02-11 05:14:33,408 - nornir.core.task -    ERROR -      start() - Host 'R6': task 'send_configs_from_file' failed with traceback:
Traceback (most recent call last):
  File "/home/ipvzero/Netbox-Demo/.venv/lib/python3.10/site-packages/nornir/core/task.py", line 99, in start
    r = self.task(self, **self.params)
  File "/home/ipvzero/Netbox-Demo/.venv/lib/python3.10/site-packages/nornir_scrapli/tasks/core/send_configs_from_file.py", line 58, in send_configs_from_file
    scrapli_conn = task.host.get_connection("scrapli", task.nornir.config)
  File "/home/ipvzero/Netbox-Demo/.venv/lib/python3.10/site-packages/nornir/core/inventory.py", line 494, in get_connection
    self.open_connection(
  File "/home/ipvzero/Netbox-Demo/.venv/lib/python3.10/site-packages/nornir/core/inventory.py", line 546, in open_connection
    conn_obj.open(
  File "/home/ipvzero/Netbox-Demo/.venv/lib/python3.10/site-packages/nornir_scrapli/connection.py", line 88, in open
    raise NornirScrapliInvalidPlatform(
nornir_scrapli.exceptions.NornirScrapliInvalidPlatform: 'platform' not provided in inventory for host `192.168.179.135`

2023-02-11 05:14:33,408 - nornir.core.task -    ERROR -      start() - Host 'R7': task 'send_configs_from_file' failed with traceback:
Traceback (most recent call last):
  File "/home/ipvzero/Netbox-Demo/.venv/lib/python3.10/site-packages/nornir/core/task.py", line 99, in start
    r = self.task(self, **self.params)
  File "/home/ipvzero/Netbox-Demo/.venv/lib/python3.10/site-packages/nornir_scrapli/tasks/core/send_configs_from_file.py", line 58, in send_configs_from_file
    scrapli_conn = task.host.get_connection("scrapli", task.nornir.config)
  File "/home/ipvzero/Netbox-Demo/.venv/lib/python3.10/site-packages/nornir/core/inventory.py", line 494, in get_connection
    self.open_connection(
  File "/home/ipvzero/Netbox-Demo/.venv/lib/python3.10/site-packages/nornir/core/inventory.py", line 546, in open_connection
    conn_obj.open(
  File "/home/ipvzero/Netbox-Demo/.venv/lib/python3.10/site-packages/nornir_scrapli/connection.py", line 88, in open
    raise NornirScrapliInvalidPlatform(
nornir_scrapli.exceptions.NornirScrapliInvalidPlatform: 'platform' not provided in inventory for host `192.168.179.136`

2023-02-11 05:14:33,408 - nornir.core.task -    ERROR -      start() - Host 'R6': task 'random_configs' failed with traceback:
Traceback (most recent call last):
  File "/home/ipvzero/Netbox-Demo/.venv/lib/python3.10/site-packages/nornir/core/task.py", line 99, in start
    r = self.task(self, **self.params)
  File "/home/ipvzero/Nornir/Progress_Bars/runbook1-progress_bar-send_config.py", line 9, in random_configs
    task.run(task=send_configs_from_file, file="conf.txt")
  File "/home/ipvzero/Netbox-Demo/.venv/lib/python3.10/site-packages/nornir/core/task.py", line 174, in run
    raise NornirSubTaskError(task=run_task, result=r)
nornir.core.exceptions.NornirSubTaskError: Subtask: send_configs_from_file (failed)


2023-02-11 05:14:33,408 - nornir.core.task -    ERROR -      start() - Host 'R7': task 'random_configs' failed with traceback:
Traceback (most recent call last):
  File "/home/ipvzero/Netbox-Demo/.venv/lib/python3.10/site-packages/nornir/core/task.py", line 99, in start
    r = self.task(self, **self.params)
  File "/home/ipvzero/Nornir/Progress_Bars/runbook1-progress_bar-send_config.py", line 9, in random_configs
    task.run(task=send_configs_from_file, file="conf.txt")
  File "/home/ipvzero/Netbox-Demo/.venv/lib/python3.10/site-packages/nornir/core/task.py", line 174, in run
    raise NornirSubTaskError(task=run_task, result=r)
nornir.core.exceptions.NornirSubTaskError: Subtask: send_configs_from_file (failed)


2023-02-11 05:18:26,104 -  nornir.core -     INFO -        run() - Running task 'random_configs' with args {'progress_bar': <tqdm.std.tqdm object at 0x7f44e41cf760>} on 7 hosts
2023-02-11 05:18:26,107 - nornir.core.task -    ERROR -      start() - Host 'R1': task 'send_configs_from_file' failed with traceback:
Traceback (most recent call last):
  File "/home/ipvzero/Netbox-Demo/.venv/lib/python3.10/site-packages/nornir/core/task.py", line 99, in start
    r = self.task(self, **self.params)
  File "/home/ipvzero/Netbox-Demo/.venv/lib/python3.10/site-packages/nornir_scrapli/tasks/core/send_configs_from_file.py", line 58, in send_configs_from_file
    scrapli_conn = task.host.get_connection("scrapli", task.nornir.config)
  File "/home/ipvzero/Netbox-Demo/.venv/lib/python3.10/site-packages/nornir/core/inventory.py", line 494, in get_connection
    self.open_connection(
  File "/home/ipvzero/Netbox-Demo/.venv/lib/python3.10/site-packages/nornir/core/inventory.py", line 546, in open_connection
    conn_obj.open(
  File "/home/ipvzero/Netbox-Demo/.venv/lib/python3.10/site-packages/nornir_scrapli/connection.py", line 88, in open
    raise NornirScrapliInvalidPlatform(
nornir_scrapli.exceptions.NornirScrapliInvalidPlatform: 'platform' not provided in inventory for host `192.168.179.130`

2023-02-11 05:18:26,107 - nornir.core.task -    ERROR -      start() - Host 'R1': task 'random_configs' failed with traceback:
Traceback (most recent call last):
  File "/home/ipvzero/Netbox-Demo/.venv/lib/python3.10/site-packages/nornir/core/task.py", line 99, in start
    r = self.task(self, **self.params)
  File "/home/ipvzero/Nornir/Progress_Bars/runbook1-progress_bar-send_config.py", line 9, in random_configs
    task.run(task=send_configs_from_file, file="conf.txt")
  File "/home/ipvzero/Netbox-Demo/.venv/lib/python3.10/site-packages/nornir/core/task.py", line 174, in run
    raise NornirSubTaskError(task=run_task, result=r)
nornir.core.exceptions.NornirSubTaskError: Subtask: send_configs_from_file (failed)


2023-02-11 05:18:26,107 - nornir.core.task -    ERROR -      start() - Host 'R2': task 'send_configs_from_file' failed with traceback:
Traceback (most recent call last):
  File "/home/ipvzero/Netbox-Demo/.venv/lib/python3.10/site-packages/nornir/core/task.py", line 99, in start
    r = self.task(self, **self.params)
  File "/home/ipvzero/Netbox-Demo/.venv/lib/python3.10/site-packages/nornir_scrapli/tasks/core/send_configs_from_file.py", line 58, in send_configs_from_file
    scrapli_conn = task.host.get_connection("scrapli", task.nornir.config)
  File "/home/ipvzero/Netbox-Demo/.venv/lib/python3.10/site-packages/nornir/core/inventory.py", line 494, in get_connection
    self.open_connection(
  File "/home/ipvzero/Netbox-Demo/.venv/lib/python3.10/site-packages/nornir/core/inventory.py", line 546, in open_connection
    conn_obj.open(
  File "/home/ipvzero/Netbox-Demo/.venv/lib/python3.10/site-packages/nornir_scrapli/connection.py", line 88, in open
    raise NornirScrapliInvalidPlatform(
nornir_scrapli.exceptions.NornirScrapliInvalidPlatform: 'platform' not provided in inventory for host `192.168.179.131`

2023-02-11 05:18:26,108 - nornir.core.task -    ERROR -      start() - Host 'R2': task 'random_configs' failed with traceback:
Traceback (most recent call last):
  File "/home/ipvzero/Netbox-Demo/.venv/lib/python3.10/site-packages/nornir/core/task.py", line 99, in start
    r = self.task(self, **self.params)
  File "/home/ipvzero/Nornir/Progress_Bars/runbook1-progress_bar-send_config.py", line 9, in random_configs
    task.run(task=send_configs_from_file, file="conf.txt")
  File "/home/ipvzero/Netbox-Demo/.venv/lib/python3.10/site-packages/nornir/core/task.py", line 174, in run
    raise NornirSubTaskError(task=run_task, result=r)
nornir.core.exceptions.NornirSubTaskError: Subtask: send_configs_from_file (failed)


2023-02-11 05:18:26,108 - nornir.core.task -    ERROR -      start() - Host 'R3': task 'send_configs_from_file' failed with traceback:
Traceback (most recent call last):
  File "/home/ipvzero/Netbox-Demo/.venv/lib/python3.10/site-packages/nornir/core/task.py", line 99, in start
    r = self.task(self, **self.params)
  File "/home/ipvzero/Netbox-Demo/.venv/lib/python3.10/site-packages/nornir_scrapli/tasks/core/send_configs_from_file.py", line 58, in send_configs_from_file
    scrapli_conn = task.host.get_connection("scrapli", task.nornir.config)
  File "/home/ipvzero/Netbox-Demo/.venv/lib/python3.10/site-packages/nornir/core/inventory.py", line 494, in get_connection
    self.open_connection(
  File "/home/ipvzero/Netbox-Demo/.venv/lib/python3.10/site-packages/nornir/core/inventory.py", line 546, in open_connection
    conn_obj.open(
  File "/home/ipvzero/Netbox-Demo/.venv/lib/python3.10/site-packages/nornir_scrapli/connection.py", line 88, in open
    raise NornirScrapliInvalidPlatform(
nornir_scrapli.exceptions.NornirScrapliInvalidPlatform: 'platform' not provided in inventory for host `192.168.179.132`

2023-02-11 05:18:26,108 - nornir.core.task -    ERROR -      start() - Host 'R3': task 'random_configs' failed with traceback:
Traceback (most recent call last):
  File "/home/ipvzero/Netbox-Demo/.venv/lib/python3.10/site-packages/nornir/core/task.py", line 99, in start
    r = self.task(self, **self.params)
  File "/home/ipvzero/Nornir/Progress_Bars/runbook1-progress_bar-send_config.py", line 9, in random_configs
    task.run(task=send_configs_from_file, file="conf.txt")
  File "/home/ipvzero/Netbox-Demo/.venv/lib/python3.10/site-packages/nornir/core/task.py", line 174, in run
    raise NornirSubTaskError(task=run_task, result=r)
nornir.core.exceptions.NornirSubTaskError: Subtask: send_configs_from_file (failed)


2023-02-11 05:18:26,108 - nornir.core.task -    ERROR -      start() - Host 'R4': task 'send_configs_from_file' failed with traceback:
Traceback (most recent call last):
  File "/home/ipvzero/Netbox-Demo/.venv/lib/python3.10/site-packages/nornir/core/task.py", line 99, in start
    r = self.task(self, **self.params)
  File "/home/ipvzero/Netbox-Demo/.venv/lib/python3.10/site-packages/nornir_scrapli/tasks/core/send_configs_from_file.py", line 58, in send_configs_from_file
    scrapli_conn = task.host.get_connection("scrapli", task.nornir.config)
  File "/home/ipvzero/Netbox-Demo/.venv/lib/python3.10/site-packages/nornir/core/inventory.py", line 494, in get_connection
    self.open_connection(
  File "/home/ipvzero/Netbox-Demo/.venv/lib/python3.10/site-packages/nornir/core/inventory.py", line 546, in open_connection
    conn_obj.open(
  File "/home/ipvzero/Netbox-Demo/.venv/lib/python3.10/site-packages/nornir_scrapli/connection.py", line 88, in open
    raise NornirScrapliInvalidPlatform(
nornir_scrapli.exceptions.NornirScrapliInvalidPlatform: 'platform' not provided in inventory for host `192.168.179.133`

2023-02-11 05:18:26,109 - nornir.core.task -    ERROR -      start() - Host 'R4': task 'random_configs' failed with traceback:
Traceback (most recent call last):
  File "/home/ipvzero/Netbox-Demo/.venv/lib/python3.10/site-packages/nornir/core/task.py", line 99, in start
    r = self.task(self, **self.params)
  File "/home/ipvzero/Nornir/Progress_Bars/runbook1-progress_bar-send_config.py", line 9, in random_configs
    task.run(task=send_configs_from_file, file="conf.txt")
  File "/home/ipvzero/Netbox-Demo/.venv/lib/python3.10/site-packages/nornir/core/task.py", line 174, in run
    raise NornirSubTaskError(task=run_task, result=r)
nornir.core.exceptions.NornirSubTaskError: Subtask: send_configs_from_file (failed)


2023-02-11 05:18:26,109 - nornir.core.task -    ERROR -      start() - Host 'R5': task 'send_configs_from_file' failed with traceback:
Traceback (most recent call last):
  File "/home/ipvzero/Netbox-Demo/.venv/lib/python3.10/site-packages/nornir/core/task.py", line 99, in start
    r = self.task(self, **self.params)
  File "/home/ipvzero/Netbox-Demo/.venv/lib/python3.10/site-packages/nornir_scrapli/tasks/core/send_configs_from_file.py", line 58, in send_configs_from_file
    scrapli_conn = task.host.get_connection("scrapli", task.nornir.config)
  File "/home/ipvzero/Netbox-Demo/.venv/lib/python3.10/site-packages/nornir/core/inventory.py", line 494, in get_connection
    self.open_connection(
  File "/home/ipvzero/Netbox-Demo/.venv/lib/python3.10/site-packages/nornir/core/inventory.py", line 546, in open_connection
    conn_obj.open(
  File "/home/ipvzero/Netbox-Demo/.venv/lib/python3.10/site-packages/nornir_scrapli/connection.py", line 88, in open
    raise NornirScrapliInvalidPlatform(
nornir_scrapli.exceptions.NornirScrapliInvalidPlatform: 'platform' not provided in inventory for host `192.168.179.134`

2023-02-11 05:18:26,109 - nornir.core.task -    ERROR -      start() - Host 'R5': task 'random_configs' failed with traceback:
Traceback (most recent call last):
  File "/home/ipvzero/Netbox-Demo/.venv/lib/python3.10/site-packages/nornir/core/task.py", line 99, in start
    r = self.task(self, **self.params)
  File "/home/ipvzero/Nornir/Progress_Bars/runbook1-progress_bar-send_config.py", line 9, in random_configs
    task.run(task=send_configs_from_file, file="conf.txt")
  File "/home/ipvzero/Netbox-Demo/.venv/lib/python3.10/site-packages/nornir/core/task.py", line 174, in run
    raise NornirSubTaskError(task=run_task, result=r)
nornir.core.exceptions.NornirSubTaskError: Subtask: send_configs_from_file (failed)


2023-02-11 05:18:26,109 - nornir.core.task -    ERROR -      start() - Host 'R6': task 'send_configs_from_file' failed with traceback:
Traceback (most recent call last):
  File "/home/ipvzero/Netbox-Demo/.venv/lib/python3.10/site-packages/nornir/core/task.py", line 99, in start
    r = self.task(self, **self.params)
  File "/home/ipvzero/Netbox-Demo/.venv/lib/python3.10/site-packages/nornir_scrapli/tasks/core/send_configs_from_file.py", line 58, in send_configs_from_file
    scrapli_conn = task.host.get_connection("scrapli", task.nornir.config)
  File "/home/ipvzero/Netbox-Demo/.venv/lib/python3.10/site-packages/nornir/core/inventory.py", line 494, in get_connection
    self.open_connection(
  File "/home/ipvzero/Netbox-Demo/.venv/lib/python3.10/site-packages/nornir/core/inventory.py", line 546, in open_connection
    conn_obj.open(
  File "/home/ipvzero/Netbox-Demo/.venv/lib/python3.10/site-packages/nornir_scrapli/connection.py", line 88, in open
    raise NornirScrapliInvalidPlatform(
nornir_scrapli.exceptions.NornirScrapliInvalidPlatform: 'platform' not provided in inventory for host `192.168.179.135`

2023-02-11 05:18:26,109 - nornir.core.task -    ERROR -      start() - Host 'R6': task 'random_configs' failed with traceback:
Traceback (most recent call last):
  File "/home/ipvzero/Netbox-Demo/.venv/lib/python3.10/site-packages/nornir/core/task.py", line 99, in start
    r = self.task(self, **self.params)
  File "/home/ipvzero/Nornir/Progress_Bars/runbook1-progress_bar-send_config.py", line 9, in random_configs
    task.run(task=send_configs_from_file, file="conf.txt")
  File "/home/ipvzero/Netbox-Demo/.venv/lib/python3.10/site-packages/nornir/core/task.py", line 174, in run
    raise NornirSubTaskError(task=run_task, result=r)
nornir.core.exceptions.NornirSubTaskError: Subtask: send_configs_from_file (failed)


2023-02-11 05:18:26,109 - nornir.core.task -    ERROR -      start() - Host 'R7': task 'send_configs_from_file' failed with traceback:
Traceback (most recent call last):
  File "/home/ipvzero/Netbox-Demo/.venv/lib/python3.10/site-packages/nornir/core/task.py", line 99, in start
    r = self.task(self, **self.params)
  File "/home/ipvzero/Netbox-Demo/.venv/lib/python3.10/site-packages/nornir_scrapli/tasks/core/send_configs_from_file.py", line 58, in send_configs_from_file
    scrapli_conn = task.host.get_connection("scrapli", task.nornir.config)
  File "/home/ipvzero/Netbox-Demo/.venv/lib/python3.10/site-packages/nornir/core/inventory.py", line 494, in get_connection
    self.open_connection(
  File "/home/ipvzero/Netbox-Demo/.venv/lib/python3.10/site-packages/nornir/core/inventory.py", line 546, in open_connection
    conn_obj.open(
  File "/home/ipvzero/Netbox-Demo/.venv/lib/python3.10/site-packages/nornir_scrapli/connection.py", line 88, in open
    raise NornirScrapliInvalidPlatform(
nornir_scrapli.exceptions.NornirScrapliInvalidPlatform: 'platform' not provided in inventory for host `192.168.179.136`

2023-02-11 05:18:26,110 - nornir.core.task -    ERROR -      start() - Host 'R7': task 'random_configs' failed with traceback:
Traceback (most recent call last):
  File "/home/ipvzero/Netbox-Demo/.venv/lib/python3.10/site-packages/nornir/core/task.py", line 99, in start
    r = self.task(self, **self.params)
  File "/home/ipvzero/Nornir/Progress_Bars/runbook1-progress_bar-send_config.py", line 9, in random_configs
    task.run(task=send_configs_from_file, file="conf.txt")
  File "/home/ipvzero/Netbox-Demo/.venv/lib/python3.10/site-packages/nornir/core/task.py", line 174, in run
    raise NornirSubTaskError(task=run_task, result=r)
nornir.core.exceptions.NornirSubTaskError: Subtask: send_configs_from_file (failed)


2023-02-11 05:19:29,497 -  nornir.core -     INFO -        run() - Running task 'random_configs' with args {'progress_bar': <tqdm.std.tqdm object at 0x7fe7b61bb760>} on 7 hosts
2023-02-11 05:19:29,499 - nornir.core.task -    ERROR -      start() - Host 'R1': task 'send_configs_from_file' failed with traceback:
Traceback (most recent call last):
  File "/home/ipvzero/Netbox-Demo/.venv/lib/python3.10/site-packages/nornir/core/task.py", line 99, in start
    r = self.task(self, **self.params)
  File "/home/ipvzero/Netbox-Demo/.venv/lib/python3.10/site-packages/nornir_scrapli/tasks/core/send_configs_from_file.py", line 58, in send_configs_from_file
    scrapli_conn = task.host.get_connection("scrapli", task.nornir.config)
  File "/home/ipvzero/Netbox-Demo/.venv/lib/python3.10/site-packages/nornir/core/inventory.py", line 494, in get_connection
    self.open_connection(
  File "/home/ipvzero/Netbox-Demo/.venv/lib/python3.10/site-packages/nornir/core/inventory.py", line 546, in open_connection
    conn_obj.open(
  File "/home/ipvzero/Netbox-Demo/.venv/lib/python3.10/site-packages/nornir_scrapli/connection.py", line 88, in open
    raise NornirScrapliInvalidPlatform(
nornir_scrapli.exceptions.NornirScrapliInvalidPlatform: 'platform' not provided in inventory for host `192.168.179.130`

2023-02-11 05:19:29,500 - nornir.core.task -    ERROR -      start() - Host 'R1': task 'random_configs' failed with traceback:
Traceback (most recent call last):
  File "/home/ipvzero/Netbox-Demo/.venv/lib/python3.10/site-packages/nornir/core/task.py", line 99, in start
    r = self.task(self, **self.params)
  File "/home/ipvzero/Nornir/Progress_Bars/runbook1-progress_bar-send_config.py", line 9, in random_configs
    task.run(task=send_configs_from_file, file="conf.txt")
  File "/home/ipvzero/Netbox-Demo/.venv/lib/python3.10/site-packages/nornir/core/task.py", line 174, in run
    raise NornirSubTaskError(task=run_task, result=r)
nornir.core.exceptions.NornirSubTaskError: Subtask: send_configs_from_file (failed)


2023-02-11 05:19:29,500 - nornir.core.task -    ERROR -      start() - Host 'R2': task 'send_configs_from_file' failed with traceback:
Traceback (most recent call last):
  File "/home/ipvzero/Netbox-Demo/.venv/lib/python3.10/site-packages/nornir/core/task.py", line 99, in start
    r = self.task(self, **self.params)
  File "/home/ipvzero/Netbox-Demo/.venv/lib/python3.10/site-packages/nornir_scrapli/tasks/core/send_configs_from_file.py", line 58, in send_configs_from_file
    scrapli_conn = task.host.get_connection("scrapli", task.nornir.config)
  File "/home/ipvzero/Netbox-Demo/.venv/lib/python3.10/site-packages/nornir/core/inventory.py", line 494, in get_connection
    self.open_connection(
  File "/home/ipvzero/Netbox-Demo/.venv/lib/python3.10/site-packages/nornir/core/inventory.py", line 546, in open_connection
    conn_obj.open(
  File "/home/ipvzero/Netbox-Demo/.venv/lib/python3.10/site-packages/nornir_scrapli/connection.py", line 88, in open
    raise NornirScrapliInvalidPlatform(
nornir_scrapli.exceptions.NornirScrapliInvalidPlatform: 'platform' not provided in inventory for host `192.168.179.131`

2023-02-11 05:19:29,501 - nornir.core.task -    ERROR -      start() - Host 'R2': task 'random_configs' failed with traceback:
Traceback (most recent call last):
  File "/home/ipvzero/Netbox-Demo/.venv/lib/python3.10/site-packages/nornir/core/task.py", line 99, in start
    r = self.task(self, **self.params)
  File "/home/ipvzero/Nornir/Progress_Bars/runbook1-progress_bar-send_config.py", line 9, in random_configs
    task.run(task=send_configs_from_file, file="conf.txt")
  File "/home/ipvzero/Netbox-Demo/.venv/lib/python3.10/site-packages/nornir/core/task.py", line 174, in run
    raise NornirSubTaskError(task=run_task, result=r)
nornir.core.exceptions.NornirSubTaskError: Subtask: send_configs_from_file (failed)


2023-02-11 05:19:29,501 - nornir.core.task -    ERROR -      start() - Host 'R4': task 'send_configs_from_file' failed with traceback:
Traceback (most recent call last):
  File "/home/ipvzero/Netbox-Demo/.venv/lib/python3.10/site-packages/nornir/core/task.py", line 99, in start
    r = self.task(self, **self.params)
  File "/home/ipvzero/Netbox-Demo/.venv/lib/python3.10/site-packages/nornir_scrapli/tasks/core/send_configs_from_file.py", line 58, in send_configs_from_file
    scrapli_conn = task.host.get_connection("scrapli", task.nornir.config)
  File "/home/ipvzero/Netbox-Demo/.venv/lib/python3.10/site-packages/nornir/core/inventory.py", line 494, in get_connection
    self.open_connection(
  File "/home/ipvzero/Netbox-Demo/.venv/lib/python3.10/site-packages/nornir/core/inventory.py", line 546, in open_connection
    conn_obj.open(
  File "/home/ipvzero/Netbox-Demo/.venv/lib/python3.10/site-packages/nornir_scrapli/connection.py", line 88, in open
    raise NornirScrapliInvalidPlatform(
nornir_scrapli.exceptions.NornirScrapliInvalidPlatform: 'platform' not provided in inventory for host `192.168.179.133`

2023-02-11 05:19:29,502 - nornir.core.task -    ERROR -      start() - Host 'R4': task 'random_configs' failed with traceback:
Traceback (most recent call last):
  File "/home/ipvzero/Netbox-Demo/.venv/lib/python3.10/site-packages/nornir/core/task.py", line 99, in start
    r = self.task(self, **self.params)
  File "/home/ipvzero/Nornir/Progress_Bars/runbook1-progress_bar-send_config.py", line 9, in random_configs
    task.run(task=send_configs_from_file, file="conf.txt")
  File "/home/ipvzero/Netbox-Demo/.venv/lib/python3.10/site-packages/nornir/core/task.py", line 174, in run
    raise NornirSubTaskError(task=run_task, result=r)
nornir.core.exceptions.NornirSubTaskError: Subtask: send_configs_from_file (failed)


2023-02-11 05:19:29,502 - nornir.core.task -    ERROR -      start() - Host 'R5': task 'send_configs_from_file' failed with traceback:
Traceback (most recent call last):
  File "/home/ipvzero/Netbox-Demo/.venv/lib/python3.10/site-packages/nornir/core/task.py", line 99, in start
    r = self.task(self, **self.params)
  File "/home/ipvzero/Netbox-Demo/.venv/lib/python3.10/site-packages/nornir_scrapli/tasks/core/send_configs_from_file.py", line 58, in send_configs_from_file
    scrapli_conn = task.host.get_connection("scrapli", task.nornir.config)
  File "/home/ipvzero/Netbox-Demo/.venv/lib/python3.10/site-packages/nornir/core/inventory.py", line 494, in get_connection
    self.open_connection(
  File "/home/ipvzero/Netbox-Demo/.venv/lib/python3.10/site-packages/nornir/core/inventory.py", line 546, in open_connection
    conn_obj.open(
  File "/home/ipvzero/Netbox-Demo/.venv/lib/python3.10/site-packages/nornir_scrapli/connection.py", line 88, in open
    raise NornirScrapliInvalidPlatform(
nornir_scrapli.exceptions.NornirScrapliInvalidPlatform: 'platform' not provided in inventory for host `192.168.179.134`

2023-02-11 05:19:29,502 - nornir.core.task -    ERROR -      start() - Host 'R5': task 'random_configs' failed with traceback:
Traceback (most recent call last):
  File "/home/ipvzero/Netbox-Demo/.venv/lib/python3.10/site-packages/nornir/core/task.py", line 99, in start
    r = self.task(self, **self.params)
  File "/home/ipvzero/Nornir/Progress_Bars/runbook1-progress_bar-send_config.py", line 9, in random_configs
    task.run(task=send_configs_from_file, file="conf.txt")
  File "/home/ipvzero/Netbox-Demo/.venv/lib/python3.10/site-packages/nornir/core/task.py", line 174, in run
    raise NornirSubTaskError(task=run_task, result=r)
nornir.core.exceptions.NornirSubTaskError: Subtask: send_configs_from_file (failed)


2023-02-11 05:19:29,503 - nornir.core.task -    ERROR -      start() - Host 'R6': task 'send_configs_from_file' failed with traceback:
Traceback (most recent call last):
  File "/home/ipvzero/Netbox-Demo/.venv/lib/python3.10/site-packages/nornir/core/task.py", line 99, in start
    r = self.task(self, **self.params)
  File "/home/ipvzero/Netbox-Demo/.venv/lib/python3.10/site-packages/nornir_scrapli/tasks/core/send_configs_from_file.py", line 58, in send_configs_from_file
    scrapli_conn = task.host.get_connection("scrapli", task.nornir.config)
  File "/home/ipvzero/Netbox-Demo/.venv/lib/python3.10/site-packages/nornir/core/inventory.py", line 494, in get_connection
    self.open_connection(
  File "/home/ipvzero/Netbox-Demo/.venv/lib/python3.10/site-packages/nornir/core/inventory.py", line 546, in open_connection
    conn_obj.open(
  File "/home/ipvzero/Netbox-Demo/.venv/lib/python3.10/site-packages/nornir_scrapli/connection.py", line 88, in open
    raise NornirScrapliInvalidPlatform(
nornir_scrapli.exceptions.NornirScrapliInvalidPlatform: 'platform' not provided in inventory for host `192.168.179.135`

2023-02-11 05:19:29,503 - nornir.core.task -    ERROR -      start() - Host 'R6': task 'random_configs' failed with traceback:
Traceback (most recent call last):
  File "/home/ipvzero/Netbox-Demo/.venv/lib/python3.10/site-packages/nornir/core/task.py", line 99, in start
    r = self.task(self, **self.params)
  File "/home/ipvzero/Nornir/Progress_Bars/runbook1-progress_bar-send_config.py", line 9, in random_configs
    task.run(task=send_configs_from_file, file="conf.txt")
  File "/home/ipvzero/Netbox-Demo/.venv/lib/python3.10/site-packages/nornir/core/task.py", line 174, in run
    raise NornirSubTaskError(task=run_task, result=r)
nornir.core.exceptions.NornirSubTaskError: Subtask: send_configs_from_file (failed)


2023-02-11 05:19:29,503 - nornir.core.task -    ERROR -      start() - Host 'R7': task 'send_configs_from_file' failed with traceback:
Traceback (most recent call last):
  File "/home/ipvzero/Netbox-Demo/.venv/lib/python3.10/site-packages/nornir/core/task.py", line 99, in start
    r = self.task(self, **self.params)
  File "/home/ipvzero/Netbox-Demo/.venv/lib/python3.10/site-packages/nornir_scrapli/tasks/core/send_configs_from_file.py", line 58, in send_configs_from_file
    scrapli_conn = task.host.get_connection("scrapli", task.nornir.config)
  File "/home/ipvzero/Netbox-Demo/.venv/lib/python3.10/site-packages/nornir/core/inventory.py", line 494, in get_connection
    self.open_connection(
  File "/home/ipvzero/Netbox-Demo/.venv/lib/python3.10/site-packages/nornir/core/inventory.py", line 546, in open_connection
    conn_obj.open(
  File "/home/ipvzero/Netbox-Demo/.venv/lib/python3.10/site-packages/nornir_scrapli/connection.py", line 88, in open
    raise NornirScrapliInvalidPlatform(
nornir_scrapli.exceptions.NornirScrapliInvalidPlatform: 'platform' not provided in inventory for host `192.168.179.136`

2023-02-11 05:19:29,504 - nornir.core.task -    ERROR -      start() - Host 'R3': task 'send_configs_from_file' failed with traceback:
Traceback (most recent call last):
  File "/home/ipvzero/Netbox-Demo/.venv/lib/python3.10/site-packages/nornir/core/task.py", line 99, in start
    r = self.task(self, **self.params)
  File "/home/ipvzero/Netbox-Demo/.venv/lib/python3.10/site-packages/nornir_scrapli/tasks/core/send_configs_from_file.py", line 58, in send_configs_from_file
    scrapli_conn = task.host.get_connection("scrapli", task.nornir.config)
  File "/home/ipvzero/Netbox-Demo/.venv/lib/python3.10/site-packages/nornir/core/inventory.py", line 494, in get_connection
    self.open_connection(
  File "/home/ipvzero/Netbox-Demo/.venv/lib/python3.10/site-packages/nornir/core/inventory.py", line 546, in open_connection
    conn_obj.open(
  File "/home/ipvzero/Netbox-Demo/.venv/lib/python3.10/site-packages/nornir_scrapli/connection.py", line 88, in open
    raise NornirScrapliInvalidPlatform(
nornir_scrapli.exceptions.NornirScrapliInvalidPlatform: 'platform' not provided in inventory for host `192.168.179.132`

2023-02-11 05:19:29,504 - nornir.core.task -    ERROR -      start() - Host 'R3': task 'random_configs' failed with traceback:
Traceback (most recent call last):
  File "/home/ipvzero/Netbox-Demo/.venv/lib/python3.10/site-packages/nornir/core/task.py", line 99, in start
    r = self.task(self, **self.params)
  File "/home/ipvzero/Nornir/Progress_Bars/runbook1-progress_bar-send_config.py", line 9, in random_configs
    task.run(task=send_configs_from_file, file="conf.txt")
  File "/home/ipvzero/Netbox-Demo/.venv/lib/python3.10/site-packages/nornir/core/task.py", line 174, in run
    raise NornirSubTaskError(task=run_task, result=r)
nornir.core.exceptions.NornirSubTaskError: Subtask: send_configs_from_file (failed)


2023-02-11 05:19:29,504 - nornir.core.task -    ERROR -      start() - Host 'R7': task 'random_configs' failed with traceback:
Traceback (most recent call last):
  File "/home/ipvzero/Netbox-Demo/.venv/lib/python3.10/site-packages/nornir/core/task.py", line 99, in start
    r = self.task(self, **self.params)
  File "/home/ipvzero/Nornir/Progress_Bars/runbook1-progress_bar-send_config.py", line 9, in random_configs
    task.run(task=send_configs_from_file, file="conf.txt")
  File "/home/ipvzero/Netbox-Demo/.venv/lib/python3.10/site-packages/nornir/core/task.py", line 174, in run
    raise NornirSubTaskError(task=run_task, result=r)
nornir.core.exceptions.NornirSubTaskError: Subtask: send_configs_from_file (failed)


2023-02-11 05:20:48,447 -  nornir.core -     INFO -        run() - Running task 'random_configs' with args {'progress_bar': <tqdm.std.tqdm object at 0x7f341bfdb760>} on 7 hosts
2023-02-11 05:20:48,452 - nornir.core.task -    ERROR -      start() - Host 'R1': task 'send_configs_from_file' failed with traceback:
Traceback (most recent call last):
  File "/home/ipvzero/Netbox-Demo/.venv/lib/python3.10/site-packages/nornir/core/task.py", line 99, in start
    r = self.task(self, **self.params)
  File "/home/ipvzero/Netbox-Demo/.venv/lib/python3.10/site-packages/nornir_scrapli/tasks/core/send_configs_from_file.py", line 58, in send_configs_from_file
    scrapli_conn = task.host.get_connection("scrapli", task.nornir.config)
  File "/home/ipvzero/Netbox-Demo/.venv/lib/python3.10/site-packages/nornir/core/inventory.py", line 494, in get_connection
    self.open_connection(
  File "/home/ipvzero/Netbox-Demo/.venv/lib/python3.10/site-packages/nornir/core/inventory.py", line 546, in open_connection
    conn_obj.open(
  File "/home/ipvzero/Netbox-Demo/.venv/lib/python3.10/site-packages/nornir_scrapli/connection.py", line 88, in open
    raise NornirScrapliInvalidPlatform(
nornir_scrapli.exceptions.NornirScrapliInvalidPlatform: 'platform' not provided in inventory for host `192.168.179.130`

2023-02-11 05:20:48,452 - nornir.core.task -    ERROR -      start() - Host 'R1': task 'random_configs' failed with traceback:
Traceback (most recent call last):
  File "/home/ipvzero/Netbox-Demo/.venv/lib/python3.10/site-packages/nornir/core/task.py", line 99, in start
    r = self.task(self, **self.params)
  File "/home/ipvzero/Nornir/Progress_Bars/runbook1-progress_bar-send_config.py", line 9, in random_configs
    task.run(task=send_configs_from_file, file="conf.txt")
  File "/home/ipvzero/Netbox-Demo/.venv/lib/python3.10/site-packages/nornir/core/task.py", line 174, in run
    raise NornirSubTaskError(task=run_task, result=r)
nornir.core.exceptions.NornirSubTaskError: Subtask: send_configs_from_file (failed)


2023-02-11 05:20:48,453 - nornir.core.task -    ERROR -      start() - Host 'R2': task 'send_configs_from_file' failed with traceback:
Traceback (most recent call last):
  File "/home/ipvzero/Netbox-Demo/.venv/lib/python3.10/site-packages/nornir/core/task.py", line 99, in start
    r = self.task(self, **self.params)
  File "/home/ipvzero/Netbox-Demo/.venv/lib/python3.10/site-packages/nornir_scrapli/tasks/core/send_configs_from_file.py", line 58, in send_configs_from_file
    scrapli_conn = task.host.get_connection("scrapli", task.nornir.config)
  File "/home/ipvzero/Netbox-Demo/.venv/lib/python3.10/site-packages/nornir/core/inventory.py", line 494, in get_connection
    self.open_connection(
  File "/home/ipvzero/Netbox-Demo/.venv/lib/python3.10/site-packages/nornir/core/inventory.py", line 546, in open_connection
    conn_obj.open(
  File "/home/ipvzero/Netbox-Demo/.venv/lib/python3.10/site-packages/nornir_scrapli/connection.py", line 88, in open
    raise NornirScrapliInvalidPlatform(
nornir_scrapli.exceptions.NornirScrapliInvalidPlatform: 'platform' not provided in inventory for host `192.168.179.131`

2023-02-11 05:20:48,453 - nornir.core.task -    ERROR -      start() - Host 'R2': task 'random_configs' failed with traceback:
Traceback (most recent call last):
  File "/home/ipvzero/Netbox-Demo/.venv/lib/python3.10/site-packages/nornir/core/task.py", line 99, in start
    r = self.task(self, **self.params)
  File "/home/ipvzero/Nornir/Progress_Bars/runbook1-progress_bar-send_config.py", line 9, in random_configs
    task.run(task=send_configs_from_file, file="conf.txt")
  File "/home/ipvzero/Netbox-Demo/.venv/lib/python3.10/site-packages/nornir/core/task.py", line 174, in run
    raise NornirSubTaskError(task=run_task, result=r)
nornir.core.exceptions.NornirSubTaskError: Subtask: send_configs_from_file (failed)


2023-02-11 05:20:48,459 - nornir.core.task -    ERROR -      start() - Host 'R3': task 'send_configs_from_file' failed with traceback:
Traceback (most recent call last):
  File "/home/ipvzero/Netbox-Demo/.venv/lib/python3.10/site-packages/nornir/core/task.py", line 99, in start
    r = self.task(self, **self.params)
  File "/home/ipvzero/Netbox-Demo/.venv/lib/python3.10/site-packages/nornir_scrapli/tasks/core/send_configs_from_file.py", line 58, in send_configs_from_file
    scrapli_conn = task.host.get_connection("scrapli", task.nornir.config)
  File "/home/ipvzero/Netbox-Demo/.venv/lib/python3.10/site-packages/nornir/core/inventory.py", line 494, in get_connection
    self.open_connection(
  File "/home/ipvzero/Netbox-Demo/.venv/lib/python3.10/site-packages/nornir/core/inventory.py", line 546, in open_connection
    conn_obj.open(
  File "/home/ipvzero/Netbox-Demo/.venv/lib/python3.10/site-packages/nornir_scrapli/connection.py", line 88, in open
    raise NornirScrapliInvalidPlatform(
nornir_scrapli.exceptions.NornirScrapliInvalidPlatform: 'platform' not provided in inventory for host `192.168.179.132`

2023-02-11 05:20:48,459 - nornir.core.task -    ERROR -      start() - Host 'R3': task 'random_configs' failed with traceback:
Traceback (most recent call last):
  File "/home/ipvzero/Netbox-Demo/.venv/lib/python3.10/site-packages/nornir/core/task.py", line 99, in start
    r = self.task(self, **self.params)
  File "/home/ipvzero/Nornir/Progress_Bars/runbook1-progress_bar-send_config.py", line 9, in random_configs
    task.run(task=send_configs_from_file, file="conf.txt")
  File "/home/ipvzero/Netbox-Demo/.venv/lib/python3.10/site-packages/nornir/core/task.py", line 174, in run
    raise NornirSubTaskError(task=run_task, result=r)
nornir.core.exceptions.NornirSubTaskError: Subtask: send_configs_from_file (failed)


2023-02-11 05:20:48,460 - nornir.core.task -    ERROR -      start() - Host 'R4': task 'send_configs_from_file' failed with traceback:
Traceback (most recent call last):
  File "/home/ipvzero/Netbox-Demo/.venv/lib/python3.10/site-packages/nornir/core/task.py", line 99, in start
    r = self.task(self, **self.params)
  File "/home/ipvzero/Netbox-Demo/.venv/lib/python3.10/site-packages/nornir_scrapli/tasks/core/send_configs_from_file.py", line 58, in send_configs_from_file
    scrapli_conn = task.host.get_connection("scrapli", task.nornir.config)
  File "/home/ipvzero/Netbox-Demo/.venv/lib/python3.10/site-packages/nornir/core/inventory.py", line 494, in get_connection
    self.open_connection(
  File "/home/ipvzero/Netbox-Demo/.venv/lib/python3.10/site-packages/nornir/core/inventory.py", line 546, in open_connection
    conn_obj.open(
  File "/home/ipvzero/Netbox-Demo/.venv/lib/python3.10/site-packages/nornir_scrapli/connection.py", line 88, in open
    raise NornirScrapliInvalidPlatform(
nornir_scrapli.exceptions.NornirScrapliInvalidPlatform: 'platform' not provided in inventory for host `192.168.179.133`

2023-02-11 05:20:48,460 - nornir.core.task -    ERROR -      start() - Host 'R4': task 'random_configs' failed with traceback:
Traceback (most recent call last):
  File "/home/ipvzero/Netbox-Demo/.venv/lib/python3.10/site-packages/nornir/core/task.py", line 99, in start
    r = self.task(self, **self.params)
  File "/home/ipvzero/Nornir/Progress_Bars/runbook1-progress_bar-send_config.py", line 9, in random_configs
    task.run(task=send_configs_from_file, file="conf.txt")
  File "/home/ipvzero/Netbox-Demo/.venv/lib/python3.10/site-packages/nornir/core/task.py", line 174, in run
    raise NornirSubTaskError(task=run_task, result=r)
nornir.core.exceptions.NornirSubTaskError: Subtask: send_configs_from_file (failed)


2023-02-11 05:20:48,460 - nornir.core.task -    ERROR -      start() - Host 'R5': task 'send_configs_from_file' failed with traceback:
Traceback (most recent call last):
  File "/home/ipvzero/Netbox-Demo/.venv/lib/python3.10/site-packages/nornir/core/task.py", line 99, in start
    r = self.task(self, **self.params)
  File "/home/ipvzero/Netbox-Demo/.venv/lib/python3.10/site-packages/nornir_scrapli/tasks/core/send_configs_from_file.py", line 58, in send_configs_from_file
    scrapli_conn = task.host.get_connection("scrapli", task.nornir.config)
  File "/home/ipvzero/Netbox-Demo/.venv/lib/python3.10/site-packages/nornir/core/inventory.py", line 494, in get_connection
    self.open_connection(
  File "/home/ipvzero/Netbox-Demo/.venv/lib/python3.10/site-packages/nornir/core/inventory.py", line 546, in open_connection
    conn_obj.open(
  File "/home/ipvzero/Netbox-Demo/.venv/lib/python3.10/site-packages/nornir_scrapli/connection.py", line 88, in open
    raise NornirScrapliInvalidPlatform(
nornir_scrapli.exceptions.NornirScrapliInvalidPlatform: 'platform' not provided in inventory for host `192.168.179.134`

2023-02-11 05:20:48,460 - nornir.core.task -    ERROR -      start() - Host 'R5': task 'random_configs' failed with traceback:
Traceback (most recent call last):
  File "/home/ipvzero/Netbox-Demo/.venv/lib/python3.10/site-packages/nornir/core/task.py", line 99, in start
    r = self.task(self, **self.params)
  File "/home/ipvzero/Nornir/Progress_Bars/runbook1-progress_bar-send_config.py", line 9, in random_configs
    task.run(task=send_configs_from_file, file="conf.txt")
  File "/home/ipvzero/Netbox-Demo/.venv/lib/python3.10/site-packages/nornir/core/task.py", line 174, in run
    raise NornirSubTaskError(task=run_task, result=r)
nornir.core.exceptions.NornirSubTaskError: Subtask: send_configs_from_file (failed)


2023-02-11 05:20:48,461 - nornir.core.task -    ERROR -      start() - Host 'R6': task 'send_configs_from_file' failed with traceback:
Traceback (most recent call last):
  File "/home/ipvzero/Netbox-Demo/.venv/lib/python3.10/site-packages/nornir/core/task.py", line 99, in start
    r = self.task(self, **self.params)
  File "/home/ipvzero/Netbox-Demo/.venv/lib/python3.10/site-packages/nornir_scrapli/tasks/core/send_configs_from_file.py", line 58, in send_configs_from_file
    scrapli_conn = task.host.get_connection("scrapli", task.nornir.config)
  File "/home/ipvzero/Netbox-Demo/.venv/lib/python3.10/site-packages/nornir/core/inventory.py", line 494, in get_connection
    self.open_connection(
  File "/home/ipvzero/Netbox-Demo/.venv/lib/python3.10/site-packages/nornir/core/inventory.py", line 546, in open_connection
    conn_obj.open(
  File "/home/ipvzero/Netbox-Demo/.venv/lib/python3.10/site-packages/nornir_scrapli/connection.py", line 88, in open
    raise NornirScrapliInvalidPlatform(
nornir_scrapli.exceptions.NornirScrapliInvalidPlatform: 'platform' not provided in inventory for host `192.168.179.135`

2023-02-11 05:20:48,461 - nornir.core.task -    ERROR -      start() - Host 'R6': task 'random_configs' failed with traceback:
Traceback (most recent call last):
  File "/home/ipvzero/Netbox-Demo/.venv/lib/python3.10/site-packages/nornir/core/task.py", line 99, in start
    r = self.task(self, **self.params)
  File "/home/ipvzero/Nornir/Progress_Bars/runbook1-progress_bar-send_config.py", line 9, in random_configs
    task.run(task=send_configs_from_file, file="conf.txt")
  File "/home/ipvzero/Netbox-Demo/.venv/lib/python3.10/site-packages/nornir/core/task.py", line 174, in run
    raise NornirSubTaskError(task=run_task, result=r)
nornir.core.exceptions.NornirSubTaskError: Subtask: send_configs_from_file (failed)


2023-02-11 05:20:52,222 - nornir.core.task -    ERROR -      start() - Host 'R7': task 'send_configs_from_file' failed with traceback:
Traceback (most recent call last):
  File "/home/ipvzero/Netbox-Demo/.venv/lib/python3.10/site-packages/nornir/core/task.py", line 99, in start
    r = self.task(self, **self.params)
  File "/home/ipvzero/Netbox-Demo/.venv/lib/python3.10/site-packages/nornir_scrapli/tasks/core/send_configs_from_file.py", line 58, in send_configs_from_file
    scrapli_conn = task.host.get_connection("scrapli", task.nornir.config)
  File "/home/ipvzero/Netbox-Demo/.venv/lib/python3.10/site-packages/nornir/core/inventory.py", line 494, in get_connection
    self.open_connection(
  File "/home/ipvzero/Netbox-Demo/.venv/lib/python3.10/site-packages/nornir/core/inventory.py", line 546, in open_connection
    conn_obj.open(
  File "/home/ipvzero/Netbox-Demo/.venv/lib/python3.10/site-packages/nornir_scrapli/connection.py", line 105, in open
    connection.open()
  File "/home/ipvzero/Netbox-Demo/.venv/lib/python3.10/site-packages/scrapli/driver/base/sync_driver.py", line 88, in open
    self.channel.channel_authenticate_ssh(
  File "/home/ipvzero/Netbox-Demo/.venv/lib/python3.10/site-packages/scrapli/decorators.py", line 216, in decorate
    return _multiprocessing_timeout(
  File "/home/ipvzero/Netbox-Demo/.venv/lib/python3.10/site-packages/scrapli/decorators.py", line 113, in _multiprocessing_timeout
    return future.result()
  File "/usr/lib/python3.10/concurrent/futures/_base.py", line 451, in result
    return self.__get_result()
  File "/usr/lib/python3.10/concurrent/futures/_base.py", line 403, in __get_result
    raise self._exception
  File "/usr/lib/python3.10/concurrent/futures/thread.py", line 58, in run
    result = self.fn(*self.args, **self.kwargs)
  File "/home/ipvzero/Netbox-Demo/.venv/lib/python3.10/site-packages/scrapli/channel/sync_channel.py", line 288, in channel_authenticate_ssh
    self._ssh_message_handler(output=authenticate_buf)
  File "/home/ipvzero/Netbox-Demo/.venv/lib/python3.10/site-packages/scrapli/channel/base_channel.py", line 432, in _ssh_message_handler
    raise ScrapliAuthenticationFailed(msg)
scrapli.exceptions.ScrapliAuthenticationFailed: No route to host

2023-02-11 05:20:52,223 - nornir.core.task -    ERROR -      start() - Host 'R7': task 'random_configs' failed with traceback:
Traceback (most recent call last):
  File "/home/ipvzero/Netbox-Demo/.venv/lib/python3.10/site-packages/nornir/core/task.py", line 99, in start
    r = self.task(self, **self.params)
  File "/home/ipvzero/Nornir/Progress_Bars/runbook1-progress_bar-send_config.py", line 9, in random_configs
    task.run(task=send_configs_from_file, file="conf.txt")
  File "/home/ipvzero/Netbox-Demo/.venv/lib/python3.10/site-packages/nornir/core/task.py", line 174, in run
    raise NornirSubTaskError(task=run_task, result=r)
nornir.core.exceptions.NornirSubTaskError: Subtask: send_configs_from_file (failed)


2023-02-11 05:28:21,066 -  nornir.core -     INFO -        run() - Running task 'random_configs' with args {'progress_bar': <tqdm.std.tqdm object at 0x7f36c11bb760>} on 7 hosts
2023-02-11 05:28:21,068 - nornir.core.task -    ERROR -      start() - Host 'R1': task 'send_configs_from_file' failed with traceback:
Traceback (most recent call last):
  File "/home/ipvzero/Netbox-Demo/.venv/lib/python3.10/site-packages/nornir/core/task.py", line 99, in start
    r = self.task(self, **self.params)
  File "/home/ipvzero/Netbox-Demo/.venv/lib/python3.10/site-packages/nornir_scrapli/tasks/core/send_configs_from_file.py", line 58, in send_configs_from_file
    scrapli_conn = task.host.get_connection("scrapli", task.nornir.config)
  File "/home/ipvzero/Netbox-Demo/.venv/lib/python3.10/site-packages/nornir/core/inventory.py", line 494, in get_connection
    self.open_connection(
  File "/home/ipvzero/Netbox-Demo/.venv/lib/python3.10/site-packages/nornir/core/inventory.py", line 546, in open_connection
    conn_obj.open(
  File "/home/ipvzero/Netbox-Demo/.venv/lib/python3.10/site-packages/nornir_scrapli/connection.py", line 88, in open
    raise NornirScrapliInvalidPlatform(
nornir_scrapli.exceptions.NornirScrapliInvalidPlatform: 'platform' not provided in inventory for host `192.168.179.130`

2023-02-11 05:28:21,069 - nornir.core.task -    ERROR -      start() - Host 'R1': task 'random_configs' failed with traceback:
Traceback (most recent call last):
  File "/home/ipvzero/Netbox-Demo/.venv/lib/python3.10/site-packages/nornir/core/task.py", line 99, in start
    r = self.task(self, **self.params)
  File "/home/ipvzero/Nornir/Progress_Bars/runbook1-progress_bar-send_config.py", line 9, in random_configs
    task.run(task=send_configs_from_file, file="conf.txt")
  File "/home/ipvzero/Netbox-Demo/.venv/lib/python3.10/site-packages/nornir/core/task.py", line 174, in run
    raise NornirSubTaskError(task=run_task, result=r)
nornir.core.exceptions.NornirSubTaskError: Subtask: send_configs_from_file (failed)


2023-02-11 05:28:21,069 - nornir.core.task -    ERROR -      start() - Host 'R2': task 'send_configs_from_file' failed with traceback:
Traceback (most recent call last):
  File "/home/ipvzero/Netbox-Demo/.venv/lib/python3.10/site-packages/nornir/core/task.py", line 99, in start
    r = self.task(self, **self.params)
  File "/home/ipvzero/Netbox-Demo/.venv/lib/python3.10/site-packages/nornir_scrapli/tasks/core/send_configs_from_file.py", line 58, in send_configs_from_file
    scrapli_conn = task.host.get_connection("scrapli", task.nornir.config)
  File "/home/ipvzero/Netbox-Demo/.venv/lib/python3.10/site-packages/nornir/core/inventory.py", line 494, in get_connection
    self.open_connection(
  File "/home/ipvzero/Netbox-Demo/.venv/lib/python3.10/site-packages/nornir/core/inventory.py", line 546, in open_connection
    conn_obj.open(
  File "/home/ipvzero/Netbox-Demo/.venv/lib/python3.10/site-packages/nornir_scrapli/connection.py", line 88, in open
    raise NornirScrapliInvalidPlatform(
nornir_scrapli.exceptions.NornirScrapliInvalidPlatform: 'platform' not provided in inventory for host `192.168.179.131`

2023-02-11 05:28:21,069 - nornir.core.task -    ERROR -      start() - Host 'R2': task 'random_configs' failed with traceback:
Traceback (most recent call last):
  File "/home/ipvzero/Netbox-Demo/.venv/lib/python3.10/site-packages/nornir/core/task.py", line 99, in start
    r = self.task(self, **self.params)
  File "/home/ipvzero/Nornir/Progress_Bars/runbook1-progress_bar-send_config.py", line 9, in random_configs
    task.run(task=send_configs_from_file, file="conf.txt")
  File "/home/ipvzero/Netbox-Demo/.venv/lib/python3.10/site-packages/nornir/core/task.py", line 174, in run
    raise NornirSubTaskError(task=run_task, result=r)
nornir.core.exceptions.NornirSubTaskError: Subtask: send_configs_from_file (failed)


2023-02-11 05:28:21,070 - nornir.core.task -    ERROR -      start() - Host 'R3': task 'send_configs_from_file' failed with traceback:
Traceback (most recent call last):
  File "/home/ipvzero/Netbox-Demo/.venv/lib/python3.10/site-packages/nornir/core/task.py", line 99, in start
    r = self.task(self, **self.params)
  File "/home/ipvzero/Netbox-Demo/.venv/lib/python3.10/site-packages/nornir_scrapli/tasks/core/send_configs_from_file.py", line 58, in send_configs_from_file
    scrapli_conn = task.host.get_connection("scrapli", task.nornir.config)
  File "/home/ipvzero/Netbox-Demo/.venv/lib/python3.10/site-packages/nornir/core/inventory.py", line 494, in get_connection
    self.open_connection(
  File "/home/ipvzero/Netbox-Demo/.venv/lib/python3.10/site-packages/nornir/core/inventory.py", line 546, in open_connection
    conn_obj.open(
  File "/home/ipvzero/Netbox-Demo/.venv/lib/python3.10/site-packages/nornir_scrapli/connection.py", line 88, in open
    raise NornirScrapliInvalidPlatform(
nornir_scrapli.exceptions.NornirScrapliInvalidPlatform: 'platform' not provided in inventory for host `192.168.179.132`

2023-02-11 05:28:21,070 - nornir.core.task -    ERROR -      start() - Host 'R3': task 'random_configs' failed with traceback:
Traceback (most recent call last):
  File "/home/ipvzero/Netbox-Demo/.venv/lib/python3.10/site-packages/nornir/core/task.py", line 99, in start
    r = self.task(self, **self.params)
  File "/home/ipvzero/Nornir/Progress_Bars/runbook1-progress_bar-send_config.py", line 9, in random_configs
    task.run(task=send_configs_from_file, file="conf.txt")
  File "/home/ipvzero/Netbox-Demo/.venv/lib/python3.10/site-packages/nornir/core/task.py", line 174, in run
    raise NornirSubTaskError(task=run_task, result=r)
nornir.core.exceptions.NornirSubTaskError: Subtask: send_configs_from_file (failed)


2023-02-11 05:28:21,070 - nornir.core.task -    ERROR -      start() - Host 'R4': task 'send_configs_from_file' failed with traceback:
Traceback (most recent call last):
  File "/home/ipvzero/Netbox-Demo/.venv/lib/python3.10/site-packages/nornir/core/task.py", line 99, in start
    r = self.task(self, **self.params)
  File "/home/ipvzero/Netbox-Demo/.venv/lib/python3.10/site-packages/nornir_scrapli/tasks/core/send_configs_from_file.py", line 58, in send_configs_from_file
    scrapli_conn = task.host.get_connection("scrapli", task.nornir.config)
  File "/home/ipvzero/Netbox-Demo/.venv/lib/python3.10/site-packages/nornir/core/inventory.py", line 494, in get_connection
    self.open_connection(
  File "/home/ipvzero/Netbox-Demo/.venv/lib/python3.10/site-packages/nornir/core/inventory.py", line 546, in open_connection
    conn_obj.open(
  File "/home/ipvzero/Netbox-Demo/.venv/lib/python3.10/site-packages/nornir_scrapli/connection.py", line 88, in open
    raise NornirScrapliInvalidPlatform(
nornir_scrapli.exceptions.NornirScrapliInvalidPlatform: 'platform' not provided in inventory for host `192.168.179.133`

2023-02-11 05:28:21,070 - nornir.core.task -    ERROR -      start() - Host 'R4': task 'random_configs' failed with traceback:
Traceback (most recent call last):
  File "/home/ipvzero/Netbox-Demo/.venv/lib/python3.10/site-packages/nornir/core/task.py", line 99, in start
    r = self.task(self, **self.params)
  File "/home/ipvzero/Nornir/Progress_Bars/runbook1-progress_bar-send_config.py", line 9, in random_configs
    task.run(task=send_configs_from_file, file="conf.txt")
  File "/home/ipvzero/Netbox-Demo/.venv/lib/python3.10/site-packages/nornir/core/task.py", line 174, in run
    raise NornirSubTaskError(task=run_task, result=r)
nornir.core.exceptions.NornirSubTaskError: Subtask: send_configs_from_file (failed)


2023-02-11 05:28:21,071 - nornir.core.task -    ERROR -      start() - Host 'R5': task 'send_configs_from_file' failed with traceback:
Traceback (most recent call last):
  File "/home/ipvzero/Netbox-Demo/.venv/lib/python3.10/site-packages/nornir/core/task.py", line 99, in start
    r = self.task(self, **self.params)
  File "/home/ipvzero/Netbox-Demo/.venv/lib/python3.10/site-packages/nornir_scrapli/tasks/core/send_configs_from_file.py", line 58, in send_configs_from_file
    scrapli_conn = task.host.get_connection("scrapli", task.nornir.config)
  File "/home/ipvzero/Netbox-Demo/.venv/lib/python3.10/site-packages/nornir/core/inventory.py", line 494, in get_connection
    self.open_connection(
  File "/home/ipvzero/Netbox-Demo/.venv/lib/python3.10/site-packages/nornir/core/inventory.py", line 546, in open_connection
    conn_obj.open(
  File "/home/ipvzero/Netbox-Demo/.venv/lib/python3.10/site-packages/nornir_scrapli/connection.py", line 88, in open
    raise NornirScrapliInvalidPlatform(
nornir_scrapli.exceptions.NornirScrapliInvalidPlatform: 'platform' not provided in inventory for host `192.168.179.134`

2023-02-11 05:28:21,071 - nornir.core.task -    ERROR -      start() - Host 'R5': task 'random_configs' failed with traceback:
Traceback (most recent call last):
  File "/home/ipvzero/Netbox-Demo/.venv/lib/python3.10/site-packages/nornir/core/task.py", line 99, in start
    r = self.task(self, **self.params)
  File "/home/ipvzero/Nornir/Progress_Bars/runbook1-progress_bar-send_config.py", line 9, in random_configs
    task.run(task=send_configs_from_file, file="conf.txt")
  File "/home/ipvzero/Netbox-Demo/.venv/lib/python3.10/site-packages/nornir/core/task.py", line 174, in run
    raise NornirSubTaskError(task=run_task, result=r)
nornir.core.exceptions.NornirSubTaskError: Subtask: send_configs_from_file (failed)


2023-02-11 05:28:21,071 - nornir.core.task -    ERROR -      start() - Host 'R6': task 'send_configs_from_file' failed with traceback:
Traceback (most recent call last):
  File "/home/ipvzero/Netbox-Demo/.venv/lib/python3.10/site-packages/nornir/core/task.py", line 99, in start
    r = self.task(self, **self.params)
  File "/home/ipvzero/Netbox-Demo/.venv/lib/python3.10/site-packages/nornir_scrapli/tasks/core/send_configs_from_file.py", line 58, in send_configs_from_file
    scrapli_conn = task.host.get_connection("scrapli", task.nornir.config)
  File "/home/ipvzero/Netbox-Demo/.venv/lib/python3.10/site-packages/nornir/core/inventory.py", line 494, in get_connection
    self.open_connection(
  File "/home/ipvzero/Netbox-Demo/.venv/lib/python3.10/site-packages/nornir/core/inventory.py", line 546, in open_connection
    conn_obj.open(
  File "/home/ipvzero/Netbox-Demo/.venv/lib/python3.10/site-packages/nornir_scrapli/connection.py", line 88, in open
    raise NornirScrapliInvalidPlatform(
nornir_scrapli.exceptions.NornirScrapliInvalidPlatform: 'platform' not provided in inventory for host `192.168.179.135`

2023-02-11 05:28:21,071 - nornir.core.task -    ERROR -      start() - Host 'R6': task 'random_configs' failed with traceback:
Traceback (most recent call last):
  File "/home/ipvzero/Netbox-Demo/.venv/lib/python3.10/site-packages/nornir/core/task.py", line 99, in start
    r = self.task(self, **self.params)
  File "/home/ipvzero/Nornir/Progress_Bars/runbook1-progress_bar-send_config.py", line 9, in random_configs
    task.run(task=send_configs_from_file, file="conf.txt")
  File "/home/ipvzero/Netbox-Demo/.venv/lib/python3.10/site-packages/nornir/core/task.py", line 174, in run
    raise NornirSubTaskError(task=run_task, result=r)
nornir.core.exceptions.NornirSubTaskError: Subtask: send_configs_from_file (failed)


2023-02-11 05:28:25,600 - nornir.core.task -    ERROR -      start() - Host 'R7': task 'send_configs_from_file' failed with traceback:
Traceback (most recent call last):
  File "/home/ipvzero/Netbox-Demo/.venv/lib/python3.10/site-packages/nornir/core/task.py", line 99, in start
    r = self.task(self, **self.params)
  File "/home/ipvzero/Netbox-Demo/.venv/lib/python3.10/site-packages/nornir_scrapli/tasks/core/send_configs_from_file.py", line 58, in send_configs_from_file
    scrapli_conn = task.host.get_connection("scrapli", task.nornir.config)
  File "/home/ipvzero/Netbox-Demo/.venv/lib/python3.10/site-packages/nornir/core/inventory.py", line 494, in get_connection
    self.open_connection(
  File "/home/ipvzero/Netbox-Demo/.venv/lib/python3.10/site-packages/nornir/core/inventory.py", line 546, in open_connection
    conn_obj.open(
  File "/home/ipvzero/Netbox-Demo/.venv/lib/python3.10/site-packages/nornir_scrapli/connection.py", line 105, in open
    connection.open()
  File "/home/ipvzero/Netbox-Demo/.venv/lib/python3.10/site-packages/scrapli/driver/base/sync_driver.py", line 88, in open
    self.channel.channel_authenticate_ssh(
  File "/home/ipvzero/Netbox-Demo/.venv/lib/python3.10/site-packages/scrapli/decorators.py", line 216, in decorate
    return _multiprocessing_timeout(
  File "/home/ipvzero/Netbox-Demo/.venv/lib/python3.10/site-packages/scrapli/decorators.py", line 113, in _multiprocessing_timeout
    return future.result()
  File "/usr/lib/python3.10/concurrent/futures/_base.py", line 451, in result
    return self.__get_result()
  File "/usr/lib/python3.10/concurrent/futures/_base.py", line 403, in __get_result
    raise self._exception
  File "/usr/lib/python3.10/concurrent/futures/thread.py", line 58, in run
    result = self.fn(*self.args, **self.kwargs)
  File "/home/ipvzero/Netbox-Demo/.venv/lib/python3.10/site-packages/scrapli/channel/sync_channel.py", line 300, in channel_authenticate_ssh
    raise ScrapliAuthenticationFailed(msg)
scrapli.exceptions.ScrapliAuthenticationFailed: password prompt seen more than once, assuming auth failed

2023-02-11 05:28:25,600 - nornir.core.task -    ERROR -      start() - Host 'R7': task 'random_configs' failed with traceback:
Traceback (most recent call last):
  File "/home/ipvzero/Netbox-Demo/.venv/lib/python3.10/site-packages/nornir/core/task.py", line 99, in start
    r = self.task(self, **self.params)
  File "/home/ipvzero/Nornir/Progress_Bars/runbook1-progress_bar-send_config.py", line 9, in random_configs
    task.run(task=send_configs_from_file, file="conf.txt")
  File "/home/ipvzero/Netbox-Demo/.venv/lib/python3.10/site-packages/nornir/core/task.py", line 174, in run
    raise NornirSubTaskError(task=run_task, result=r)
nornir.core.exceptions.NornirSubTaskError: Subtask: send_configs_from_file (failed)


2023-02-11 05:29:02,642 -  nornir.core -     INFO -        run() - Running task 'random_configs' with args {'progress_bar': <tqdm.std.tqdm object at 0x7fdec2fbb760>} on 7 hosts
2023-02-11 05:29:02,644 - nornir.core.task -    ERROR -      start() - Host 'R1': task 'send_configs_from_file' failed with traceback:
Traceback (most recent call last):
  File "/home/ipvzero/Netbox-Demo/.venv/lib/python3.10/site-packages/nornir/core/task.py", line 99, in start
    r = self.task(self, **self.params)
  File "/home/ipvzero/Netbox-Demo/.venv/lib/python3.10/site-packages/nornir_scrapli/tasks/core/send_configs_from_file.py", line 58, in send_configs_from_file
    scrapli_conn = task.host.get_connection("scrapli", task.nornir.config)
  File "/home/ipvzero/Netbox-Demo/.venv/lib/python3.10/site-packages/nornir/core/inventory.py", line 494, in get_connection
    self.open_connection(
  File "/home/ipvzero/Netbox-Demo/.venv/lib/python3.10/site-packages/nornir/core/inventory.py", line 546, in open_connection
    conn_obj.open(
  File "/home/ipvzero/Netbox-Demo/.venv/lib/python3.10/site-packages/nornir_scrapli/connection.py", line 88, in open
    raise NornirScrapliInvalidPlatform(
nornir_scrapli.exceptions.NornirScrapliInvalidPlatform: 'platform' not provided in inventory for host `192.168.179.130`

2023-02-11 05:29:02,644 - nornir.core.task -    ERROR -      start() - Host 'R1': task 'random_configs' failed with traceback:
Traceback (most recent call last):
  File "/home/ipvzero/Netbox-Demo/.venv/lib/python3.10/site-packages/nornir/core/task.py", line 99, in start
    r = self.task(self, **self.params)
  File "/home/ipvzero/Nornir/Progress_Bars/runbook1-progress_bar-send_config.py", line 9, in random_configs
    task.run(task=send_configs_from_file, file="conf.txt")
  File "/home/ipvzero/Netbox-Demo/.venv/lib/python3.10/site-packages/nornir/core/task.py", line 174, in run
    raise NornirSubTaskError(task=run_task, result=r)
nornir.core.exceptions.NornirSubTaskError: Subtask: send_configs_from_file (failed)


2023-02-11 05:29:02,644 - nornir.core.task -    ERROR -      start() - Host 'R2': task 'send_configs_from_file' failed with traceback:
Traceback (most recent call last):
  File "/home/ipvzero/Netbox-Demo/.venv/lib/python3.10/site-packages/nornir/core/task.py", line 99, in start
    r = self.task(self, **self.params)
  File "/home/ipvzero/Netbox-Demo/.venv/lib/python3.10/site-packages/nornir_scrapli/tasks/core/send_configs_from_file.py", line 58, in send_configs_from_file
    scrapli_conn = task.host.get_connection("scrapli", task.nornir.config)
  File "/home/ipvzero/Netbox-Demo/.venv/lib/python3.10/site-packages/nornir/core/inventory.py", line 494, in get_connection
    self.open_connection(
  File "/home/ipvzero/Netbox-Demo/.venv/lib/python3.10/site-packages/nornir/core/inventory.py", line 546, in open_connection
    conn_obj.open(
  File "/home/ipvzero/Netbox-Demo/.venv/lib/python3.10/site-packages/nornir_scrapli/connection.py", line 88, in open
    raise NornirScrapliInvalidPlatform(
nornir_scrapli.exceptions.NornirScrapliInvalidPlatform: 'platform' not provided in inventory for host `192.168.179.131`

2023-02-11 05:29:02,644 - nornir.core.task -    ERROR -      start() - Host 'R2': task 'random_configs' failed with traceback:
Traceback (most recent call last):
  File "/home/ipvzero/Netbox-Demo/.venv/lib/python3.10/site-packages/nornir/core/task.py", line 99, in start
    r = self.task(self, **self.params)
  File "/home/ipvzero/Nornir/Progress_Bars/runbook1-progress_bar-send_config.py", line 9, in random_configs
    task.run(task=send_configs_from_file, file="conf.txt")
  File "/home/ipvzero/Netbox-Demo/.venv/lib/python3.10/site-packages/nornir/core/task.py", line 174, in run
    raise NornirSubTaskError(task=run_task, result=r)
nornir.core.exceptions.NornirSubTaskError: Subtask: send_configs_from_file (failed)


2023-02-11 05:29:02,645 - nornir.core.task -    ERROR -      start() - Host 'R3': task 'send_configs_from_file' failed with traceback:
Traceback (most recent call last):
  File "/home/ipvzero/Netbox-Demo/.venv/lib/python3.10/site-packages/nornir/core/task.py", line 99, in start
    r = self.task(self, **self.params)
  File "/home/ipvzero/Netbox-Demo/.venv/lib/python3.10/site-packages/nornir_scrapli/tasks/core/send_configs_from_file.py", line 58, in send_configs_from_file
    scrapli_conn = task.host.get_connection("scrapli", task.nornir.config)
  File "/home/ipvzero/Netbox-Demo/.venv/lib/python3.10/site-packages/nornir/core/inventory.py", line 494, in get_connection
    self.open_connection(
  File "/home/ipvzero/Netbox-Demo/.venv/lib/python3.10/site-packages/nornir/core/inventory.py", line 546, in open_connection
    conn_obj.open(
  File "/home/ipvzero/Netbox-Demo/.venv/lib/python3.10/site-packages/nornir_scrapli/connection.py", line 88, in open
    raise NornirScrapliInvalidPlatform(
nornir_scrapli.exceptions.NornirScrapliInvalidPlatform: 'platform' not provided in inventory for host `192.168.179.132`

2023-02-11 05:29:02,645 - nornir.core.task -    ERROR -      start() - Host 'R3': task 'random_configs' failed with traceback:
Traceback (most recent call last):
  File "/home/ipvzero/Netbox-Demo/.venv/lib/python3.10/site-packages/nornir/core/task.py", line 99, in start
    r = self.task(self, **self.params)
  File "/home/ipvzero/Nornir/Progress_Bars/runbook1-progress_bar-send_config.py", line 9, in random_configs
    task.run(task=send_configs_from_file, file="conf.txt")
  File "/home/ipvzero/Netbox-Demo/.venv/lib/python3.10/site-packages/nornir/core/task.py", line 174, in run
    raise NornirSubTaskError(task=run_task, result=r)
nornir.core.exceptions.NornirSubTaskError: Subtask: send_configs_from_file (failed)


2023-02-11 05:29:02,645 - nornir.core.task -    ERROR -      start() - Host 'R4': task 'send_configs_from_file' failed with traceback:
Traceback (most recent call last):
  File "/home/ipvzero/Netbox-Demo/.venv/lib/python3.10/site-packages/nornir/core/task.py", line 99, in start
    r = self.task(self, **self.params)
  File "/home/ipvzero/Netbox-Demo/.venv/lib/python3.10/site-packages/nornir_scrapli/tasks/core/send_configs_from_file.py", line 58, in send_configs_from_file
    scrapli_conn = task.host.get_connection("scrapli", task.nornir.config)
  File "/home/ipvzero/Netbox-Demo/.venv/lib/python3.10/site-packages/nornir/core/inventory.py", line 494, in get_connection
    self.open_connection(
  File "/home/ipvzero/Netbox-Demo/.venv/lib/python3.10/site-packages/nornir/core/inventory.py", line 546, in open_connection
    conn_obj.open(
  File "/home/ipvzero/Netbox-Demo/.venv/lib/python3.10/site-packages/nornir_scrapli/connection.py", line 88, in open
    raise NornirScrapliInvalidPlatform(
nornir_scrapli.exceptions.NornirScrapliInvalidPlatform: 'platform' not provided in inventory for host `192.168.179.133`

2023-02-11 05:29:02,645 - nornir.core.task -    ERROR -      start() - Host 'R4': task 'random_configs' failed with traceback:
Traceback (most recent call last):
  File "/home/ipvzero/Netbox-Demo/.venv/lib/python3.10/site-packages/nornir/core/task.py", line 99, in start
    r = self.task(self, **self.params)
  File "/home/ipvzero/Nornir/Progress_Bars/runbook1-progress_bar-send_config.py", line 9, in random_configs
    task.run(task=send_configs_from_file, file="conf.txt")
  File "/home/ipvzero/Netbox-Demo/.venv/lib/python3.10/site-packages/nornir/core/task.py", line 174, in run
    raise NornirSubTaskError(task=run_task, result=r)
nornir.core.exceptions.NornirSubTaskError: Subtask: send_configs_from_file (failed)


2023-02-11 05:29:02,645 - nornir.core.task -    ERROR -      start() - Host 'R5': task 'send_configs_from_file' failed with traceback:
Traceback (most recent call last):
  File "/home/ipvzero/Netbox-Demo/.venv/lib/python3.10/site-packages/nornir/core/task.py", line 99, in start
    r = self.task(self, **self.params)
  File "/home/ipvzero/Netbox-Demo/.venv/lib/python3.10/site-packages/nornir_scrapli/tasks/core/send_configs_from_file.py", line 58, in send_configs_from_file
    scrapli_conn = task.host.get_connection("scrapli", task.nornir.config)
  File "/home/ipvzero/Netbox-Demo/.venv/lib/python3.10/site-packages/nornir/core/inventory.py", line 494, in get_connection
    self.open_connection(
  File "/home/ipvzero/Netbox-Demo/.venv/lib/python3.10/site-packages/nornir/core/inventory.py", line 546, in open_connection
    conn_obj.open(
  File "/home/ipvzero/Netbox-Demo/.venv/lib/python3.10/site-packages/nornir_scrapli/connection.py", line 88, in open
    raise NornirScrapliInvalidPlatform(
nornir_scrapli.exceptions.NornirScrapliInvalidPlatform: 'platform' not provided in inventory for host `192.168.179.134`

2023-02-11 05:29:02,646 - nornir.core.task -    ERROR -      start() - Host 'R5': task 'random_configs' failed with traceback:
Traceback (most recent call last):
  File "/home/ipvzero/Netbox-Demo/.venv/lib/python3.10/site-packages/nornir/core/task.py", line 99, in start
    r = self.task(self, **self.params)
  File "/home/ipvzero/Nornir/Progress_Bars/runbook1-progress_bar-send_config.py", line 9, in random_configs
    task.run(task=send_configs_from_file, file="conf.txt")
  File "/home/ipvzero/Netbox-Demo/.venv/lib/python3.10/site-packages/nornir/core/task.py", line 174, in run
    raise NornirSubTaskError(task=run_task, result=r)
nornir.core.exceptions.NornirSubTaskError: Subtask: send_configs_from_file (failed)


2023-02-11 05:29:02,646 - nornir.core.task -    ERROR -      start() - Host 'R6': task 'send_configs_from_file' failed with traceback:
Traceback (most recent call last):
  File "/home/ipvzero/Netbox-Demo/.venv/lib/python3.10/site-packages/nornir/core/task.py", line 99, in start
    r = self.task(self, **self.params)
  File "/home/ipvzero/Netbox-Demo/.venv/lib/python3.10/site-packages/nornir_scrapli/tasks/core/send_configs_from_file.py", line 58, in send_configs_from_file
    scrapli_conn = task.host.get_connection("scrapli", task.nornir.config)
  File "/home/ipvzero/Netbox-Demo/.venv/lib/python3.10/site-packages/nornir/core/inventory.py", line 494, in get_connection
    self.open_connection(
  File "/home/ipvzero/Netbox-Demo/.venv/lib/python3.10/site-packages/nornir/core/inventory.py", line 546, in open_connection
    conn_obj.open(
  File "/home/ipvzero/Netbox-Demo/.venv/lib/python3.10/site-packages/nornir_scrapli/connection.py", line 88, in open
    raise NornirScrapliInvalidPlatform(
nornir_scrapli.exceptions.NornirScrapliInvalidPlatform: 'platform' not provided in inventory for host `192.168.179.135`

2023-02-11 05:29:02,646 - nornir.core.task -    ERROR -      start() - Host 'R6': task 'random_configs' failed with traceback:
Traceback (most recent call last):
  File "/home/ipvzero/Netbox-Demo/.venv/lib/python3.10/site-packages/nornir/core/task.py", line 99, in start
    r = self.task(self, **self.params)
  File "/home/ipvzero/Nornir/Progress_Bars/runbook1-progress_bar-send_config.py", line 9, in random_configs
    task.run(task=send_configs_from_file, file="conf.txt")
  File "/home/ipvzero/Netbox-Demo/.venv/lib/python3.10/site-packages/nornir/core/task.py", line 174, in run
    raise NornirSubTaskError(task=run_task, result=r)
nornir.core.exceptions.NornirSubTaskError: Subtask: send_configs_from_file (failed)


2023-02-11 05:29:07,356 - nornir.core.task -    ERROR -      start() - Host 'R7': task 'send_configs_from_file' failed with traceback:
Traceback (most recent call last):
  File "/home/ipvzero/Netbox-Demo/.venv/lib/python3.10/site-packages/nornir/core/task.py", line 99, in start
    r = self.task(self, **self.params)
  File "/home/ipvzero/Netbox-Demo/.venv/lib/python3.10/site-packages/nornir_scrapli/tasks/core/send_configs_from_file.py", line 58, in send_configs_from_file
    scrapli_conn = task.host.get_connection("scrapli", task.nornir.config)
  File "/home/ipvzero/Netbox-Demo/.venv/lib/python3.10/site-packages/nornir/core/inventory.py", line 494, in get_connection
    self.open_connection(
  File "/home/ipvzero/Netbox-Demo/.venv/lib/python3.10/site-packages/nornir/core/inventory.py", line 546, in open_connection
    conn_obj.open(
  File "/home/ipvzero/Netbox-Demo/.venv/lib/python3.10/site-packages/nornir_scrapli/connection.py", line 105, in open
    connection.open()
  File "/home/ipvzero/Netbox-Demo/.venv/lib/python3.10/site-packages/scrapli/driver/base/sync_driver.py", line 88, in open
    self.channel.channel_authenticate_ssh(
  File "/home/ipvzero/Netbox-Demo/.venv/lib/python3.10/site-packages/scrapli/decorators.py", line 216, in decorate
    return _multiprocessing_timeout(
  File "/home/ipvzero/Netbox-Demo/.venv/lib/python3.10/site-packages/scrapli/decorators.py", line 113, in _multiprocessing_timeout
    return future.result()
  File "/usr/lib/python3.10/concurrent/futures/_base.py", line 451, in result
    return self.__get_result()
  File "/usr/lib/python3.10/concurrent/futures/_base.py", line 403, in __get_result
    raise self._exception
  File "/usr/lib/python3.10/concurrent/futures/thread.py", line 58, in run
    result = self.fn(*self.args, **self.kwargs)
  File "/home/ipvzero/Netbox-Demo/.venv/lib/python3.10/site-packages/scrapli/channel/sync_channel.py", line 300, in channel_authenticate_ssh
    raise ScrapliAuthenticationFailed(msg)
scrapli.exceptions.ScrapliAuthenticationFailed: password prompt seen more than once, assuming auth failed

2023-02-11 05:29:07,356 - nornir.core.task -    ERROR -      start() - Host 'R7': task 'random_configs' failed with traceback:
Traceback (most recent call last):
  File "/home/ipvzero/Netbox-Demo/.venv/lib/python3.10/site-packages/nornir/core/task.py", line 99, in start
    r = self.task(self, **self.params)
  File "/home/ipvzero/Nornir/Progress_Bars/runbook1-progress_bar-send_config.py", line 9, in random_configs
    task.run(task=send_configs_from_file, file="conf.txt")
  File "/home/ipvzero/Netbox-Demo/.venv/lib/python3.10/site-packages/nornir/core/task.py", line 174, in run
    raise NornirSubTaskError(task=run_task, result=r)
nornir.core.exceptions.NornirSubTaskError: Subtask: send_configs_from_file (failed)


2023-02-11 05:29:54,447 -  nornir.core -     INFO -        run() - Running task 'random_configs' with args {'progress_bar': <tqdm.std.tqdm object at 0x7fbffb87fcd0>} on 7 hosts
2023-02-11 05:29:54,450 - nornir.core.task -    ERROR -      start() - Host 'R1': task 'send_configs_from_file' failed with traceback:
Traceback (most recent call last):
  File "/home/ipvzero/Netbox-Demo/.venv/lib/python3.10/site-packages/nornir/core/task.py", line 99, in start
    r = self.task(self, **self.params)
  File "/home/ipvzero/Netbox-Demo/.venv/lib/python3.10/site-packages/nornir_scrapli/tasks/core/send_configs_from_file.py", line 58, in send_configs_from_file
    scrapli_conn = task.host.get_connection("scrapli", task.nornir.config)
  File "/home/ipvzero/Netbox-Demo/.venv/lib/python3.10/site-packages/nornir/core/inventory.py", line 494, in get_connection
    self.open_connection(
  File "/home/ipvzero/Netbox-Demo/.venv/lib/python3.10/site-packages/nornir/core/inventory.py", line 546, in open_connection
    conn_obj.open(
  File "/home/ipvzero/Netbox-Demo/.venv/lib/python3.10/site-packages/nornir_scrapli/connection.py", line 88, in open
    raise NornirScrapliInvalidPlatform(
nornir_scrapli.exceptions.NornirScrapliInvalidPlatform: 'platform' not provided in inventory for host `192.168.179.130`

2023-02-11 05:29:54,451 - nornir.core.task -    ERROR -      start() - Host 'R2': task 'send_configs_from_file' failed with traceback:
Traceback (most recent call last):
  File "/home/ipvzero/Netbox-Demo/.venv/lib/python3.10/site-packages/nornir/core/task.py", line 99, in start
    r = self.task(self, **self.params)
  File "/home/ipvzero/Netbox-Demo/.venv/lib/python3.10/site-packages/nornir_scrapli/tasks/core/send_configs_from_file.py", line 58, in send_configs_from_file
    scrapli_conn = task.host.get_connection("scrapli", task.nornir.config)
  File "/home/ipvzero/Netbox-Demo/.venv/lib/python3.10/site-packages/nornir/core/inventory.py", line 494, in get_connection
    self.open_connection(
  File "/home/ipvzero/Netbox-Demo/.venv/lib/python3.10/site-packages/nornir/core/inventory.py", line 546, in open_connection
    conn_obj.open(
  File "/home/ipvzero/Netbox-Demo/.venv/lib/python3.10/site-packages/nornir_scrapli/connection.py", line 88, in open
    raise NornirScrapliInvalidPlatform(
nornir_scrapli.exceptions.NornirScrapliInvalidPlatform: 'platform' not provided in inventory for host `192.168.179.131`

2023-02-11 05:29:54,451 - nornir.core.task -    ERROR -      start() - Host 'R1': task 'random_configs' failed with traceback:
Traceback (most recent call last):
  File "/home/ipvzero/Netbox-Demo/.venv/lib/python3.10/site-packages/nornir/core/task.py", line 99, in start
    r = self.task(self, **self.params)
  File "/home/ipvzero/Nornir/Progress_Bars/runbook1-progress_bar-send_config.py", line 13, in random_configs
    task.run(task=send_configs_from_file, file="conf.txt")
  File "/home/ipvzero/Netbox-Demo/.venv/lib/python3.10/site-packages/nornir/core/task.py", line 174, in run
    raise NornirSubTaskError(task=run_task, result=r)
nornir.core.exceptions.NornirSubTaskError: Subtask: send_configs_from_file (failed)


2023-02-11 05:29:54,452 - nornir.core.task -    ERROR -      start() - Host 'R3': task 'send_configs_from_file' failed with traceback:
Traceback (most recent call last):
  File "/home/ipvzero/Netbox-Demo/.venv/lib/python3.10/site-packages/nornir/core/task.py", line 99, in start
    r = self.task(self, **self.params)
  File "/home/ipvzero/Netbox-Demo/.venv/lib/python3.10/site-packages/nornir_scrapli/tasks/core/send_configs_from_file.py", line 58, in send_configs_from_file
    scrapli_conn = task.host.get_connection("scrapli", task.nornir.config)
  File "/home/ipvzero/Netbox-Demo/.venv/lib/python3.10/site-packages/nornir/core/inventory.py", line 494, in get_connection
    self.open_connection(
  File "/home/ipvzero/Netbox-Demo/.venv/lib/python3.10/site-packages/nornir/core/inventory.py", line 546, in open_connection
    conn_obj.open(
  File "/home/ipvzero/Netbox-Demo/.venv/lib/python3.10/site-packages/nornir_scrapli/connection.py", line 88, in open
    raise NornirScrapliInvalidPlatform(
nornir_scrapli.exceptions.NornirScrapliInvalidPlatform: 'platform' not provided in inventory for host `192.168.179.132`

2023-02-11 05:29:54,452 - nornir.core.task -    ERROR -      start() - Host 'R2': task 'random_configs' failed with traceback:
Traceback (most recent call last):
  File "/home/ipvzero/Netbox-Demo/.venv/lib/python3.10/site-packages/nornir/core/task.py", line 99, in start
    r = self.task(self, **self.params)
  File "/home/ipvzero/Nornir/Progress_Bars/runbook1-progress_bar-send_config.py", line 13, in random_configs
    task.run(task=send_configs_from_file, file="conf.txt")
  File "/home/ipvzero/Netbox-Demo/.venv/lib/python3.10/site-packages/nornir/core/task.py", line 174, in run
    raise NornirSubTaskError(task=run_task, result=r)
nornir.core.exceptions.NornirSubTaskError: Subtask: send_configs_from_file (failed)


2023-02-11 05:29:54,452 - nornir.core.task -    ERROR -      start() - Host 'R3': task 'random_configs' failed with traceback:
Traceback (most recent call last):
  File "/home/ipvzero/Netbox-Demo/.venv/lib/python3.10/site-packages/nornir/core/task.py", line 99, in start
    r = self.task(self, **self.params)
  File "/home/ipvzero/Nornir/Progress_Bars/runbook1-progress_bar-send_config.py", line 13, in random_configs
    task.run(task=send_configs_from_file, file="conf.txt")
  File "/home/ipvzero/Netbox-Demo/.venv/lib/python3.10/site-packages/nornir/core/task.py", line 174, in run
    raise NornirSubTaskError(task=run_task, result=r)
nornir.core.exceptions.NornirSubTaskError: Subtask: send_configs_from_file (failed)


2023-02-11 05:29:54,453 - nornir.core.task -    ERROR -      start() - Host 'R4': task 'send_configs_from_file' failed with traceback:
Traceback (most recent call last):
  File "/home/ipvzero/Netbox-Demo/.venv/lib/python3.10/site-packages/nornir/core/task.py", line 99, in start
    r = self.task(self, **self.params)
  File "/home/ipvzero/Netbox-Demo/.venv/lib/python3.10/site-packages/nornir_scrapli/tasks/core/send_configs_from_file.py", line 58, in send_configs_from_file
    scrapli_conn = task.host.get_connection("scrapli", task.nornir.config)
  File "/home/ipvzero/Netbox-Demo/.venv/lib/python3.10/site-packages/nornir/core/inventory.py", line 494, in get_connection
    self.open_connection(
  File "/home/ipvzero/Netbox-Demo/.venv/lib/python3.10/site-packages/nornir/core/inventory.py", line 546, in open_connection
    conn_obj.open(
  File "/home/ipvzero/Netbox-Demo/.venv/lib/python3.10/site-packages/nornir_scrapli/connection.py", line 88, in open
    raise NornirScrapliInvalidPlatform(
nornir_scrapli.exceptions.NornirScrapliInvalidPlatform: 'platform' not provided in inventory for host `192.168.179.133`

2023-02-11 05:29:54,453 - nornir.core.task -    ERROR -      start() - Host 'R4': task 'random_configs' failed with traceback:
Traceback (most recent call last):
  File "/home/ipvzero/Netbox-Demo/.venv/lib/python3.10/site-packages/nornir/core/task.py", line 99, in start
    r = self.task(self, **self.params)
  File "/home/ipvzero/Nornir/Progress_Bars/runbook1-progress_bar-send_config.py", line 13, in random_configs
    task.run(task=send_configs_from_file, file="conf.txt")
  File "/home/ipvzero/Netbox-Demo/.venv/lib/python3.10/site-packages/nornir/core/task.py", line 174, in run
    raise NornirSubTaskError(task=run_task, result=r)
nornir.core.exceptions.NornirSubTaskError: Subtask: send_configs_from_file (failed)


2023-02-11 05:29:54,453 - nornir.core.task -    ERROR -      start() - Host 'R6': task 'send_configs_from_file' failed with traceback:
Traceback (most recent call last):
  File "/home/ipvzero/Netbox-Demo/.venv/lib/python3.10/site-packages/nornir/core/task.py", line 99, in start
    r = self.task(self, **self.params)
  File "/home/ipvzero/Netbox-Demo/.venv/lib/python3.10/site-packages/nornir_scrapli/tasks/core/send_configs_from_file.py", line 58, in send_configs_from_file
    scrapli_conn = task.host.get_connection("scrapli", task.nornir.config)
  File "/home/ipvzero/Netbox-Demo/.venv/lib/python3.10/site-packages/nornir/core/inventory.py", line 494, in get_connection
    self.open_connection(
  File "/home/ipvzero/Netbox-Demo/.venv/lib/python3.10/site-packages/nornir/core/inventory.py", line 546, in open_connection
    conn_obj.open(
  File "/home/ipvzero/Netbox-Demo/.venv/lib/python3.10/site-packages/nornir_scrapli/connection.py", line 88, in open
    raise NornirScrapliInvalidPlatform(
nornir_scrapli.exceptions.NornirScrapliInvalidPlatform: 'platform' not provided in inventory for host `192.168.179.135`

2023-02-11 05:29:54,454 - nornir.core.task -    ERROR -      start() - Host 'R6': task 'random_configs' failed with traceback:
Traceback (most recent call last):
  File "/home/ipvzero/Netbox-Demo/.venv/lib/python3.10/site-packages/nornir/core/task.py", line 99, in start
    r = self.task(self, **self.params)
  File "/home/ipvzero/Nornir/Progress_Bars/runbook1-progress_bar-send_config.py", line 13, in random_configs
    task.run(task=send_configs_from_file, file="conf.txt")
  File "/home/ipvzero/Netbox-Demo/.venv/lib/python3.10/site-packages/nornir/core/task.py", line 174, in run
    raise NornirSubTaskError(task=run_task, result=r)
nornir.core.exceptions.NornirSubTaskError: Subtask: send_configs_from_file (failed)


2023-02-11 05:29:54,454 - nornir.core.task -    ERROR -      start() - Host 'R5': task 'send_configs_from_file' failed with traceback:
Traceback (most recent call last):
  File "/home/ipvzero/Netbox-Demo/.venv/lib/python3.10/site-packages/nornir/core/task.py", line 99, in start
    r = self.task(self, **self.params)
  File "/home/ipvzero/Netbox-Demo/.venv/lib/python3.10/site-packages/nornir_scrapli/tasks/core/send_configs_from_file.py", line 58, in send_configs_from_file
    scrapli_conn = task.host.get_connection("scrapli", task.nornir.config)
  File "/home/ipvzero/Netbox-Demo/.venv/lib/python3.10/site-packages/nornir/core/inventory.py", line 494, in get_connection
    self.open_connection(
  File "/home/ipvzero/Netbox-Demo/.venv/lib/python3.10/site-packages/nornir/core/inventory.py", line 546, in open_connection
    conn_obj.open(
  File "/home/ipvzero/Netbox-Demo/.venv/lib/python3.10/site-packages/nornir_scrapli/connection.py", line 88, in open
    raise NornirScrapliInvalidPlatform(
nornir_scrapli.exceptions.NornirScrapliInvalidPlatform: 'platform' not provided in inventory for host `192.168.179.134`

2023-02-11 05:29:54,455 - nornir.core.task -    ERROR -      start() - Host 'R5': task 'random_configs' failed with traceback:
Traceback (most recent call last):
  File "/home/ipvzero/Netbox-Demo/.venv/lib/python3.10/site-packages/nornir/core/task.py", line 99, in start
    r = self.task(self, **self.params)
  File "/home/ipvzero/Nornir/Progress_Bars/runbook1-progress_bar-send_config.py", line 13, in random_configs
    task.run(task=send_configs_from_file, file="conf.txt")
  File "/home/ipvzero/Netbox-Demo/.venv/lib/python3.10/site-packages/nornir/core/task.py", line 174, in run
    raise NornirSubTaskError(task=run_task, result=r)
nornir.core.exceptions.NornirSubTaskError: Subtask: send_configs_from_file (failed)


2023-02-11 05:29:59,150 - nornir.core.task -    ERROR -      start() - Host 'R7': task 'send_configs_from_file' failed with traceback:
Traceback (most recent call last):
  File "/home/ipvzero/Netbox-Demo/.venv/lib/python3.10/site-packages/nornir/core/task.py", line 99, in start
    r = self.task(self, **self.params)
  File "/home/ipvzero/Netbox-Demo/.venv/lib/python3.10/site-packages/nornir_scrapli/tasks/core/send_configs_from_file.py", line 58, in send_configs_from_file
    scrapli_conn = task.host.get_connection("scrapli", task.nornir.config)
  File "/home/ipvzero/Netbox-Demo/.venv/lib/python3.10/site-packages/nornir/core/inventory.py", line 494, in get_connection
    self.open_connection(
  File "/home/ipvzero/Netbox-Demo/.venv/lib/python3.10/site-packages/nornir/core/inventory.py", line 546, in open_connection
    conn_obj.open(
  File "/home/ipvzero/Netbox-Demo/.venv/lib/python3.10/site-packages/nornir_scrapli/connection.py", line 105, in open
    connection.open()
  File "/home/ipvzero/Netbox-Demo/.venv/lib/python3.10/site-packages/scrapli/driver/base/sync_driver.py", line 88, in open
    self.channel.channel_authenticate_ssh(
  File "/home/ipvzero/Netbox-Demo/.venv/lib/python3.10/site-packages/scrapli/decorators.py", line 216, in decorate
    return _multiprocessing_timeout(
  File "/home/ipvzero/Netbox-Demo/.venv/lib/python3.10/site-packages/scrapli/decorators.py", line 113, in _multiprocessing_timeout
    return future.result()
  File "/usr/lib/python3.10/concurrent/futures/_base.py", line 451, in result
    return self.__get_result()
  File "/usr/lib/python3.10/concurrent/futures/_base.py", line 403, in __get_result
    raise self._exception
  File "/usr/lib/python3.10/concurrent/futures/thread.py", line 58, in run
    result = self.fn(*self.args, **self.kwargs)
  File "/home/ipvzero/Netbox-Demo/.venv/lib/python3.10/site-packages/scrapli/channel/sync_channel.py", line 300, in channel_authenticate_ssh
    raise ScrapliAuthenticationFailed(msg)
scrapli.exceptions.ScrapliAuthenticationFailed: password prompt seen more than once, assuming auth failed

2023-02-11 05:29:59,151 - nornir.core.task -    ERROR -      start() - Host 'R7': task 'random_configs' failed with traceback:
Traceback (most recent call last):
  File "/home/ipvzero/Netbox-Demo/.venv/lib/python3.10/site-packages/nornir/core/task.py", line 99, in start
    r = self.task(self, **self.params)
  File "/home/ipvzero/Nornir/Progress_Bars/runbook1-progress_bar-send_config.py", line 13, in random_configs
    task.run(task=send_configs_from_file, file="conf.txt")
  File "/home/ipvzero/Netbox-Demo/.venv/lib/python3.10/site-packages/nornir/core/task.py", line 174, in run
    raise NornirSubTaskError(task=run_task, result=r)
nornir.core.exceptions.NornirSubTaskError: Subtask: send_configs_from_file (failed)


2023-02-11 05:30:56,289 -  nornir.core -     INFO -        run() - Running task 'random_configs' with args {'progress_bar': <tqdm.std.tqdm object at 0x7fdaabbb3d60>} on 7 hosts
2023-02-11 05:30:56,292 - nornir.core.task -    ERROR -      start() - Host 'R1': task 'send_configs_from_file' failed with traceback:
Traceback (most recent call last):
  File "/home/ipvzero/Netbox-Demo/.venv/lib/python3.10/site-packages/nornir/core/task.py", line 99, in start
    r = self.task(self, **self.params)
  File "/home/ipvzero/Netbox-Demo/.venv/lib/python3.10/site-packages/nornir_scrapli/tasks/core/send_configs_from_file.py", line 58, in send_configs_from_file
    scrapli_conn = task.host.get_connection("scrapli", task.nornir.config)
  File "/home/ipvzero/Netbox-Demo/.venv/lib/python3.10/site-packages/nornir/core/inventory.py", line 494, in get_connection
    self.open_connection(
  File "/home/ipvzero/Netbox-Demo/.venv/lib/python3.10/site-packages/nornir/core/inventory.py", line 546, in open_connection
    conn_obj.open(
  File "/home/ipvzero/Netbox-Demo/.venv/lib/python3.10/site-packages/nornir_scrapli/connection.py", line 88, in open
    raise NornirScrapliInvalidPlatform(
nornir_scrapli.exceptions.NornirScrapliInvalidPlatform: 'platform' not provided in inventory for host `192.168.179.130`

2023-02-11 05:30:56,293 - nornir.core.task -    ERROR -      start() - Host 'R1': task 'random_configs' failed with traceback:
Traceback (most recent call last):
  File "/home/ipvzero/Netbox-Demo/.venv/lib/python3.10/site-packages/nornir/core/task.py", line 99, in start
    r = self.task(self, **self.params)
  File "/home/ipvzero/Nornir/Progress_Bars/runbook1-progress_bar-send_config.py", line 13, in random_configs
    task.run(task=send_configs_from_file, file="conf.txt")
  File "/home/ipvzero/Netbox-Demo/.venv/lib/python3.10/site-packages/nornir/core/task.py", line 174, in run
    raise NornirSubTaskError(task=run_task, result=r)
nornir.core.exceptions.NornirSubTaskError: Subtask: send_configs_from_file (failed)


2023-02-11 05:30:56,293 - nornir.core.task -    ERROR -      start() - Host 'R2': task 'send_configs_from_file' failed with traceback:
Traceback (most recent call last):
  File "/home/ipvzero/Netbox-Demo/.venv/lib/python3.10/site-packages/nornir/core/task.py", line 99, in start
    r = self.task(self, **self.params)
  File "/home/ipvzero/Netbox-Demo/.venv/lib/python3.10/site-packages/nornir_scrapli/tasks/core/send_configs_from_file.py", line 58, in send_configs_from_file
    scrapli_conn = task.host.get_connection("scrapli", task.nornir.config)
  File "/home/ipvzero/Netbox-Demo/.venv/lib/python3.10/site-packages/nornir/core/inventory.py", line 494, in get_connection
    self.open_connection(
  File "/home/ipvzero/Netbox-Demo/.venv/lib/python3.10/site-packages/nornir/core/inventory.py", line 546, in open_connection
    conn_obj.open(
  File "/home/ipvzero/Netbox-Demo/.venv/lib/python3.10/site-packages/nornir_scrapli/connection.py", line 88, in open
    raise NornirScrapliInvalidPlatform(
nornir_scrapli.exceptions.NornirScrapliInvalidPlatform: 'platform' not provided in inventory for host `192.168.179.131`

2023-02-11 05:30:56,293 - nornir.core.task -    ERROR -      start() - Host 'R2': task 'random_configs' failed with traceback:
Traceback (most recent call last):
  File "/home/ipvzero/Netbox-Demo/.venv/lib/python3.10/site-packages/nornir/core/task.py", line 99, in start
    r = self.task(self, **self.params)
  File "/home/ipvzero/Nornir/Progress_Bars/runbook1-progress_bar-send_config.py", line 13, in random_configs
    task.run(task=send_configs_from_file, file="conf.txt")
  File "/home/ipvzero/Netbox-Demo/.venv/lib/python3.10/site-packages/nornir/core/task.py", line 174, in run
    raise NornirSubTaskError(task=run_task, result=r)
nornir.core.exceptions.NornirSubTaskError: Subtask: send_configs_from_file (failed)


2023-02-11 05:30:56,294 - nornir.core.task -    ERROR -      start() - Host 'R3': task 'send_configs_from_file' failed with traceback:
Traceback (most recent call last):
  File "/home/ipvzero/Netbox-Demo/.venv/lib/python3.10/site-packages/nornir/core/task.py", line 99, in start
    r = self.task(self, **self.params)
  File "/home/ipvzero/Netbox-Demo/.venv/lib/python3.10/site-packages/nornir_scrapli/tasks/core/send_configs_from_file.py", line 58, in send_configs_from_file
    scrapli_conn = task.host.get_connection("scrapli", task.nornir.config)
  File "/home/ipvzero/Netbox-Demo/.venv/lib/python3.10/site-packages/nornir/core/inventory.py", line 494, in get_connection
    self.open_connection(
  File "/home/ipvzero/Netbox-Demo/.venv/lib/python3.10/site-packages/nornir/core/inventory.py", line 546, in open_connection
    conn_obj.open(
  File "/home/ipvzero/Netbox-Demo/.venv/lib/python3.10/site-packages/nornir_scrapli/connection.py", line 88, in open
    raise NornirScrapliInvalidPlatform(
nornir_scrapli.exceptions.NornirScrapliInvalidPlatform: 'platform' not provided in inventory for host `192.168.179.132`

2023-02-11 05:30:56,294 - nornir.core.task -    ERROR -      start() - Host 'R3': task 'random_configs' failed with traceback:
Traceback (most recent call last):
  File "/home/ipvzero/Netbox-Demo/.venv/lib/python3.10/site-packages/nornir/core/task.py", line 99, in start
    r = self.task(self, **self.params)
  File "/home/ipvzero/Nornir/Progress_Bars/runbook1-progress_bar-send_config.py", line 13, in random_configs
    task.run(task=send_configs_from_file, file="conf.txt")
  File "/home/ipvzero/Netbox-Demo/.venv/lib/python3.10/site-packages/nornir/core/task.py", line 174, in run
    raise NornirSubTaskError(task=run_task, result=r)
nornir.core.exceptions.NornirSubTaskError: Subtask: send_configs_from_file (failed)


2023-02-11 05:30:56,294 - nornir.core.task -    ERROR -      start() - Host 'R4': task 'send_configs_from_file' failed with traceback:
Traceback (most recent call last):
  File "/home/ipvzero/Netbox-Demo/.venv/lib/python3.10/site-packages/nornir/core/task.py", line 99, in start
    r = self.task(self, **self.params)
  File "/home/ipvzero/Netbox-Demo/.venv/lib/python3.10/site-packages/nornir_scrapli/tasks/core/send_configs_from_file.py", line 58, in send_configs_from_file
    scrapli_conn = task.host.get_connection("scrapli", task.nornir.config)
  File "/home/ipvzero/Netbox-Demo/.venv/lib/python3.10/site-packages/nornir/core/inventory.py", line 494, in get_connection
    self.open_connection(
  File "/home/ipvzero/Netbox-Demo/.venv/lib/python3.10/site-packages/nornir/core/inventory.py", line 546, in open_connection
    conn_obj.open(
  File "/home/ipvzero/Netbox-Demo/.venv/lib/python3.10/site-packages/nornir_scrapli/connection.py", line 88, in open
    raise NornirScrapliInvalidPlatform(
nornir_scrapli.exceptions.NornirScrapliInvalidPlatform: 'platform' not provided in inventory for host `192.168.179.133`

2023-02-11 05:30:56,294 - nornir.core.task -    ERROR -      start() - Host 'R4': task 'random_configs' failed with traceback:
Traceback (most recent call last):
  File "/home/ipvzero/Netbox-Demo/.venv/lib/python3.10/site-packages/nornir/core/task.py", line 99, in start
    r = self.task(self, **self.params)
  File "/home/ipvzero/Nornir/Progress_Bars/runbook1-progress_bar-send_config.py", line 13, in random_configs
    task.run(task=send_configs_from_file, file="conf.txt")
  File "/home/ipvzero/Netbox-Demo/.venv/lib/python3.10/site-packages/nornir/core/task.py", line 174, in run
    raise NornirSubTaskError(task=run_task, result=r)
nornir.core.exceptions.NornirSubTaskError: Subtask: send_configs_from_file (failed)


2023-02-11 05:30:56,294 - nornir.core.task -    ERROR -      start() - Host 'R5': task 'send_configs_from_file' failed with traceback:
Traceback (most recent call last):
  File "/home/ipvzero/Netbox-Demo/.venv/lib/python3.10/site-packages/nornir/core/task.py", line 99, in start
    r = self.task(self, **self.params)
  File "/home/ipvzero/Netbox-Demo/.venv/lib/python3.10/site-packages/nornir_scrapli/tasks/core/send_configs_from_file.py", line 58, in send_configs_from_file
    scrapli_conn = task.host.get_connection("scrapli", task.nornir.config)
  File "/home/ipvzero/Netbox-Demo/.venv/lib/python3.10/site-packages/nornir/core/inventory.py", line 494, in get_connection
    self.open_connection(
  File "/home/ipvzero/Netbox-Demo/.venv/lib/python3.10/site-packages/nornir/core/inventory.py", line 546, in open_connection
    conn_obj.open(
  File "/home/ipvzero/Netbox-Demo/.venv/lib/python3.10/site-packages/nornir_scrapli/connection.py", line 88, in open
    raise NornirScrapliInvalidPlatform(
nornir_scrapli.exceptions.NornirScrapliInvalidPlatform: 'platform' not provided in inventory for host `192.168.179.134`

2023-02-11 05:30:56,295 - nornir.core.task -    ERROR -      start() - Host 'R5': task 'random_configs' failed with traceback:
Traceback (most recent call last):
  File "/home/ipvzero/Netbox-Demo/.venv/lib/python3.10/site-packages/nornir/core/task.py", line 99, in start
    r = self.task(self, **self.params)
  File "/home/ipvzero/Nornir/Progress_Bars/runbook1-progress_bar-send_config.py", line 13, in random_configs
    task.run(task=send_configs_from_file, file="conf.txt")
  File "/home/ipvzero/Netbox-Demo/.venv/lib/python3.10/site-packages/nornir/core/task.py", line 174, in run
    raise NornirSubTaskError(task=run_task, result=r)
nornir.core.exceptions.NornirSubTaskError: Subtask: send_configs_from_file (failed)


2023-02-11 05:30:56,295 - nornir.core.task -    ERROR -      start() - Host 'R6': task 'send_configs_from_file' failed with traceback:
Traceback (most recent call last):
  File "/home/ipvzero/Netbox-Demo/.venv/lib/python3.10/site-packages/nornir/core/task.py", line 99, in start
    r = self.task(self, **self.params)
  File "/home/ipvzero/Netbox-Demo/.venv/lib/python3.10/site-packages/nornir_scrapli/tasks/core/send_configs_from_file.py", line 58, in send_configs_from_file
    scrapli_conn = task.host.get_connection("scrapli", task.nornir.config)
  File "/home/ipvzero/Netbox-Demo/.venv/lib/python3.10/site-packages/nornir/core/inventory.py", line 494, in get_connection
    self.open_connection(
  File "/home/ipvzero/Netbox-Demo/.venv/lib/python3.10/site-packages/nornir/core/inventory.py", line 546, in open_connection
    conn_obj.open(
  File "/home/ipvzero/Netbox-Demo/.venv/lib/python3.10/site-packages/nornir_scrapli/connection.py", line 88, in open
    raise NornirScrapliInvalidPlatform(
nornir_scrapli.exceptions.NornirScrapliInvalidPlatform: 'platform' not provided in inventory for host `192.168.179.135`

2023-02-11 05:30:56,295 - nornir.core.task -    ERROR -      start() - Host 'R6': task 'random_configs' failed with traceback:
Traceback (most recent call last):
  File "/home/ipvzero/Netbox-Demo/.venv/lib/python3.10/site-packages/nornir/core/task.py", line 99, in start
    r = self.task(self, **self.params)
  File "/home/ipvzero/Nornir/Progress_Bars/runbook1-progress_bar-send_config.py", line 13, in random_configs
    task.run(task=send_configs_from_file, file="conf.txt")
  File "/home/ipvzero/Netbox-Demo/.venv/lib/python3.10/site-packages/nornir/core/task.py", line 174, in run
    raise NornirSubTaskError(task=run_task, result=r)
nornir.core.exceptions.NornirSubTaskError: Subtask: send_configs_from_file (failed)


2023-02-11 05:31:00,821 - nornir.core.task -    ERROR -      start() - Host 'R7': task 'send_configs_from_file' failed with traceback:
Traceback (most recent call last):
  File "/home/ipvzero/Netbox-Demo/.venv/lib/python3.10/site-packages/nornir/core/task.py", line 99, in start
    r = self.task(self, **self.params)
  File "/home/ipvzero/Netbox-Demo/.venv/lib/python3.10/site-packages/nornir_scrapli/tasks/core/send_configs_from_file.py", line 58, in send_configs_from_file
    scrapli_conn = task.host.get_connection("scrapli", task.nornir.config)
  File "/home/ipvzero/Netbox-Demo/.venv/lib/python3.10/site-packages/nornir/core/inventory.py", line 494, in get_connection
    self.open_connection(
  File "/home/ipvzero/Netbox-Demo/.venv/lib/python3.10/site-packages/nornir/core/inventory.py", line 546, in open_connection
    conn_obj.open(
  File "/home/ipvzero/Netbox-Demo/.venv/lib/python3.10/site-packages/nornir_scrapli/connection.py", line 105, in open
    connection.open()
  File "/home/ipvzero/Netbox-Demo/.venv/lib/python3.10/site-packages/scrapli/driver/base/sync_driver.py", line 88, in open
    self.channel.channel_authenticate_ssh(
  File "/home/ipvzero/Netbox-Demo/.venv/lib/python3.10/site-packages/scrapli/decorators.py", line 216, in decorate
    return _multiprocessing_timeout(
  File "/home/ipvzero/Netbox-Demo/.venv/lib/python3.10/site-packages/scrapli/decorators.py", line 113, in _multiprocessing_timeout
    return future.result()
  File "/usr/lib/python3.10/concurrent/futures/_base.py", line 451, in result
    return self.__get_result()
  File "/usr/lib/python3.10/concurrent/futures/_base.py", line 403, in __get_result
    raise self._exception
  File "/usr/lib/python3.10/concurrent/futures/thread.py", line 58, in run
    result = self.fn(*self.args, **self.kwargs)
  File "/home/ipvzero/Netbox-Demo/.venv/lib/python3.10/site-packages/scrapli/channel/sync_channel.py", line 300, in channel_authenticate_ssh
    raise ScrapliAuthenticationFailed(msg)
scrapli.exceptions.ScrapliAuthenticationFailed: password prompt seen more than once, assuming auth failed

2023-02-11 05:31:00,821 - nornir.core.task -    ERROR -      start() - Host 'R7': task 'random_configs' failed with traceback:
Traceback (most recent call last):
  File "/home/ipvzero/Netbox-Demo/.venv/lib/python3.10/site-packages/nornir/core/task.py", line 99, in start
    r = self.task(self, **self.params)
  File "/home/ipvzero/Nornir/Progress_Bars/runbook1-progress_bar-send_config.py", line 13, in random_configs
    task.run(task=send_configs_from_file, file="conf.txt")
  File "/home/ipvzero/Netbox-Demo/.venv/lib/python3.10/site-packages/nornir/core/task.py", line 174, in run
    raise NornirSubTaskError(task=run_task, result=r)
nornir.core.exceptions.NornirSubTaskError: Subtask: send_configs_from_file (failed)


2023-02-11 05:36:11,507 -  nornir.core -     INFO -        run() - Running task 'random_configs' with args {'progress_bar': <tqdm.std.tqdm object at 0x7fa89607fcd0>} on 7 hosts
2023-02-11 05:36:11,510 - nornir.core.task -    ERROR -      start() - Host 'R1': task 'send_configs_from_file' failed with traceback:
Traceback (most recent call last):
  File "/home/ipvzero/Netbox-Demo/.venv/lib/python3.10/site-packages/nornir/core/task.py", line 99, in start
    r = self.task(self, **self.params)
  File "/home/ipvzero/Netbox-Demo/.venv/lib/python3.10/site-packages/nornir_scrapli/tasks/core/send_configs_from_file.py", line 58, in send_configs_from_file
    scrapli_conn = task.host.get_connection("scrapli", task.nornir.config)
  File "/home/ipvzero/Netbox-Demo/.venv/lib/python3.10/site-packages/nornir/core/inventory.py", line 494, in get_connection
    self.open_connection(
  File "/home/ipvzero/Netbox-Demo/.venv/lib/python3.10/site-packages/nornir/core/inventory.py", line 546, in open_connection
    conn_obj.open(
  File "/home/ipvzero/Netbox-Demo/.venv/lib/python3.10/site-packages/nornir_scrapli/connection.py", line 88, in open
    raise NornirScrapliInvalidPlatform(
nornir_scrapli.exceptions.NornirScrapliInvalidPlatform: 'platform' not provided in inventory for host `192.168.179.130`

2023-02-11 05:36:11,510 - nornir.core.task -    ERROR -      start() - Host 'R2': task 'send_configs_from_file' failed with traceback:
Traceback (most recent call last):
  File "/home/ipvzero/Netbox-Demo/.venv/lib/python3.10/site-packages/nornir/core/task.py", line 99, in start
    r = self.task(self, **self.params)
  File "/home/ipvzero/Netbox-Demo/.venv/lib/python3.10/site-packages/nornir_scrapli/tasks/core/send_configs_from_file.py", line 58, in send_configs_from_file
    scrapli_conn = task.host.get_connection("scrapli", task.nornir.config)
  File "/home/ipvzero/Netbox-Demo/.venv/lib/python3.10/site-packages/nornir/core/inventory.py", line 494, in get_connection
    self.open_connection(
  File "/home/ipvzero/Netbox-Demo/.venv/lib/python3.10/site-packages/nornir/core/inventory.py", line 546, in open_connection
    conn_obj.open(
  File "/home/ipvzero/Netbox-Demo/.venv/lib/python3.10/site-packages/nornir_scrapli/connection.py", line 88, in open
    raise NornirScrapliInvalidPlatform(
nornir_scrapli.exceptions.NornirScrapliInvalidPlatform: 'platform' not provided in inventory for host `192.168.179.131`

2023-02-11 05:36:11,511 - nornir.core.task -    ERROR -      start() - Host 'R2': task 'random_configs' failed with traceback:
Traceback (most recent call last):
  File "/home/ipvzero/Netbox-Demo/.venv/lib/python3.10/site-packages/nornir/core/task.py", line 99, in start
    r = self.task(self, **self.params)
  File "/home/ipvzero/Nornir/Progress_Bars/runbook1-progress_bar-send_config.py", line 13, in random_configs
    task.run(task=send_configs_from_file, file="conf.txt")
  File "/home/ipvzero/Netbox-Demo/.venv/lib/python3.10/site-packages/nornir/core/task.py", line 174, in run
    raise NornirSubTaskError(task=run_task, result=r)
nornir.core.exceptions.NornirSubTaskError: Subtask: send_configs_from_file (failed)


2023-02-11 05:36:11,511 - nornir.core.task -    ERROR -      start() - Host 'R3': task 'send_configs_from_file' failed with traceback:
Traceback (most recent call last):
  File "/home/ipvzero/Netbox-Demo/.venv/lib/python3.10/site-packages/nornir/core/task.py", line 99, in start
    r = self.task(self, **self.params)
  File "/home/ipvzero/Netbox-Demo/.venv/lib/python3.10/site-packages/nornir_scrapli/tasks/core/send_configs_from_file.py", line 58, in send_configs_from_file
    scrapli_conn = task.host.get_connection("scrapli", task.nornir.config)
  File "/home/ipvzero/Netbox-Demo/.venv/lib/python3.10/site-packages/nornir/core/inventory.py", line 494, in get_connection
    self.open_connection(
  File "/home/ipvzero/Netbox-Demo/.venv/lib/python3.10/site-packages/nornir/core/inventory.py", line 546, in open_connection
    conn_obj.open(
  File "/home/ipvzero/Netbox-Demo/.venv/lib/python3.10/site-packages/nornir_scrapli/connection.py", line 88, in open
    raise NornirScrapliInvalidPlatform(
nornir_scrapli.exceptions.NornirScrapliInvalidPlatform: 'platform' not provided in inventory for host `192.168.179.132`

2023-02-11 05:36:11,512 - nornir.core.task -    ERROR -      start() - Host 'R3': task 'random_configs' failed with traceback:
Traceback (most recent call last):
  File "/home/ipvzero/Netbox-Demo/.venv/lib/python3.10/site-packages/nornir/core/task.py", line 99, in start
    r = self.task(self, **self.params)
  File "/home/ipvzero/Nornir/Progress_Bars/runbook1-progress_bar-send_config.py", line 13, in random_configs
    task.run(task=send_configs_from_file, file="conf.txt")
  File "/home/ipvzero/Netbox-Demo/.venv/lib/python3.10/site-packages/nornir/core/task.py", line 174, in run
    raise NornirSubTaskError(task=run_task, result=r)
nornir.core.exceptions.NornirSubTaskError: Subtask: send_configs_from_file (failed)


2023-02-11 05:36:11,512 - nornir.core.task -    ERROR -      start() - Host 'R1': task 'random_configs' failed with traceback:
Traceback (most recent call last):
  File "/home/ipvzero/Netbox-Demo/.venv/lib/python3.10/site-packages/nornir/core/task.py", line 99, in start
    r = self.task(self, **self.params)
  File "/home/ipvzero/Nornir/Progress_Bars/runbook1-progress_bar-send_config.py", line 13, in random_configs
    task.run(task=send_configs_from_file, file="conf.txt")
  File "/home/ipvzero/Netbox-Demo/.venv/lib/python3.10/site-packages/nornir/core/task.py", line 174, in run
    raise NornirSubTaskError(task=run_task, result=r)
nornir.core.exceptions.NornirSubTaskError: Subtask: send_configs_from_file (failed)


2023-02-11 05:36:11,512 - nornir.core.task -    ERROR -      start() - Host 'R4': task 'send_configs_from_file' failed with traceback:
Traceback (most recent call last):
  File "/home/ipvzero/Netbox-Demo/.venv/lib/python3.10/site-packages/nornir/core/task.py", line 99, in start
    r = self.task(self, **self.params)
  File "/home/ipvzero/Netbox-Demo/.venv/lib/python3.10/site-packages/nornir_scrapli/tasks/core/send_configs_from_file.py", line 58, in send_configs_from_file
    scrapli_conn = task.host.get_connection("scrapli", task.nornir.config)
  File "/home/ipvzero/Netbox-Demo/.venv/lib/python3.10/site-packages/nornir/core/inventory.py", line 494, in get_connection
    self.open_connection(
  File "/home/ipvzero/Netbox-Demo/.venv/lib/python3.10/site-packages/nornir/core/inventory.py", line 546, in open_connection
    conn_obj.open(
  File "/home/ipvzero/Netbox-Demo/.venv/lib/python3.10/site-packages/nornir_scrapli/connection.py", line 88, in open
    raise NornirScrapliInvalidPlatform(
nornir_scrapli.exceptions.NornirScrapliInvalidPlatform: 'platform' not provided in inventory for host `192.168.179.133`

2023-02-11 05:36:11,512 - nornir.core.task -    ERROR -      start() - Host 'R5': task 'send_configs_from_file' failed with traceback:
Traceback (most recent call last):
  File "/home/ipvzero/Netbox-Demo/.venv/lib/python3.10/site-packages/nornir/core/task.py", line 99, in start
    r = self.task(self, **self.params)
  File "/home/ipvzero/Netbox-Demo/.venv/lib/python3.10/site-packages/nornir_scrapli/tasks/core/send_configs_from_file.py", line 58, in send_configs_from_file
    scrapli_conn = task.host.get_connection("scrapli", task.nornir.config)
  File "/home/ipvzero/Netbox-Demo/.venv/lib/python3.10/site-packages/nornir/core/inventory.py", line 494, in get_connection
    self.open_connection(
  File "/home/ipvzero/Netbox-Demo/.venv/lib/python3.10/site-packages/nornir/core/inventory.py", line 546, in open_connection
    conn_obj.open(
  File "/home/ipvzero/Netbox-Demo/.venv/lib/python3.10/site-packages/nornir_scrapli/connection.py", line 88, in open
    raise NornirScrapliInvalidPlatform(
nornir_scrapli.exceptions.NornirScrapliInvalidPlatform: 'platform' not provided in inventory for host `192.168.179.134`

2023-02-11 05:36:11,513 - nornir.core.task -    ERROR -      start() - Host 'R5': task 'random_configs' failed with traceback:
Traceback (most recent call last):
  File "/home/ipvzero/Netbox-Demo/.venv/lib/python3.10/site-packages/nornir/core/task.py", line 99, in start
    r = self.task(self, **self.params)
  File "/home/ipvzero/Nornir/Progress_Bars/runbook1-progress_bar-send_config.py", line 13, in random_configs
    task.run(task=send_configs_from_file, file="conf.txt")
  File "/home/ipvzero/Netbox-Demo/.venv/lib/python3.10/site-packages/nornir/core/task.py", line 174, in run
    raise NornirSubTaskError(task=run_task, result=r)
nornir.core.exceptions.NornirSubTaskError: Subtask: send_configs_from_file (failed)


2023-02-11 05:36:11,513 - nornir.core.task -    ERROR -      start() - Host 'R4': task 'random_configs' failed with traceback:
Traceback (most recent call last):
  File "/home/ipvzero/Netbox-Demo/.venv/lib/python3.10/site-packages/nornir/core/task.py", line 99, in start
    r = self.task(self, **self.params)
  File "/home/ipvzero/Nornir/Progress_Bars/runbook1-progress_bar-send_config.py", line 13, in random_configs
    task.run(task=send_configs_from_file, file="conf.txt")
  File "/home/ipvzero/Netbox-Demo/.venv/lib/python3.10/site-packages/nornir/core/task.py", line 174, in run
    raise NornirSubTaskError(task=run_task, result=r)
nornir.core.exceptions.NornirSubTaskError: Subtask: send_configs_from_file (failed)


2023-02-11 05:36:11,514 - nornir.core.task -    ERROR -      start() - Host 'R6': task 'send_configs_from_file' failed with traceback:
Traceback (most recent call last):
  File "/home/ipvzero/Netbox-Demo/.venv/lib/python3.10/site-packages/nornir/core/task.py", line 99, in start
    r = self.task(self, **self.params)
  File "/home/ipvzero/Netbox-Demo/.venv/lib/python3.10/site-packages/nornir_scrapli/tasks/core/send_configs_from_file.py", line 58, in send_configs_from_file
    scrapli_conn = task.host.get_connection("scrapli", task.nornir.config)
  File "/home/ipvzero/Netbox-Demo/.venv/lib/python3.10/site-packages/nornir/core/inventory.py", line 494, in get_connection
    self.open_connection(
  File "/home/ipvzero/Netbox-Demo/.venv/lib/python3.10/site-packages/nornir/core/inventory.py", line 546, in open_connection
    conn_obj.open(
  File "/home/ipvzero/Netbox-Demo/.venv/lib/python3.10/site-packages/nornir_scrapli/connection.py", line 88, in open
    raise NornirScrapliInvalidPlatform(
nornir_scrapli.exceptions.NornirScrapliInvalidPlatform: 'platform' not provided in inventory for host `192.168.179.135`

2023-02-11 05:36:11,515 - nornir.core.task -    ERROR -      start() - Host 'R6': task 'random_configs' failed with traceback:
Traceback (most recent call last):
  File "/home/ipvzero/Netbox-Demo/.venv/lib/python3.10/site-packages/nornir/core/task.py", line 99, in start
    r = self.task(self, **self.params)
  File "/home/ipvzero/Nornir/Progress_Bars/runbook1-progress_bar-send_config.py", line 13, in random_configs
    task.run(task=send_configs_from_file, file="conf.txt")
  File "/home/ipvzero/Netbox-Demo/.venv/lib/python3.10/site-packages/nornir/core/task.py", line 174, in run
    raise NornirSubTaskError(task=run_task, result=r)
nornir.core.exceptions.NornirSubTaskError: Subtask: send_configs_from_file (failed)


2023-02-11 05:36:12,283 - nornir.core.task -    ERROR -      start() - Host 'R7': task 'send_configs_from_file' failed with traceback:
Traceback (most recent call last):
  File "/home/ipvzero/Netbox-Demo/.venv/lib/python3.10/site-packages/nornir/core/task.py", line 99, in start
    r = self.task(self, **self.params)
  File "/home/ipvzero/Netbox-Demo/.venv/lib/python3.10/site-packages/nornir_scrapli/tasks/core/send_configs_from_file.py", line 68, in send_configs_from_file
    scrapli_response = scrapli_conn.send_configs_from_file(
  File "/home/ipvzero/Netbox-Demo/.venv/lib/python3.10/site-packages/scrapli/driver/network/sync_driver.py", line 628, in send_configs_from_file
    configs = self._pre_send_from_file(file=file, caller="send_configs_from_file")
  File "/home/ipvzero/Netbox-Demo/.venv/lib/python3.10/site-packages/scrapli/driver/generic/base_driver.py", line 338, in _pre_send_from_file
    resolved_file = resolve_file(file)
  File "/home/ipvzero/Netbox-Demo/.venv/lib/python3.10/site-packages/scrapli/helper.py", line 231, in resolve_file
    raise ScrapliValueError(f"File path `{file}` could not be resolved")
scrapli.exceptions.ScrapliValueError: File path `conf.txt` could not be resolved

2023-02-11 05:36:12,283 - nornir.core.task -    ERROR -      start() - Host 'R7': task 'random_configs' failed with traceback:
Traceback (most recent call last):
  File "/home/ipvzero/Netbox-Demo/.venv/lib/python3.10/site-packages/nornir/core/task.py", line 99, in start
    r = self.task(self, **self.params)
  File "/home/ipvzero/Nornir/Progress_Bars/runbook1-progress_bar-send_config.py", line 13, in random_configs
    task.run(task=send_configs_from_file, file="conf.txt")
  File "/home/ipvzero/Netbox-Demo/.venv/lib/python3.10/site-packages/nornir/core/task.py", line 174, in run
    raise NornirSubTaskError(task=run_task, result=r)
nornir.core.exceptions.NornirSubTaskError: Subtask: send_configs_from_file (failed)


2023-02-11 05:36:47,535 -  nornir.core -     INFO -        run() - Running task 'random_configs' with args {'progress_bar': <tqdm.std.tqdm object at 0x7f07fefdbcd0>} on 7 hosts
2023-02-11 05:36:47,538 - nornir.core.task -    ERROR -      start() - Host 'R1': task 'send_configs_from_file' failed with traceback:
Traceback (most recent call last):
  File "/home/ipvzero/Netbox-Demo/.venv/lib/python3.10/site-packages/nornir/core/task.py", line 99, in start
    r = self.task(self, **self.params)
  File "/home/ipvzero/Netbox-Demo/.venv/lib/python3.10/site-packages/nornir_scrapli/tasks/core/send_configs_from_file.py", line 58, in send_configs_from_file
    scrapli_conn = task.host.get_connection("scrapli", task.nornir.config)
  File "/home/ipvzero/Netbox-Demo/.venv/lib/python3.10/site-packages/nornir/core/inventory.py", line 494, in get_connection
    self.open_connection(
  File "/home/ipvzero/Netbox-Demo/.venv/lib/python3.10/site-packages/nornir/core/inventory.py", line 546, in open_connection
    conn_obj.open(
  File "/home/ipvzero/Netbox-Demo/.venv/lib/python3.10/site-packages/nornir_scrapli/connection.py", line 88, in open
    raise NornirScrapliInvalidPlatform(
nornir_scrapli.exceptions.NornirScrapliInvalidPlatform: 'platform' not provided in inventory for host `192.168.179.130`

2023-02-11 05:36:47,538 - nornir.core.task -    ERROR -      start() - Host 'R1': task 'random_configs' failed with traceback:
Traceback (most recent call last):
  File "/home/ipvzero/Netbox-Demo/.venv/lib/python3.10/site-packages/nornir/core/task.py", line 99, in start
    r = self.task(self, **self.params)
  File "/home/ipvzero/Nornir/Progress_Bars/runbook1-progress_bar-send_config.py", line 13, in random_configs
    task.run(task=send_configs_from_file, file="config.txt")
  File "/home/ipvzero/Netbox-Demo/.venv/lib/python3.10/site-packages/nornir/core/task.py", line 174, in run
    raise NornirSubTaskError(task=run_task, result=r)
nornir.core.exceptions.NornirSubTaskError: Subtask: send_configs_from_file (failed)


2023-02-11 05:36:47,539 - nornir.core.task -    ERROR -      start() - Host 'R2': task 'send_configs_from_file' failed with traceback:
Traceback (most recent call last):
  File "/home/ipvzero/Netbox-Demo/.venv/lib/python3.10/site-packages/nornir/core/task.py", line 99, in start
    r = self.task(self, **self.params)
  File "/home/ipvzero/Netbox-Demo/.venv/lib/python3.10/site-packages/nornir_scrapli/tasks/core/send_configs_from_file.py", line 58, in send_configs_from_file
    scrapli_conn = task.host.get_connection("scrapli", task.nornir.config)
  File "/home/ipvzero/Netbox-Demo/.venv/lib/python3.10/site-packages/nornir/core/inventory.py", line 494, in get_connection
    self.open_connection(
  File "/home/ipvzero/Netbox-Demo/.venv/lib/python3.10/site-packages/nornir/core/inventory.py", line 546, in open_connection
    conn_obj.open(
  File "/home/ipvzero/Netbox-Demo/.venv/lib/python3.10/site-packages/nornir_scrapli/connection.py", line 88, in open
    raise NornirScrapliInvalidPlatform(
nornir_scrapli.exceptions.NornirScrapliInvalidPlatform: 'platform' not provided in inventory for host `192.168.179.131`

2023-02-11 05:36:47,539 - nornir.core.task -    ERROR -      start() - Host 'R2': task 'random_configs' failed with traceback:
Traceback (most recent call last):
  File "/home/ipvzero/Netbox-Demo/.venv/lib/python3.10/site-packages/nornir/core/task.py", line 99, in start
    r = self.task(self, **self.params)
  File "/home/ipvzero/Nornir/Progress_Bars/runbook1-progress_bar-send_config.py", line 13, in random_configs
    task.run(task=send_configs_from_file, file="config.txt")
  File "/home/ipvzero/Netbox-Demo/.venv/lib/python3.10/site-packages/nornir/core/task.py", line 174, in run
    raise NornirSubTaskError(task=run_task, result=r)
nornir.core.exceptions.NornirSubTaskError: Subtask: send_configs_from_file (failed)


2023-02-11 05:36:47,539 - nornir.core.task -    ERROR -      start() - Host 'R3': task 'send_configs_from_file' failed with traceback:
Traceback (most recent call last):
  File "/home/ipvzero/Netbox-Demo/.venv/lib/python3.10/site-packages/nornir/core/task.py", line 99, in start
    r = self.task(self, **self.params)
  File "/home/ipvzero/Netbox-Demo/.venv/lib/python3.10/site-packages/nornir_scrapli/tasks/core/send_configs_from_file.py", line 58, in send_configs_from_file
    scrapli_conn = task.host.get_connection("scrapli", task.nornir.config)
  File "/home/ipvzero/Netbox-Demo/.venv/lib/python3.10/site-packages/nornir/core/inventory.py", line 494, in get_connection
    self.open_connection(
  File "/home/ipvzero/Netbox-Demo/.venv/lib/python3.10/site-packages/nornir/core/inventory.py", line 546, in open_connection
    conn_obj.open(
  File "/home/ipvzero/Netbox-Demo/.venv/lib/python3.10/site-packages/nornir_scrapli/connection.py", line 88, in open
    raise NornirScrapliInvalidPlatform(
nornir_scrapli.exceptions.NornirScrapliInvalidPlatform: 'platform' not provided in inventory for host `192.168.179.132`

2023-02-11 05:36:47,539 - nornir.core.task -    ERROR -      start() - Host 'R3': task 'random_configs' failed with traceback:
Traceback (most recent call last):
  File "/home/ipvzero/Netbox-Demo/.venv/lib/python3.10/site-packages/nornir/core/task.py", line 99, in start
    r = self.task(self, **self.params)
  File "/home/ipvzero/Nornir/Progress_Bars/runbook1-progress_bar-send_config.py", line 13, in random_configs
    task.run(task=send_configs_from_file, file="config.txt")
  File "/home/ipvzero/Netbox-Demo/.venv/lib/python3.10/site-packages/nornir/core/task.py", line 174, in run
    raise NornirSubTaskError(task=run_task, result=r)
nornir.core.exceptions.NornirSubTaskError: Subtask: send_configs_from_file (failed)


2023-02-11 05:36:47,540 - nornir.core.task -    ERROR -      start() - Host 'R4': task 'send_configs_from_file' failed with traceback:
Traceback (most recent call last):
  File "/home/ipvzero/Netbox-Demo/.venv/lib/python3.10/site-packages/nornir/core/task.py", line 99, in start
    r = self.task(self, **self.params)
  File "/home/ipvzero/Netbox-Demo/.venv/lib/python3.10/site-packages/nornir_scrapli/tasks/core/send_configs_from_file.py", line 58, in send_configs_from_file
    scrapli_conn = task.host.get_connection("scrapli", task.nornir.config)
  File "/home/ipvzero/Netbox-Demo/.venv/lib/python3.10/site-packages/nornir/core/inventory.py", line 494, in get_connection
    self.open_connection(
  File "/home/ipvzero/Netbox-Demo/.venv/lib/python3.10/site-packages/nornir/core/inventory.py", line 546, in open_connection
    conn_obj.open(
  File "/home/ipvzero/Netbox-Demo/.venv/lib/python3.10/site-packages/nornir_scrapli/connection.py", line 88, in open
    raise NornirScrapliInvalidPlatform(
nornir_scrapli.exceptions.NornirScrapliInvalidPlatform: 'platform' not provided in inventory for host `192.168.179.133`

2023-02-11 05:36:47,540 - nornir.core.task -    ERROR -      start() - Host 'R4': task 'random_configs' failed with traceback:
Traceback (most recent call last):
  File "/home/ipvzero/Netbox-Demo/.venv/lib/python3.10/site-packages/nornir/core/task.py", line 99, in start
    r = self.task(self, **self.params)
  File "/home/ipvzero/Nornir/Progress_Bars/runbook1-progress_bar-send_config.py", line 13, in random_configs
    task.run(task=send_configs_from_file, file="config.txt")
  File "/home/ipvzero/Netbox-Demo/.venv/lib/python3.10/site-packages/nornir/core/task.py", line 174, in run
    raise NornirSubTaskError(task=run_task, result=r)
nornir.core.exceptions.NornirSubTaskError: Subtask: send_configs_from_file (failed)


2023-02-11 05:36:47,540 - nornir.core.task -    ERROR -      start() - Host 'R5': task 'send_configs_from_file' failed with traceback:
Traceback (most recent call last):
  File "/home/ipvzero/Netbox-Demo/.venv/lib/python3.10/site-packages/nornir/core/task.py", line 99, in start
    r = self.task(self, **self.params)
  File "/home/ipvzero/Netbox-Demo/.venv/lib/python3.10/site-packages/nornir_scrapli/tasks/core/send_configs_from_file.py", line 58, in send_configs_from_file
    scrapli_conn = task.host.get_connection("scrapli", task.nornir.config)
  File "/home/ipvzero/Netbox-Demo/.venv/lib/python3.10/site-packages/nornir/core/inventory.py", line 494, in get_connection
    self.open_connection(
  File "/home/ipvzero/Netbox-Demo/.venv/lib/python3.10/site-packages/nornir/core/inventory.py", line 546, in open_connection
    conn_obj.open(
  File "/home/ipvzero/Netbox-Demo/.venv/lib/python3.10/site-packages/nornir_scrapli/connection.py", line 88, in open
    raise NornirScrapliInvalidPlatform(
nornir_scrapli.exceptions.NornirScrapliInvalidPlatform: 'platform' not provided in inventory for host `192.168.179.134`

2023-02-11 05:36:47,540 - nornir.core.task -    ERROR -      start() - Host 'R5': task 'random_configs' failed with traceback:
Traceback (most recent call last):
  File "/home/ipvzero/Netbox-Demo/.venv/lib/python3.10/site-packages/nornir/core/task.py", line 99, in start
    r = self.task(self, **self.params)
  File "/home/ipvzero/Nornir/Progress_Bars/runbook1-progress_bar-send_config.py", line 13, in random_configs
    task.run(task=send_configs_from_file, file="config.txt")
  File "/home/ipvzero/Netbox-Demo/.venv/lib/python3.10/site-packages/nornir/core/task.py", line 174, in run
    raise NornirSubTaskError(task=run_task, result=r)
nornir.core.exceptions.NornirSubTaskError: Subtask: send_configs_from_file (failed)


2023-02-11 05:36:47,540 - nornir.core.task -    ERROR -      start() - Host 'R6': task 'send_configs_from_file' failed with traceback:
Traceback (most recent call last):
  File "/home/ipvzero/Netbox-Demo/.venv/lib/python3.10/site-packages/nornir/core/task.py", line 99, in start
    r = self.task(self, **self.params)
  File "/home/ipvzero/Netbox-Demo/.venv/lib/python3.10/site-packages/nornir_scrapli/tasks/core/send_configs_from_file.py", line 58, in send_configs_from_file
    scrapli_conn = task.host.get_connection("scrapli", task.nornir.config)
  File "/home/ipvzero/Netbox-Demo/.venv/lib/python3.10/site-packages/nornir/core/inventory.py", line 494, in get_connection
    self.open_connection(
  File "/home/ipvzero/Netbox-Demo/.venv/lib/python3.10/site-packages/nornir/core/inventory.py", line 546, in open_connection
    conn_obj.open(
  File "/home/ipvzero/Netbox-Demo/.venv/lib/python3.10/site-packages/nornir_scrapli/connection.py", line 88, in open
    raise NornirScrapliInvalidPlatform(
nornir_scrapli.exceptions.NornirScrapliInvalidPlatform: 'platform' not provided in inventory for host `192.168.179.135`

2023-02-11 05:36:47,541 - nornir.core.task -    ERROR -      start() - Host 'R6': task 'random_configs' failed with traceback:
Traceback (most recent call last):
  File "/home/ipvzero/Netbox-Demo/.venv/lib/python3.10/site-packages/nornir/core/task.py", line 99, in start
    r = self.task(self, **self.params)
  File "/home/ipvzero/Nornir/Progress_Bars/runbook1-progress_bar-send_config.py", line 13, in random_configs
    task.run(task=send_configs_from_file, file="config.txt")
  File "/home/ipvzero/Netbox-Demo/.venv/lib/python3.10/site-packages/nornir/core/task.py", line 174, in run
    raise NornirSubTaskError(task=run_task, result=r)
nornir.core.exceptions.NornirSubTaskError: Subtask: send_configs_from_file (failed)


2023-02-11 05:37:49,083 -  nornir.core -     INFO -        run() - Running task 'random_configs' with args {'progress_bar': <tqdm.std.tqdm object at 0x7f38319b3cd0>} on 7 hosts
2023-02-11 05:38:23,693 -  nornir.core -     INFO -        run() - Running task 'random_configs' with args {'progress_bar': <tqdm.std.tqdm object at 0x7f53a75bfcd0>} on 7 hosts
